2015-05-05 17:42:22,416 ERROR base 28680 -1360004288 Internal Server Error: /test/
Traceback (most recent call last):
  File "/usr/local/lib/python2.7/dist-packages/django/core/handlers/base.py", line 112, in get_response
    response = wrapped_callback(request, *callback_args, **callback_kwargs)
  File "/usr/local/lib/python2.7/dist-packages/django/views/generic/base.py", line 69, in view
    return self.dispatch(request, *args, **kwargs)
  File "/usr/local/lib/python2.7/dist-packages/django/utils/decorators.py", line 29, in _wrapper
    return bound_func(*args, **kwargs)
  File "/usr/local/lib/python2.7/dist-packages/django/contrib/auth/decorators.py", line 22, in _wrapped_view
    return view_func(request, *args, **kwargs)
  File "/usr/local/lib/python2.7/dist-packages/django/utils/decorators.py", line 25, in bound_func
    return func(self, *args2, **kwargs2)
  File "/home/mikhail/EclipseWorkspace/oncoFinder2/oncoFinder2/core/views.py", line 724, in dispatch
    return super(Test, self).dispatch(request, *args, **kwargs)
  File "/usr/local/lib/python2.7/dist-packages/django/views/generic/base.py", line 87, in dispatch
    return handler(request, *args, **kwargs)
  File "/usr/local/lib/python2.7/dist-packages/django/views/generic/base.py", line 154, in get
    context = self.get_context_data(**kwargs)
  File "/home/mikhail/EclipseWorkspace/oncoFinder2/oncoFinder2/core/views.py", line 941, in get_context_data
    df_my_nodes = read_excel(settings.MEDIA_ROOT+"/nodes/"+p+".xlsx", sheetname="nodes" )
  File "/usr/local/lib/python2.7/dist-packages/pandas/io/excel.py", line 127, in read_excel
    return ExcelFile(io, engine=engine).parse(sheetname=sheetname, **kwds)
  File "/usr/local/lib/python2.7/dist-packages/pandas/io/excel.py", line 164, in __init__
    self.book = xlrd.open_workbook(io)
  File "/usr/local/lib/python2.7/dist-packages/xlrd-0.9.2-py2.7.egg/xlrd/__init__.py", line 394, in open_workbook
    f = open(filename, "rb")
IOError: [Errno 2] No such file or directory: '/home/mikhail/EclipseWorkspace/oncoFinder2/oncoFinder2/oncoFinder2/media/nodes/p38_p_Signaling_Pathway.xlsx'
2015-05-05 17:43:22,982 ERROR base 28680 -1389364416 Internal Server Error: /test/
Traceback (most recent call last):
  File "/usr/local/lib/python2.7/dist-packages/django/core/handlers/base.py", line 112, in get_response
    response = wrapped_callback(request, *callback_args, **callback_kwargs)
  File "/usr/local/lib/python2.7/dist-packages/django/views/generic/base.py", line 69, in view
    return self.dispatch(request, *args, **kwargs)
  File "/usr/local/lib/python2.7/dist-packages/django/utils/decorators.py", line 29, in _wrapper
    return bound_func(*args, **kwargs)
  File "/usr/local/lib/python2.7/dist-packages/django/contrib/auth/decorators.py", line 22, in _wrapped_view
    return view_func(request, *args, **kwargs)
  File "/usr/local/lib/python2.7/dist-packages/django/utils/decorators.py", line 25, in bound_func
    return func(self, *args2, **kwargs2)
  File "/home/mikhail/EclipseWorkspace/oncoFinder2/oncoFinder2/core/views.py", line 724, in dispatch
    return super(Test, self).dispatch(request, *args, **kwargs)
  File "/usr/local/lib/python2.7/dist-packages/django/views/generic/base.py", line 87, in dispatch
    return handler(request, *args, **kwargs)
  File "/usr/local/lib/python2.7/dist-packages/django/views/generic/base.py", line 154, in get
    context = self.get_context_data(**kwargs)
  File "/home/mikhail/EclipseWorkspace/oncoFinder2/oncoFinder2/core/views.py", line 958, in get_context_data
    raise Exception('yoyyo1')
Exception: yoyyo1
2015-05-08 14:18:55,059 ERROR base 8348 -1397761216 Internal Server Error: /calculation-parameters/doc5437/
Traceback (most recent call last):
  File "/usr/local/lib/python2.7/dist-packages/django/core/handlers/base.py", line 112, in get_response
    response = wrapped_callback(request, *callback_args, **callback_kwargs)
  File "/usr/local/lib/python2.7/dist-packages/django/views/generic/base.py", line 69, in view
    return self.dispatch(request, *args, **kwargs)
  File "/usr/local/lib/python2.7/dist-packages/django/utils/decorators.py", line 29, in _wrapper
    return bound_func(*args, **kwargs)
  File "/usr/local/lib/python2.7/dist-packages/django/contrib/auth/decorators.py", line 22, in _wrapped_view
    return view_func(request, *args, **kwargs)
  File "/usr/local/lib/python2.7/dist-packages/django/utils/decorators.py", line 25, in bound_func
    return func(self, *args2, **kwargs2)
  File "/home/mikhail/EclipseWorkspace/oncoFinder2/oncoFinder2/core/views.py", line 47, in dispatch
    return super(CoreSetCalculationParameters, self).dispatch(request, *args, **kwargs)
  File "/usr/local/lib/python2.7/dist-packages/django/views/generic/base.py", line 87, in dispatch
    return handler(request, *args, **kwargs)
  File "/usr/local/lib/python2.7/dist-packages/django/views/generic/edit.py", line 171, in post
    return self.form_valid(form)
  File "/home/mikhail/EclipseWorkspace/oncoFinder2/oncoFinder2/core/views.py", line 351, in form_valid
    index_col='Old Pathway Name')
  File "/usr/local/lib/python2.7/dist-packages/pandas/io/excel.py", line 127, in read_excel
    return ExcelFile(io, engine=engine).parse(sheetname=sheetname, **kwds)
  File "/usr/local/lib/python2.7/dist-packages/pandas/io/excel.py", line 164, in __init__
    self.book = xlrd.open_workbook(io)
  File "/usr/local/lib/python2.7/dist-packages/xlrd-0.9.2-py2.7.egg/xlrd/__init__.py", line 394, in open_workbook
    f = open(filename, "rb")
IOError: [Errno 2] No such file or directory: '/home/mikhail/EclipseWorkspace/oncoFinder2/oncoFinder2/oncoFinder2/media/TRpathways_update_final_updated2.xlsx'
2015-05-08 15:07:50,919 ERROR base 10248 -1356784832 Internal Server Error: /calculation-parameters/doc5437/
Traceback (most recent call last):
  File "/usr/local/lib/python2.7/dist-packages/django/core/handlers/base.py", line 112, in get_response
    response = wrapped_callback(request, *callback_args, **callback_kwargs)
  File "/usr/local/lib/python2.7/dist-packages/django/views/generic/base.py", line 69, in view
    return self.dispatch(request, *args, **kwargs)
  File "/usr/local/lib/python2.7/dist-packages/django/utils/decorators.py", line 29, in _wrapper
    return bound_func(*args, **kwargs)
  File "/usr/local/lib/python2.7/dist-packages/django/contrib/auth/decorators.py", line 22, in _wrapped_view
    return view_func(request, *args, **kwargs)
  File "/usr/local/lib/python2.7/dist-packages/django/utils/decorators.py", line 25, in bound_func
    return func(self, *args2, **kwargs2)
  File "/home/mikhail/EclipseWorkspace/oncoFinder2/oncoFinder2/core/views.py", line 47, in dispatch
    return super(CoreSetCalculationParameters, self).dispatch(request, *args, **kwargs)
  File "/usr/local/lib/python2.7/dist-packages/django/views/generic/base.py", line 87, in dispatch
    return handler(request, *args, **kwargs)
  File "/usr/local/lib/python2.7/dist-packages/django/views/generic/edit.py", line 171, in post
    return self.form_valid(form)
  File "/home/mikhail/EclipseWorkspace/oncoFinder2/oncoFinder2/core/views.py", line 594, in form_valid
    raise Exception('DS')
Exception: DS
