2015-03-30 09:46:35,921 ERROR base 17097 -1251480768 Internal Server Error: /document/new/
Traceback (most recent call last):
  File "/usr/local/lib/python2.7/dist-packages/django/core/handlers/base.py", line 114, in get_response
    response = wrapped_callback(request, *callback_args, **callback_kwargs)
  File "/usr/local/lib/python2.7/dist-packages/django/views/generic/base.py", line 69, in view
    return self.dispatch(request, *args, **kwargs)
  File "/usr/local/lib/python2.7/dist-packages/django/utils/decorators.py", line 29, in _wrapper
    return bound_func(*args, **kwargs)
  File "/usr/local/lib/python2.7/dist-packages/django/contrib/auth/decorators.py", line 22, in _wrapped_view
    return view_func(request, *args, **kwargs)
  File "/usr/local/lib/python2.7/dist-packages/django/utils/decorators.py", line 25, in bound_func
    return func(self, *args2, **kwargs2)
  File "/home/mikhail/EclipseWorkspace/oncoFinder2/oncoFinder2/profiles/views.py", line 170, in dispatch
    return view(request, *args, **kwargs)
  File "/usr/local/lib/python2.7/dist-packages/django/views/generic/base.py", line 69, in view
    return self.dispatch(request, *args, **kwargs)
  File "/usr/local/lib/python2.7/dist-packages/django/utils/decorators.py", line 29, in _wrapper
    return bound_func(*args, **kwargs)
  File "/usr/local/lib/python2.7/dist-packages/django/contrib/auth/decorators.py", line 22, in _wrapped_view
    return view_func(request, *args, **kwargs)
  File "/usr/local/lib/python2.7/dist-packages/django/utils/decorators.py", line 25, in bound_func
    return func(self, *args2, **kwargs2)
  File "/home/mikhail/EclipseWorkspace/oncoFinder2/oncoFinder2/profiles/preprocess_views.py", line 182, in dispatch
    return super(MedicPreprocess, self).dispatch(request, *args, **kwargs)
  File "/usr/local/lib/python2.7/dist-packages/django/views/generic/base.py", line 87, in dispatch
    return handler(request, *args, **kwargs)
  File "/usr/local/lib/python2.7/dist-packages/django/views/generic/edit.py", line 171, in post
    return self.form_valid(form)
  File "/home/mikhail/EclipseWorkspace/oncoFinder2/oncoFinder2/profiles/preprocess_views.py", line 189, in form_valid
    norms_df = read_csv(norms.file_norms)
  File "/usr/local/lib/python2.7/dist-packages/pandas/io/parsers.py", line 463, in parser_f
    return _read(filepath_or_buffer, kwds)
  File "/usr/local/lib/python2.7/dist-packages/pandas/io/parsers.py", line 249, in _read
    return parser.read()
  File "/usr/local/lib/python2.7/dist-packages/pandas/io/parsers.py", line 706, in read
    ret = self._engine.read(nrows)
  File "/usr/local/lib/python2.7/dist-packages/pandas/io/parsers.py", line 1150, in read
    data = self._reader.read(nrows)
  File "pandas/parser.pyx", line 754, in pandas.parser.TextReader.read (pandas/parser.c:7390)
  File "pandas/parser.pyx", line 776, in pandas.parser.TextReader._read_low_memory (pandas/parser.c:7630)
  File "pandas/parser.pyx", line 829, in pandas.parser.TextReader._read_rows (pandas/parser.c:8252)
  File "pandas/parser.pyx", line 816, in pandas.parser.TextReader._tokenize_rows (pandas/parser.c:8126)
  File "pandas/parser.pyx", line 1728, in pandas.parser.raise_parser_error (pandas/parser.c:20384)
CParserError: Error tokenizing data. C error: Expected 1 fields in line 6002, saw 26

2015-03-30 09:47:20,310 ERROR base 18385 -1251480768 Internal Server Error: /document/new/
Traceback (most recent call last):
  File "/usr/local/lib/python2.7/dist-packages/django/core/handlers/base.py", line 114, in get_response
    response = wrapped_callback(request, *callback_args, **callback_kwargs)
  File "/usr/local/lib/python2.7/dist-packages/django/views/generic/base.py", line 69, in view
    return self.dispatch(request, *args, **kwargs)
  File "/usr/local/lib/python2.7/dist-packages/django/utils/decorators.py", line 29, in _wrapper
    return bound_func(*args, **kwargs)
  File "/usr/local/lib/python2.7/dist-packages/django/contrib/auth/decorators.py", line 22, in _wrapped_view
    return view_func(request, *args, **kwargs)
  File "/usr/local/lib/python2.7/dist-packages/django/utils/decorators.py", line 25, in bound_func
    return func(self, *args2, **kwargs2)
  File "/home/mikhail/EclipseWorkspace/oncoFinder2/oncoFinder2/profiles/views.py", line 170, in dispatch
    return view(request, *args, **kwargs)
  File "/usr/local/lib/python2.7/dist-packages/django/views/generic/base.py", line 69, in view
    return self.dispatch(request, *args, **kwargs)
  File "/usr/local/lib/python2.7/dist-packages/django/utils/decorators.py", line 29, in _wrapper
    return bound_func(*args, **kwargs)
  File "/usr/local/lib/python2.7/dist-packages/django/contrib/auth/decorators.py", line 22, in _wrapped_view
    return view_func(request, *args, **kwargs)
  File "/usr/local/lib/python2.7/dist-packages/django/utils/decorators.py", line 25, in bound_func
    return func(self, *args2, **kwargs2)
  File "/home/mikhail/EclipseWorkspace/oncoFinder2/oncoFinder2/profiles/preprocess_views.py", line 182, in dispatch
    return super(MedicPreprocess, self).dispatch(request, *args, **kwargs)
  File "/usr/local/lib/python2.7/dist-packages/django/views/generic/base.py", line 87, in dispatch
    return handler(request, *args, **kwargs)
  File "/usr/local/lib/python2.7/dist-packages/django/views/generic/edit.py", line 171, in post
    return self.form_valid(form)
  File "/home/mikhail/EclipseWorkspace/oncoFinder2/oncoFinder2/profiles/preprocess_views.py", line 190, in form_valid
    norms_df = read_csv(norms.file_norms)
  File "/usr/local/lib/python2.7/dist-packages/pandas/io/parsers.py", line 463, in parser_f
    return _read(filepath_or_buffer, kwds)
  File "/usr/local/lib/python2.7/dist-packages/pandas/io/parsers.py", line 249, in _read
    return parser.read()
  File "/usr/local/lib/python2.7/dist-packages/pandas/io/parsers.py", line 706, in read
    ret = self._engine.read(nrows)
  File "/usr/local/lib/python2.7/dist-packages/pandas/io/parsers.py", line 1150, in read
    data = self._reader.read(nrows)
  File "pandas/parser.pyx", line 754, in pandas.parser.TextReader.read (pandas/parser.c:7390)
  File "pandas/parser.pyx", line 776, in pandas.parser.TextReader._read_low_memory (pandas/parser.c:7630)
  File "pandas/parser.pyx", line 829, in pandas.parser.TextReader._read_rows (pandas/parser.c:8252)
  File "pandas/parser.pyx", line 816, in pandas.parser.TextReader._tokenize_rows (pandas/parser.c:8126)
  File "pandas/parser.pyx", line 1728, in pandas.parser.raise_parser_error (pandas/parser.c:20384)
CParserError: Error tokenizing data. C error: Expected 1 fields in line 6002, saw 26

2015-03-30 09:49:32,960 ERROR base 18385 -1355187392 Internal Server Error: /document/new/
Traceback (most recent call last):
  File "/usr/local/lib/python2.7/dist-packages/django/core/handlers/base.py", line 114, in get_response
    response = wrapped_callback(request, *callback_args, **callback_kwargs)
  File "/usr/local/lib/python2.7/dist-packages/django/views/generic/base.py", line 69, in view
    return self.dispatch(request, *args, **kwargs)
  File "/usr/local/lib/python2.7/dist-packages/django/utils/decorators.py", line 29, in _wrapper
    return bound_func(*args, **kwargs)
  File "/usr/local/lib/python2.7/dist-packages/django/contrib/auth/decorators.py", line 22, in _wrapped_view
    return view_func(request, *args, **kwargs)
  File "/usr/local/lib/python2.7/dist-packages/django/utils/decorators.py", line 25, in bound_func
    return func(self, *args2, **kwargs2)
  File "/home/mikhail/EclipseWorkspace/oncoFinder2/oncoFinder2/profiles/views.py", line 170, in dispatch
    return view(request, *args, **kwargs)
  File "/usr/local/lib/python2.7/dist-packages/django/views/generic/base.py", line 69, in view
    return self.dispatch(request, *args, **kwargs)
  File "/usr/local/lib/python2.7/dist-packages/django/utils/decorators.py", line 29, in _wrapper
    return bound_func(*args, **kwargs)
  File "/usr/local/lib/python2.7/dist-packages/django/contrib/auth/decorators.py", line 22, in _wrapped_view
    return view_func(request, *args, **kwargs)
  File "/usr/local/lib/python2.7/dist-packages/django/utils/decorators.py", line 25, in bound_func
    return func(self, *args2, **kwargs2)
  File "/home/mikhail/EclipseWorkspace/oncoFinder2/oncoFinder2/profiles/preprocess_views.py", line 182, in dispatch
    return super(MedicPreprocess, self).dispatch(request, *args, **kwargs)
  File "/usr/local/lib/python2.7/dist-packages/django/views/generic/base.py", line 87, in dispatch
    return handler(request, *args, **kwargs)
  File "/usr/local/lib/python2.7/dist-packages/django/views/generic/edit.py", line 171, in post
    return self.form_valid(form)
  File "/home/mikhail/EclipseWorkspace/oncoFinder2/oncoFinder2/profiles/preprocess_views.py", line 213, in form_valid
    raise Exception("prepro view")
Exception: prepro view
2015-03-30 09:50:50,061 ERROR base 19476 -1250485440 Internal Server Error: /document/new/
Traceback (most recent call last):
  File "/usr/local/lib/python2.7/dist-packages/django/core/handlers/base.py", line 114, in get_response
    response = wrapped_callback(request, *callback_args, **callback_kwargs)
  File "/usr/local/lib/python2.7/dist-packages/django/views/generic/base.py", line 69, in view
    return self.dispatch(request, *args, **kwargs)
  File "/usr/local/lib/python2.7/dist-packages/django/utils/decorators.py", line 29, in _wrapper
    return bound_func(*args, **kwargs)
  File "/usr/local/lib/python2.7/dist-packages/django/contrib/auth/decorators.py", line 22, in _wrapped_view
    return view_func(request, *args, **kwargs)
  File "/usr/local/lib/python2.7/dist-packages/django/utils/decorators.py", line 25, in bound_func
    return func(self, *args2, **kwargs2)
  File "/home/mikhail/EclipseWorkspace/oncoFinder2/oncoFinder2/profiles/views.py", line 170, in dispatch
    return view(request, *args, **kwargs)
  File "/usr/local/lib/python2.7/dist-packages/django/views/generic/base.py", line 69, in view
    return self.dispatch(request, *args, **kwargs)
  File "/usr/local/lib/python2.7/dist-packages/django/utils/decorators.py", line 29, in _wrapper
    return bound_func(*args, **kwargs)
  File "/usr/local/lib/python2.7/dist-packages/django/contrib/auth/decorators.py", line 22, in _wrapped_view
    return view_func(request, *args, **kwargs)
  File "/usr/local/lib/python2.7/dist-packages/django/utils/decorators.py", line 25, in bound_func
    return func(self, *args2, **kwargs2)
  File "/home/mikhail/EclipseWorkspace/oncoFinder2/oncoFinder2/profiles/preprocess_views.py", line 182, in dispatch
    return super(MedicPreprocess, self).dispatch(request, *args, **kwargs)
  File "/usr/local/lib/python2.7/dist-packages/django/views/generic/base.py", line 87, in dispatch
    return handler(request, *args, **kwargs)
  File "/usr/local/lib/python2.7/dist-packages/django/views/generic/edit.py", line 171, in post
    return self.form_valid(form)
  File "/home/mikhail/EclipseWorkspace/oncoFinder2/oncoFinder2/profiles/preprocess_views.py", line 191, in form_valid
    norms_df = read_csv(norms.file_norms, delimiter=dialect.delimiter)
  File "/usr/local/lib/python2.7/dist-packages/pandas/io/parsers.py", line 463, in parser_f
    return _read(filepath_or_buffer, kwds)
  File "/usr/local/lib/python2.7/dist-packages/pandas/io/parsers.py", line 239, in _read
    parser = TextFileReader(filepath_or_buffer, **kwds)
  File "/usr/local/lib/python2.7/dist-packages/pandas/io/parsers.py", line 553, in __init__
    self._make_engine(self.engine)
  File "/usr/local/lib/python2.7/dist-packages/pandas/io/parsers.py", line 690, in _make_engine
    self._engine = CParserWrapper(self.f, **self.options)
  File "/usr/local/lib/python2.7/dist-packages/pandas/io/parsers.py", line 1052, in __init__
    self._reader = _parser.TextReader(src, **kwds)
  File "pandas/parser.pyx", line 508, in pandas.parser.TextReader.__cinit__ (pandas/parser.c:4770)
ValueError: No columns to parse from file
2015-03-30 09:52:00,169 ERROR base 19476 -1354138816 Internal Server Error: /document/new/
Traceback (most recent call last):
  File "/usr/local/lib/python2.7/dist-packages/django/core/handlers/base.py", line 114, in get_response
    response = wrapped_callback(request, *callback_args, **callback_kwargs)
  File "/usr/local/lib/python2.7/dist-packages/django/views/generic/base.py", line 69, in view
    return self.dispatch(request, *args, **kwargs)
  File "/usr/local/lib/python2.7/dist-packages/django/utils/decorators.py", line 29, in _wrapper
    return bound_func(*args, **kwargs)
  File "/usr/local/lib/python2.7/dist-packages/django/contrib/auth/decorators.py", line 22, in _wrapped_view
    return view_func(request, *args, **kwargs)
  File "/usr/local/lib/python2.7/dist-packages/django/utils/decorators.py", line 25, in bound_func
    return func(self, *args2, **kwargs2)
  File "/home/mikhail/EclipseWorkspace/oncoFinder2/oncoFinder2/profiles/views.py", line 170, in dispatch
    return view(request, *args, **kwargs)
  File "/usr/local/lib/python2.7/dist-packages/django/views/generic/base.py", line 69, in view
    return self.dispatch(request, *args, **kwargs)
  File "/usr/local/lib/python2.7/dist-packages/django/utils/decorators.py", line 29, in _wrapper
    return bound_func(*args, **kwargs)
  File "/usr/local/lib/python2.7/dist-packages/django/contrib/auth/decorators.py", line 22, in _wrapped_view
    return view_func(request, *args, **kwargs)
  File "/usr/local/lib/python2.7/dist-packages/django/utils/decorators.py", line 25, in bound_func
    return func(self, *args2, **kwargs2)
  File "/home/mikhail/EclipseWorkspace/oncoFinder2/oncoFinder2/profiles/preprocess_views.py", line 182, in dispatch
    return super(MedicPreprocess, self).dispatch(request, *args, **kwargs)
  File "/usr/local/lib/python2.7/dist-packages/django/views/generic/base.py", line 87, in dispatch
    return handler(request, *args, **kwargs)
  File "/usr/local/lib/python2.7/dist-packages/django/views/generic/edit.py", line 171, in post
    return self.form_valid(form)
  File "/home/mikhail/EclipseWorkspace/oncoFinder2/oncoFinder2/profiles/preprocess_views.py", line 191, in form_valid
    norms_df = read_csv(norms.file_norms, delimiter=dialect.delimiter)
  File "/usr/local/lib/python2.7/dist-packages/pandas/io/parsers.py", line 463, in parser_f
    return _read(filepath_or_buffer, kwds)
  File "/usr/local/lib/python2.7/dist-packages/pandas/io/parsers.py", line 239, in _read
    parser = TextFileReader(filepath_or_buffer, **kwds)
  File "/usr/local/lib/python2.7/dist-packages/pandas/io/parsers.py", line 553, in __init__
    self._make_engine(self.engine)
  File "/usr/local/lib/python2.7/dist-packages/pandas/io/parsers.py", line 690, in _make_engine
    self._engine = CParserWrapper(self.f, **self.options)
  File "/usr/local/lib/python2.7/dist-packages/pandas/io/parsers.py", line 1052, in __init__
    self._reader = _parser.TextReader(src, **kwds)
  File "pandas/parser.pyx", line 508, in pandas.parser.TextReader.__cinit__ (pandas/parser.c:4770)
ValueError: No columns to parse from file
2015-03-30 09:52:13,873 ERROR base 20304 -1251480768 Internal Server Error: /document/new/
Traceback (most recent call last):
  File "/usr/local/lib/python2.7/dist-packages/django/core/handlers/base.py", line 114, in get_response
    response = wrapped_callback(request, *callback_args, **callback_kwargs)
  File "/usr/local/lib/python2.7/dist-packages/django/views/generic/base.py", line 69, in view
    return self.dispatch(request, *args, **kwargs)
  File "/usr/local/lib/python2.7/dist-packages/django/utils/decorators.py", line 29, in _wrapper
    return bound_func(*args, **kwargs)
  File "/usr/local/lib/python2.7/dist-packages/django/contrib/auth/decorators.py", line 22, in _wrapped_view
    return view_func(request, *args, **kwargs)
  File "/usr/local/lib/python2.7/dist-packages/django/utils/decorators.py", line 25, in bound_func
    return func(self, *args2, **kwargs2)
  File "/home/mikhail/EclipseWorkspace/oncoFinder2/oncoFinder2/profiles/views.py", line 170, in dispatch
    return view(request, *args, **kwargs)
  File "/usr/local/lib/python2.7/dist-packages/django/views/generic/base.py", line 69, in view
    return self.dispatch(request, *args, **kwargs)
  File "/usr/local/lib/python2.7/dist-packages/django/utils/decorators.py", line 29, in _wrapper
    return bound_func(*args, **kwargs)
  File "/usr/local/lib/python2.7/dist-packages/django/contrib/auth/decorators.py", line 22, in _wrapped_view
    return view_func(request, *args, **kwargs)
  File "/usr/local/lib/python2.7/dist-packages/django/utils/decorators.py", line 25, in bound_func
    return func(self, *args2, **kwargs2)
  File "/home/mikhail/EclipseWorkspace/oncoFinder2/oncoFinder2/profiles/preprocess_views.py", line 182, in dispatch
    return super(MedicPreprocess, self).dispatch(request, *args, **kwargs)
  File "/usr/local/lib/python2.7/dist-packages/django/views/generic/base.py", line 87, in dispatch
    return handler(request, *args, **kwargs)
  File "/usr/local/lib/python2.7/dist-packages/django/views/generic/edit.py", line 171, in post
    return self.form_valid(form)
  File "/home/mikhail/EclipseWorkspace/oncoFinder2/oncoFinder2/profiles/preprocess_views.py", line 191, in form_valid
    norms_df = read_csv(norms.file_norms)
  File "/usr/local/lib/python2.7/dist-packages/pandas/io/parsers.py", line 463, in parser_f
    return _read(filepath_or_buffer, kwds)
  File "/usr/local/lib/python2.7/dist-packages/pandas/io/parsers.py", line 239, in _read
    parser = TextFileReader(filepath_or_buffer, **kwds)
  File "/usr/local/lib/python2.7/dist-packages/pandas/io/parsers.py", line 553, in __init__
    self._make_engine(self.engine)
  File "/usr/local/lib/python2.7/dist-packages/pandas/io/parsers.py", line 690, in _make_engine
    self._engine = CParserWrapper(self.f, **self.options)
  File "/usr/local/lib/python2.7/dist-packages/pandas/io/parsers.py", line 1052, in __init__
    self._reader = _parser.TextReader(src, **kwds)
  File "pandas/parser.pyx", line 508, in pandas.parser.TextReader.__cinit__ (pandas/parser.c:4770)
ValueError: No columns to parse from file
2015-03-30 09:52:48,035 ERROR base 20389 -1250432192 Internal Server Error: /document/new/
Traceback (most recent call last):
  File "/usr/local/lib/python2.7/dist-packages/django/core/handlers/base.py", line 114, in get_response
    response = wrapped_callback(request, *callback_args, **callback_kwargs)
  File "/usr/local/lib/python2.7/dist-packages/django/views/generic/base.py", line 69, in view
    return self.dispatch(request, *args, **kwargs)
  File "/usr/local/lib/python2.7/dist-packages/django/utils/decorators.py", line 29, in _wrapper
    return bound_func(*args, **kwargs)
  File "/usr/local/lib/python2.7/dist-packages/django/contrib/auth/decorators.py", line 22, in _wrapped_view
    return view_func(request, *args, **kwargs)
  File "/usr/local/lib/python2.7/dist-packages/django/utils/decorators.py", line 25, in bound_func
    return func(self, *args2, **kwargs2)
  File "/home/mikhail/EclipseWorkspace/oncoFinder2/oncoFinder2/profiles/views.py", line 170, in dispatch
    return view(request, *args, **kwargs)
  File "/usr/local/lib/python2.7/dist-packages/django/views/generic/base.py", line 69, in view
    return self.dispatch(request, *args, **kwargs)
  File "/usr/local/lib/python2.7/dist-packages/django/utils/decorators.py", line 29, in _wrapper
    return bound_func(*args, **kwargs)
  File "/usr/local/lib/python2.7/dist-packages/django/contrib/auth/decorators.py", line 22, in _wrapped_view
    return view_func(request, *args, **kwargs)
  File "/usr/local/lib/python2.7/dist-packages/django/utils/decorators.py", line 25, in bound_func
    return func(self, *args2, **kwargs2)
  File "/home/mikhail/EclipseWorkspace/oncoFinder2/oncoFinder2/profiles/preprocess_views.py", line 182, in dispatch
    return super(MedicPreprocess, self).dispatch(request, *args, **kwargs)
  File "/usr/local/lib/python2.7/dist-packages/django/views/generic/base.py", line 87, in dispatch
    return handler(request, *args, **kwargs)
  File "/usr/local/lib/python2.7/dist-packages/django/views/generic/edit.py", line 171, in post
    return self.form_valid(form)
  File "/home/mikhail/EclipseWorkspace/oncoFinder2/oncoFinder2/profiles/preprocess_views.py", line 215, in form_valid
    raise Exception("prepro view")
Exception: prepro view
2015-03-30 09:53:57,181 ERROR base 20389 -1250432192 Internal Server Error: /document/new/
Traceback (most recent call last):
  File "/usr/local/lib/python2.7/dist-packages/django/core/handlers/base.py", line 114, in get_response
    response = wrapped_callback(request, *callback_args, **callback_kwargs)
  File "/usr/local/lib/python2.7/dist-packages/django/views/generic/base.py", line 69, in view
    return self.dispatch(request, *args, **kwargs)
  File "/usr/local/lib/python2.7/dist-packages/django/utils/decorators.py", line 29, in _wrapper
    return bound_func(*args, **kwargs)
  File "/usr/local/lib/python2.7/dist-packages/django/contrib/auth/decorators.py", line 22, in _wrapped_view
    return view_func(request, *args, **kwargs)
  File "/usr/local/lib/python2.7/dist-packages/django/utils/decorators.py", line 25, in bound_func
    return func(self, *args2, **kwargs2)
  File "/home/mikhail/EclipseWorkspace/oncoFinder2/oncoFinder2/profiles/views.py", line 170, in dispatch
    return view(request, *args, **kwargs)
  File "/usr/local/lib/python2.7/dist-packages/django/views/generic/base.py", line 69, in view
    return self.dispatch(request, *args, **kwargs)
  File "/usr/local/lib/python2.7/dist-packages/django/utils/decorators.py", line 29, in _wrapper
    return bound_func(*args, **kwargs)
  File "/usr/local/lib/python2.7/dist-packages/django/contrib/auth/decorators.py", line 22, in _wrapped_view
    return view_func(request, *args, **kwargs)
  File "/usr/local/lib/python2.7/dist-packages/django/utils/decorators.py", line 25, in bound_func
    return func(self, *args2, **kwargs2)
  File "/home/mikhail/EclipseWorkspace/oncoFinder2/oncoFinder2/profiles/preprocess_views.py", line 182, in dispatch
    return super(MedicPreprocess, self).dispatch(request, *args, **kwargs)
  File "/usr/local/lib/python2.7/dist-packages/django/views/generic/base.py", line 87, in dispatch
    return handler(request, *args, **kwargs)
  File "/usr/local/lib/python2.7/dist-packages/django/views/generic/edit.py", line 171, in post
    return self.form_valid(form)
  File "/home/mikhail/EclipseWorkspace/oncoFinder2/oncoFinder2/profiles/preprocess_views.py", line 215, in form_valid
    raise Exception("prepro view")
Exception: prepro view
2015-03-30 09:56:48,854 ERROR base 21609 -1250432192 Internal Server Error: /document/new/
Traceback (most recent call last):
  File "/usr/local/lib/python2.7/dist-packages/django/core/handlers/base.py", line 114, in get_response
    response = wrapped_callback(request, *callback_args, **callback_kwargs)
  File "/usr/local/lib/python2.7/dist-packages/django/views/generic/base.py", line 69, in view
    return self.dispatch(request, *args, **kwargs)
  File "/usr/local/lib/python2.7/dist-packages/django/utils/decorators.py", line 29, in _wrapper
    return bound_func(*args, **kwargs)
  File "/usr/local/lib/python2.7/dist-packages/django/contrib/auth/decorators.py", line 22, in _wrapped_view
    return view_func(request, *args, **kwargs)
  File "/usr/local/lib/python2.7/dist-packages/django/utils/decorators.py", line 25, in bound_func
    return func(self, *args2, **kwargs2)
  File "/home/mikhail/EclipseWorkspace/oncoFinder2/oncoFinder2/profiles/views.py", line 170, in dispatch
    return view(request, *args, **kwargs)
  File "/usr/local/lib/python2.7/dist-packages/django/views/generic/base.py", line 69, in view
    return self.dispatch(request, *args, **kwargs)
  File "/usr/local/lib/python2.7/dist-packages/django/utils/decorators.py", line 29, in _wrapper
    return bound_func(*args, **kwargs)
  File "/usr/local/lib/python2.7/dist-packages/django/contrib/auth/decorators.py", line 22, in _wrapped_view
    return view_func(request, *args, **kwargs)
  File "/usr/local/lib/python2.7/dist-packages/django/utils/decorators.py", line 25, in bound_func
    return func(self, *args2, **kwargs2)
  File "/home/mikhail/EclipseWorkspace/oncoFinder2/oncoFinder2/profiles/preprocess_views.py", line 182, in dispatch
    return super(MedicPreprocess, self).dispatch(request, *args, **kwargs)
  File "/usr/local/lib/python2.7/dist-packages/django/views/generic/base.py", line 87, in dispatch
    return handler(request, *args, **kwargs)
  File "/usr/local/lib/python2.7/dist-packages/django/views/generic/edit.py", line 171, in post
    return self.form_valid(form)
  File "/home/mikhail/EclipseWorkspace/oncoFinder2/oncoFinder2/profiles/preprocess_views.py", line 210, in form_valid
    raise Exception("prepro view")
Exception: prepro view
2015-03-30 09:58:29,459 ERROR base 22524 -1250432192 Internal Server Error: /document/new/
Traceback (most recent call last):
  File "/usr/local/lib/python2.7/dist-packages/django/core/handlers/base.py", line 114, in get_response
    response = wrapped_callback(request, *callback_args, **callback_kwargs)
  File "/usr/local/lib/python2.7/dist-packages/django/views/generic/base.py", line 69, in view
    return self.dispatch(request, *args, **kwargs)
  File "/usr/local/lib/python2.7/dist-packages/django/utils/decorators.py", line 29, in _wrapper
    return bound_func(*args, **kwargs)
  File "/usr/local/lib/python2.7/dist-packages/django/contrib/auth/decorators.py", line 22, in _wrapped_view
    return view_func(request, *args, **kwargs)
  File "/usr/local/lib/python2.7/dist-packages/django/utils/decorators.py", line 25, in bound_func
    return func(self, *args2, **kwargs2)
  File "/home/mikhail/EclipseWorkspace/oncoFinder2/oncoFinder2/profiles/views.py", line 170, in dispatch
    return view(request, *args, **kwargs)
  File "/usr/local/lib/python2.7/dist-packages/django/views/generic/base.py", line 69, in view
    return self.dispatch(request, *args, **kwargs)
  File "/usr/local/lib/python2.7/dist-packages/django/utils/decorators.py", line 29, in _wrapper
    return bound_func(*args, **kwargs)
  File "/usr/local/lib/python2.7/dist-packages/django/contrib/auth/decorators.py", line 22, in _wrapped_view
    return view_func(request, *args, **kwargs)
  File "/usr/local/lib/python2.7/dist-packages/django/utils/decorators.py", line 25, in bound_func
    return func(self, *args2, **kwargs2)
  File "/home/mikhail/EclipseWorkspace/oncoFinder2/oncoFinder2/profiles/preprocess_views.py", line 183, in dispatch
    return super(MedicPreprocess, self).dispatch(request, *args, **kwargs)
  File "/usr/local/lib/python2.7/dist-packages/django/views/generic/base.py", line 87, in dispatch
    return handler(request, *args, **kwargs)
  File "/usr/local/lib/python2.7/dist-packages/django/views/generic/edit.py", line 171, in post
    return self.form_valid(form)
  File "/home/mikhail/EclipseWorkspace/oncoFinder2/oncoFinder2/profiles/preprocess_views.py", line 211, in form_valid
    raise Exception("prepro view")
Exception: prepro view
2015-03-30 09:59:55,519 ERROR base 23093 -1251480768 Internal Server Error: /document/new/
Traceback (most recent call last):
  File "/usr/local/lib/python2.7/dist-packages/django/core/handlers/base.py", line 114, in get_response
    response = wrapped_callback(request, *callback_args, **callback_kwargs)
  File "/usr/local/lib/python2.7/dist-packages/django/views/generic/base.py", line 69, in view
    return self.dispatch(request, *args, **kwargs)
  File "/usr/local/lib/python2.7/dist-packages/django/utils/decorators.py", line 29, in _wrapper
    return bound_func(*args, **kwargs)
  File "/usr/local/lib/python2.7/dist-packages/django/contrib/auth/decorators.py", line 22, in _wrapped_view
    return view_func(request, *args, **kwargs)
  File "/usr/local/lib/python2.7/dist-packages/django/utils/decorators.py", line 25, in bound_func
    return func(self, *args2, **kwargs2)
  File "/home/mikhail/EclipseWorkspace/oncoFinder2/oncoFinder2/profiles/views.py", line 170, in dispatch
    return view(request, *args, **kwargs)
  File "/usr/local/lib/python2.7/dist-packages/django/views/generic/base.py", line 69, in view
    return self.dispatch(request, *args, **kwargs)
  File "/usr/local/lib/python2.7/dist-packages/django/utils/decorators.py", line 29, in _wrapper
    return bound_func(*args, **kwargs)
  File "/usr/local/lib/python2.7/dist-packages/django/contrib/auth/decorators.py", line 22, in _wrapped_view
    return view_func(request, *args, **kwargs)
  File "/usr/local/lib/python2.7/dist-packages/django/utils/decorators.py", line 25, in bound_func
    return func(self, *args2, **kwargs2)
  File "/home/mikhail/EclipseWorkspace/oncoFinder2/oncoFinder2/profiles/preprocess_views.py", line 183, in dispatch
    return super(MedicPreprocess, self).dispatch(request, *args, **kwargs)
  File "/usr/local/lib/python2.7/dist-packages/django/views/generic/base.py", line 87, in dispatch
    return handler(request, *args, **kwargs)
  File "/usr/local/lib/python2.7/dist-packages/django/views/generic/edit.py", line 171, in post
    return self.form_valid(form)
  File "/home/mikhail/EclipseWorkspace/oncoFinder2/oncoFinder2/profiles/preprocess_views.py", line 215, in form_valid
    raise Exception("prepro view")
Exception: prepro view
2015-03-30 10:01:15,173 ERROR base 23631 -1250952384 Internal Server Error: /document/new/
Traceback (most recent call last):
  File "/usr/local/lib/python2.7/dist-packages/django/core/handlers/base.py", line 114, in get_response
    response = wrapped_callback(request, *callback_args, **callback_kwargs)
  File "/usr/local/lib/python2.7/dist-packages/django/views/generic/base.py", line 69, in view
    return self.dispatch(request, *args, **kwargs)
  File "/usr/local/lib/python2.7/dist-packages/django/utils/decorators.py", line 29, in _wrapper
    return bound_func(*args, **kwargs)
  File "/usr/local/lib/python2.7/dist-packages/django/contrib/auth/decorators.py", line 22, in _wrapped_view
    return view_func(request, *args, **kwargs)
  File "/usr/local/lib/python2.7/dist-packages/django/utils/decorators.py", line 25, in bound_func
    return func(self, *args2, **kwargs2)
  File "/home/mikhail/EclipseWorkspace/oncoFinder2/oncoFinder2/profiles/views.py", line 170, in dispatch
    return view(request, *args, **kwargs)
  File "/usr/local/lib/python2.7/dist-packages/django/views/generic/base.py", line 69, in view
    return self.dispatch(request, *args, **kwargs)
  File "/usr/local/lib/python2.7/dist-packages/django/utils/decorators.py", line 29, in _wrapper
    return bound_func(*args, **kwargs)
  File "/usr/local/lib/python2.7/dist-packages/django/contrib/auth/decorators.py", line 22, in _wrapped_view
    return view_func(request, *args, **kwargs)
  File "/usr/local/lib/python2.7/dist-packages/django/utils/decorators.py", line 25, in bound_func
    return func(self, *args2, **kwargs2)
  File "/home/mikhail/EclipseWorkspace/oncoFinder2/oncoFinder2/profiles/preprocess_views.py", line 183, in dispatch
    return super(MedicPreprocess, self).dispatch(request, *args, **kwargs)
  File "/usr/local/lib/python2.7/dist-packages/django/views/generic/base.py", line 87, in dispatch
    return handler(request, *args, **kwargs)
  File "/usr/local/lib/python2.7/dist-packages/django/views/generic/edit.py", line 171, in post
    return self.form_valid(form)
  File "/home/mikhail/EclipseWorkspace/oncoFinder2/oncoFinder2/profiles/preprocess_views.py", line 226, in form_valid
    raise Exception("prepro view")
Exception: prepro view
2015-03-30 10:02:19,533 ERROR base 24194 -1249903808 Internal Server Error: /document/new/
Traceback (most recent call last):
  File "/usr/local/lib/python2.7/dist-packages/django/core/handlers/base.py", line 114, in get_response
    response = wrapped_callback(request, *callback_args, **callback_kwargs)
  File "/usr/local/lib/python2.7/dist-packages/django/views/generic/base.py", line 69, in view
    return self.dispatch(request, *args, **kwargs)
  File "/usr/local/lib/python2.7/dist-packages/django/utils/decorators.py", line 29, in _wrapper
    return bound_func(*args, **kwargs)
  File "/usr/local/lib/python2.7/dist-packages/django/contrib/auth/decorators.py", line 22, in _wrapped_view
    return view_func(request, *args, **kwargs)
  File "/usr/local/lib/python2.7/dist-packages/django/utils/decorators.py", line 25, in bound_func
    return func(self, *args2, **kwargs2)
  File "/home/mikhail/EclipseWorkspace/oncoFinder2/oncoFinder2/profiles/views.py", line 170, in dispatch
    return view(request, *args, **kwargs)
  File "/usr/local/lib/python2.7/dist-packages/django/views/generic/base.py", line 69, in view
    return self.dispatch(request, *args, **kwargs)
  File "/usr/local/lib/python2.7/dist-packages/django/utils/decorators.py", line 29, in _wrapper
    return bound_func(*args, **kwargs)
  File "/usr/local/lib/python2.7/dist-packages/django/contrib/auth/decorators.py", line 22, in _wrapped_view
    return view_func(request, *args, **kwargs)
  File "/usr/local/lib/python2.7/dist-packages/django/utils/decorators.py", line 25, in bound_func
    return func(self, *args2, **kwargs2)
  File "/home/mikhail/EclipseWorkspace/oncoFinder2/oncoFinder2/profiles/preprocess_views.py", line 183, in dispatch
    return super(MedicPreprocess, self).dispatch(request, *args, **kwargs)
  File "/usr/local/lib/python2.7/dist-packages/django/views/generic/base.py", line 87, in dispatch
    return handler(request, *args, **kwargs)
  File "/usr/local/lib/python2.7/dist-packages/django/views/generic/edit.py", line 171, in post
    return self.form_valid(form)
  File "/home/mikhail/EclipseWorkspace/oncoFinder2/oncoFinder2/profiles/preprocess_views.py", line 226, in form_valid
    raise Exception("prepro view")
Exception: prepro view
2015-03-30 10:25:21,171 ERROR base 30642 -1249903808 Internal Server Error: /calculation-parameters/doc5261/
Traceback (most recent call last):
  File "/usr/local/lib/python2.7/dist-packages/django/core/handlers/base.py", line 114, in get_response
    response = wrapped_callback(request, *callback_args, **callback_kwargs)
  File "/usr/local/lib/python2.7/dist-packages/django/views/generic/base.py", line 69, in view
    return self.dispatch(request, *args, **kwargs)
  File "/usr/local/lib/python2.7/dist-packages/django/utils/decorators.py", line 29, in _wrapper
    return bound_func(*args, **kwargs)
  File "/usr/local/lib/python2.7/dist-packages/django/contrib/auth/decorators.py", line 22, in _wrapped_view
    return view_func(request, *args, **kwargs)
  File "/usr/local/lib/python2.7/dist-packages/django/utils/decorators.py", line 25, in bound_func
    return func(self, *args2, **kwargs2)
  File "/home/mikhail/EclipseWorkspace/oncoFinder2/oncoFinder2/core/views.py", line 47, in dispatch
    return super(CoreSetCalculationParameters, self).dispatch(request, *args, **kwargs)
  File "/usr/local/lib/python2.7/dist-packages/django/views/generic/base.py", line 87, in dispatch
    return handler(request, *args, **kwargs)
  File "/usr/local/lib/python2.7/dist-packages/django/views/generic/edit.py", line 171, in post
    return self.form_valid(form)
  File "/home/mikhail/EclipseWorkspace/oncoFinder2/oncoFinder2/core/views.py", line 623, in form_valid
    output_file = default_storage.save(settings.MEDIA_ROOT+"/"+path+"/"+file_name, ContentFile(''))
UnboundLocalError: local variable 'default_storage' referenced before assignment
2015-03-30 10:25:53,445 ERROR base 30642 -1397208256 Internal Server Error: /medic/calculate/
Traceback (most recent call last):
  File "/usr/local/lib/python2.7/dist-packages/django/core/handlers/base.py", line 114, in get_response
    response = wrapped_callback(request, *callback_args, **callback_kwargs)
  File "/usr/local/lib/python2.7/dist-packages/django/views/generic/base.py", line 69, in view
    return self.dispatch(request, *args, **kwargs)
  File "/usr/local/lib/python2.7/dist-packages/django/utils/decorators.py", line 29, in _wrapper
    return bound_func(*args, **kwargs)
  File "/usr/local/lib/python2.7/dist-packages/django/contrib/auth/decorators.py", line 22, in _wrapped_view
    return view_func(request, *args, **kwargs)
  File "/usr/local/lib/python2.7/dist-packages/django/utils/decorators.py", line 25, in bound_func
    return func(self, *args2, **kwargs2)
  File "/home/mikhail/EclipseWorkspace/oncoFinder2/oncoFinder2/medic/views.py", line 555, in dispatch
    return super(MedicPatientCalculation, self).dispatch(request, *args, **kwargs)
  File "/usr/local/lib/python2.7/dist-packages/django/views/generic/base.py", line 87, in dispatch
    return handler(request, *args, **kwargs)
  File "/usr/local/lib/python2.7/dist-packages/django/views/generic/edit.py", line 171, in post
    return self.form_valid(form)
  File "/home/mikhail/EclipseWorkspace/oncoFinder2/oncoFinder2/medic/views.py", line 564, in form_valid
    raise Exception('test excp')
Exception: test excp
2015-03-30 10:29:47,931 ERROR base 2104 -1250432192 Internal Server Error: /medic/calculate/
Traceback (most recent call last):
  File "/usr/local/lib/python2.7/dist-packages/django/core/handlers/base.py", line 114, in get_response
    response = wrapped_callback(request, *callback_args, **callback_kwargs)
  File "/usr/local/lib/python2.7/dist-packages/django/views/generic/base.py", line 69, in view
    return self.dispatch(request, *args, **kwargs)
  File "/usr/local/lib/python2.7/dist-packages/django/utils/decorators.py", line 29, in _wrapper
    return bound_func(*args, **kwargs)
  File "/usr/local/lib/python2.7/dist-packages/django/contrib/auth/decorators.py", line 22, in _wrapped_view
    return view_func(request, *args, **kwargs)
  File "/usr/local/lib/python2.7/dist-packages/django/utils/decorators.py", line 25, in bound_func
    return func(self, *args2, **kwargs2)
  File "/home/mikhail/EclipseWorkspace/oncoFinder2/oncoFinder2/medic/views.py", line 555, in dispatch
    return super(MedicPatientCalculation, self).dispatch(request, *args, **kwargs)
  File "/usr/local/lib/python2.7/dist-packages/django/views/generic/base.py", line 87, in dispatch
    return handler(request, *args, **kwargs)
  File "/usr/local/lib/python2.7/dist-packages/django/views/generic/edit.py", line 171, in post
    return self.form_valid(form)
  File "/home/mikhail/EclipseWorkspace/oncoFinder2/oncoFinder2/medic/views.py", line 565, in form_valid
    context = self.get_context_data()
  File "/home/mikhail/EclipseWorkspace/oncoFinder2/oncoFinder2/medic/views.py", line 559, in get_context_data
    input_document = Document.objects.get(pk=self.kwargs['pk'])
KeyError: 'pk'
2015-03-30 10:34:45,525 ERROR base 4381 -1251480768 Internal Server Error: /medic/calculate/
Traceback (most recent call last):
  File "/usr/local/lib/python2.7/dist-packages/django/core/handlers/base.py", line 114, in get_response
    response = wrapped_callback(request, *callback_args, **callback_kwargs)
  File "/usr/local/lib/python2.7/dist-packages/django/views/generic/base.py", line 69, in view
    return self.dispatch(request, *args, **kwargs)
  File "/usr/local/lib/python2.7/dist-packages/django/utils/decorators.py", line 29, in _wrapper
    return bound_func(*args, **kwargs)
  File "/usr/local/lib/python2.7/dist-packages/django/contrib/auth/decorators.py", line 22, in _wrapped_view
    return view_func(request, *args, **kwargs)
  File "/usr/local/lib/python2.7/dist-packages/django/utils/decorators.py", line 25, in bound_func
    return func(self, *args2, **kwargs2)
  File "/home/mikhail/EclipseWorkspace/oncoFinder2/oncoFinder2/medic/views.py", line 555, in dispatch
    return super(MedicPatientCalculation, self).dispatch(request, *args, **kwargs)
  File "/usr/local/lib/python2.7/dist-packages/django/views/generic/base.py", line 87, in dispatch
    return handler(request, *args, **kwargs)
  File "/usr/local/lib/python2.7/dist-packages/django/views/generic/edit.py", line 171, in post
    return self.form_valid(form)
  File "/home/mikhail/EclipseWorkspace/oncoFinder2/oncoFinder2/medic/views.py", line 567, in form_valid
    raise Exception('test excp')
Exception: test excp
2015-03-30 10:35:32,578 ERROR base 4381 -1271923904 Internal Server Error: /medic/calculate/
Traceback (most recent call last):
  File "/usr/local/lib/python2.7/dist-packages/django/core/handlers/base.py", line 114, in get_response
    response = wrapped_callback(request, *callback_args, **callback_kwargs)
  File "/usr/local/lib/python2.7/dist-packages/django/views/generic/base.py", line 69, in view
    return self.dispatch(request, *args, **kwargs)
  File "/usr/local/lib/python2.7/dist-packages/django/utils/decorators.py", line 29, in _wrapper
    return bound_func(*args, **kwargs)
  File "/usr/local/lib/python2.7/dist-packages/django/contrib/auth/decorators.py", line 22, in _wrapped_view
    return view_func(request, *args, **kwargs)
  File "/usr/local/lib/python2.7/dist-packages/django/utils/decorators.py", line 25, in bound_func
    return func(self, *args2, **kwargs2)
  File "/home/mikhail/EclipseWorkspace/oncoFinder2/oncoFinder2/medic/views.py", line 555, in dispatch
    return super(MedicPatientCalculation, self).dispatch(request, *args, **kwargs)
  File "/usr/local/lib/python2.7/dist-packages/django/views/generic/base.py", line 87, in dispatch
    return handler(request, *args, **kwargs)
  File "/usr/local/lib/python2.7/dist-packages/django/views/generic/edit.py", line 171, in post
    return self.form_valid(form)
  File "/home/mikhail/EclipseWorkspace/oncoFinder2/oncoFinder2/medic/views.py", line 567, in form_valid
    raise Exception('test excp')
Exception: test excp
2015-03-30 10:37:36,072 ERROR base 5635 -1250432192 Internal Server Error: /medic/calculate/
Traceback (most recent call last):
  File "/usr/local/lib/python2.7/dist-packages/django/core/handlers/base.py", line 114, in get_response
    response = wrapped_callback(request, *callback_args, **callback_kwargs)
  File "/usr/local/lib/python2.7/dist-packages/django/views/generic/base.py", line 69, in view
    return self.dispatch(request, *args, **kwargs)
  File "/usr/local/lib/python2.7/dist-packages/django/utils/decorators.py", line 29, in _wrapper
    return bound_func(*args, **kwargs)
  File "/usr/local/lib/python2.7/dist-packages/django/contrib/auth/decorators.py", line 22, in _wrapped_view
    return view_func(request, *args, **kwargs)
  File "/usr/local/lib/python2.7/dist-packages/django/utils/decorators.py", line 25, in bound_func
    return func(self, *args2, **kwargs2)
  File "/home/mikhail/EclipseWorkspace/oncoFinder2/oncoFinder2/medic/views.py", line 555, in dispatch
    return super(MedicPatientCalculation, self).dispatch(request, *args, **kwargs)
  File "/usr/local/lib/python2.7/dist-packages/django/views/generic/base.py", line 87, in dispatch
    return handler(request, *args, **kwargs)
  File "/usr/local/lib/python2.7/dist-packages/django/views/generic/edit.py", line 171, in post
    return self.form_valid(form)
  File "/home/mikhail/EclipseWorkspace/oncoFinder2/oncoFinder2/medic/views.py", line 567, in form_valid
    raise Exception('test excp')
Exception: test excp
2015-03-30 10:42:47,391 ERROR base 7647 -1251480768 Internal Server Error: /medic/calculate/
Traceback (most recent call last):
  File "/usr/local/lib/python2.7/dist-packages/django/core/handlers/base.py", line 114, in get_response
    response = wrapped_callback(request, *callback_args, **callback_kwargs)
  File "/usr/local/lib/python2.7/dist-packages/django/views/generic/base.py", line 69, in view
    return self.dispatch(request, *args, **kwargs)
  File "/usr/local/lib/python2.7/dist-packages/django/utils/decorators.py", line 29, in _wrapper
    return bound_func(*args, **kwargs)
  File "/usr/local/lib/python2.7/dist-packages/django/contrib/auth/decorators.py", line 22, in _wrapped_view
    return view_func(request, *args, **kwargs)
  File "/usr/local/lib/python2.7/dist-packages/django/utils/decorators.py", line 25, in bound_func
    return func(self, *args2, **kwargs2)
  File "/home/mikhail/EclipseWorkspace/oncoFinder2/oncoFinder2/medic/views.py", line 555, in dispatch
    return super(MedicPatientCalculation, self).dispatch(request, *args, **kwargs)
  File "/usr/local/lib/python2.7/dist-packages/django/views/generic/base.py", line 87, in dispatch
    return handler(request, *args, **kwargs)
  File "/usr/local/lib/python2.7/dist-packages/django/views/generic/edit.py", line 171, in post
    return self.form_valid(form)
  File "/home/mikhail/EclipseWorkspace/oncoFinder2/oncoFinder2/medic/views.py", line 578, in form_valid
    raise Exception('test excp')
Exception: test excp
2015-03-30 10:46:10,078 ERROR base 8472 -1250432192 Internal Server Error: /medic/calculate/
Traceback (most recent call last):
  File "/usr/local/lib/python2.7/dist-packages/django/core/handlers/base.py", line 114, in get_response
    response = wrapped_callback(request, *callback_args, **callback_kwargs)
  File "/usr/local/lib/python2.7/dist-packages/django/views/generic/base.py", line 69, in view
    return self.dispatch(request, *args, **kwargs)
  File "/usr/local/lib/python2.7/dist-packages/django/utils/decorators.py", line 29, in _wrapper
    return bound_func(*args, **kwargs)
  File "/usr/local/lib/python2.7/dist-packages/django/contrib/auth/decorators.py", line 22, in _wrapped_view
    return view_func(request, *args, **kwargs)
  File "/usr/local/lib/python2.7/dist-packages/django/utils/decorators.py", line 25, in bound_func
    return func(self, *args2, **kwargs2)
  File "/home/mikhail/EclipseWorkspace/oncoFinder2/oncoFinder2/medic/views.py", line 555, in dispatch
    return super(MedicPatientCalculation, self).dispatch(request, *args, **kwargs)
  File "/usr/local/lib/python2.7/dist-packages/django/views/generic/base.py", line 87, in dispatch
    return handler(request, *args, **kwargs)
  File "/usr/local/lib/python2.7/dist-packages/django/views/generic/edit.py", line 171, in post
    return self.form_valid(form)
  File "/home/mikhail/EclipseWorkspace/oncoFinder2/oncoFinder2/medic/views.py", line 579, in form_valid
    raise Exception('from cycle')
Exception: from cycle
2015-03-30 10:59:09,448 ERROR base 13412 -1250432192 Internal Server Error: /medic/calculate/
Traceback (most recent call last):
  File "/usr/local/lib/python2.7/dist-packages/django/core/handlers/base.py", line 114, in get_response
    response = wrapped_callback(request, *callback_args, **callback_kwargs)
  File "/usr/local/lib/python2.7/dist-packages/django/views/generic/base.py", line 69, in view
    return self.dispatch(request, *args, **kwargs)
  File "/usr/local/lib/python2.7/dist-packages/django/utils/decorators.py", line 29, in _wrapper
    return bound_func(*args, **kwargs)
  File "/usr/local/lib/python2.7/dist-packages/django/contrib/auth/decorators.py", line 22, in _wrapped_view
    return view_func(request, *args, **kwargs)
  File "/usr/local/lib/python2.7/dist-packages/django/utils/decorators.py", line 25, in bound_func
    return func(self, *args2, **kwargs2)
  File "/home/mikhail/EclipseWorkspace/oncoFinder2/oncoFinder2/medic/views.py", line 555, in dispatch
    return super(MedicPatientCalculation, self).dispatch(request, *args, **kwargs)
  File "/usr/local/lib/python2.7/dist-packages/django/views/generic/base.py", line 87, in dispatch
    return handler(request, *args, **kwargs)
  File "/usr/local/lib/python2.7/dist-packages/django/views/generic/edit.py", line 171, in post
    return self.form_valid(form)
  File "/home/mikhail/EclipseWorkspace/oncoFinder2/oncoFinder2/medic/views.py", line 593, in form_valid
    raise Exception('from cycle')
Exception: from cycle
2015-03-30 11:02:48,024 ERROR base 14420 -1249903808 Internal Server Error: /medic/calculate/
Traceback (most recent call last):
  File "/usr/local/lib/python2.7/dist-packages/django/core/handlers/base.py", line 114, in get_response
    response = wrapped_callback(request, *callback_args, **callback_kwargs)
  File "/usr/local/lib/python2.7/dist-packages/django/views/generic/base.py", line 69, in view
    return self.dispatch(request, *args, **kwargs)
  File "/usr/local/lib/python2.7/dist-packages/django/utils/decorators.py", line 29, in _wrapper
    return bound_func(*args, **kwargs)
  File "/usr/local/lib/python2.7/dist-packages/django/contrib/auth/decorators.py", line 22, in _wrapped_view
    return view_func(request, *args, **kwargs)
  File "/usr/local/lib/python2.7/dist-packages/django/utils/decorators.py", line 25, in bound_func
    return func(self, *args2, **kwargs2)
  File "/home/mikhail/EclipseWorkspace/oncoFinder2/oncoFinder2/medic/views.py", line 556, in dispatch
    return super(MedicPatientCalculation, self).dispatch(request, *args, **kwargs)
  File "/usr/local/lib/python2.7/dist-packages/django/views/generic/base.py", line 87, in dispatch
    return handler(request, *args, **kwargs)
  File "/usr/local/lib/python2.7/dist-packages/django/views/generic/edit.py", line 171, in post
    return self.form_valid(form)
  File "/home/mikhail/EclipseWorkspace/oncoFinder2/oncoFinder2/medic/views.py", line 602, in form_valid
    raise Exception('from cycle')
Exception: from cycle
2015-03-30 11:04:24,747 ERROR base 15827 -1250432192 Internal Server Error: /medic/calculate/
Traceback (most recent call last):
  File "/usr/local/lib/python2.7/dist-packages/django/core/handlers/base.py", line 114, in get_response
    response = wrapped_callback(request, *callback_args, **callback_kwargs)
  File "/usr/local/lib/python2.7/dist-packages/django/views/generic/base.py", line 69, in view
    return self.dispatch(request, *args, **kwargs)
  File "/usr/local/lib/python2.7/dist-packages/django/utils/decorators.py", line 29, in _wrapper
    return bound_func(*args, **kwargs)
  File "/usr/local/lib/python2.7/dist-packages/django/contrib/auth/decorators.py", line 22, in _wrapped_view
    return view_func(request, *args, **kwargs)
  File "/usr/local/lib/python2.7/dist-packages/django/utils/decorators.py", line 25, in bound_func
    return func(self, *args2, **kwargs2)
  File "/home/mikhail/EclipseWorkspace/oncoFinder2/oncoFinder2/medic/views.py", line 556, in dispatch
    return super(MedicPatientCalculation, self).dispatch(request, *args, **kwargs)
  File "/usr/local/lib/python2.7/dist-packages/django/views/generic/base.py", line 87, in dispatch
    return handler(request, *args, **kwargs)
  File "/usr/local/lib/python2.7/dist-packages/django/views/generic/edit.py", line 171, in post
    return self.form_valid(form)
  File "/home/mikhail/EclipseWorkspace/oncoFinder2/oncoFinder2/medic/views.py", line 605, in form_valid
    raise Exception('from cycle')
Exception: from cycle
2015-03-30 11:07:58,967 ERROR base 16733 -1250432192 Internal Server Error: /medic/calculate/
Traceback (most recent call last):
  File "/usr/local/lib/python2.7/dist-packages/django/core/handlers/base.py", line 114, in get_response
    response = wrapped_callback(request, *callback_args, **callback_kwargs)
  File "/usr/local/lib/python2.7/dist-packages/django/views/generic/base.py", line 69, in view
    return self.dispatch(request, *args, **kwargs)
  File "/usr/local/lib/python2.7/dist-packages/django/utils/decorators.py", line 29, in _wrapper
    return bound_func(*args, **kwargs)
  File "/usr/local/lib/python2.7/dist-packages/django/contrib/auth/decorators.py", line 22, in _wrapped_view
    return view_func(request, *args, **kwargs)
  File "/usr/local/lib/python2.7/dist-packages/django/utils/decorators.py", line 25, in bound_func
    return func(self, *args2, **kwargs2)
  File "/home/mikhail/EclipseWorkspace/oncoFinder2/oncoFinder2/medic/views.py", line 556, in dispatch
    return super(MedicPatientCalculation, self).dispatch(request, *args, **kwargs)
  File "/usr/local/lib/python2.7/dist-packages/django/views/generic/base.py", line 87, in dispatch
    return handler(request, *args, **kwargs)
  File "/usr/local/lib/python2.7/dist-packages/django/views/generic/edit.py", line 171, in post
    return self.form_valid(form)
  File "/home/mikhail/EclipseWorkspace/oncoFinder2/oncoFinder2/medic/views.py", line 604, in form_valid
    df_for_pas1 = df_after_xpn[original_columns]
TypeError: 'NoneType' object has no attribute '__getitem__'
2015-03-30 11:09:10,369 ERROR base 17678 -1250952384 Internal Server Error: /medic/calculate/
Traceback (most recent call last):
  File "/usr/local/lib/python2.7/dist-packages/django/core/handlers/base.py", line 114, in get_response
    response = wrapped_callback(request, *callback_args, **callback_kwargs)
  File "/usr/local/lib/python2.7/dist-packages/django/views/generic/base.py", line 69, in view
    return self.dispatch(request, *args, **kwargs)
  File "/usr/local/lib/python2.7/dist-packages/django/utils/decorators.py", line 29, in _wrapper
    return bound_func(*args, **kwargs)
  File "/usr/local/lib/python2.7/dist-packages/django/contrib/auth/decorators.py", line 22, in _wrapped_view
    return view_func(request, *args, **kwargs)
  File "/usr/local/lib/python2.7/dist-packages/django/utils/decorators.py", line 25, in bound_func
    return func(self, *args2, **kwargs2)
  File "/home/mikhail/EclipseWorkspace/oncoFinder2/oncoFinder2/medic/views.py", line 556, in dispatch
    return super(MedicPatientCalculation, self).dispatch(request, *args, **kwargs)
  File "/usr/local/lib/python2.7/dist-packages/django/views/generic/base.py", line 87, in dispatch
    return handler(request, *args, **kwargs)
  File "/usr/local/lib/python2.7/dist-packages/django/views/generic/edit.py", line 171, in post
    return self.form_valid(form)
  File "/home/mikhail/EclipseWorkspace/oncoFinder2/oncoFinder2/medic/views.py", line 610, in form_valid
    raise Exception('from cycle')
Exception: from cycle
2015-03-30 11:12:28,628 ERROR base 18293 -1251480768 Internal Server Error: /medic/calculate/
Traceback (most recent call last):
  File "/usr/local/lib/python2.7/dist-packages/django/core/handlers/base.py", line 114, in get_response
    response = wrapped_callback(request, *callback_args, **callback_kwargs)
  File "/usr/local/lib/python2.7/dist-packages/django/views/generic/base.py", line 69, in view
    return self.dispatch(request, *args, **kwargs)
  File "/usr/local/lib/python2.7/dist-packages/django/utils/decorators.py", line 29, in _wrapper
    return bound_func(*args, **kwargs)
  File "/usr/local/lib/python2.7/dist-packages/django/contrib/auth/decorators.py", line 22, in _wrapped_view
    return view_func(request, *args, **kwargs)
  File "/usr/local/lib/python2.7/dist-packages/django/utils/decorators.py", line 25, in bound_func
    return func(self, *args2, **kwargs2)
  File "/home/mikhail/EclipseWorkspace/oncoFinder2/oncoFinder2/medic/views.py", line 557, in dispatch
    return super(MedicPatientCalculation, self).dispatch(request, *args, **kwargs)
  File "/usr/local/lib/python2.7/dist-packages/django/views/generic/base.py", line 87, in dispatch
    return handler(request, *args, **kwargs)
  File "/usr/local/lib/python2.7/dist-packages/django/views/generic/edit.py", line 171, in post
    return self.form_valid(form)
  File "/home/mikhail/EclipseWorkspace/oncoFinder2/oncoFinder2/medic/views.py", line 631, in form_valid
    raise Exception('from cycle')
Exception: from cycle
2015-03-30 11:13:29,792 ERROR base 19546 -1250432192 Internal Server Error: /medic/calculate/
Traceback (most recent call last):
  File "/usr/local/lib/python2.7/dist-packages/django/core/handlers/base.py", line 114, in get_response
    response = wrapped_callback(request, *callback_args, **callback_kwargs)
  File "/usr/local/lib/python2.7/dist-packages/django/views/generic/base.py", line 69, in view
    return self.dispatch(request, *args, **kwargs)
  File "/usr/local/lib/python2.7/dist-packages/django/utils/decorators.py", line 29, in _wrapper
    return bound_func(*args, **kwargs)
  File "/usr/local/lib/python2.7/dist-packages/django/contrib/auth/decorators.py", line 22, in _wrapped_view
    return view_func(request, *args, **kwargs)
  File "/usr/local/lib/python2.7/dist-packages/django/utils/decorators.py", line 25, in bound_func
    return func(self, *args2, **kwargs2)
  File "/home/mikhail/EclipseWorkspace/oncoFinder2/oncoFinder2/medic/views.py", line 557, in dispatch
    return super(MedicPatientCalculation, self).dispatch(request, *args, **kwargs)
  File "/usr/local/lib/python2.7/dist-packages/django/views/generic/base.py", line 87, in dispatch
    return handler(request, *args, **kwargs)
  File "/usr/local/lib/python2.7/dist-packages/django/views/generic/edit.py", line 171, in post
    return self.form_valid(form)
  File "/home/mikhail/EclipseWorkspace/oncoFinder2/oncoFinder2/medic/views.py", line 631, in form_valid
    raise Exception('from cycle')
Exception: from cycle
2015-03-30 11:13:49,792 ERROR base 19761 -1250432192 Internal Server Error: /medic/calculate/
Traceback (most recent call last):
  File "/usr/local/lib/python2.7/dist-packages/django/core/handlers/base.py", line 114, in get_response
    response = wrapped_callback(request, *callback_args, **callback_kwargs)
  File "/usr/local/lib/python2.7/dist-packages/django/views/generic/base.py", line 69, in view
    return self.dispatch(request, *args, **kwargs)
  File "/usr/local/lib/python2.7/dist-packages/django/utils/decorators.py", line 29, in _wrapper
    return bound_func(*args, **kwargs)
  File "/usr/local/lib/python2.7/dist-packages/django/contrib/auth/decorators.py", line 22, in _wrapped_view
    return view_func(request, *args, **kwargs)
  File "/usr/local/lib/python2.7/dist-packages/django/utils/decorators.py", line 25, in bound_func
    return func(self, *args2, **kwargs2)
  File "/home/mikhail/EclipseWorkspace/oncoFinder2/oncoFinder2/medic/views.py", line 557, in dispatch
    return super(MedicPatientCalculation, self).dispatch(request, *args, **kwargs)
  File "/usr/local/lib/python2.7/dist-packages/django/views/generic/base.py", line 87, in dispatch
    return handler(request, *args, **kwargs)
  File "/usr/local/lib/python2.7/dist-packages/django/views/generic/edit.py", line 171, in post
    return self.form_valid(form)
  File "/home/mikhail/EclipseWorkspace/oncoFinder2/oncoFinder2/medic/views.py", line 631, in form_valid
    raise Exception('from cycle')
Exception: from cycle
2015-03-30 11:14:06,566 ERROR base 19867 -1250432192 Internal Server Error: /medic/calculate/
Traceback (most recent call last):
  File "/usr/local/lib/python2.7/dist-packages/django/core/handlers/base.py", line 114, in get_response
    response = wrapped_callback(request, *callback_args, **callback_kwargs)
  File "/usr/local/lib/python2.7/dist-packages/django/views/generic/base.py", line 69, in view
    return self.dispatch(request, *args, **kwargs)
  File "/usr/local/lib/python2.7/dist-packages/django/utils/decorators.py", line 29, in _wrapper
    return bound_func(*args, **kwargs)
  File "/usr/local/lib/python2.7/dist-packages/django/contrib/auth/decorators.py", line 22, in _wrapped_view
    return view_func(request, *args, **kwargs)
  File "/usr/local/lib/python2.7/dist-packages/django/utils/decorators.py", line 25, in bound_func
    return func(self, *args2, **kwargs2)
  File "/home/mikhail/EclipseWorkspace/oncoFinder2/oncoFinder2/medic/views.py", line 557, in dispatch
    return super(MedicPatientCalculation, self).dispatch(request, *args, **kwargs)
  File "/usr/local/lib/python2.7/dist-packages/django/views/generic/base.py", line 87, in dispatch
    return handler(request, *args, **kwargs)
  File "/usr/local/lib/python2.7/dist-packages/django/views/generic/edit.py", line 171, in post
    return self.form_valid(form)
  File "/home/mikhail/EclipseWorkspace/oncoFinder2/oncoFinder2/medic/views.py", line 631, in form_valid
    raise Exception('from cycle')
Exception: from cycle
2015-03-30 11:14:40,031 ERROR base 20006 -1250432192 Internal Server Error: /medic/calculate/
Traceback (most recent call last):
  File "/usr/local/lib/python2.7/dist-packages/django/core/handlers/base.py", line 114, in get_response
    response = wrapped_callback(request, *callback_args, **callback_kwargs)
  File "/usr/local/lib/python2.7/dist-packages/django/views/generic/base.py", line 69, in view
    return self.dispatch(request, *args, **kwargs)
  File "/usr/local/lib/python2.7/dist-packages/django/utils/decorators.py", line 29, in _wrapper
    return bound_func(*args, **kwargs)
  File "/usr/local/lib/python2.7/dist-packages/django/contrib/auth/decorators.py", line 22, in _wrapped_view
    return view_func(request, *args, **kwargs)
  File "/usr/local/lib/python2.7/dist-packages/django/utils/decorators.py", line 25, in bound_func
    return func(self, *args2, **kwargs2)
  File "/home/mikhail/EclipseWorkspace/oncoFinder2/oncoFinder2/medic/views.py", line 557, in dispatch
    return super(MedicPatientCalculation, self).dispatch(request, *args, **kwargs)
  File "/usr/local/lib/python2.7/dist-packages/django/views/generic/base.py", line 87, in dispatch
    return handler(request, *args, **kwargs)
  File "/usr/local/lib/python2.7/dist-packages/django/views/generic/edit.py", line 171, in post
    return self.form_valid(form)
  File "/home/mikhail/EclipseWorkspace/oncoFinder2/oncoFinder2/medic/views.py", line 631, in form_valid
    raise Exception('from cycle')
Exception: from cycle
2015-03-30 11:17:36,408 ERROR base 20798 -1251480768 Internal Server Error: /medic/calculate/
Traceback (most recent call last):
  File "/usr/local/lib/python2.7/dist-packages/django/core/handlers/base.py", line 114, in get_response
    response = wrapped_callback(request, *callback_args, **callback_kwargs)
  File "/usr/local/lib/python2.7/dist-packages/django/views/generic/base.py", line 69, in view
    return self.dispatch(request, *args, **kwargs)
  File "/usr/local/lib/python2.7/dist-packages/django/utils/decorators.py", line 29, in _wrapper
    return bound_func(*args, **kwargs)
  File "/usr/local/lib/python2.7/dist-packages/django/contrib/auth/decorators.py", line 22, in _wrapped_view
    return view_func(request, *args, **kwargs)
  File "/usr/local/lib/python2.7/dist-packages/django/utils/decorators.py", line 25, in bound_func
    return func(self, *args2, **kwargs2)
  File "/home/mikhail/EclipseWorkspace/oncoFinder2/oncoFinder2/medic/views.py", line 558, in dispatch
    return super(MedicPatientCalculation, self).dispatch(request, *args, **kwargs)
  File "/usr/local/lib/python2.7/dist-packages/django/views/generic/base.py", line 87, in dispatch
    return handler(request, *args, **kwargs)
  File "/usr/local/lib/python2.7/dist-packages/django/views/generic/edit.py", line 171, in post
    return self.form_valid(form)
  File "/home/mikhail/EclipseWorkspace/oncoFinder2/oncoFinder2/medic/views.py", line 644, in form_valid
    raise Exception('from cycle')
Exception: from cycle
2015-03-30 11:26:29,877 ERROR base 22542 -1250432192 Internal Server Error: /medic/calculate/
Traceback (most recent call last):
  File "/usr/local/lib/python2.7/dist-packages/django/core/handlers/base.py", line 114, in get_response
    response = wrapped_callback(request, *callback_args, **callback_kwargs)
  File "/usr/local/lib/python2.7/dist-packages/django/views/generic/base.py", line 69, in view
    return self.dispatch(request, *args, **kwargs)
  File "/usr/local/lib/python2.7/dist-packages/django/utils/decorators.py", line 29, in _wrapper
    return bound_func(*args, **kwargs)
  File "/usr/local/lib/python2.7/dist-packages/django/contrib/auth/decorators.py", line 22, in _wrapped_view
    return view_func(request, *args, **kwargs)
  File "/usr/local/lib/python2.7/dist-packages/django/utils/decorators.py", line 25, in bound_func
    return func(self, *args2, **kwargs2)
  File "/home/mikhail/EclipseWorkspace/oncoFinder2/oncoFinder2/medic/views.py", line 561, in dispatch
    return super(MedicPatientCalculation, self).dispatch(request, *args, **kwargs)
  File "/usr/local/lib/python2.7/dist-packages/django/views/generic/base.py", line 87, in dispatch
    return handler(request, *args, **kwargs)
  File "/usr/local/lib/python2.7/dist-packages/django/views/generic/edit.py", line 171, in post
    return self.form_valid(form)
  File "/home/mikhail/EclipseWorkspace/oncoFinder2/oncoFinder2/medic/views.py", line 659, in form_valid
    raise Exception('end of view')
Exception: end of view
2015-03-30 11:35:56,318 ERROR base 25572 -1427113152 Internal Server Error: /document/doc5262/treat64/
Traceback (most recent call last):
  File "/usr/local/lib/python2.7/dist-packages/django/core/handlers/base.py", line 114, in get_response
    response = wrapped_callback(request, *callback_args, **callback_kwargs)
  File "/usr/local/lib/python2.7/dist-packages/django/views/generic/base.py", line 69, in view
    return self.dispatch(request, *args, **kwargs)
  File "/usr/local/lib/python2.7/dist-packages/django/utils/decorators.py", line 29, in _wrapper
    return bound_func(*args, **kwargs)
  File "/usr/local/lib/python2.7/dist-packages/django/contrib/auth/decorators.py", line 22, in _wrapped_view
    return view_func(request, *args, **kwargs)
  File "/usr/local/lib/python2.7/dist-packages/django/utils/decorators.py", line 25, in bound_func
    return func(self, *args2, **kwargs2)
  File "/home/mikhail/EclipseWorkspace/oncoFinder2/oncoFinder2/medic/views.py", line 338, in dispatch
    return super(PatientTreatmentDetail, self).dispatch(request, *args, **kwargs)
  File "/usr/local/lib/python2.7/dist-packages/django/views/generic/base.py", line 87, in dispatch
    return handler(request, *args, **kwargs)
  File "/usr/local/lib/python2.7/dist-packages/django/views/generic/detail.py", line 111, in get
    context = self.get_context_data(object=self.object)
  File "/home/mikhail/EclipseWorkspace/oncoFinder2/oncoFinder2/medic/views.py", line 353, in get_context_data
    df_output = read_excel(filename, sheetname="PAS1")
  File "/usr/local/lib/python2.7/dist-packages/pandas/io/excel.py", line 127, in read_excel
    return ExcelFile(io, engine=engine).parse(sheetname=sheetname, **kwds)
  File "/usr/local/lib/python2.7/dist-packages/pandas/io/excel.py", line 164, in __init__
    self.book = xlrd.open_workbook(io)
  File "/usr/local/lib/python2.7/dist-packages/xlrd-0.9.2-py2.7.egg/xlrd/__init__.py", line 394, in open_workbook
    f = open(filename, "rb")
IOError: [Errno 2] No such file or directory: u'/home/mikhail/EclipseWorkspace/oncoFinder2/oncoFinder2/oncoFinder2/media/users/admin/new-medic/output/patient_results.csv'
2015-03-30 11:39:18,674 ERROR base 28455 -1250432192 Internal Server Error: /document/doc5262/treat64/
Traceback (most recent call last):
  File "/usr/local/lib/python2.7/dist-packages/django/core/handlers/base.py", line 114, in get_response
    response = wrapped_callback(request, *callback_args, **callback_kwargs)
  File "/usr/local/lib/python2.7/dist-packages/django/views/generic/base.py", line 69, in view
    return self.dispatch(request, *args, **kwargs)
  File "/usr/local/lib/python2.7/dist-packages/django/utils/decorators.py", line 29, in _wrapper
    return bound_func(*args, **kwargs)
  File "/usr/local/lib/python2.7/dist-packages/django/contrib/auth/decorators.py", line 22, in _wrapped_view
    return view_func(request, *args, **kwargs)
  File "/usr/local/lib/python2.7/dist-packages/django/utils/decorators.py", line 25, in bound_func
    return func(self, *args2, **kwargs2)
  File "/home/mikhail/EclipseWorkspace/oncoFinder2/oncoFinder2/medic/views.py", line 338, in dispatch
    return super(PatientTreatmentDetail, self).dispatch(request, *args, **kwargs)
  File "/usr/local/lib/python2.7/dist-packages/django/views/generic/base.py", line 87, in dispatch
    return handler(request, *args, **kwargs)
  File "/usr/local/lib/python2.7/dist-packages/django/views/generic/detail.py", line 111, in get
    context = self.get_context_data(object=self.object)
  File "/home/mikhail/EclipseWorkspace/oncoFinder2/oncoFinder2/medic/views.py", line 355, in get_context_data
    dialect = sniffer.sniff(open(filename, 'r').read(), delimiters='\t,;')
IOError: [Errno 2] No such file or directory: u'/home/mikhail/EclipseWorkspace/oncoFinder2/oncoFinder2/oncoFinder2/media/users/admin/new-medic/output/patient_results.csv'
2015-03-30 11:39:41,068 ERROR base 29817 -1250432192 Internal Server Error: /document/doc5262/treat64/
Traceback (most recent call last):
  File "/usr/local/lib/python2.7/dist-packages/django/core/handlers/base.py", line 114, in get_response
    response = wrapped_callback(request, *callback_args, **callback_kwargs)
  File "/usr/local/lib/python2.7/dist-packages/django/views/generic/base.py", line 69, in view
    return self.dispatch(request, *args, **kwargs)
  File "/usr/local/lib/python2.7/dist-packages/django/utils/decorators.py", line 29, in _wrapper
    return bound_func(*args, **kwargs)
  File "/usr/local/lib/python2.7/dist-packages/django/contrib/auth/decorators.py", line 22, in _wrapped_view
    return view_func(request, *args, **kwargs)
  File "/usr/local/lib/python2.7/dist-packages/django/utils/decorators.py", line 25, in bound_func
    return func(self, *args2, **kwargs2)
  File "/home/mikhail/EclipseWorkspace/oncoFinder2/oncoFinder2/medic/views.py", line 338, in dispatch
    return super(PatientTreatmentDetail, self).dispatch(request, *args, **kwargs)
  File "/usr/local/lib/python2.7/dist-packages/django/views/generic/base.py", line 87, in dispatch
    return handler(request, *args, **kwargs)
  File "/usr/local/lib/python2.7/dist-packages/django/views/generic/detail.py", line 111, in get
    context = self.get_context_data(object=self.object)
  File "/home/mikhail/EclipseWorkspace/oncoFinder2/oncoFinder2/medic/views.py", line 361, in get_context_data
    df_pms1 = read_excel(file_pms1, sheetname="PMS1", index_col="Pathway").transpose()
  File "/usr/local/lib/python2.7/dist-packages/pandas/io/excel.py", line 127, in read_excel
    return ExcelFile(io, engine=engine).parse(sheetname=sheetname, **kwds)
  File "/usr/local/lib/python2.7/dist-packages/pandas/io/excel.py", line 164, in __init__
    self.book = xlrd.open_workbook(io)
  File "/usr/local/lib/python2.7/dist-packages/xlrd-0.9.2-py2.7.egg/xlrd/__init__.py", line 435, in open_workbook
    ragged_rows=ragged_rows,
  File "/usr/local/lib/python2.7/dist-packages/xlrd-0.9.2-py2.7.egg/xlrd/book.py", line 91, in open_workbook_xls
    biff_version = bk.getbof(XL_WORKBOOK_GLOBALS)
  File "/usr/local/lib/python2.7/dist-packages/xlrd-0.9.2-py2.7.egg/xlrd/book.py", line 1258, in getbof
    bof_error('Expected BOF record; found %r' % self.mem[savpos:savpos+8])
  File "/usr/local/lib/python2.7/dist-packages/xlrd-0.9.2-py2.7.egg/xlrd/book.py", line 1252, in bof_error
    raise XLRDError('Unsupported format, or corrupt file: ' + msg)
XLRDError: Unsupported format, or corrupt file: Expected BOF record; found 'Pathway,'
2015-03-30 11:40:29,683 ERROR base 30157 -1251480768 Internal Server Error: /document/doc5262/treat64/
Traceback (most recent call last):
  File "/usr/local/lib/python2.7/dist-packages/django/core/handlers/base.py", line 114, in get_response
    response = wrapped_callback(request, *callback_args, **callback_kwargs)
  File "/usr/local/lib/python2.7/dist-packages/django/views/generic/base.py", line 69, in view
    return self.dispatch(request, *args, **kwargs)
  File "/usr/local/lib/python2.7/dist-packages/django/utils/decorators.py", line 29, in _wrapper
    return bound_func(*args, **kwargs)
  File "/usr/local/lib/python2.7/dist-packages/django/contrib/auth/decorators.py", line 22, in _wrapped_view
    return view_func(request, *args, **kwargs)
  File "/usr/local/lib/python2.7/dist-packages/django/utils/decorators.py", line 25, in bound_func
    return func(self, *args2, **kwargs2)
  File "/home/mikhail/EclipseWorkspace/oncoFinder2/oncoFinder2/medic/views.py", line 338, in dispatch
    return super(PatientTreatmentDetail, self).dispatch(request, *args, **kwargs)
  File "/usr/local/lib/python2.7/dist-packages/django/views/generic/base.py", line 87, in dispatch
    return handler(request, *args, **kwargs)
  File "/usr/local/lib/python2.7/dist-packages/django/views/generic/detail.py", line 111, in get
    context = self.get_context_data(object=self.object)
  File "/home/mikhail/EclipseWorkspace/oncoFinder2/oncoFinder2/medic/views.py", line 362, in get_context_data
    df_required_paths = df_pms1[path_cols]
  File "/usr/local/lib/python2.7/dist-packages/pandas/core/frame.py", line 1737, in __getitem__
    return self._getitem_array(key)
  File "/usr/local/lib/python2.7/dist-packages/pandas/core/frame.py", line 1781, in _getitem_array
    indexer = self.ix._convert_to_indexer(key, axis=1)
  File "/usr/local/lib/python2.7/dist-packages/pandas/core/indexing.py", line 1135, in _convert_to_indexer
    raise KeyError('%s not in index' % objarr[mask])
KeyError: "['Unnamed: 0'] not in index"
2015-03-30 11:41:09,609 ERROR base 30157 -1353938112 Internal Server Error: /document/doc5262/treat64/
Traceback (most recent call last):
  File "/usr/local/lib/python2.7/dist-packages/django/core/handlers/base.py", line 114, in get_response
    response = wrapped_callback(request, *callback_args, **callback_kwargs)
  File "/usr/local/lib/python2.7/dist-packages/django/views/generic/base.py", line 69, in view
    return self.dispatch(request, *args, **kwargs)
  File "/usr/local/lib/python2.7/dist-packages/django/utils/decorators.py", line 29, in _wrapper
    return bound_func(*args, **kwargs)
  File "/usr/local/lib/python2.7/dist-packages/django/contrib/auth/decorators.py", line 22, in _wrapped_view
    return view_func(request, *args, **kwargs)
  File "/usr/local/lib/python2.7/dist-packages/django/utils/decorators.py", line 25, in bound_func
    return func(self, *args2, **kwargs2)
  File "/home/mikhail/EclipseWorkspace/oncoFinder2/oncoFinder2/medic/views.py", line 338, in dispatch
    return super(PatientTreatmentDetail, self).dispatch(request, *args, **kwargs)
  File "/usr/local/lib/python2.7/dist-packages/django/views/generic/base.py", line 87, in dispatch
    return handler(request, *args, **kwargs)
  File "/usr/local/lib/python2.7/dist-packages/django/views/generic/detail.py", line 111, in get
    context = self.get_context_data(object=self.object)
  File "/home/mikhail/EclipseWorkspace/oncoFinder2/oncoFinder2/medic/views.py", line 362, in get_context_data
    df_required_paths = df_pms1[path_cols]
  File "/usr/local/lib/python2.7/dist-packages/pandas/core/frame.py", line 1737, in __getitem__
    return self._getitem_array(key)
  File "/usr/local/lib/python2.7/dist-packages/pandas/core/frame.py", line 1781, in _getitem_array
    indexer = self.ix._convert_to_indexer(key, axis=1)
  File "/usr/local/lib/python2.7/dist-packages/pandas/core/indexing.py", line 1135, in _convert_to_indexer
    raise KeyError('%s not in index' % objarr[mask])
KeyError: "['Unnamed: 0'] not in index"
2015-03-30 11:41:21,853 ERROR base 30157 -1353938112 Internal Server Error: /document/doc5262/treat63/
Traceback (most recent call last):
  File "/usr/local/lib/python2.7/dist-packages/django/core/handlers/base.py", line 114, in get_response
    response = wrapped_callback(request, *callback_args, **callback_kwargs)
  File "/usr/local/lib/python2.7/dist-packages/django/views/generic/base.py", line 69, in view
    return self.dispatch(request, *args, **kwargs)
  File "/usr/local/lib/python2.7/dist-packages/django/utils/decorators.py", line 29, in _wrapper
    return bound_func(*args, **kwargs)
  File "/usr/local/lib/python2.7/dist-packages/django/contrib/auth/decorators.py", line 22, in _wrapped_view
    return view_func(request, *args, **kwargs)
  File "/usr/local/lib/python2.7/dist-packages/django/utils/decorators.py", line 25, in bound_func
    return func(self, *args2, **kwargs2)
  File "/home/mikhail/EclipseWorkspace/oncoFinder2/oncoFinder2/medic/views.py", line 338, in dispatch
    return super(PatientTreatmentDetail, self).dispatch(request, *args, **kwargs)
  File "/usr/local/lib/python2.7/dist-packages/django/views/generic/base.py", line 87, in dispatch
    return handler(request, *args, **kwargs)
  File "/usr/local/lib/python2.7/dist-packages/django/views/generic/detail.py", line 111, in get
    context = self.get_context_data(object=self.object)
  File "/home/mikhail/EclipseWorkspace/oncoFinder2/oncoFinder2/medic/views.py", line 362, in get_context_data
    df_required_paths = df_pms1[path_cols]
  File "/usr/local/lib/python2.7/dist-packages/pandas/core/frame.py", line 1737, in __getitem__
    return self._getitem_array(key)
  File "/usr/local/lib/python2.7/dist-packages/pandas/core/frame.py", line 1781, in _getitem_array
    indexer = self.ix._convert_to_indexer(key, axis=1)
  File "/usr/local/lib/python2.7/dist-packages/pandas/core/indexing.py", line 1135, in _convert_to_indexer
    raise KeyError('%s not in index' % objarr[mask])
KeyError: "['Unnamed: 0'] not in index"
2015-03-30 11:42:45,001 ERROR base 30995 -1251480768 Internal Server Error: /document/doc5262/treat63/
Traceback (most recent call last):
  File "/usr/local/lib/python2.7/dist-packages/django/core/handlers/base.py", line 114, in get_response
    response = wrapped_callback(request, *callback_args, **callback_kwargs)
  File "/usr/local/lib/python2.7/dist-packages/django/views/generic/base.py", line 69, in view
    return self.dispatch(request, *args, **kwargs)
  File "/usr/local/lib/python2.7/dist-packages/django/utils/decorators.py", line 29, in _wrapper
    return bound_func(*args, **kwargs)
  File "/usr/local/lib/python2.7/dist-packages/django/contrib/auth/decorators.py", line 22, in _wrapped_view
    return view_func(request, *args, **kwargs)
  File "/usr/local/lib/python2.7/dist-packages/django/utils/decorators.py", line 25, in bound_func
    return func(self, *args2, **kwargs2)
  File "/home/mikhail/EclipseWorkspace/oncoFinder2/oncoFinder2/medic/views.py", line 338, in dispatch
    return super(PatientTreatmentDetail, self).dispatch(request, *args, **kwargs)
  File "/usr/local/lib/python2.7/dist-packages/django/views/generic/base.py", line 87, in dispatch
    return handler(request, *args, **kwargs)
  File "/usr/local/lib/python2.7/dist-packages/django/views/generic/detail.py", line 111, in get
    context = self.get_context_data(object=self.object)
  File "/home/mikhail/EclipseWorkspace/oncoFinder2/oncoFinder2/medic/views.py", line 483, in get_context_data
    specificity = (float(true_negative))/(false_positive+true_negative)
ZeroDivisionError: float division by zero
2015-03-30 11:47:28,472 ERROR base 32733 -1250952384 Internal Server Error: /document/doc5262/treat63/
Traceback (most recent call last):
  File "/usr/local/lib/python2.7/dist-packages/django/core/handlers/base.py", line 114, in get_response
    response = wrapped_callback(request, *callback_args, **callback_kwargs)
  File "/usr/local/lib/python2.7/dist-packages/django/views/generic/base.py", line 69, in view
    return self.dispatch(request, *args, **kwargs)
  File "/usr/local/lib/python2.7/dist-packages/django/utils/decorators.py", line 29, in _wrapper
    return bound_func(*args, **kwargs)
  File "/usr/local/lib/python2.7/dist-packages/django/contrib/auth/decorators.py", line 22, in _wrapped_view
    return view_func(request, *args, **kwargs)
  File "/usr/local/lib/python2.7/dist-packages/django/utils/decorators.py", line 25, in bound_func
    return func(self, *args2, **kwargs2)
  File "/home/mikhail/EclipseWorkspace/oncoFinder2/oncoFinder2/medic/views.py", line 338, in dispatch
    return super(PatientTreatmentDetail, self).dispatch(request, *args, **kwargs)
  File "/usr/local/lib/python2.7/dist-packages/django/views/generic/base.py", line 87, in dispatch
    return handler(request, *args, **kwargs)
  File "/usr/local/lib/python2.7/dist-packages/django/views/generic/detail.py", line 111, in get
    context = self.get_context_data(object=self.object)
  File "/home/mikhail/EclipseWorkspace/oncoFinder2/oncoFinder2/medic/views.py", line 487, in get_context_data
    sensitivity = (float(true_positive))/(true_positive+false_negative)
ZeroDivisionError: float division by zero
2015-03-30 11:51:23,574 ERROR base 590 -1249903808 Internal Server Error: /document/doc5262/treat63/
Traceback (most recent call last):
  File "/usr/local/lib/python2.7/dist-packages/django/core/handlers/base.py", line 114, in get_response
    response = wrapped_callback(request, *callback_args, **callback_kwargs)
  File "/usr/local/lib/python2.7/dist-packages/django/views/generic/base.py", line 69, in view
    return self.dispatch(request, *args, **kwargs)
  File "/usr/local/lib/python2.7/dist-packages/django/utils/decorators.py", line 29, in _wrapper
    return bound_func(*args, **kwargs)
  File "/usr/local/lib/python2.7/dist-packages/django/contrib/auth/decorators.py", line 22, in _wrapped_view
    return view_func(request, *args, **kwargs)
  File "/usr/local/lib/python2.7/dist-packages/django/utils/decorators.py", line 25, in bound_func
    return func(self, *args2, **kwargs2)
  File "/home/mikhail/EclipseWorkspace/oncoFinder2/oncoFinder2/medic/views.py", line 338, in dispatch
    return super(PatientTreatmentDetail, self).dispatch(request, *args, **kwargs)
  File "/usr/local/lib/python2.7/dist-packages/django/views/generic/base.py", line 87, in dispatch
    return handler(request, *args, **kwargs)
  File "/usr/local/lib/python2.7/dist-packages/django/views/generic/detail.py", line 111, in get
    context = self.get_context_data(object=self.object)
  File "/home/mikhail/EclipseWorkspace/oncoFinder2/oncoFinder2/medic/views.py", line 464, in get_context_data
    raise Exception("fucj")
Exception: fucj
2015-03-30 11:52:54,179 ERROR base 2563 -1250485440 Internal Server Error: /document/doc5262/treat63/
Traceback (most recent call last):
  File "/usr/local/lib/python2.7/dist-packages/django/core/handlers/base.py", line 114, in get_response
    response = wrapped_callback(request, *callback_args, **callback_kwargs)
  File "/usr/local/lib/python2.7/dist-packages/django/views/generic/base.py", line 69, in view
    return self.dispatch(request, *args, **kwargs)
  File "/usr/local/lib/python2.7/dist-packages/django/utils/decorators.py", line 29, in _wrapper
    return bound_func(*args, **kwargs)
  File "/usr/local/lib/python2.7/dist-packages/django/contrib/auth/decorators.py", line 22, in _wrapped_view
    return view_func(request, *args, **kwargs)
  File "/usr/local/lib/python2.7/dist-packages/django/utils/decorators.py", line 25, in bound_func
    return func(self, *args2, **kwargs2)
  File "/home/mikhail/EclipseWorkspace/oncoFinder2/oncoFinder2/medic/views.py", line 338, in dispatch
    return super(PatientTreatmentDetail, self).dispatch(request, *args, **kwargs)
  File "/usr/local/lib/python2.7/dist-packages/django/views/generic/base.py", line 87, in dispatch
    return handler(request, *args, **kwargs)
  File "/usr/local/lib/python2.7/dist-packages/django/views/generic/detail.py", line 111, in get
    context = self.get_context_data(object=self.object)
  File "/home/mikhail/EclipseWorkspace/oncoFinder2/oncoFinder2/medic/views.py", line 464, in get_context_data
    raise Exception("fucj")
Exception: fucj
2015-03-30 11:53:44,924 ERROR base 2811 -1385178304 Internal Server Error: /document/doc5262/treat64/
Traceback (most recent call last):
  File "/usr/local/lib/python2.7/dist-packages/django/core/handlers/base.py", line 114, in get_response
    response = wrapped_callback(request, *callback_args, **callback_kwargs)
  File "/usr/local/lib/python2.7/dist-packages/django/views/generic/base.py", line 69, in view
    return self.dispatch(request, *args, **kwargs)
  File "/usr/local/lib/python2.7/dist-packages/django/utils/decorators.py", line 29, in _wrapper
    return bound_func(*args, **kwargs)
  File "/usr/local/lib/python2.7/dist-packages/django/contrib/auth/decorators.py", line 22, in _wrapped_view
    return view_func(request, *args, **kwargs)
  File "/usr/local/lib/python2.7/dist-packages/django/utils/decorators.py", line 25, in bound_func
    return func(self, *args2, **kwargs2)
  File "/home/mikhail/EclipseWorkspace/oncoFinder2/oncoFinder2/medic/views.py", line 338, in dispatch
    return super(PatientTreatmentDetail, self).dispatch(request, *args, **kwargs)
  File "/usr/local/lib/python2.7/dist-packages/django/views/generic/base.py", line 87, in dispatch
    return handler(request, *args, **kwargs)
  File "/usr/local/lib/python2.7/dist-packages/django/views/generic/detail.py", line 111, in get
    context = self.get_context_data(object=self.object)
  File "/home/mikhail/EclipseWorkspace/oncoFinder2/oncoFinder2/medic/views.py", line 408, in get_context_data
    ratio = float(patient_Rcount)/float(path_num)
ZeroDivisionError: float division by zero
2015-03-30 11:53:58,590 ERROR base 2811 -1251480768 Internal Server Error: /document/doc5262/treat64/
Traceback (most recent call last):
  File "/usr/local/lib/python2.7/dist-packages/django/core/handlers/base.py", line 114, in get_response
    response = wrapped_callback(request, *callback_args, **callback_kwargs)
  File "/usr/local/lib/python2.7/dist-packages/django/views/generic/base.py", line 69, in view
    return self.dispatch(request, *args, **kwargs)
  File "/usr/local/lib/python2.7/dist-packages/django/utils/decorators.py", line 29, in _wrapper
    return bound_func(*args, **kwargs)
  File "/usr/local/lib/python2.7/dist-packages/django/contrib/auth/decorators.py", line 22, in _wrapped_view
    return view_func(request, *args, **kwargs)
  File "/usr/local/lib/python2.7/dist-packages/django/utils/decorators.py", line 25, in bound_func
    return func(self, *args2, **kwargs2)
  File "/home/mikhail/EclipseWorkspace/oncoFinder2/oncoFinder2/medic/views.py", line 338, in dispatch
    return super(PatientTreatmentDetail, self).dispatch(request, *args, **kwargs)
  File "/usr/local/lib/python2.7/dist-packages/django/views/generic/base.py", line 87, in dispatch
    return handler(request, *args, **kwargs)
  File "/home/mikhail/EclipseWorkspace/oncoFinder2/oncoFinder2/medic/views.py", line 520, in post
    context = self.get_context_data(object=self.object)
  File "/home/mikhail/EclipseWorkspace/oncoFinder2/oncoFinder2/medic/views.py", line 408, in get_context_data
    ratio = float(patient_Rcount)/float(path_num)
ZeroDivisionError: float division by zero
2015-03-30 11:55:38,109 ERROR base 2811 -1385178304 Internal Server Error: /document/doc5262/treat64/
Traceback (most recent call last):
  File "/usr/local/lib/python2.7/dist-packages/django/core/handlers/base.py", line 114, in get_response
    response = wrapped_callback(request, *callback_args, **callback_kwargs)
  File "/usr/local/lib/python2.7/dist-packages/django/views/generic/base.py", line 69, in view
    return self.dispatch(request, *args, **kwargs)
  File "/usr/local/lib/python2.7/dist-packages/django/utils/decorators.py", line 29, in _wrapper
    return bound_func(*args, **kwargs)
  File "/usr/local/lib/python2.7/dist-packages/django/contrib/auth/decorators.py", line 22, in _wrapped_view
    return view_func(request, *args, **kwargs)
  File "/usr/local/lib/python2.7/dist-packages/django/utils/decorators.py", line 25, in bound_func
    return func(self, *args2, **kwargs2)
  File "/home/mikhail/EclipseWorkspace/oncoFinder2/oncoFinder2/medic/views.py", line 338, in dispatch
    return super(PatientTreatmentDetail, self).dispatch(request, *args, **kwargs)
  File "/usr/local/lib/python2.7/dist-packages/django/views/generic/base.py", line 87, in dispatch
    return handler(request, *args, **kwargs)
  File "/home/mikhail/EclipseWorkspace/oncoFinder2/oncoFinder2/medic/views.py", line 520, in post
    context = self.get_context_data(object=self.object)
  File "/home/mikhail/EclipseWorkspace/oncoFinder2/oncoFinder2/medic/views.py", line 408, in get_context_data
    ratio = float(patient_Rcount)/float(path_num)
ZeroDivisionError: float division by zero
2015-03-30 11:55:45,502 ERROR base 2811 -1385178304 Internal Server Error: /document/doc5262/treat64/
Traceback (most recent call last):
  File "/usr/local/lib/python2.7/dist-packages/django/core/handlers/base.py", line 114, in get_response
    response = wrapped_callback(request, *callback_args, **callback_kwargs)
  File "/usr/local/lib/python2.7/dist-packages/django/views/generic/base.py", line 69, in view
    return self.dispatch(request, *args, **kwargs)
  File "/usr/local/lib/python2.7/dist-packages/django/utils/decorators.py", line 29, in _wrapper
    return bound_func(*args, **kwargs)
  File "/usr/local/lib/python2.7/dist-packages/django/contrib/auth/decorators.py", line 22, in _wrapped_view
    return view_func(request, *args, **kwargs)
  File "/usr/local/lib/python2.7/dist-packages/django/utils/decorators.py", line 25, in bound_func
    return func(self, *args2, **kwargs2)
  File "/home/mikhail/EclipseWorkspace/oncoFinder2/oncoFinder2/medic/views.py", line 338, in dispatch
    return super(PatientTreatmentDetail, self).dispatch(request, *args, **kwargs)
  File "/usr/local/lib/python2.7/dist-packages/django/views/generic/base.py", line 87, in dispatch
    return handler(request, *args, **kwargs)
  File "/usr/local/lib/python2.7/dist-packages/django/views/generic/detail.py", line 111, in get
    context = self.get_context_data(object=self.object)
  File "/home/mikhail/EclipseWorkspace/oncoFinder2/oncoFinder2/medic/views.py", line 408, in get_context_data
    ratio = float(patient_Rcount)/float(path_num)
ZeroDivisionError: float division by zero
2015-03-30 13:17:21,464 ERROR base 19944 -1261438144 Internal Server Error: /document/doc5262/treat64/
Traceback (most recent call last):
  File "/usr/local/lib/python2.7/dist-packages/django/core/handlers/base.py", line 114, in get_response
    response = wrapped_callback(request, *callback_args, **callback_kwargs)
  File "/usr/local/lib/python2.7/dist-packages/django/views/generic/base.py", line 69, in view
    return self.dispatch(request, *args, **kwargs)
  File "/usr/local/lib/python2.7/dist-packages/django/utils/decorators.py", line 29, in _wrapper
    return bound_func(*args, **kwargs)
  File "/usr/local/lib/python2.7/dist-packages/django/contrib/auth/decorators.py", line 22, in _wrapped_view
    return view_func(request, *args, **kwargs)
  File "/usr/local/lib/python2.7/dist-packages/django/utils/decorators.py", line 25, in bound_func
    return func(self, *args2, **kwargs2)
  File "/home/mikhail/EclipseWorkspace/oncoFinder2/oncoFinder2/medic/views.py", line 338, in dispatch
    return super(PatientTreatmentDetail, self).dispatch(request, *args, **kwargs)
  File "/usr/local/lib/python2.7/dist-packages/django/views/generic/base.py", line 87, in dispatch
    return handler(request, *args, **kwargs)
  File "/usr/local/lib/python2.7/dist-packages/django/views/generic/detail.py", line 111, in get
    context = self.get_context_data(object=self.object)
  File "/home/mikhail/EclipseWorkspace/oncoFinder2/oncoFinder2/medic/views.py", line 408, in get_context_data
    ratio = float(patient_Rcount)/float(path_num)
ZeroDivisionError: float division by zero
2015-03-30 17:02:38,507 ERROR base 3530 -1287660736 Internal Server Error: /document/doc5262/treat64/
Traceback (most recent call last):
  File "/usr/local/lib/python2.7/dist-packages/django/core/handlers/base.py", line 114, in get_response
    response = wrapped_callback(request, *callback_args, **callback_kwargs)
  File "/usr/local/lib/python2.7/dist-packages/django/views/generic/base.py", line 69, in view
    return self.dispatch(request, *args, **kwargs)
  File "/usr/local/lib/python2.7/dist-packages/django/utils/decorators.py", line 29, in _wrapper
    return bound_func(*args, **kwargs)
  File "/usr/local/lib/python2.7/dist-packages/django/contrib/auth/decorators.py", line 22, in _wrapped_view
    return view_func(request, *args, **kwargs)
  File "/usr/local/lib/python2.7/dist-packages/django/utils/decorators.py", line 25, in bound_func
    return func(self, *args2, **kwargs2)
  File "/home/mikhail/EclipseWorkspace/oncoFinder2/oncoFinder2/medic/views.py", line 338, in dispatch
    return super(PatientTreatmentDetail, self).dispatch(request, *args, **kwargs)
  File "/usr/local/lib/python2.7/dist-packages/django/views/generic/base.py", line 87, in dispatch
    return handler(request, *args, **kwargs)
  File "/home/mikhail/EclipseWorkspace/oncoFinder2/oncoFinder2/medic/views.py", line 520, in post
    context = self.get_context_data(object=self.object)
  File "/home/mikhail/EclipseWorkspace/oncoFinder2/oncoFinder2/medic/views.py", line 408, in get_context_data
    ratio = float(patient_Rcount)/float(path_num)
ZeroDivisionError: float division by zero
2015-03-31 13:29:03,405 ERROR base 29711 -1287660736 Internal Server Error: /document/doc5015/
Traceback (most recent call last):
  File "/usr/local/lib/python2.7/dist-packages/django/core/handlers/base.py", line 114, in get_response
    response = wrapped_callback(request, *callback_args, **callback_kwargs)
  File "/usr/local/lib/python2.7/dist-packages/django/views/generic/base.py", line 69, in view
    return self.dispatch(request, *args, **kwargs)
  File "/usr/local/lib/python2.7/dist-packages/django/utils/decorators.py", line 29, in _wrapper
    return bound_func(*args, **kwargs)
  File "/usr/local/lib/python2.7/dist-packages/django/contrib/auth/decorators.py", line 22, in _wrapped_view
    return view_func(request, *args, **kwargs)
  File "/usr/local/lib/python2.7/dist-packages/django/utils/decorators.py", line 25, in bound_func
    return func(self, *args2, **kwargs2)
  File "/home/mikhail/EclipseWorkspace/oncoFinder2/oncoFinder2/profiles/views.py", line 297, in dispatch
    return super(DocumentDetail, self).dispatch(request, *args, **kwargs)
  File "/usr/local/lib/python2.7/dist-packages/django/views/generic/base.py", line 87, in dispatch
    return handler(request, *args, **kwargs)
  File "/usr/local/lib/python2.7/dist-packages/django/views/generic/detail.py", line 111, in get
    context = self.get_context_data(object=self.object)
  File "/home/mikhail/EclipseWorkspace/oncoFinder2/oncoFinder2/profiles/views.py", line 305, in get_context_data
    dialect = sniffer.sniff(open(filename, 'r').read(), delimiters='\t,;') # defining the separator of the csv file
IOError: [Errno 2] No such file or directory: u'/home/mikhail/EclipseWorkspace/oncoFinder2/oncoFinder2/oncoFinder2/media/users/admin/testing-p-val-filter/input/input_example.csv'
