2015-08-20 19:25:17,512 ERROR base 4550 -1404056768 Internal Server Error: /celery/
Traceback (most recent call last):
  File "/usr/local/lib/python2.7/dist-packages/django/core/handlers/base.py", line 112, in get_response
    response = wrapped_callback(request, *callback_args, **callback_kwargs)
  File "/usr/local/lib/python2.7/dist-packages/django/views/generic/base.py", line 69, in view
    return self.dispatch(request, *args, **kwargs)
  File "/usr/local/lib/python2.7/dist-packages/django/utils/decorators.py", line 29, in _wrapper
    return bound_func(*args, **kwargs)
  File "/usr/local/lib/python2.7/dist-packages/django/contrib/auth/decorators.py", line 22, in _wrapped_view
    return view_func(request, *args, **kwargs)
  File "/usr/local/lib/python2.7/dist-packages/django/utils/decorators.py", line 25, in bound_func
    return func(self, *args2, **kwargs2)
  File "/home/mikhail/EclipseWorkspace/oncoFinder2/oncoFinder2/core/views.py", line 1322, in dispatch
    return super(Celery, self).dispatch(request, *args, **kwargs)
  File "/usr/local/lib/python2.7/dist-packages/django/views/generic/base.py", line 87, in dispatch
    return handler(request, *args, **kwargs)
  File "/usr/local/lib/python2.7/dist-packages/django/views/generic/base.py", line 154, in get
    context = self.get_context_data(**kwargs)
  File "/home/mikhail/EclipseWorkspace/oncoFinder2/oncoFinder2/core/views.py", line 1331, in get_context_data
    raise Exception('stop')
Exception: stop
2015-08-20 19:25:30,806 ERROR base 4796 -1357907136 Internal Server Error: /celery/
Traceback (most recent call last):
  File "/usr/local/lib/python2.7/dist-packages/django/core/handlers/base.py", line 112, in get_response
    response = wrapped_callback(request, *callback_args, **callback_kwargs)
  File "/usr/local/lib/python2.7/dist-packages/django/views/generic/base.py", line 69, in view
    return self.dispatch(request, *args, **kwargs)
  File "/usr/local/lib/python2.7/dist-packages/django/utils/decorators.py", line 29, in _wrapper
    return bound_func(*args, **kwargs)
  File "/usr/local/lib/python2.7/dist-packages/django/contrib/auth/decorators.py", line 22, in _wrapped_view
    return view_func(request, *args, **kwargs)
  File "/usr/local/lib/python2.7/dist-packages/django/utils/decorators.py", line 25, in bound_func
    return func(self, *args2, **kwargs2)
  File "/home/mikhail/EclipseWorkspace/oncoFinder2/oncoFinder2/core/views.py", line 1322, in dispatch
    return super(Celery, self).dispatch(request, *args, **kwargs)
  File "/usr/local/lib/python2.7/dist-packages/django/views/generic/base.py", line 87, in dispatch
    return handler(request, *args, **kwargs)
  File "/usr/local/lib/python2.7/dist-packages/django/views/generic/base.py", line 154, in get
    context = self.get_context_data(**kwargs)
  File "/home/mikhail/EclipseWorkspace/oncoFinder2/oncoFinder2/core/views.py", line 1331, in get_context_data
    raise Exception('stop')
Exception: stop
2015-08-20 19:25:33,213 ERROR base 4796 -1387267264 Internal Server Error: /celery/
Traceback (most recent call last):
  File "/usr/local/lib/python2.7/dist-packages/django/core/handlers/base.py", line 112, in get_response
    response = wrapped_callback(request, *callback_args, **callback_kwargs)
  File "/usr/local/lib/python2.7/dist-packages/django/views/generic/base.py", line 69, in view
    return self.dispatch(request, *args, **kwargs)
  File "/usr/local/lib/python2.7/dist-packages/django/utils/decorators.py", line 29, in _wrapper
    return bound_func(*args, **kwargs)
  File "/usr/local/lib/python2.7/dist-packages/django/contrib/auth/decorators.py", line 22, in _wrapped_view
    return view_func(request, *args, **kwargs)
  File "/usr/local/lib/python2.7/dist-packages/django/utils/decorators.py", line 25, in bound_func
    return func(self, *args2, **kwargs2)
  File "/home/mikhail/EclipseWorkspace/oncoFinder2/oncoFinder2/core/views.py", line 1322, in dispatch
    return super(Celery, self).dispatch(request, *args, **kwargs)
  File "/usr/local/lib/python2.7/dist-packages/django/views/generic/base.py", line 87, in dispatch
    return handler(request, *args, **kwargs)
  File "/usr/local/lib/python2.7/dist-packages/django/views/generic/base.py", line 154, in get
    context = self.get_context_data(**kwargs)
  File "/home/mikhail/EclipseWorkspace/oncoFinder2/oncoFinder2/core/views.py", line 1331, in get_context_data
    raise Exception('stop')
Exception: stop
2015-08-20 19:25:34,674 ERROR base 4796 -1357907136 Internal Server Error: /celery/
Traceback (most recent call last):
  File "/usr/local/lib/python2.7/dist-packages/django/core/handlers/base.py", line 112, in get_response
    response = wrapped_callback(request, *callback_args, **callback_kwargs)
  File "/usr/local/lib/python2.7/dist-packages/django/views/generic/base.py", line 69, in view
    return self.dispatch(request, *args, **kwargs)
  File "/usr/local/lib/python2.7/dist-packages/django/utils/decorators.py", line 29, in _wrapper
    return bound_func(*args, **kwargs)
  File "/usr/local/lib/python2.7/dist-packages/django/contrib/auth/decorators.py", line 22, in _wrapped_view
    return view_func(request, *args, **kwargs)
  File "/usr/local/lib/python2.7/dist-packages/django/utils/decorators.py", line 25, in bound_func
    return func(self, *args2, **kwargs2)
  File "/home/mikhail/EclipseWorkspace/oncoFinder2/oncoFinder2/core/views.py", line 1322, in dispatch
    return super(Celery, self).dispatch(request, *args, **kwargs)
  File "/usr/local/lib/python2.7/dist-packages/django/views/generic/base.py", line 87, in dispatch
    return handler(request, *args, **kwargs)
  File "/usr/local/lib/python2.7/dist-packages/django/views/generic/base.py", line 154, in get
    context = self.get_context_data(**kwargs)
  File "/home/mikhail/EclipseWorkspace/oncoFinder2/oncoFinder2/core/views.py", line 1331, in get_context_data
    raise Exception('stop')
Exception: stop
2015-08-24 11:20:45,724 ERROR base 24226 -1356702912 Internal Server Error: /calculation-parameters/doc7008/
Traceback (most recent call last):
  File "/usr/local/lib/python2.7/dist-packages/django/core/handlers/base.py", line 112, in get_response
    response = wrapped_callback(request, *callback_args, **callback_kwargs)
  File "/usr/local/lib/python2.7/dist-packages/django/views/generic/base.py", line 69, in view
    return self.dispatch(request, *args, **kwargs)
  File "/usr/local/lib/python2.7/dist-packages/django/utils/decorators.py", line 29, in _wrapper
    return bound_func(*args, **kwargs)
  File "/usr/local/lib/python2.7/dist-packages/django/contrib/auth/decorators.py", line 22, in _wrapped_view
    return view_func(request, *args, **kwargs)
  File "/usr/local/lib/python2.7/dist-packages/django/utils/decorators.py", line 25, in bound_func
    return func(self, *args2, **kwargs2)
  File "/home/mikhail/EclipseWorkspace/oncoFinder2/oncoFinder2/core/views.py", line 48, in dispatch
    return super(CoreSetCalculationParameters, self).dispatch(request, *args, **kwargs)
  File "/usr/local/lib/python2.7/dist-packages/django/views/generic/base.py", line 87, in dispatch
    return handler(request, *args, **kwargs)
  File "/usr/local/lib/python2.7/dist-packages/django/views/generic/edit.py", line 171, in post
    return self.form_valid(form)
  File "/home/mikhail/EclipseWorkspace/oncoFinder2/oncoFinder2/core/views.py", line 219, in form_valid
    log_process_doc_df = np.log(process_doc_df).fillna(0)
AttributeError: log
2015-08-24 11:21:30,592 ERROR base 24226 -1356702912 Internal Server Error: /calculation-parameters/doc7008/
Traceback (most recent call last):
  File "/usr/local/lib/python2.7/dist-packages/django/core/handlers/base.py", line 112, in get_response
    response = wrapped_callback(request, *callback_args, **callback_kwargs)
  File "/usr/local/lib/python2.7/dist-packages/django/views/generic/base.py", line 69, in view
    return self.dispatch(request, *args, **kwargs)
  File "/usr/local/lib/python2.7/dist-packages/django/utils/decorators.py", line 29, in _wrapper
    return bound_func(*args, **kwargs)
  File "/usr/local/lib/python2.7/dist-packages/django/contrib/auth/decorators.py", line 22, in _wrapped_view
    return view_func(request, *args, **kwargs)
  File "/usr/local/lib/python2.7/dist-packages/django/utils/decorators.py", line 25, in bound_func
    return func(self, *args2, **kwargs2)
  File "/home/mikhail/EclipseWorkspace/oncoFinder2/oncoFinder2/core/views.py", line 48, in dispatch
    return super(CoreSetCalculationParameters, self).dispatch(request, *args, **kwargs)
  File "/usr/local/lib/python2.7/dist-packages/django/views/generic/base.py", line 87, in dispatch
    return handler(request, *args, **kwargs)
  File "/usr/local/lib/python2.7/dist-packages/django/views/generic/edit.py", line 171, in post
    return self.form_valid(form)
  File "/home/mikhail/EclipseWorkspace/oncoFinder2/oncoFinder2/core/views.py", line 373, in form_valid
    pas1_norms_samples = np.log(joined_df[tumour_columns+normal_columns])
AttributeError: log
2015-08-24 14:09:47,541 ERROR base 23198 -1391465664 Internal Server Error: /calculation-parameters/doc7008/
Traceback (most recent call last):
  File "/usr/local/lib/python2.7/dist-packages/django/core/handlers/base.py", line 112, in get_response
    response = wrapped_callback(request, *callback_args, **callback_kwargs)
  File "/usr/local/lib/python2.7/dist-packages/django/views/generic/base.py", line 69, in view
    return self.dispatch(request, *args, **kwargs)
  File "/usr/local/lib/python2.7/dist-packages/django/utils/decorators.py", line 29, in _wrapper
    return bound_func(*args, **kwargs)
  File "/usr/local/lib/python2.7/dist-packages/django/contrib/auth/decorators.py", line 22, in _wrapped_view
    return view_func(request, *args, **kwargs)
  File "/usr/local/lib/python2.7/dist-packages/django/utils/decorators.py", line 25, in bound_func
    return func(self, *args2, **kwargs2)
  File "/home/mikhail/EclipseWorkspace/oncoFinder2/oncoFinder2/core/views.py", line 48, in dispatch
    return super(CoreSetCalculationParameters, self).dispatch(request, *args, **kwargs)
  File "/usr/local/lib/python2.7/dist-packages/django/views/generic/base.py", line 87, in dispatch
    return handler(request, *args, **kwargs)
  File "/usr/local/lib/python2.7/dist-packages/django/views/generic/edit.py", line 171, in post
    return self.form_valid(form)
  File "/home/mikhail/EclipseWorkspace/oncoFinder2/oncoFinder2/core/views.py", line 373, in form_valid
    bbb = np.log(aaa)
AttributeError: log
2015-08-24 14:10:18,189 ERROR base 23526 -1358955712 Internal Server Error: /calculation-parameters/doc7008/
Traceback (most recent call last):
  File "/usr/local/lib/python2.7/dist-packages/django/core/handlers/base.py", line 112, in get_response
    response = wrapped_callback(request, *callback_args, **callback_kwargs)
  File "/usr/local/lib/python2.7/dist-packages/django/views/generic/base.py", line 69, in view
    return self.dispatch(request, *args, **kwargs)
  File "/usr/local/lib/python2.7/dist-packages/django/utils/decorators.py", line 29, in _wrapper
    return bound_func(*args, **kwargs)
  File "/usr/local/lib/python2.7/dist-packages/django/contrib/auth/decorators.py", line 22, in _wrapped_view
    return view_func(request, *args, **kwargs)
  File "/usr/local/lib/python2.7/dist-packages/django/utils/decorators.py", line 25, in bound_func
    return func(self, *args2, **kwargs2)
  File "/home/mikhail/EclipseWorkspace/oncoFinder2/oncoFinder2/core/views.py", line 48, in dispatch
    return super(CoreSetCalculationParameters, self).dispatch(request, *args, **kwargs)
  File "/usr/local/lib/python2.7/dist-packages/django/views/generic/base.py", line 87, in dispatch
    return handler(request, *args, **kwargs)
  File "/usr/local/lib/python2.7/dist-packages/django/views/generic/edit.py", line 171, in post
    return self.form_valid(form)
  File "/home/mikhail/EclipseWorkspace/oncoFinder2/oncoFinder2/core/views.py", line 373, in form_valid
    bbb = np.log(aaa)
AttributeError: log
2015-08-24 14:11:02,656 ERROR base 23802 -1357907136 Internal Server Error: /calculation-parameters/doc7008/
Traceback (most recent call last):
  File "/usr/local/lib/python2.7/dist-packages/django/core/handlers/base.py", line 112, in get_response
    response = wrapped_callback(request, *callback_args, **callback_kwargs)
  File "/usr/local/lib/python2.7/dist-packages/django/views/generic/base.py", line 69, in view
    return self.dispatch(request, *args, **kwargs)
  File "/usr/local/lib/python2.7/dist-packages/django/utils/decorators.py", line 29, in _wrapper
    return bound_func(*args, **kwargs)
  File "/usr/local/lib/python2.7/dist-packages/django/contrib/auth/decorators.py", line 22, in _wrapped_view
    return view_func(request, *args, **kwargs)
  File "/usr/local/lib/python2.7/dist-packages/django/utils/decorators.py", line 25, in bound_func
    return func(self, *args2, **kwargs2)
  File "/home/mikhail/EclipseWorkspace/oncoFinder2/oncoFinder2/core/views.py", line 48, in dispatch
    return super(CoreSetCalculationParameters, self).dispatch(request, *args, **kwargs)
  File "/usr/local/lib/python2.7/dist-packages/django/views/generic/base.py", line 87, in dispatch
    return handler(request, *args, **kwargs)
  File "/usr/local/lib/python2.7/dist-packages/django/views/generic/edit.py", line 171, in post
    return self.form_valid(form)
  File "/home/mikhail/EclipseWorkspace/oncoFinder2/oncoFinder2/core/views.py", line 373, in form_valid
    bbb = np.log(aaa, axis=1)
TypeError: 'axis' is an invalid keyword to ufunc 'log'
2015-08-24 14:14:04,814 ERROR base 25049 -1357833408 Internal Server Error: /calculation-parameters/doc7008/
Traceback (most recent call last):
  File "/usr/local/lib/python2.7/dist-packages/django/core/handlers/base.py", line 112, in get_response
    response = wrapped_callback(request, *callback_args, **callback_kwargs)
  File "/usr/local/lib/python2.7/dist-packages/django/views/generic/base.py", line 69, in view
    return self.dispatch(request, *args, **kwargs)
  File "/usr/local/lib/python2.7/dist-packages/django/utils/decorators.py", line 29, in _wrapper
    return bound_func(*args, **kwargs)
  File "/usr/local/lib/python2.7/dist-packages/django/contrib/auth/decorators.py", line 22, in _wrapped_view
    return view_func(request, *args, **kwargs)
  File "/usr/local/lib/python2.7/dist-packages/django/utils/decorators.py", line 25, in bound_func
    return func(self, *args2, **kwargs2)
  File "/home/mikhail/EclipseWorkspace/oncoFinder2/oncoFinder2/core/views.py", line 48, in dispatch
    return super(CoreSetCalculationParameters, self).dispatch(request, *args, **kwargs)
  File "/usr/local/lib/python2.7/dist-packages/django/views/generic/base.py", line 87, in dispatch
    return handler(request, *args, **kwargs)
  File "/usr/local/lib/python2.7/dist-packages/django/views/generic/edit.py", line 171, in post
    return self.form_valid(form)
  File "/home/mikhail/EclipseWorkspace/oncoFinder2/oncoFinder2/core/views.py", line 374, in form_valid
    pas1_norms_samples = np.log(joined_df[tumour_columns+normal_columns])
AttributeError: log
2015-08-24 14:14:39,215 ERROR base 25255 -1357907136 Internal Server Error: /calculation-parameters/doc7008/
Traceback (most recent call last):
  File "/usr/local/lib/python2.7/dist-packages/django/core/handlers/base.py", line 112, in get_response
    response = wrapped_callback(request, *callback_args, **callback_kwargs)
  File "/usr/local/lib/python2.7/dist-packages/django/views/generic/base.py", line 69, in view
    return self.dispatch(request, *args, **kwargs)
  File "/usr/local/lib/python2.7/dist-packages/django/utils/decorators.py", line 29, in _wrapper
    return bound_func(*args, **kwargs)
  File "/usr/local/lib/python2.7/dist-packages/django/contrib/auth/decorators.py", line 22, in _wrapped_view
    return view_func(request, *args, **kwargs)
  File "/usr/local/lib/python2.7/dist-packages/django/utils/decorators.py", line 25, in bound_func
    return func(self, *args2, **kwargs2)
  File "/home/mikhail/EclipseWorkspace/oncoFinder2/oncoFinder2/core/views.py", line 48, in dispatch
    return super(CoreSetCalculationParameters, self).dispatch(request, *args, **kwargs)
  File "/usr/local/lib/python2.7/dist-packages/django/views/generic/base.py", line 87, in dispatch
    return handler(request, *args, **kwargs)
  File "/usr/local/lib/python2.7/dist-packages/django/views/generic/edit.py", line 171, in post
    return self.form_valid(form)
  File "/home/mikhail/EclipseWorkspace/oncoFinder2/oncoFinder2/core/views.py", line 374, in form_valid
    pas1_norms_samples = np.log(joined_df[tumour_columns+normal_columns])
AttributeError: log
2015-08-24 14:16:52,213 ERROR base 26084 -1357907136 Internal Server Error: /calculation-parameters/doc7008/
Traceback (most recent call last):
  File "/usr/local/lib/python2.7/dist-packages/django/core/handlers/base.py", line 112, in get_response
    response = wrapped_callback(request, *callback_args, **callback_kwargs)
  File "/usr/local/lib/python2.7/dist-packages/django/views/generic/base.py", line 69, in view
    return self.dispatch(request, *args, **kwargs)
  File "/usr/local/lib/python2.7/dist-packages/django/utils/decorators.py", line 29, in _wrapper
    return bound_func(*args, **kwargs)
  File "/usr/local/lib/python2.7/dist-packages/django/contrib/auth/decorators.py", line 22, in _wrapped_view
    return view_func(request, *args, **kwargs)
  File "/usr/local/lib/python2.7/dist-packages/django/utils/decorators.py", line 25, in bound_func
    return func(self, *args2, **kwargs2)
  File "/home/mikhail/EclipseWorkspace/oncoFinder2/oncoFinder2/core/views.py", line 48, in dispatch
    return super(CoreSetCalculationParameters, self).dispatch(request, *args, **kwargs)
  File "/usr/local/lib/python2.7/dist-packages/django/views/generic/base.py", line 87, in dispatch
    return handler(request, *args, **kwargs)
  File "/usr/local/lib/python2.7/dist-packages/django/views/generic/edit.py", line 171, in post
    return self.form_valid(form)
  File "/home/mikhail/EclipseWorkspace/oncoFinder2/oncoFinder2/core/views.py", line 374, in form_valid
    pas1_norms_samples = np.log(joined_df[tumour_columns+normal_columns])
AttributeError: log
2015-08-24 14:17:30,247 ERROR base 26366 -1357907136 Internal Server Error: /calculation-parameters/doc7008/
Traceback (most recent call last):
  File "/usr/local/lib/python2.7/dist-packages/django/core/handlers/base.py", line 112, in get_response
    response = wrapped_callback(request, *callback_args, **callback_kwargs)
  File "/usr/local/lib/python2.7/dist-packages/django/views/generic/base.py", line 69, in view
    return self.dispatch(request, *args, **kwargs)
  File "/usr/local/lib/python2.7/dist-packages/django/utils/decorators.py", line 29, in _wrapper
    return bound_func(*args, **kwargs)
  File "/usr/local/lib/python2.7/dist-packages/django/contrib/auth/decorators.py", line 22, in _wrapped_view
    return view_func(request, *args, **kwargs)
  File "/usr/local/lib/python2.7/dist-packages/django/utils/decorators.py", line 25, in bound_func
    return func(self, *args2, **kwargs2)
  File "/home/mikhail/EclipseWorkspace/oncoFinder2/oncoFinder2/core/views.py", line 48, in dispatch
    return super(CoreSetCalculationParameters, self).dispatch(request, *args, **kwargs)
  File "/usr/local/lib/python2.7/dist-packages/django/views/generic/base.py", line 87, in dispatch
    return handler(request, *args, **kwargs)
  File "/usr/local/lib/python2.7/dist-packages/django/views/generic/edit.py", line 171, in post
    return self.form_valid(form)
  File "/home/mikhail/EclipseWorkspace/oncoFinder2/oncoFinder2/core/views.py", line 835, in form_valid
    cnr_doc_df.to_excel(writer,'CNR')
  File "/usr/local/lib/python2.7/dist-packages/pandas/core/frame.py", line 1267, in to_excel
    startrow=startrow, startcol=startcol)
  File "/usr/local/lib/python2.7/dist-packages/pandas/io/excel.py", line 1339, in write_cells
    cell.val, style)
  File "/usr/local/lib/python2.7/dist-packages/xlsxwriter/worksheet.py", line 63, in cell_wrapper
    return method(self, *args, **kwargs)
  File "/usr/local/lib/python2.7/dist-packages/xlsxwriter/worksheet.py", line 430, in write
    raise TypeError("Unsupported type %s in write()" % type(token))
TypeError: Unsupported type <class 'numpy.ma.core.MaskedConstant'> in write()
2015-08-24 14:20:20,270 ERROR base 27643 -1357833408 Internal Server Error: /calculation-parameters/doc7008/
Traceback (most recent call last):
  File "/usr/local/lib/python2.7/dist-packages/django/core/handlers/base.py", line 112, in get_response
    response = wrapped_callback(request, *callback_args, **callback_kwargs)
  File "/usr/local/lib/python2.7/dist-packages/django/views/generic/base.py", line 69, in view
    return self.dispatch(request, *args, **kwargs)
  File "/usr/local/lib/python2.7/dist-packages/django/utils/decorators.py", line 29, in _wrapper
    return bound_func(*args, **kwargs)
  File "/usr/local/lib/python2.7/dist-packages/django/contrib/auth/decorators.py", line 22, in _wrapped_view
    return view_func(request, *args, **kwargs)
  File "/usr/local/lib/python2.7/dist-packages/django/utils/decorators.py", line 25, in bound_func
    return func(self, *args2, **kwargs2)
  File "/home/mikhail/EclipseWorkspace/oncoFinder2/oncoFinder2/core/views.py", line 48, in dispatch
    return super(CoreSetCalculationParameters, self).dispatch(request, *args, **kwargs)
  File "/usr/local/lib/python2.7/dist-packages/django/views/generic/base.py", line 87, in dispatch
    return handler(request, *args, **kwargs)
  File "/usr/local/lib/python2.7/dist-packages/django/views/generic/edit.py", line 171, in post
    return self.form_valid(form)
  File "/home/mikhail/EclipseWorkspace/oncoFinder2/oncoFinder2/core/views.py", line 836, in form_valid
    cnr_doc_df.to_excel(writer,'CNR')
  File "/usr/local/lib/python2.7/dist-packages/pandas/core/frame.py", line 1267, in to_excel
    startrow=startrow, startcol=startcol)
  File "/usr/local/lib/python2.7/dist-packages/pandas/io/excel.py", line 1339, in write_cells
    cell.val, style)
  File "/usr/local/lib/python2.7/dist-packages/xlsxwriter/worksheet.py", line 63, in cell_wrapper
    return method(self, *args, **kwargs)
  File "/usr/local/lib/python2.7/dist-packages/xlsxwriter/worksheet.py", line 430, in write
    raise TypeError("Unsupported type %s in write()" % type(token))
TypeError: Unsupported type <class 'numpy.ma.core.MaskedConstant'> in write()
2015-08-24 14:21:59,819 ERROR base 27643 -1448092864 Internal Server Error: /document/doc7011/Tumour_X5500024052861011409506.H02.CEL_p-val/
Traceback (most recent call last):
  File "/usr/local/lib/python2.7/dist-packages/django/core/handlers/base.py", line 112, in get_response
    response = wrapped_callback(request, *callback_args, **callback_kwargs)
  File "/usr/local/lib/python2.7/dist-packages/django/views/generic/base.py", line 69, in view
    return self.dispatch(request, *args, **kwargs)
  File "/usr/local/lib/python2.7/dist-packages/django/utils/decorators.py", line 29, in _wrapper
    return bound_func(*args, **kwargs)
  File "/usr/local/lib/python2.7/dist-packages/django/contrib/auth/decorators.py", line 22, in _wrapped_view
    return view_func(request, *args, **kwargs)
  File "/usr/local/lib/python2.7/dist-packages/django/utils/decorators.py", line 25, in bound_func
    return func(self, *args2, **kwargs2)
  File "/home/mikhail/EclipseWorkspace/oncoFinder2/oncoFinder2/profiles/views.py", line 402, in dispatch
    return super(SampleDetail, self).dispatch(request, *args, **kwargs)
  File "/usr/local/lib/python2.7/dist-packages/django/views/generic/base.py", line 87, in dispatch
    return handler(request, *args, **kwargs)
  File "/usr/local/lib/python2.7/dist-packages/django/views/generic/detail.py", line 111, in get
    context = self.get_context_data(object=self.object)
  File "/home/mikhail/EclipseWorkspace/oncoFinder2/oncoFinder2/profiles/views.py", line 419, in get_context_data
    df_cnr_raw = df_file_cnr[[sample, 'gMean_norm', 'std']]
  File "/usr/local/lib/python2.7/dist-packages/pandas/core/frame.py", line 1781, in __getitem__
    return self._getitem_array(key)
  File "/usr/local/lib/python2.7/dist-packages/pandas/core/frame.py", line 1825, in _getitem_array
    indexer = self.ix._convert_to_indexer(key, axis=1)
  File "/usr/local/lib/python2.7/dist-packages/pandas/core/indexing.py", line 1140, in _convert_to_indexer
    raise KeyError('%s not in index' % objarr[mask])
KeyError: "[u'Tumour_X5500024052861011409506.H02.CEL_p-val'] not in index"
2015-08-24 14:23:14,659 ERROR base 28775 -1357907136 Internal Server Error: /calculation-parameters/doc7008/
Traceback (most recent call last):
  File "/usr/local/lib/python2.7/dist-packages/django/core/handlers/base.py", line 112, in get_response
    response = wrapped_callback(request, *callback_args, **callback_kwargs)
  File "/usr/local/lib/python2.7/dist-packages/django/views/generic/base.py", line 69, in view
    return self.dispatch(request, *args, **kwargs)
  File "/usr/local/lib/python2.7/dist-packages/django/utils/decorators.py", line 29, in _wrapper
    return bound_func(*args, **kwargs)
  File "/usr/local/lib/python2.7/dist-packages/django/contrib/auth/decorators.py", line 22, in _wrapped_view
    return view_func(request, *args, **kwargs)
  File "/usr/local/lib/python2.7/dist-packages/django/utils/decorators.py", line 25, in bound_func
    return func(self, *args2, **kwargs2)
  File "/home/mikhail/EclipseWorkspace/oncoFinder2/oncoFinder2/core/views.py", line 48, in dispatch
    return super(CoreSetCalculationParameters, self).dispatch(request, *args, **kwargs)
  File "/usr/local/lib/python2.7/dist-packages/django/views/generic/base.py", line 87, in dispatch
    return handler(request, *args, **kwargs)
  File "/usr/local/lib/python2.7/dist-packages/django/views/generic/edit.py", line 171, in post
    return self.form_valid(form)
  File "/home/mikhail/EclipseWorkspace/oncoFinder2/oncoFinder2/core/views.py", line 836, in form_valid
    cnr_doc_df.to_excel(writer,'CNR')
  File "/usr/local/lib/python2.7/dist-packages/pandas/core/frame.py", line 1267, in to_excel
    startrow=startrow, startcol=startcol)
  File "/usr/local/lib/python2.7/dist-packages/pandas/io/excel.py", line 1339, in write_cells
    cell.val, style)
  File "/usr/local/lib/python2.7/dist-packages/xlsxwriter/worksheet.py", line 63, in cell_wrapper
    return method(self, *args, **kwargs)
  File "/usr/local/lib/python2.7/dist-packages/xlsxwriter/worksheet.py", line 430, in write
    raise TypeError("Unsupported type %s in write()" % type(token))
TypeError: Unsupported type <class 'numpy.ma.core.MaskedConstant'> in write()
2015-08-24 14:25:24,736 ERROR base 29606 -1358955712 Internal Server Error: /calculation-parameters/doc7008/
Traceback (most recent call last):
  File "/usr/local/lib/python2.7/dist-packages/django/core/handlers/base.py", line 112, in get_response
    response = wrapped_callback(request, *callback_args, **callback_kwargs)
  File "/usr/local/lib/python2.7/dist-packages/django/views/generic/base.py", line 69, in view
    return self.dispatch(request, *args, **kwargs)
  File "/usr/local/lib/python2.7/dist-packages/django/utils/decorators.py", line 29, in _wrapper
    return bound_func(*args, **kwargs)
  File "/usr/local/lib/python2.7/dist-packages/django/contrib/auth/decorators.py", line 22, in _wrapped_view
    return view_func(request, *args, **kwargs)
  File "/usr/local/lib/python2.7/dist-packages/django/utils/decorators.py", line 25, in bound_func
    return func(self, *args2, **kwargs2)
  File "/home/mikhail/EclipseWorkspace/oncoFinder2/oncoFinder2/core/views.py", line 48, in dispatch
    return super(CoreSetCalculationParameters, self).dispatch(request, *args, **kwargs)
  File "/usr/local/lib/python2.7/dist-packages/django/views/generic/base.py", line 87, in dispatch
    return handler(request, *args, **kwargs)
  File "/usr/local/lib/python2.7/dist-packages/django/views/generic/edit.py", line 171, in post
    return self.form_valid(form)
  File "/home/mikhail/EclipseWorkspace/oncoFinder2/oncoFinder2/core/views.py", line 834, in form_valid
    cnr_doc_df.fillna(0, inplace=True).astype('float32')
AttributeError: 'NoneType' object has no attribute 'astype'
2015-08-24 14:25:54,501 ERROR base 29917 -1358955712 Internal Server Error: /calculation-parameters/doc7008/
Traceback (most recent call last):
  File "/usr/local/lib/python2.7/dist-packages/django/core/handlers/base.py", line 112, in get_response
    response = wrapped_callback(request, *callback_args, **callback_kwargs)
  File "/usr/local/lib/python2.7/dist-packages/django/views/generic/base.py", line 69, in view
    return self.dispatch(request, *args, **kwargs)
  File "/usr/local/lib/python2.7/dist-packages/django/utils/decorators.py", line 29, in _wrapper
    return bound_func(*args, **kwargs)
  File "/usr/local/lib/python2.7/dist-packages/django/contrib/auth/decorators.py", line 22, in _wrapped_view
    return view_func(request, *args, **kwargs)
  File "/usr/local/lib/python2.7/dist-packages/django/utils/decorators.py", line 25, in bound_func
    return func(self, *args2, **kwargs2)
  File "/home/mikhail/EclipseWorkspace/oncoFinder2/oncoFinder2/core/views.py", line 48, in dispatch
    return super(CoreSetCalculationParameters, self).dispatch(request, *args, **kwargs)
  File "/usr/local/lib/python2.7/dist-packages/django/views/generic/base.py", line 87, in dispatch
    return handler(request, *args, **kwargs)
  File "/usr/local/lib/python2.7/dist-packages/django/views/generic/edit.py", line 171, in post
    return self.form_valid(form)
  File "/home/mikhail/EclipseWorkspace/oncoFinder2/oncoFinder2/core/views.py", line 836, in form_valid
    cnr_doc_df.to_excel(writer,'CNR')
  File "/usr/local/lib/python2.7/dist-packages/pandas/core/frame.py", line 1267, in to_excel
    startrow=startrow, startcol=startcol)
  File "/usr/local/lib/python2.7/dist-packages/pandas/io/excel.py", line 1339, in write_cells
    cell.val, style)
  File "/usr/local/lib/python2.7/dist-packages/xlsxwriter/worksheet.py", line 63, in cell_wrapper
    return method(self, *args, **kwargs)
  File "/usr/local/lib/python2.7/dist-packages/xlsxwriter/worksheet.py", line 430, in write
    raise TypeError("Unsupported type %s in write()" % type(token))
TypeError: Unsupported type <class 'numpy.ma.core.MaskedConstant'> in write()
2015-08-24 14:27:23,162 ERROR base 30492 -1357284544 Internal Server Error: /calculation-parameters/doc7008/
Traceback (most recent call last):
  File "/usr/local/lib/python2.7/dist-packages/django/core/handlers/base.py", line 112, in get_response
    response = wrapped_callback(request, *callback_args, **callback_kwargs)
  File "/usr/local/lib/python2.7/dist-packages/django/views/generic/base.py", line 69, in view
    return self.dispatch(request, *args, **kwargs)
  File "/usr/local/lib/python2.7/dist-packages/django/utils/decorators.py", line 29, in _wrapper
    return bound_func(*args, **kwargs)
  File "/usr/local/lib/python2.7/dist-packages/django/contrib/auth/decorators.py", line 22, in _wrapped_view
    return view_func(request, *args, **kwargs)
  File "/usr/local/lib/python2.7/dist-packages/django/utils/decorators.py", line 25, in bound_func
    return func(self, *args2, **kwargs2)
  File "/home/mikhail/EclipseWorkspace/oncoFinder2/oncoFinder2/core/views.py", line 48, in dispatch
    return super(CoreSetCalculationParameters, self).dispatch(request, *args, **kwargs)
  File "/usr/local/lib/python2.7/dist-packages/django/views/generic/base.py", line 87, in dispatch
    return handler(request, *args, **kwargs)
  File "/usr/local/lib/python2.7/dist-packages/django/views/generic/edit.py", line 171, in post
    return self.form_valid(form)
  File "/home/mikhail/EclipseWorkspace/oncoFinder2/oncoFinder2/core/views.py", line 836, in form_valid
    cnr_doc_df.to_excel(writer,'CNR')
  File "/usr/local/lib/python2.7/dist-packages/pandas/core/frame.py", line 1267, in to_excel
    startrow=startrow, startcol=startcol)
  File "/usr/local/lib/python2.7/dist-packages/pandas/io/excel.py", line 1339, in write_cells
    cell.val, style)
  File "/usr/local/lib/python2.7/dist-packages/xlsxwriter/worksheet.py", line 63, in cell_wrapper
    return method(self, *args, **kwargs)
  File "/usr/local/lib/python2.7/dist-packages/xlsxwriter/worksheet.py", line 430, in write
    raise TypeError("Unsupported type %s in write()" % type(token))
TypeError: Unsupported type <class 'numpy.ma.core.MaskedConstant'> in write()
2015-08-24 14:30:47,908 ERROR base 31786 -1357284544 Internal Server Error: /calculation-parameters/doc7008/
Traceback (most recent call last):
  File "/usr/local/lib/python2.7/dist-packages/django/core/handlers/base.py", line 112, in get_response
    response = wrapped_callback(request, *callback_args, **callback_kwargs)
  File "/usr/local/lib/python2.7/dist-packages/django/views/generic/base.py", line 69, in view
    return self.dispatch(request, *args, **kwargs)
  File "/usr/local/lib/python2.7/dist-packages/django/utils/decorators.py", line 29, in _wrapper
    return bound_func(*args, **kwargs)
  File "/usr/local/lib/python2.7/dist-packages/django/contrib/auth/decorators.py", line 22, in _wrapped_view
    return view_func(request, *args, **kwargs)
  File "/usr/local/lib/python2.7/dist-packages/django/utils/decorators.py", line 25, in bound_func
    return func(self, *args2, **kwargs2)
  File "/home/mikhail/EclipseWorkspace/oncoFinder2/oncoFinder2/core/views.py", line 48, in dispatch
    return super(CoreSetCalculationParameters, self).dispatch(request, *args, **kwargs)
  File "/usr/local/lib/python2.7/dist-packages/django/views/generic/base.py", line 87, in dispatch
    return handler(request, *args, **kwargs)
  File "/usr/local/lib/python2.7/dist-packages/django/views/generic/edit.py", line 171, in post
    return self.form_valid(form)
  File "/home/mikhail/EclipseWorkspace/oncoFinder2/oncoFinder2/core/views.py", line 834, in form_valid
    cnr_doc_df.to_excel(output_file,sheet_name='CNR')
  File "/usr/local/lib/python2.7/dist-packages/pandas/core/frame.py", line 1267, in to_excel
    startrow=startrow, startcol=startcol)
  File "/usr/local/lib/python2.7/dist-packages/pandas/io/excel.py", line 1339, in write_cells
    cell.val, style)
  File "/usr/local/lib/python2.7/dist-packages/xlsxwriter/worksheet.py", line 63, in cell_wrapper
    return method(self, *args, **kwargs)
  File "/usr/local/lib/python2.7/dist-packages/xlsxwriter/worksheet.py", line 430, in write
    raise TypeError("Unsupported type %s in write()" % type(token))
TypeError: Unsupported type <class 'numpy.ma.core.MaskedConstant'> in write()
2015-08-24 14:31:25,499 ERROR base 32097 -1357907136 Internal Server Error: /calculation-parameters/doc7008/
Traceback (most recent call last):
  File "/usr/local/lib/python2.7/dist-packages/django/core/handlers/base.py", line 112, in get_response
    response = wrapped_callback(request, *callback_args, **callback_kwargs)
  File "/usr/local/lib/python2.7/dist-packages/django/views/generic/base.py", line 69, in view
    return self.dispatch(request, *args, **kwargs)
  File "/usr/local/lib/python2.7/dist-packages/django/utils/decorators.py", line 29, in _wrapper
    return bound_func(*args, **kwargs)
  File "/usr/local/lib/python2.7/dist-packages/django/contrib/auth/decorators.py", line 22, in _wrapped_view
    return view_func(request, *args, **kwargs)
  File "/usr/local/lib/python2.7/dist-packages/django/utils/decorators.py", line 25, in bound_func
    return func(self, *args2, **kwargs2)
  File "/home/mikhail/EclipseWorkspace/oncoFinder2/oncoFinder2/core/views.py", line 48, in dispatch
    return super(CoreSetCalculationParameters, self).dispatch(request, *args, **kwargs)
  File "/usr/local/lib/python2.7/dist-packages/django/views/generic/base.py", line 87, in dispatch
    return handler(request, *args, **kwargs)
  File "/usr/local/lib/python2.7/dist-packages/django/views/generic/edit.py", line 171, in post
    return self.form_valid(form)
  File "/home/mikhail/EclipseWorkspace/oncoFinder2/oncoFinder2/core/views.py", line 834, in form_valid
    cnr_doc_df.to_excel(output_file,sheet_name='CNR')
  File "/usr/local/lib/python2.7/dist-packages/pandas/core/frame.py", line 1267, in to_excel
    startrow=startrow, startcol=startcol)
  File "/usr/local/lib/python2.7/dist-packages/pandas/io/excel.py", line 1339, in write_cells
    cell.val, style)
  File "/usr/local/lib/python2.7/dist-packages/xlsxwriter/worksheet.py", line 63, in cell_wrapper
    return method(self, *args, **kwargs)
  File "/usr/local/lib/python2.7/dist-packages/xlsxwriter/worksheet.py", line 430, in write
    raise TypeError("Unsupported type %s in write()" % type(token))
TypeError: Unsupported type <class 'numpy.ma.core.MaskedConstant'> in write()
2015-09-04 09:25:07,327 ERROR base 31871 -1359930560 Internal Server Error: /utils/path
Traceback (most recent call last):
  File "/usr/local/lib/python2.7/dist-packages/django/core/handlers/base.py", line 112, in get_response
    response = wrapped_callback(request, *callback_args, **callback_kwargs)
  File "/usr/local/lib/python2.7/dist-packages/django/views/generic/base.py", line 69, in view
    return self.dispatch(request, *args, **kwargs)
  File "/usr/local/lib/python2.7/dist-packages/django/utils/decorators.py", line 29, in _wrapper
    return bound_func(*args, **kwargs)
  File "/usr/local/lib/python2.7/dist-packages/django/contrib/auth/decorators.py", line 22, in _wrapped_view
    return view_func(request, *args, **kwargs)
  File "/usr/local/lib/python2.7/dist-packages/django/utils/decorators.py", line 25, in bound_func
    return func(self, *args2, **kwargs2)
  File "/home/mikhail/EclipseWorkspace/oncoFinder2/oncoFinder2/core/utils_views.py", line 185, in dispatch
    return super(ConvertPath, self).dispatch(request, *args, **kwargs)
  File "/usr/local/lib/python2.7/dist-packages/django/views/generic/base.py", line 87, in dispatch
    return handler(request, *args, **kwargs)
  File "/usr/local/lib/python2.7/dist-packages/django/views/generic/base.py", line 154, in get
    context = self.get_context_data(**kwargs)
  File "/home/mikhail/EclipseWorkspace/oncoFinder2/oncoFinder2/core/utils_views.py", line 193, in get_context_data
    raise Exception('just stop exception. Check view!')
Exception: just stop exception. Check view!
2015-09-04 10:15:34,593 ERROR base 1108 -1358496960 Internal Server Error: /utils/path
Traceback (most recent call last):
  File "/usr/local/lib/python2.7/dist-packages/django/core/handlers/base.py", line 112, in get_response
    response = wrapped_callback(request, *callback_args, **callback_kwargs)
  File "/usr/local/lib/python2.7/dist-packages/django/views/generic/base.py", line 69, in view
    return self.dispatch(request, *args, **kwargs)
  File "/usr/local/lib/python2.7/dist-packages/django/utils/decorators.py", line 29, in _wrapper
    return bound_func(*args, **kwargs)
  File "/usr/local/lib/python2.7/dist-packages/django/contrib/auth/decorators.py", line 22, in _wrapped_view
    return view_func(request, *args, **kwargs)
  File "/usr/local/lib/python2.7/dist-packages/django/utils/decorators.py", line 25, in bound_func
    return func(self, *args2, **kwargs2)
  File "/home/mikhail/EclipseWorkspace/oncoFinder2/oncoFinder2/core/utils_views.py", line 185, in dispatch
    return super(ConvertPath, self).dispatch(request, *args, **kwargs)
  File "/usr/local/lib/python2.7/dist-packages/django/views/generic/base.py", line 87, in dispatch
    return handler(request, *args, **kwargs)
  File "/usr/local/lib/python2.7/dist-packages/django/views/generic/base.py", line 154, in get
    context = self.get_context_data(**kwargs)
  File "/home/mikhail/EclipseWorkspace/oncoFinder2/oncoFinder2/core/utils_views.py", line 361, in get_context_data
    raise Exception('NCI Done')
Exception: NCI Done
2015-09-04 10:31:10,559 ERROR base 25321 -1387271360 Internal Server Error: /db/pathways/human/nci/nci_a6b1_and_a6b4_integrin_signaling_pathway_cell_migration/4779/
Traceback (most recent call last):
  File "/usr/local/lib/python2.7/dist-packages/django/core/handlers/base.py", line 112, in get_response
    response = wrapped_callback(request, *callback_args, **callback_kwargs)
  File "/usr/local/lib/python2.7/dist-packages/django/views/generic/base.py", line 69, in view
    return self.dispatch(request, *args, **kwargs)
  File "/usr/local/lib/python2.7/dist-packages/django/utils/decorators.py", line 29, in _wrapper
    return bound_func(*args, **kwargs)
  File "/usr/local/lib/python2.7/dist-packages/django/contrib/auth/decorators.py", line 22, in _wrapped_view
    return view_func(request, *args, **kwargs)
  File "/usr/local/lib/python2.7/dist-packages/django/utils/decorators.py", line 25, in bound_func
    return func(self, *args2, **kwargs2)
  File "/usr/local/lib/python2.7/dist-packages/django/utils/decorators.py", line 29, in _wrapper
    return bound_func(*args, **kwargs)
  File "/usr/local/lib/python2.7/dist-packages/django/contrib/admin/views/decorators.py", line 17, in _checklogin
    return view_func(request, *args, **kwargs)
  File "/usr/local/lib/python2.7/dist-packages/django/utils/decorators.py", line 25, in bound_func
    return func(self, *args2, **kwargs2)
  File "/home/mikhail/EclipseWorkspace/oncoFinder2/oncoFinder2/database/views.py", line 53, in dispatch
    return super(PathwayDetail, self).dispatch(request, *args, **kwargs)
  File "/usr/local/lib/python2.7/dist-packages/django/views/generic/base.py", line 87, in dispatch
    return handler(request, *args, **kwargs)
  File "/usr/local/lib/python2.7/dist-packages/django/views/generic/detail.py", line 111, in get
    context = self.get_context_data(object=self.object)
  File "/home/mikhail/EclipseWorkspace/oncoFinder2/oncoFinder2/database/views.py", line 79, in get_context_data
    A.draw(settings.MEDIA_ROOT+"/pathway_pics/"+self.object.organism+"/"+self.object.database+"/"+self.object.name+".svg")
  File "/usr/local/lib/python2.7/dist-packages/pygraphviz-1.3rc2-py2.7-linux-i686.egg/pygraphviz/agraph.py", line 1471, in draw
    fh = self._get_fh(path, 'w+b')
  File "/usr/local/lib/python2.7/dist-packages/pygraphviz-1.3rc2-py2.7-linux-i686.egg/pygraphviz/agraph.py", line 1500, in _get_fh
    fh = open(path, mode=mode)
IOError: [Errno 2] No such file or directory: u'/home/mikhail/EclipseWorkspace/oncoFinder2/oncoFinder2/oncoFinder2/media/pathway_pics/human/nci/NCI_a6b1_and_a6b4_Integrin_signaling_Pathway_(cell_migration).svg'
2015-09-04 10:36:52,347 ERROR base 28335 -1408246976 Internal Server Error: /document/doc6928/
Traceback (most recent call last):
  File "/usr/local/lib/python2.7/dist-packages/django/core/handlers/base.py", line 112, in get_response
    response = wrapped_callback(request, *callback_args, **callback_kwargs)
  File "/usr/local/lib/python2.7/dist-packages/django/views/generic/base.py", line 69, in view
    return self.dispatch(request, *args, **kwargs)
  File "/usr/local/lib/python2.7/dist-packages/django/utils/decorators.py", line 29, in _wrapper
    return bound_func(*args, **kwargs)
  File "/usr/local/lib/python2.7/dist-packages/django/contrib/auth/decorators.py", line 22, in _wrapped_view
    return view_func(request, *args, **kwargs)
  File "/usr/local/lib/python2.7/dist-packages/django/utils/decorators.py", line 25, in bound_func
    return func(self, *args2, **kwargs2)
  File "/home/mikhail/EclipseWorkspace/oncoFinder2/oncoFinder2/profiles/views.py", line 301, in dispatch
    return super(DocumentDetail, self).dispatch(request, *args, **kwargs)
  File "/usr/local/lib/python2.7/dist-packages/django/views/generic/base.py", line 87, in dispatch
    return handler(request, *args, **kwargs)
  File "/usr/local/lib/python2.7/dist-packages/django/views/generic/detail.py", line 111, in get
    context = self.get_context_data(object=self.object)
  File "/home/mikhail/EclipseWorkspace/oncoFinder2/oncoFinder2/profiles/views.py", line 309, in get_context_data
    dialect = sniffer.sniff(open(filename, 'r').read(), delimiters='\t,;') # defining the separator of the csv file
IOError: [Errno 2] No such file or directory: u'/home/mikhail/EclipseWorkspace/oncoFinder2/oncoFinder2/oncoFinder2/media/users/admin/fast-calculations/input/gcrma11.csv'
2015-09-08 15:29:58,873 ERROR base 5486 -1405093056 Internal Server Error: /test/
Traceback (most recent call last):
  File "/usr/local/lib/python2.7/dist-packages/django/core/handlers/base.py", line 112, in get_response
    response = wrapped_callback(request, *callback_args, **callback_kwargs)
  File "/usr/local/lib/python2.7/dist-packages/django/views/generic/base.py", line 69, in view
    return self.dispatch(request, *args, **kwargs)
  File "/usr/local/lib/python2.7/dist-packages/django/utils/decorators.py", line 29, in _wrapper
    return bound_func(*args, **kwargs)
  File "/usr/local/lib/python2.7/dist-packages/django/contrib/auth/decorators.py", line 22, in _wrapped_view
    return view_func(request, *args, **kwargs)
  File "/usr/local/lib/python2.7/dist-packages/django/utils/decorators.py", line 25, in bound_func
    return func(self, *args2, **kwargs2)
  File "/home/mikhail/EclipseWorkspace/oncoFinder2/oncoFinder2/core/views.py", line 936, in dispatch
    return super(Test, self).dispatch(request, *args, **kwargs)
  File "/usr/local/lib/python2.7/dist-packages/django/views/generic/base.py", line 87, in dispatch
    return handler(request, *args, **kwargs)
  File "/usr/local/lib/python2.7/dist-packages/django/views/generic/base.py", line 154, in get
    context = self.get_context_data(**kwargs)
  File "/home/mikhail/EclipseWorkspace/oncoFinder2/oncoFinder2/core/views.py", line 944, in get_context_data
    raise Exception('test')
Exception: test
2015-09-08 15:31:39,102 ERROR base 6729 -1360004288 Internal Server Error: /test/
Traceback (most recent call last):
  File "/usr/local/lib/python2.7/dist-packages/django/core/handlers/base.py", line 112, in get_response
    response = wrapped_callback(request, *callback_args, **callback_kwargs)
  File "/usr/local/lib/python2.7/dist-packages/django/views/generic/base.py", line 69, in view
    return self.dispatch(request, *args, **kwargs)
  File "/usr/local/lib/python2.7/dist-packages/django/utils/decorators.py", line 29, in _wrapper
    return bound_func(*args, **kwargs)
  File "/usr/local/lib/python2.7/dist-packages/django/contrib/auth/decorators.py", line 22, in _wrapped_view
    return view_func(request, *args, **kwargs)
  File "/usr/local/lib/python2.7/dist-packages/django/utils/decorators.py", line 25, in bound_func
    return func(self, *args2, **kwargs2)
  File "/home/mikhail/EclipseWorkspace/oncoFinder2/oncoFinder2/core/views.py", line 936, in dispatch
    return super(Test, self).dispatch(request, *args, **kwargs)
  File "/usr/local/lib/python2.7/dist-packages/django/views/generic/base.py", line 87, in dispatch
    return handler(request, *args, **kwargs)
  File "/usr/local/lib/python2.7/dist-packages/django/views/generic/base.py", line 154, in get
    context = self.get_context_data(**kwargs)
  File "/home/mikhail/EclipseWorkspace/oncoFinder2/oncoFinder2/core/views.py", line 943, in get_context_data
    paths = Pathway.objects.filter(organism='human', db='primary_old')
  File "/usr/local/lib/python2.7/dist-packages/django/db/models/manager.py", line 163, in filter
    return self.get_queryset().filter(*args, **kwargs)
  File "/usr/local/lib/python2.7/dist-packages/django/db/models/query.py", line 593, in filter
    return self._filter_or_exclude(False, *args, **kwargs)
  File "/usr/local/lib/python2.7/dist-packages/django/db/models/query.py", line 611, in _filter_or_exclude
    clone.query.add_q(Q(*args, **kwargs))
  File "/usr/local/lib/python2.7/dist-packages/django/db/models/sql/query.py", line 1204, in add_q
    clause = self._add_q(where_part, used_aliases)
  File "/usr/local/lib/python2.7/dist-packages/django/db/models/sql/query.py", line 1240, in _add_q
    current_negated=current_negated)
  File "/usr/local/lib/python2.7/dist-packages/django/db/models/sql/query.py", line 1103, in build_filter
    allow_explicit_fk=True)
  File "/usr/local/lib/python2.7/dist-packages/django/db/models/sql/query.py", line 1363, in setup_joins
    names, opts, allow_many, allow_explicit_fk)
  File "/usr/local/lib/python2.7/dist-packages/django/db/models/sql/query.py", line 1283, in names_to_path
    "Choices are: %s" % (name, ", ".join(available)))
FieldError: Cannot resolve keyword 'db' into field. Choices are: amcf, comment, database, gene, id, image, info, name, node, organism, pathway_id
2015-09-08 15:31:52,543 ERROR base 6881 -1360430272 Internal Server Error: /test/
Traceback (most recent call last):
  File "/usr/local/lib/python2.7/dist-packages/django/core/handlers/base.py", line 112, in get_response
    response = wrapped_callback(request, *callback_args, **callback_kwargs)
  File "/usr/local/lib/python2.7/dist-packages/django/views/generic/base.py", line 69, in view
    return self.dispatch(request, *args, **kwargs)
  File "/usr/local/lib/python2.7/dist-packages/django/utils/decorators.py", line 29, in _wrapper
    return bound_func(*args, **kwargs)
  File "/usr/local/lib/python2.7/dist-packages/django/contrib/auth/decorators.py", line 22, in _wrapped_view
    return view_func(request, *args, **kwargs)
  File "/usr/local/lib/python2.7/dist-packages/django/utils/decorators.py", line 25, in bound_func
    return func(self, *args2, **kwargs2)
  File "/home/mikhail/EclipseWorkspace/oncoFinder2/oncoFinder2/core/views.py", line 936, in dispatch
    return super(Test, self).dispatch(request, *args, **kwargs)
  File "/usr/local/lib/python2.7/dist-packages/django/views/generic/base.py", line 87, in dispatch
    return handler(request, *args, **kwargs)
  File "/usr/local/lib/python2.7/dist-packages/django/views/generic/base.py", line 154, in get
    context = self.get_context_data(**kwargs)
  File "/home/mikhail/EclipseWorkspace/oncoFinder2/oncoFinder2/core/views.py", line 948, in get_context_data
    raise Exception('test')
Exception: test
2015-09-08 15:34:27,990 ERROR base 7947 -1361052864 Internal Server Error: /test/
Traceback (most recent call last):
  File "/usr/local/lib/python2.7/dist-packages/django/core/handlers/base.py", line 112, in get_response
    response = wrapped_callback(request, *callback_args, **callback_kwargs)
  File "/usr/local/lib/python2.7/dist-packages/django/views/generic/base.py", line 69, in view
    return self.dispatch(request, *args, **kwargs)
  File "/usr/local/lib/python2.7/dist-packages/django/utils/decorators.py", line 29, in _wrapper
    return bound_func(*args, **kwargs)
  File "/usr/local/lib/python2.7/dist-packages/django/contrib/auth/decorators.py", line 22, in _wrapped_view
    return view_func(request, *args, **kwargs)
  File "/usr/local/lib/python2.7/dist-packages/django/utils/decorators.py", line 25, in bound_func
    return func(self, *args2, **kwargs2)
  File "/home/mikhail/EclipseWorkspace/oncoFinder2/oncoFinder2/core/views.py", line 936, in dispatch
    return super(Test, self).dispatch(request, *args, **kwargs)
  File "/usr/local/lib/python2.7/dist-packages/django/views/generic/base.py", line 87, in dispatch
    return handler(request, *args, **kwargs)
  File "/usr/local/lib/python2.7/dist-packages/django/views/generic/base.py", line 154, in get
    context = self.get_context_data(**kwargs)
  File "/home/mikhail/EclipseWorkspace/oncoFinder2/oncoFinder2/core/views.py", line 953, in get_context_data
    raise Exception('test')
Exception: test
2015-09-08 15:36:49,417 ERROR base 8870 -1360176320 Internal Server Error: /test/
Traceback (most recent call last):
  File "/usr/local/lib/python2.7/dist-packages/django/core/handlers/base.py", line 112, in get_response
    response = wrapped_callback(request, *callback_args, **callback_kwargs)
  File "/usr/local/lib/python2.7/dist-packages/django/views/generic/base.py", line 69, in view
    return self.dispatch(request, *args, **kwargs)
  File "/usr/local/lib/python2.7/dist-packages/django/utils/decorators.py", line 29, in _wrapper
    return bound_func(*args, **kwargs)
  File "/usr/local/lib/python2.7/dist-packages/django/contrib/auth/decorators.py", line 22, in _wrapped_view
    return view_func(request, *args, **kwargs)
  File "/usr/local/lib/python2.7/dist-packages/django/utils/decorators.py", line 25, in bound_func
    return func(self, *args2, **kwargs2)
  File "/home/mikhail/EclipseWorkspace/oncoFinder2/oncoFinder2/core/views.py", line 936, in dispatch
    return super(Test, self).dispatch(request, *args, **kwargs)
  File "/usr/local/lib/python2.7/dist-packages/django/views/generic/base.py", line 87, in dispatch
    return handler(request, *args, **kwargs)
  File "/usr/local/lib/python2.7/dist-packages/django/views/generic/base.py", line 154, in get
    context = self.get_context_data(**kwargs)
  File "/home/mikhail/EclipseWorkspace/oncoFinder2/oncoFinder2/core/views.py", line 962, in get_context_data
    raise Exception('test')
Exception: test
2015-09-08 15:37:37,171 ERROR base 9170 -1359930560 Internal Server Error: /test/
Traceback (most recent call last):
  File "/usr/local/lib/python2.7/dist-packages/django/core/handlers/base.py", line 112, in get_response
    response = wrapped_callback(request, *callback_args, **callback_kwargs)
  File "/usr/local/lib/python2.7/dist-packages/django/views/generic/base.py", line 69, in view
    return self.dispatch(request, *args, **kwargs)
  File "/usr/local/lib/python2.7/dist-packages/django/utils/decorators.py", line 29, in _wrapper
    return bound_func(*args, **kwargs)
  File "/usr/local/lib/python2.7/dist-packages/django/contrib/auth/decorators.py", line 22, in _wrapped_view
    return view_func(request, *args, **kwargs)
  File "/usr/local/lib/python2.7/dist-packages/django/utils/decorators.py", line 25, in bound_func
    return func(self, *args2, **kwargs2)
  File "/home/mikhail/EclipseWorkspace/oncoFinder2/oncoFinder2/core/views.py", line 936, in dispatch
    return super(Test, self).dispatch(request, *args, **kwargs)
  File "/usr/local/lib/python2.7/dist-packages/django/views/generic/base.py", line 87, in dispatch
    return handler(request, *args, **kwargs)
  File "/usr/local/lib/python2.7/dist-packages/django/views/generic/base.py", line 154, in get
    context = self.get_context_data(**kwargs)
  File "/home/mikhail/EclipseWorkspace/oncoFinder2/oncoFinder2/core/views.py", line 966, in get_context_data
    raise Exception('test')
Exception: test
2015-09-08 15:42:27,500 ERROR base 11078 -1360004288 Internal Server Error: /test/
Traceback (most recent call last):
  File "/usr/local/lib/python2.7/dist-packages/django/core/handlers/base.py", line 112, in get_response
    response = wrapped_callback(request, *callback_args, **callback_kwargs)
  File "/usr/local/lib/python2.7/dist-packages/django/views/generic/base.py", line 69, in view
    return self.dispatch(request, *args, **kwargs)
  File "/usr/local/lib/python2.7/dist-packages/django/utils/decorators.py", line 29, in _wrapper
    return bound_func(*args, **kwargs)
  File "/usr/local/lib/python2.7/dist-packages/django/contrib/auth/decorators.py", line 22, in _wrapped_view
    return view_func(request, *args, **kwargs)
  File "/usr/local/lib/python2.7/dist-packages/django/utils/decorators.py", line 25, in bound_func
    return func(self, *args2, **kwargs2)
  File "/home/mikhail/EclipseWorkspace/oncoFinder2/oncoFinder2/core/views.py", line 936, in dispatch
    return super(Test, self).dispatch(request, *args, **kwargs)
  File "/usr/local/lib/python2.7/dist-packages/django/views/generic/base.py", line 87, in dispatch
    return handler(request, *args, **kwargs)
  File "/usr/local/lib/python2.7/dist-packages/django/views/generic/base.py", line 154, in get
    context = self.get_context_data(**kwargs)
  File "/home/mikhail/EclipseWorkspace/oncoFinder2/oncoFinder2/core/views.py", line 967, in get_context_data
    raise Exception('test')
Exception: test
2015-09-08 15:43:11,682 ERROR base 11408 -1359930560 Internal Server Error: /test/
Traceback (most recent call last):
  File "/usr/local/lib/python2.7/dist-packages/django/core/handlers/base.py", line 112, in get_response
    response = wrapped_callback(request, *callback_args, **callback_kwargs)
  File "/usr/local/lib/python2.7/dist-packages/django/views/generic/base.py", line 69, in view
    return self.dispatch(request, *args, **kwargs)
  File "/usr/local/lib/python2.7/dist-packages/django/utils/decorators.py", line 29, in _wrapper
    return bound_func(*args, **kwargs)
  File "/usr/local/lib/python2.7/dist-packages/django/contrib/auth/decorators.py", line 22, in _wrapped_view
    return view_func(request, *args, **kwargs)
  File "/usr/local/lib/python2.7/dist-packages/django/utils/decorators.py", line 25, in bound_func
    return func(self, *args2, **kwargs2)
  File "/home/mikhail/EclipseWorkspace/oncoFinder2/oncoFinder2/core/views.py", line 936, in dispatch
    return super(Test, self).dispatch(request, *args, **kwargs)
  File "/usr/local/lib/python2.7/dist-packages/django/views/generic/base.py", line 87, in dispatch
    return handler(request, *args, **kwargs)
  File "/usr/local/lib/python2.7/dist-packages/django/views/generic/base.py", line 154, in get
    context = self.get_context_data(**kwargs)
  File "/home/mikhail/EclipseWorkspace/oncoFinder2/oncoFinder2/core/views.py", line 967, in get_context_data
    raise Exception('test')
Exception: test
2015-09-10 09:52:30,987 ERROR forms 7115 -1360176320 User was trying to upload file with wrong format.
2015-09-18 15:11:48,722 ERROR base 11559 -1370490048 Internal Server Error: /test/
Traceback (most recent call last):
  File "/usr/local/lib/python2.7/dist-packages/django/core/handlers/base.py", line 112, in get_response
    response = wrapped_callback(request, *callback_args, **callback_kwargs)
  File "/usr/local/lib/python2.7/dist-packages/django/views/generic/base.py", line 69, in view
    return self.dispatch(request, *args, **kwargs)
  File "/usr/local/lib/python2.7/dist-packages/django/utils/decorators.py", line 29, in _wrapper
    return bound_func(*args, **kwargs)
  File "/usr/local/lib/python2.7/dist-packages/django/contrib/auth/decorators.py", line 22, in _wrapped_view
    return view_func(request, *args, **kwargs)
  File "/usr/local/lib/python2.7/dist-packages/django/utils/decorators.py", line 25, in bound_func
    return func(self, *args2, **kwargs2)
  File "/home/mikhail/EclipseWorkspace/oncoFinder2/oncoFinder2/core/views.py", line 936, in dispatch
    return super(Test, self).dispatch(request, *args, **kwargs)
  File "/usr/local/lib/python2.7/dist-packages/django/views/generic/base.py", line 87, in dispatch
    return handler(request, *args, **kwargs)
  File "/usr/local/lib/python2.7/dist-packages/django/views/generic/base.py", line 154, in get
    context = self.get_context_data(**kwargs)
  File "/home/mikhail/EclipseWorkspace/oncoFinder2/oncoFinder2/core/views.py", line 943, in get_context_data
    raise Exception('test')
Exception: test
2015-09-18 15:14:31,077 ERROR base 13187 -1360004288 Internal Server Error: /test/
Traceback (most recent call last):
  File "/usr/local/lib/python2.7/dist-packages/django/core/handlers/base.py", line 112, in get_response
    response = wrapped_callback(request, *callback_args, **callback_kwargs)
  File "/usr/local/lib/python2.7/dist-packages/django/views/generic/base.py", line 69, in view
    return self.dispatch(request, *args, **kwargs)
  File "/usr/local/lib/python2.7/dist-packages/django/utils/decorators.py", line 29, in _wrapper
    return bound_func(*args, **kwargs)
  File "/usr/local/lib/python2.7/dist-packages/django/contrib/auth/decorators.py", line 22, in _wrapped_view
    return view_func(request, *args, **kwargs)
  File "/usr/local/lib/python2.7/dist-packages/django/utils/decorators.py", line 25, in bound_func
    return func(self, *args2, **kwargs2)
  File "/home/mikhail/EclipseWorkspace/oncoFinder2/oncoFinder2/core/views.py", line 936, in dispatch
    return super(Test, self).dispatch(request, *args, **kwargs)
  File "/usr/local/lib/python2.7/dist-packages/django/views/generic/base.py", line 87, in dispatch
    return handler(request, *args, **kwargs)
  File "/usr/local/lib/python2.7/dist-packages/django/views/generic/base.py", line 154, in get
    context = self.get_context_data(**kwargs)
  File "/home/mikhail/EclipseWorkspace/oncoFinder2/oncoFinder2/core/views.py", line 947, in get_context_data
    raise Exception('test')
Exception: test
2015-09-18 15:15:11,739 ERROR base 13522 -1361052864 Internal Server Error: /test/
Traceback (most recent call last):
  File "/usr/local/lib/python2.7/dist-packages/django/core/handlers/base.py", line 112, in get_response
    response = wrapped_callback(request, *callback_args, **callback_kwargs)
  File "/usr/local/lib/python2.7/dist-packages/django/views/generic/base.py", line 69, in view
    return self.dispatch(request, *args, **kwargs)
  File "/usr/local/lib/python2.7/dist-packages/django/utils/decorators.py", line 29, in _wrapper
    return bound_func(*args, **kwargs)
  File "/usr/local/lib/python2.7/dist-packages/django/contrib/auth/decorators.py", line 22, in _wrapped_view
    return view_func(request, *args, **kwargs)
  File "/usr/local/lib/python2.7/dist-packages/django/utils/decorators.py", line 25, in bound_func
    return func(self, *args2, **kwargs2)
  File "/home/mikhail/EclipseWorkspace/oncoFinder2/oncoFinder2/core/views.py", line 936, in dispatch
    return super(Test, self).dispatch(request, *args, **kwargs)
  File "/usr/local/lib/python2.7/dist-packages/django/views/generic/base.py", line 87, in dispatch
    return handler(request, *args, **kwargs)
  File "/usr/local/lib/python2.7/dist-packages/django/views/generic/base.py", line 154, in get
    context = self.get_context_data(**kwargs)
  File "/home/mikhail/EclipseWorkspace/oncoFinder2/oncoFinder2/core/views.py", line 943, in get_context_data
    pathways = Gene.objects.filter(pathway__organism='human', pathway__database__in=['metabolism', 'cytoskeleton']).oderby('pathway__name').values('pathway__name', 'name', 'arr')
AttributeError: 'QuerySet' object has no attribute 'oderby'
2015-09-18 15:15:21,599 ERROR base 13591 -1361052864 Internal Server Error: /test/
Traceback (most recent call last):
  File "/usr/local/lib/python2.7/dist-packages/django/core/handlers/base.py", line 112, in get_response
    response = wrapped_callback(request, *callback_args, **callback_kwargs)
  File "/usr/local/lib/python2.7/dist-packages/django/views/generic/base.py", line 69, in view
    return self.dispatch(request, *args, **kwargs)
  File "/usr/local/lib/python2.7/dist-packages/django/utils/decorators.py", line 29, in _wrapper
    return bound_func(*args, **kwargs)
  File "/usr/local/lib/python2.7/dist-packages/django/contrib/auth/decorators.py", line 22, in _wrapped_view
    return view_func(request, *args, **kwargs)
  File "/usr/local/lib/python2.7/dist-packages/django/utils/decorators.py", line 25, in bound_func
    return func(self, *args2, **kwargs2)
  File "/home/mikhail/EclipseWorkspace/oncoFinder2/oncoFinder2/core/views.py", line 936, in dispatch
    return super(Test, self).dispatch(request, *args, **kwargs)
  File "/usr/local/lib/python2.7/dist-packages/django/views/generic/base.py", line 87, in dispatch
    return handler(request, *args, **kwargs)
  File "/usr/local/lib/python2.7/dist-packages/django/views/generic/base.py", line 154, in get
    context = self.get_context_data(**kwargs)
  File "/home/mikhail/EclipseWorkspace/oncoFinder2/oncoFinder2/core/views.py", line 943, in get_context_data
    pathways = Gene.objects.filter(pathway__organism='human', pathway__database__in=['metabolism', 'cytoskeleton']).orerby('pathway__name').values('pathway__name', 'name', 'arr')
AttributeError: 'QuerySet' object has no attribute 'orerby'
2015-09-18 15:15:30,047 ERROR base 13672 -1360004288 Internal Server Error: /test/
Traceback (most recent call last):
  File "/usr/local/lib/python2.7/dist-packages/django/core/handlers/base.py", line 112, in get_response
    response = wrapped_callback(request, *callback_args, **callback_kwargs)
  File "/usr/local/lib/python2.7/dist-packages/django/views/generic/base.py", line 69, in view
    return self.dispatch(request, *args, **kwargs)
  File "/usr/local/lib/python2.7/dist-packages/django/utils/decorators.py", line 29, in _wrapper
    return bound_func(*args, **kwargs)
  File "/usr/local/lib/python2.7/dist-packages/django/contrib/auth/decorators.py", line 22, in _wrapped_view
    return view_func(request, *args, **kwargs)
  File "/usr/local/lib/python2.7/dist-packages/django/utils/decorators.py", line 25, in bound_func
    return func(self, *args2, **kwargs2)
  File "/home/mikhail/EclipseWorkspace/oncoFinder2/oncoFinder2/core/views.py", line 936, in dispatch
    return super(Test, self).dispatch(request, *args, **kwargs)
  File "/usr/local/lib/python2.7/dist-packages/django/views/generic/base.py", line 87, in dispatch
    return handler(request, *args, **kwargs)
  File "/usr/local/lib/python2.7/dist-packages/django/views/generic/base.py", line 154, in get
    context = self.get_context_data(**kwargs)
  File "/home/mikhail/EclipseWorkspace/oncoFinder2/oncoFinder2/core/views.py", line 943, in get_context_data
    pathways = Gene.objects.filter(pathway__organism='human', pathway__database__in=['metabolism', 'cytoskeleton']).orer_by('pathway__name').values('pathway__name', 'name', 'arr')
AttributeError: 'QuerySet' object has no attribute 'orer_by'
2015-09-18 15:15:45,145 ERROR base 13775 -1359930560 Internal Server Error: /test/
Traceback (most recent call last):
  File "/usr/local/lib/python2.7/dist-packages/django/core/handlers/base.py", line 112, in get_response
    response = wrapped_callback(request, *callback_args, **callback_kwargs)
  File "/usr/local/lib/python2.7/dist-packages/django/views/generic/base.py", line 69, in view
    return self.dispatch(request, *args, **kwargs)
  File "/usr/local/lib/python2.7/dist-packages/django/utils/decorators.py", line 29, in _wrapper
    return bound_func(*args, **kwargs)
  File "/usr/local/lib/python2.7/dist-packages/django/contrib/auth/decorators.py", line 22, in _wrapped_view
    return view_func(request, *args, **kwargs)
  File "/usr/local/lib/python2.7/dist-packages/django/utils/decorators.py", line 25, in bound_func
    return func(self, *args2, **kwargs2)
  File "/home/mikhail/EclipseWorkspace/oncoFinder2/oncoFinder2/core/views.py", line 936, in dispatch
    return super(Test, self).dispatch(request, *args, **kwargs)
  File "/usr/local/lib/python2.7/dist-packages/django/views/generic/base.py", line 87, in dispatch
    return handler(request, *args, **kwargs)
  File "/usr/local/lib/python2.7/dist-packages/django/views/generic/base.py", line 154, in get
    context = self.get_context_data(**kwargs)
  File "/home/mikhail/EclipseWorkspace/oncoFinder2/oncoFinder2/core/views.py", line 947, in get_context_data
    raise Exception('test')
Exception: test
2015-09-18 15:16:09,231 ERROR base 13979 -1360004288 Internal Server Error: /test/
Traceback (most recent call last):
  File "/usr/local/lib/python2.7/dist-packages/django/core/handlers/base.py", line 112, in get_response
    response = wrapped_callback(request, *callback_args, **callback_kwargs)
  File "/usr/local/lib/python2.7/dist-packages/django/views/generic/base.py", line 69, in view
    return self.dispatch(request, *args, **kwargs)
  File "/usr/local/lib/python2.7/dist-packages/django/utils/decorators.py", line 29, in _wrapper
    return bound_func(*args, **kwargs)
  File "/usr/local/lib/python2.7/dist-packages/django/contrib/auth/decorators.py", line 22, in _wrapped_view
    return view_func(request, *args, **kwargs)
  File "/usr/local/lib/python2.7/dist-packages/django/utils/decorators.py", line 25, in bound_func
    return func(self, *args2, **kwargs2)
  File "/home/mikhail/EclipseWorkspace/oncoFinder2/oncoFinder2/core/views.py", line 936, in dispatch
    return super(Test, self).dispatch(request, *args, **kwargs)
  File "/usr/local/lib/python2.7/dist-packages/django/views/generic/base.py", line 87, in dispatch
    return handler(request, *args, **kwargs)
  File "/usr/local/lib/python2.7/dist-packages/django/views/generic/base.py", line 154, in get
    context = self.get_context_data(**kwargs)
  File "/home/mikhail/EclipseWorkspace/oncoFinder2/oncoFinder2/core/views.py", line 947, in get_context_data
    raise Exception('test')
Exception: test
2015-09-18 15:17:38,204 ERROR base 14554 -1361052864 Internal Server Error: /test/
Traceback (most recent call last):
  File "/usr/local/lib/python2.7/dist-packages/django/core/handlers/base.py", line 112, in get_response
    response = wrapped_callback(request, *callback_args, **callback_kwargs)
  File "/usr/local/lib/python2.7/dist-packages/django/views/generic/base.py", line 69, in view
    return self.dispatch(request, *args, **kwargs)
  File "/usr/local/lib/python2.7/dist-packages/django/utils/decorators.py", line 29, in _wrapper
    return bound_func(*args, **kwargs)
  File "/usr/local/lib/python2.7/dist-packages/django/contrib/auth/decorators.py", line 22, in _wrapped_view
    return view_func(request, *args, **kwargs)
  File "/usr/local/lib/python2.7/dist-packages/django/utils/decorators.py", line 25, in bound_func
    return func(self, *args2, **kwargs2)
  File "/home/mikhail/EclipseWorkspace/oncoFinder2/oncoFinder2/core/views.py", line 936, in dispatch
    return super(Test, self).dispatch(request, *args, **kwargs)
  File "/usr/local/lib/python2.7/dist-packages/django/views/generic/base.py", line 87, in dispatch
    return handler(request, *args, **kwargs)
  File "/usr/local/lib/python2.7/dist-packages/django/views/generic/base.py", line 154, in get
    context = self.get_context_data(**kwargs)
  File "/home/mikhail/EclipseWorkspace/oncoFinder2/oncoFinder2/core/views.py", line 948, in get_context_data
    raise Exception('test')
Exception: test
2015-09-18 15:18:31,878 ERROR base 14930 -1360004288 Internal Server Error: /test/
Traceback (most recent call last):
  File "/usr/local/lib/python2.7/dist-packages/django/core/handlers/base.py", line 112, in get_response
    response = wrapped_callback(request, *callback_args, **callback_kwargs)
  File "/usr/local/lib/python2.7/dist-packages/django/views/generic/base.py", line 69, in view
    return self.dispatch(request, *args, **kwargs)
  File "/usr/local/lib/python2.7/dist-packages/django/utils/decorators.py", line 29, in _wrapper
    return bound_func(*args, **kwargs)
  File "/usr/local/lib/python2.7/dist-packages/django/contrib/auth/decorators.py", line 22, in _wrapped_view
    return view_func(request, *args, **kwargs)
  File "/usr/local/lib/python2.7/dist-packages/django/utils/decorators.py", line 25, in bound_func
    return func(self, *args2, **kwargs2)
  File "/home/mikhail/EclipseWorkspace/oncoFinder2/oncoFinder2/core/views.py", line 936, in dispatch
    return super(Test, self).dispatch(request, *args, **kwargs)
  File "/usr/local/lib/python2.7/dist-packages/django/views/generic/base.py", line 87, in dispatch
    return handler(request, *args, **kwargs)
  File "/usr/local/lib/python2.7/dist-packages/django/views/generic/base.py", line 154, in get
    context = self.get_context_data(**kwargs)
  File "/home/mikhail/EclipseWorkspace/oncoFinder2/oncoFinder2/core/views.py", line 948, in get_context_data
    raise Exception('test')
Exception: test
2015-09-18 15:20:10,857 ERROR base 15659 -1360004288 Internal Server Error: /test/
Traceback (most recent call last):
  File "/usr/local/lib/python2.7/dist-packages/django/core/handlers/base.py", line 112, in get_response
    response = wrapped_callback(request, *callback_args, **callback_kwargs)
  File "/usr/local/lib/python2.7/dist-packages/django/views/generic/base.py", line 69, in view
    return self.dispatch(request, *args, **kwargs)
  File "/usr/local/lib/python2.7/dist-packages/django/utils/decorators.py", line 29, in _wrapper
    return bound_func(*args, **kwargs)
  File "/usr/local/lib/python2.7/dist-packages/django/contrib/auth/decorators.py", line 22, in _wrapped_view
    return view_func(request, *args, **kwargs)
  File "/usr/local/lib/python2.7/dist-packages/django/utils/decorators.py", line 25, in bound_func
    return func(self, *args2, **kwargs2)
  File "/home/mikhail/EclipseWorkspace/oncoFinder2/oncoFinder2/core/views.py", line 936, in dispatch
    return super(Test, self).dispatch(request, *args, **kwargs)
  File "/usr/local/lib/python2.7/dist-packages/django/views/generic/base.py", line 87, in dispatch
    return handler(request, *args, **kwargs)
  File "/usr/local/lib/python2.7/dist-packages/django/views/generic/base.py", line 154, in get
    context = self.get_context_data(**kwargs)
  File "/home/mikhail/EclipseWorkspace/oncoFinder2/oncoFinder2/core/views.py", line 947, in get_context_data
    df.to_csv(settings.MEDIA_ROOT+"/gene-arr-path-metabolism-cytoskeleton.csv", index=False)
  File "/usr/local/lib/python2.7/dist-packages/pandas/core/frame.py", line 1185, in to_csv
    formatter.save()
  File "/usr/local/lib/python2.7/dist-packages/pandas/core/format.py", line 1432, in save
    self._save()
  File "/usr/local/lib/python2.7/dist-packages/pandas/core/format.py", line 1532, in _save
    self._save_chunk(start_i, end_i)
  File "/usr/local/lib/python2.7/dist-packages/pandas/core/format.py", line 1555, in _save_chunk
    lib.write_csv_rows(self.data, ix, self.nlevels, self.cols, self.writer)
  File "pandas/lib.pyx", line 975, in pandas.lib.write_csv_rows (pandas/lib.c:16715)
UnicodeEncodeError: 'ascii' codec can't encode character u'\u2013' in position 28: ordinal not in range(128)
2015-09-22 11:22:54,225 ERROR base 12712 -1390417088 Internal Server Error: /test/
Traceback (most recent call last):
  File "/usr/local/lib/python2.7/dist-packages/django/core/handlers/base.py", line 112, in get_response
    response = wrapped_callback(request, *callback_args, **callback_kwargs)
  File "/usr/local/lib/python2.7/dist-packages/django/views/generic/base.py", line 69, in view
    return self.dispatch(request, *args, **kwargs)
  File "/usr/local/lib/python2.7/dist-packages/django/utils/decorators.py", line 29, in _wrapper
    return bound_func(*args, **kwargs)
  File "/usr/local/lib/python2.7/dist-packages/django/contrib/auth/decorators.py", line 22, in _wrapped_view
    return view_func(request, *args, **kwargs)
  File "/usr/local/lib/python2.7/dist-packages/django/utils/decorators.py", line 25, in bound_func
    return func(self, *args2, **kwargs2)
  File "/home/mikhail/EclipseWorkspace/oncoFinder2/oncoFinder2/core/views.py", line 936, in dispatch
    return super(Test, self).dispatch(request, *args, **kwargs)
  File "/usr/local/lib/python2.7/dist-packages/django/views/generic/base.py", line 87, in dispatch
    return handler(request, *args, **kwargs)
  File "/usr/local/lib/python2.7/dist-packages/django/views/generic/base.py", line 154, in get
    context = self.get_context_data(**kwargs)
  File "/home/mikhail/EclipseWorkspace/oncoFinder2/oncoFinder2/core/views.py", line 943, in get_context_data
    raise Exception('test')
Exception: test
2015-09-22 11:22:54,488 ERROR base 12712 -1398809792 Internal Server Error: /test/
Traceback (most recent call last):
  File "/usr/local/lib/python2.7/dist-packages/django/core/handlers/base.py", line 112, in get_response
    response = wrapped_callback(request, *callback_args, **callback_kwargs)
  File "/usr/local/lib/python2.7/dist-packages/django/views/generic/base.py", line 69, in view
    return self.dispatch(request, *args, **kwargs)
  File "/usr/local/lib/python2.7/dist-packages/django/utils/decorators.py", line 29, in _wrapper
    return bound_func(*args, **kwargs)
  File "/usr/local/lib/python2.7/dist-packages/django/contrib/auth/decorators.py", line 22, in _wrapped_view
    return view_func(request, *args, **kwargs)
  File "/usr/local/lib/python2.7/dist-packages/django/utils/decorators.py", line 25, in bound_func
    return func(self, *args2, **kwargs2)
  File "/home/mikhail/EclipseWorkspace/oncoFinder2/oncoFinder2/core/views.py", line 936, in dispatch
    return super(Test, self).dispatch(request, *args, **kwargs)
  File "/usr/local/lib/python2.7/dist-packages/django/views/generic/base.py", line 87, in dispatch
    return handler(request, *args, **kwargs)
  File "/usr/local/lib/python2.7/dist-packages/django/views/generic/base.py", line 154, in get
    context = self.get_context_data(**kwargs)
  File "/home/mikhail/EclipseWorkspace/oncoFinder2/oncoFinder2/core/views.py", line 943, in get_context_data
    raise Exception('test')
Exception: test
2015-09-22 11:23:31,430 ERROR base 14171 -1360004288 Internal Server Error: /test/
Traceback (most recent call last):
  File "/usr/local/lib/python2.7/dist-packages/django/core/handlers/base.py", line 112, in get_response
    response = wrapped_callback(request, *callback_args, **callback_kwargs)
  File "/usr/local/lib/python2.7/dist-packages/django/views/generic/base.py", line 69, in view
    return self.dispatch(request, *args, **kwargs)
  File "/usr/local/lib/python2.7/dist-packages/django/utils/decorators.py", line 29, in _wrapper
    return bound_func(*args, **kwargs)
  File "/usr/local/lib/python2.7/dist-packages/django/contrib/auth/decorators.py", line 22, in _wrapped_view
    return view_func(request, *args, **kwargs)
  File "/usr/local/lib/python2.7/dist-packages/django/utils/decorators.py", line 25, in bound_func
    return func(self, *args2, **kwargs2)
  File "/home/mikhail/EclipseWorkspace/oncoFinder2/oncoFinder2/core/views.py", line 936, in dispatch
    return super(Test, self).dispatch(request, *args, **kwargs)
  File "/usr/local/lib/python2.7/dist-packages/django/views/generic/base.py", line 87, in dispatch
    return handler(request, *args, **kwargs)
  File "/usr/local/lib/python2.7/dist-packages/django/views/generic/base.py", line 154, in get
    context = self.get_context_data(**kwargs)
  File "/home/mikhail/EclipseWorkspace/oncoFinder2/oncoFinder2/core/views.py", line 943, in get_context_data
    raise Exception('test')
Exception: test
2015-09-22 11:30:28,351 ERROR base 17353 -1360004288 Internal Server Error: /test/
Traceback (most recent call last):
  File "/usr/local/lib/python2.7/dist-packages/django/core/handlers/base.py", line 112, in get_response
    response = wrapped_callback(request, *callback_args, **callback_kwargs)
  File "/usr/local/lib/python2.7/dist-packages/django/views/generic/base.py", line 69, in view
    return self.dispatch(request, *args, **kwargs)
  File "/usr/local/lib/python2.7/dist-packages/django/utils/decorators.py", line 29, in _wrapper
    return bound_func(*args, **kwargs)
  File "/usr/local/lib/python2.7/dist-packages/django/contrib/auth/decorators.py", line 22, in _wrapped_view
    return view_func(request, *args, **kwargs)
  File "/usr/local/lib/python2.7/dist-packages/django/utils/decorators.py", line 25, in bound_func
    return func(self, *args2, **kwargs2)
  File "/home/mikhail/EclipseWorkspace/oncoFinder2/oncoFinder2/core/views.py", line 936, in dispatch
    return super(Test, self).dispatch(request, *args, **kwargs)
  File "/usr/local/lib/python2.7/dist-packages/django/views/generic/base.py", line 87, in dispatch
    return handler(request, *args, **kwargs)
  File "/usr/local/lib/python2.7/dist-packages/django/views/generic/base.py", line 154, in get
    context = self.get_context_data(**kwargs)
  File "/home/mikhail/EclipseWorkspace/oncoFinder2/oncoFinder2/core/views.py", line 944, in get_context_data
    genes = Gene.objects.filter(pathway__batabase='primary_old', pathway__organism='human').values('name')
  File "/usr/local/lib/python2.7/dist-packages/django/db/models/manager.py", line 163, in filter
    return self.get_queryset().filter(*args, **kwargs)
  File "/usr/local/lib/python2.7/dist-packages/django/db/models/query.py", line 593, in filter
    return self._filter_or_exclude(False, *args, **kwargs)
  File "/usr/local/lib/python2.7/dist-packages/django/db/models/query.py", line 611, in _filter_or_exclude
    clone.query.add_q(Q(*args, **kwargs))
  File "/usr/local/lib/python2.7/dist-packages/django/db/models/sql/query.py", line 1204, in add_q
    clause = self._add_q(where_part, used_aliases)
  File "/usr/local/lib/python2.7/dist-packages/django/db/models/sql/query.py", line 1240, in _add_q
    current_negated=current_negated)
  File "/usr/local/lib/python2.7/dist-packages/django/db/models/sql/query.py", line 1103, in build_filter
    allow_explicit_fk=True)
  File "/usr/local/lib/python2.7/dist-packages/django/db/models/sql/query.py", line 1363, in setup_joins
    names, opts, allow_many, allow_explicit_fk)
  File "/usr/local/lib/python2.7/dist-packages/django/db/models/sql/query.py", line 1283, in names_to_path
    "Choices are: %s" % (name, ", ".join(available)))
FieldError: Cannot resolve keyword 'batabase' into field. Choices are: amcf, comment, database, gene, id, image, info, name, node, organism, pathway_id
2015-09-22 11:31:19,026 ERROR base 17698 -1360004288 Internal Server Error: /test/
Traceback (most recent call last):
  File "/usr/local/lib/python2.7/dist-packages/django/core/handlers/base.py", line 112, in get_response
    response = wrapped_callback(request, *callback_args, **callback_kwargs)
  File "/usr/local/lib/python2.7/dist-packages/django/views/generic/base.py", line 69, in view
    return self.dispatch(request, *args, **kwargs)
  File "/usr/local/lib/python2.7/dist-packages/django/utils/decorators.py", line 29, in _wrapper
    return bound_func(*args, **kwargs)
  File "/usr/local/lib/python2.7/dist-packages/django/contrib/auth/decorators.py", line 22, in _wrapped_view
    return view_func(request, *args, **kwargs)
  File "/usr/local/lib/python2.7/dist-packages/django/utils/decorators.py", line 25, in bound_func
    return func(self, *args2, **kwargs2)
  File "/home/mikhail/EclipseWorkspace/oncoFinder2/oncoFinder2/core/views.py", line 936, in dispatch
    return super(Test, self).dispatch(request, *args, **kwargs)
  File "/usr/local/lib/python2.7/dist-packages/django/views/generic/base.py", line 87, in dispatch
    return handler(request, *args, **kwargs)
  File "/usr/local/lib/python2.7/dist-packages/django/views/generic/base.py", line 154, in get
    context = self.get_context_data(**kwargs)
  File "/home/mikhail/EclipseWorkspace/oncoFinder2/oncoFinder2/core/views.py", line 946, in get_context_data
    df_db = pd.DataFrame(list(genes))
NameError: global name 'gzenes' is not defined
2015-09-22 11:31:24,137 ERROR base 17698 -1389368512 Internal Server Error: /test/
Traceback (most recent call last):
  File "/usr/local/lib/python2.7/dist-packages/django/core/handlers/base.py", line 112, in get_response
    response = wrapped_callback(request, *callback_args, **callback_kwargs)
  File "/usr/local/lib/python2.7/dist-packages/django/views/generic/base.py", line 69, in view
    return self.dispatch(request, *args, **kwargs)
  File "/usr/local/lib/python2.7/dist-packages/django/utils/decorators.py", line 29, in _wrapper
    return bound_func(*args, **kwargs)
  File "/usr/local/lib/python2.7/dist-packages/django/contrib/auth/decorators.py", line 22, in _wrapped_view
    return view_func(request, *args, **kwargs)
  File "/usr/local/lib/python2.7/dist-packages/django/utils/decorators.py", line 25, in bound_func
    return func(self, *args2, **kwargs2)
  File "/home/mikhail/EclipseWorkspace/oncoFinder2/oncoFinder2/core/views.py", line 936, in dispatch
    return super(Test, self).dispatch(request, *args, **kwargs)
  File "/usr/local/lib/python2.7/dist-packages/django/views/generic/base.py", line 87, in dispatch
    return handler(request, *args, **kwargs)
  File "/usr/local/lib/python2.7/dist-packages/django/views/generic/base.py", line 154, in get
    context = self.get_context_data(**kwargs)
  File "/home/mikhail/EclipseWorkspace/oncoFinder2/oncoFinder2/core/views.py", line 946, in get_context_data
    df_db = pd.DataFrame(list(genes))
NameError: global name 'gzenes' is not defined
2015-09-22 11:31:36,077 ERROR base 17831 -1360004288 Internal Server Error: /test/
Traceback (most recent call last):
  File "/usr/local/lib/python2.7/dist-packages/django/core/handlers/base.py", line 112, in get_response
    response = wrapped_callback(request, *callback_args, **callback_kwargs)
  File "/usr/local/lib/python2.7/dist-packages/django/views/generic/base.py", line 69, in view
    return self.dispatch(request, *args, **kwargs)
  File "/usr/local/lib/python2.7/dist-packages/django/utils/decorators.py", line 29, in _wrapper
    return bound_func(*args, **kwargs)
  File "/usr/local/lib/python2.7/dist-packages/django/contrib/auth/decorators.py", line 22, in _wrapped_view
    return view_func(request, *args, **kwargs)
  File "/usr/local/lib/python2.7/dist-packages/django/utils/decorators.py", line 25, in bound_func
    return func(self, *args2, **kwargs2)
  File "/home/mikhail/EclipseWorkspace/oncoFinder2/oncoFinder2/core/views.py", line 936, in dispatch
    return super(Test, self).dispatch(request, *args, **kwargs)
  File "/usr/local/lib/python2.7/dist-packages/django/views/generic/base.py", line 87, in dispatch
    return handler(request, *args, **kwargs)
  File "/usr/local/lib/python2.7/dist-packages/django/views/generic/base.py", line 154, in get
    context = self.get_context_data(**kwargs)
  File "/home/mikhail/EclipseWorkspace/oncoFinder2/oncoFinder2/core/views.py", line 947, in get_context_data
    raise Exception('test')
Exception: test
2015-09-22 11:33:29,875 ERROR base 18542 -1360004288 Internal Server Error: /test/
Traceback (most recent call last):
  File "/usr/local/lib/python2.7/dist-packages/django/core/handlers/base.py", line 112, in get_response
    response = wrapped_callback(request, *callback_args, **callback_kwargs)
  File "/usr/local/lib/python2.7/dist-packages/django/views/generic/base.py", line 69, in view
    return self.dispatch(request, *args, **kwargs)
  File "/usr/local/lib/python2.7/dist-packages/django/utils/decorators.py", line 29, in _wrapper
    return bound_func(*args, **kwargs)
  File "/usr/local/lib/python2.7/dist-packages/django/contrib/auth/decorators.py", line 22, in _wrapped_view
    return view_func(request, *args, **kwargs)
  File "/usr/local/lib/python2.7/dist-packages/django/utils/decorators.py", line 25, in bound_func
    return func(self, *args2, **kwargs2)
  File "/home/mikhail/EclipseWorkspace/oncoFinder2/oncoFinder2/core/views.py", line 936, in dispatch
    return super(Test, self).dispatch(request, *args, **kwargs)
  File "/usr/local/lib/python2.7/dist-packages/django/views/generic/base.py", line 87, in dispatch
    return handler(request, *args, **kwargs)
  File "/usr/local/lib/python2.7/dist-packages/django/views/generic/base.py", line 154, in get
    context = self.get_context_data(**kwargs)
  File "/home/mikhail/EclipseWorkspace/oncoFinder2/oncoFinder2/core/views.py", line 947, in get_context_data
    df_db = df_db.goupby('name')
  File "/usr/local/lib/python2.7/dist-packages/pandas/core/generic.py", line 1978, in __getattr__
    (type(self).__name__, name))
AttributeError: 'DataFrame' object has no attribute 'goupby'
2015-09-22 11:33:48,402 ERROR base 18736 -1360004288 Internal Server Error: /test/
Traceback (most recent call last):
  File "/usr/local/lib/python2.7/dist-packages/django/core/handlers/base.py", line 112, in get_response
    response = wrapped_callback(request, *callback_args, **callback_kwargs)
  File "/usr/local/lib/python2.7/dist-packages/django/views/generic/base.py", line 69, in view
    return self.dispatch(request, *args, **kwargs)
  File "/usr/local/lib/python2.7/dist-packages/django/utils/decorators.py", line 29, in _wrapper
    return bound_func(*args, **kwargs)
  File "/usr/local/lib/python2.7/dist-packages/django/contrib/auth/decorators.py", line 22, in _wrapped_view
    return view_func(request, *args, **kwargs)
  File "/usr/local/lib/python2.7/dist-packages/django/utils/decorators.py", line 25, in bound_func
    return func(self, *args2, **kwargs2)
  File "/home/mikhail/EclipseWorkspace/oncoFinder2/oncoFinder2/core/views.py", line 936, in dispatch
    return super(Test, self).dispatch(request, *args, **kwargs)
  File "/usr/local/lib/python2.7/dist-packages/django/views/generic/base.py", line 87, in dispatch
    return handler(request, *args, **kwargs)
  File "/usr/local/lib/python2.7/dist-packages/django/views/generic/base.py", line 154, in get
    context = self.get_context_data(**kwargs)
  File "/home/mikhail/EclipseWorkspace/oncoFinder2/oncoFinder2/core/views.py", line 948, in get_context_data
    raise Exception('test')
Exception: test
2015-09-22 11:34:14,150 ERROR base 18980 -1360004288 Internal Server Error: /test/
Traceback (most recent call last):
  File "/usr/local/lib/python2.7/dist-packages/django/core/handlers/base.py", line 112, in get_response
    response = wrapped_callback(request, *callback_args, **callback_kwargs)
  File "/usr/local/lib/python2.7/dist-packages/django/views/generic/base.py", line 69, in view
    return self.dispatch(request, *args, **kwargs)
  File "/usr/local/lib/python2.7/dist-packages/django/utils/decorators.py", line 29, in _wrapper
    return bound_func(*args, **kwargs)
  File "/usr/local/lib/python2.7/dist-packages/django/contrib/auth/decorators.py", line 22, in _wrapped_view
    return view_func(request, *args, **kwargs)
  File "/usr/local/lib/python2.7/dist-packages/django/utils/decorators.py", line 25, in bound_func
    return func(self, *args2, **kwargs2)
  File "/home/mikhail/EclipseWorkspace/oncoFinder2/oncoFinder2/core/views.py", line 936, in dispatch
    return super(Test, self).dispatch(request, *args, **kwargs)
  File "/usr/local/lib/python2.7/dist-packages/django/views/generic/base.py", line 87, in dispatch
    return handler(request, *args, **kwargs)
  File "/usr/local/lib/python2.7/dist-packages/django/views/generic/base.py", line 154, in get
    context = self.get_context_data(**kwargs)
  File "/home/mikhail/EclipseWorkspace/oncoFinder2/oncoFinder2/core/views.py", line 947, in get_context_data
    df_db = df_db.groupby('name').mean()
  File "/usr/local/lib/python2.7/dist-packages/pandas/core/groupby.py", line 692, in mean
    return self._cython_agg_general('mean')
  File "/usr/local/lib/python2.7/dist-packages/pandas/core/groupby.py", line 2526, in _cython_agg_general
    new_items, new_blocks = self._cython_agg_blocks(how, numeric_only=numeric_only)
  File "/usr/local/lib/python2.7/dist-packages/pandas/core/groupby.py", line 2573, in _cython_agg_blocks
    raise DataError('No numeric types to aggregate')
DataError: No numeric types to aggregate
2015-09-22 11:34:38,066 ERROR base 19128 -1360004288 Internal Server Error: /test/
Traceback (most recent call last):
  File "/usr/local/lib/python2.7/dist-packages/django/core/handlers/base.py", line 112, in get_response
    response = wrapped_callback(request, *callback_args, **callback_kwargs)
  File "/usr/local/lib/python2.7/dist-packages/django/views/generic/base.py", line 69, in view
    return self.dispatch(request, *args, **kwargs)
  File "/usr/local/lib/python2.7/dist-packages/django/utils/decorators.py", line 29, in _wrapper
    return bound_func(*args, **kwargs)
  File "/usr/local/lib/python2.7/dist-packages/django/contrib/auth/decorators.py", line 22, in _wrapped_view
    return view_func(request, *args, **kwargs)
  File "/usr/local/lib/python2.7/dist-packages/django/utils/decorators.py", line 25, in bound_func
    return func(self, *args2, **kwargs2)
  File "/home/mikhail/EclipseWorkspace/oncoFinder2/oncoFinder2/core/views.py", line 936, in dispatch
    return super(Test, self).dispatch(request, *args, **kwargs)
  File "/usr/local/lib/python2.7/dist-packages/django/views/generic/base.py", line 87, in dispatch
    return handler(request, *args, **kwargs)
  File "/usr/local/lib/python2.7/dist-packages/django/views/generic/base.py", line 154, in get
    context = self.get_context_data(**kwargs)
  File "/home/mikhail/EclipseWorkspace/oncoFinder2/oncoFinder2/core/views.py", line 947, in get_context_data
    df_db = df_db.groupby('name').mean()
  File "/usr/local/lib/python2.7/dist-packages/pandas/core/groupby.py", line 692, in mean
    return self._cython_agg_general('mean')
  File "/usr/local/lib/python2.7/dist-packages/pandas/core/groupby.py", line 2526, in _cython_agg_general
    new_items, new_blocks = self._cython_agg_blocks(how, numeric_only=numeric_only)
  File "/usr/local/lib/python2.7/dist-packages/pandas/core/groupby.py", line 2573, in _cython_agg_blocks
    raise DataError('No numeric types to aggregate')
DataError: No numeric types to aggregate
2015-09-22 11:36:16,024 ERROR base 19741 -1359930560 Internal Server Error: /test/
Traceback (most recent call last):
  File "/usr/local/lib/python2.7/dist-packages/django/core/handlers/base.py", line 112, in get_response
    response = wrapped_callback(request, *callback_args, **callback_kwargs)
  File "/usr/local/lib/python2.7/dist-packages/django/views/generic/base.py", line 69, in view
    return self.dispatch(request, *args, **kwargs)
  File "/usr/local/lib/python2.7/dist-packages/django/utils/decorators.py", line 29, in _wrapper
    return bound_func(*args, **kwargs)
  File "/usr/local/lib/python2.7/dist-packages/django/contrib/auth/decorators.py", line 22, in _wrapped_view
    return view_func(request, *args, **kwargs)
  File "/usr/local/lib/python2.7/dist-packages/django/utils/decorators.py", line 25, in bound_func
    return func(self, *args2, **kwargs2)
  File "/home/mikhail/EclipseWorkspace/oncoFinder2/oncoFinder2/core/views.py", line 936, in dispatch
    return super(Test, self).dispatch(request, *args, **kwargs)
  File "/usr/local/lib/python2.7/dist-packages/django/views/generic/base.py", line 87, in dispatch
    return handler(request, *args, **kwargs)
  File "/usr/local/lib/python2.7/dist-packages/django/views/generic/base.py", line 154, in get
    context = self.get_context_data(**kwargs)
  File "/home/mikhail/EclipseWorkspace/oncoFinder2/oncoFinder2/core/views.py", line 951, in get_context_data
    raise Exception('test')
Exception: test
2015-09-22 11:37:19,057 ERROR base 20228 -1361052864 Internal Server Error: /test/
Traceback (most recent call last):
  File "/usr/local/lib/python2.7/dist-packages/django/core/handlers/base.py", line 112, in get_response
    response = wrapped_callback(request, *callback_args, **callback_kwargs)
  File "/usr/local/lib/python2.7/dist-packages/django/views/generic/base.py", line 69, in view
    return self.dispatch(request, *args, **kwargs)
  File "/usr/local/lib/python2.7/dist-packages/django/utils/decorators.py", line 29, in _wrapper
    return bound_func(*args, **kwargs)
  File "/usr/local/lib/python2.7/dist-packages/django/contrib/auth/decorators.py", line 22, in _wrapped_view
    return view_func(request, *args, **kwargs)
  File "/usr/local/lib/python2.7/dist-packages/django/utils/decorators.py", line 25, in bound_func
    return func(self, *args2, **kwargs2)
  File "/home/mikhail/EclipseWorkspace/oncoFinder2/oncoFinder2/core/views.py", line 936, in dispatch
    return super(Test, self).dispatch(request, *args, **kwargs)
  File "/usr/local/lib/python2.7/dist-packages/django/views/generic/base.py", line 87, in dispatch
    return handler(request, *args, **kwargs)
  File "/usr/local/lib/python2.7/dist-packages/django/views/generic/base.py", line 154, in get
    context = self.get_context_data(**kwargs)
  File "/home/mikhail/EclipseWorkspace/oncoFinder2/oncoFinder2/core/views.py", line 943, in get_context_data
    df_chip = df_chip.groupby('SYMBOL').mean()
  File "/usr/local/lib/python2.7/dist-packages/pandas/core/generic.py", line 2925, in groupby
    sort=sort, group_keys=group_keys, squeeze=squeeze)
  File "/usr/local/lib/python2.7/dist-packages/pandas/core/groupby.py", line 1191, in groupby
    return klass(obj, by, **kwds)
  File "/usr/local/lib/python2.7/dist-packages/pandas/core/groupby.py", line 384, in __init__
    level=level, sort=sort)
  File "/usr/local/lib/python2.7/dist-packages/pandas/core/groupby.py", line 2122, in _get_grouper
    in_axis, name, gpr = True, gpr, obj[gpr]
  File "/usr/local/lib/python2.7/dist-packages/pandas/core/frame.py", line 1787, in __getitem__
    return self._getitem_column(key)
  File "/usr/local/lib/python2.7/dist-packages/pandas/core/frame.py", line 1794, in _getitem_column
    return self._get_item_cache(key)
  File "/usr/local/lib/python2.7/dist-packages/pandas/core/generic.py", line 1079, in _get_item_cache
    values = self._data.get(item)
  File "/usr/local/lib/python2.7/dist-packages/pandas/core/internals.py", line 2843, in get
    loc = self.items.get_loc(item)
  File "/usr/local/lib/python2.7/dist-packages/pandas/core/index.py", line 1437, in get_loc
    return self._engine.get_loc(_values_from_object(key))
  File "pandas/index.pyx", line 134, in pandas.index.IndexEngine.get_loc (pandas/index.c:3824)
  File "pandas/index.pyx", line 154, in pandas.index.IndexEngine.get_loc (pandas/index.c:3704)
  File "pandas/hashtable.pyx", line 697, in pandas.hashtable.PyObjectHashTable.get_item (pandas/hashtable.c:12349)
  File "pandas/hashtable.pyx", line 705, in pandas.hashtable.PyObjectHashTable.get_item (pandas/hashtable.c:12300)
KeyError: 'SYMBOL'
2015-09-22 11:38:35,277 ERROR base 20781 -1360004288 Internal Server Error: /test/
Traceback (most recent call last):
  File "/usr/local/lib/python2.7/dist-packages/django/core/handlers/base.py", line 112, in get_response
    response = wrapped_callback(request, *callback_args, **callback_kwargs)
  File "/usr/local/lib/python2.7/dist-packages/django/views/generic/base.py", line 69, in view
    return self.dispatch(request, *args, **kwargs)
  File "/usr/local/lib/python2.7/dist-packages/django/utils/decorators.py", line 29, in _wrapper
    return bound_func(*args, **kwargs)
  File "/usr/local/lib/python2.7/dist-packages/django/contrib/auth/decorators.py", line 22, in _wrapped_view
    return view_func(request, *args, **kwargs)
  File "/usr/local/lib/python2.7/dist-packages/django/utils/decorators.py", line 25, in bound_func
    return func(self, *args2, **kwargs2)
  File "/home/mikhail/EclipseWorkspace/oncoFinder2/oncoFinder2/core/views.py", line 936, in dispatch
    return super(Test, self).dispatch(request, *args, **kwargs)
  File "/usr/local/lib/python2.7/dist-packages/django/views/generic/base.py", line 87, in dispatch
    return handler(request, *args, **kwargs)
  File "/usr/local/lib/python2.7/dist-packages/django/views/generic/base.py", line 154, in get
    context = self.get_context_data(**kwargs)
  File "/home/mikhail/EclipseWorkspace/oncoFinder2/oncoFinder2/core/views.py", line 951, in get_context_data
    raise Exception('test')
Exception: test
2015-09-22 11:45:19,790 ERROR base 23275 -1359127744 Internal Server Error: /test/
Traceback (most recent call last):
  File "/usr/local/lib/python2.7/dist-packages/django/core/handlers/base.py", line 112, in get_response
    response = wrapped_callback(request, *callback_args, **callback_kwargs)
  File "/usr/local/lib/python2.7/dist-packages/django/views/generic/base.py", line 69, in view
    return self.dispatch(request, *args, **kwargs)
  File "/usr/local/lib/python2.7/dist-packages/django/utils/decorators.py", line 29, in _wrapper
    return bound_func(*args, **kwargs)
  File "/usr/local/lib/python2.7/dist-packages/django/contrib/auth/decorators.py", line 22, in _wrapped_view
    return view_func(request, *args, **kwargs)
  File "/usr/local/lib/python2.7/dist-packages/django/utils/decorators.py", line 25, in bound_func
    return func(self, *args2, **kwargs2)
  File "/home/mikhail/EclipseWorkspace/oncoFinder2/oncoFinder2/core/views.py", line 936, in dispatch
    return super(Test, self).dispatch(request, *args, **kwargs)
  File "/usr/local/lib/python2.7/dist-packages/django/views/generic/base.py", line 87, in dispatch
    return handler(request, *args, **kwargs)
  File "/usr/local/lib/python2.7/dist-packages/django/views/generic/base.py", line 154, in get
    context = self.get_context_data(**kwargs)
  File "/home/mikhail/EclipseWorkspace/oncoFinder2/oncoFinder2/core/views.py", line 953, in get_context_data
    raise Exception('test')
Exception: test
2015-09-22 11:47:18,435 ERROR base 23980 -1360004288 Internal Server Error: /test/
Traceback (most recent call last):
  File "/usr/local/lib/python2.7/dist-packages/django/core/handlers/base.py", line 112, in get_response
    response = wrapped_callback(request, *callback_args, **callback_kwargs)
  File "/usr/local/lib/python2.7/dist-packages/django/views/generic/base.py", line 69, in view
    return self.dispatch(request, *args, **kwargs)
  File "/usr/local/lib/python2.7/dist-packages/django/utils/decorators.py", line 29, in _wrapper
    return bound_func(*args, **kwargs)
  File "/usr/local/lib/python2.7/dist-packages/django/contrib/auth/decorators.py", line 22, in _wrapped_view
    return view_func(request, *args, **kwargs)
  File "/usr/local/lib/python2.7/dist-packages/django/utils/decorators.py", line 25, in bound_func
    return func(self, *args2, **kwargs2)
  File "/home/mikhail/EclipseWorkspace/oncoFinder2/oncoFinder2/core/views.py", line 936, in dispatch
    return super(Test, self).dispatch(request, *args, **kwargs)
  File "/usr/local/lib/python2.7/dist-packages/django/views/generic/base.py", line 87, in dispatch
    return handler(request, *args, **kwargs)
  File "/usr/local/lib/python2.7/dist-packages/django/views/generic/base.py", line 154, in get
    context = self.get_context_data(**kwargs)
  File "/home/mikhail/EclipseWorkspace/oncoFinder2/oncoFinder2/core/views.py", line 953, in get_context_data
    raise Exception('test')
Exception: test
2015-09-22 11:53:54,928 ERROR base 26584 -1360004288 Internal Server Error: /test/
Traceback (most recent call last):
  File "/usr/local/lib/python2.7/dist-packages/django/core/handlers/base.py", line 112, in get_response
    response = wrapped_callback(request, *callback_args, **callback_kwargs)
  File "/usr/local/lib/python2.7/dist-packages/django/views/generic/base.py", line 69, in view
    return self.dispatch(request, *args, **kwargs)
  File "/usr/local/lib/python2.7/dist-packages/django/utils/decorators.py", line 29, in _wrapper
    return bound_func(*args, **kwargs)
  File "/usr/local/lib/python2.7/dist-packages/django/contrib/auth/decorators.py", line 22, in _wrapped_view
    return view_func(request, *args, **kwargs)
  File "/usr/local/lib/python2.7/dist-packages/django/utils/decorators.py", line 25, in bound_func
    return func(self, *args2, **kwargs2)
  File "/home/mikhail/EclipseWorkspace/oncoFinder2/oncoFinder2/core/views.py", line 936, in dispatch
    return super(Test, self).dispatch(request, *args, **kwargs)
  File "/usr/local/lib/python2.7/dist-packages/django/views/generic/base.py", line 87, in dispatch
    return handler(request, *args, **kwargs)
  File "/usr/local/lib/python2.7/dist-packages/django/views/generic/base.py", line 154, in get
    context = self.get_context_data(**kwargs)
  File "/home/mikhail/EclipseWorkspace/oncoFinder2/oncoFinder2/core/views.py", line 961, in get_context_data
    raise Exception('test')
Exception: test
2015-09-22 11:55:42,618 ERROR base 27281 -1361052864 Internal Server Error: /test/
Traceback (most recent call last):
  File "/usr/local/lib/python2.7/dist-packages/django/core/handlers/base.py", line 112, in get_response
    response = wrapped_callback(request, *callback_args, **callback_kwargs)
  File "/usr/local/lib/python2.7/dist-packages/django/views/generic/base.py", line 69, in view
    return self.dispatch(request, *args, **kwargs)
  File "/usr/local/lib/python2.7/dist-packages/django/utils/decorators.py", line 29, in _wrapper
    return bound_func(*args, **kwargs)
  File "/usr/local/lib/python2.7/dist-packages/django/contrib/auth/decorators.py", line 22, in _wrapped_view
    return view_func(request, *args, **kwargs)
  File "/usr/local/lib/python2.7/dist-packages/django/utils/decorators.py", line 25, in bound_func
    return func(self, *args2, **kwargs2)
  File "/home/mikhail/EclipseWorkspace/oncoFinder2/oncoFinder2/core/views.py", line 936, in dispatch
    return super(Test, self).dispatch(request, *args, **kwargs)
  File "/usr/local/lib/python2.7/dist-packages/django/views/generic/base.py", line 87, in dispatch
    return handler(request, *args, **kwargs)
  File "/usr/local/lib/python2.7/dist-packages/django/views/generic/base.py", line 154, in get
    context = self.get_context_data(**kwargs)
  File "/home/mikhail/EclipseWorkspace/oncoFinder2/oncoFinder2/core/views.py", line 961, in get_context_data
    raise Exception('test')
Exception: test
2015-09-22 11:56:51,247 ERROR base 27774 -1360004288 Internal Server Error: /test/
Traceback (most recent call last):
  File "/usr/local/lib/python2.7/dist-packages/django/core/handlers/base.py", line 112, in get_response
    response = wrapped_callback(request, *callback_args, **callback_kwargs)
  File "/usr/local/lib/python2.7/dist-packages/django/views/generic/base.py", line 69, in view
    return self.dispatch(request, *args, **kwargs)
  File "/usr/local/lib/python2.7/dist-packages/django/utils/decorators.py", line 29, in _wrapper
    return bound_func(*args, **kwargs)
  File "/usr/local/lib/python2.7/dist-packages/django/contrib/auth/decorators.py", line 22, in _wrapped_view
    return view_func(request, *args, **kwargs)
  File "/usr/local/lib/python2.7/dist-packages/django/utils/decorators.py", line 25, in bound_func
    return func(self, *args2, **kwargs2)
  File "/home/mikhail/EclipseWorkspace/oncoFinder2/oncoFinder2/core/views.py", line 936, in dispatch
    return super(Test, self).dispatch(request, *args, **kwargs)
  File "/usr/local/lib/python2.7/dist-packages/django/views/generic/base.py", line 87, in dispatch
    return handler(request, *args, **kwargs)
  File "/usr/local/lib/python2.7/dist-packages/django/views/generic/base.py", line 154, in get
    context = self.get_context_data(**kwargs)
  File "/home/mikhail/EclipseWorkspace/oncoFinder2/oncoFinder2/core/views.py", line 961, in get_context_data
    raise Exception('test')
Exception: test
2015-09-22 11:57:39,761 ERROR base 28108 -1361052864 Internal Server Error: /test/
Traceback (most recent call last):
  File "/usr/local/lib/python2.7/dist-packages/django/core/handlers/base.py", line 112, in get_response
    response = wrapped_callback(request, *callback_args, **callback_kwargs)
  File "/usr/local/lib/python2.7/dist-packages/django/views/generic/base.py", line 69, in view
    return self.dispatch(request, *args, **kwargs)
  File "/usr/local/lib/python2.7/dist-packages/django/utils/decorators.py", line 29, in _wrapper
    return bound_func(*args, **kwargs)
  File "/usr/local/lib/python2.7/dist-packages/django/contrib/auth/decorators.py", line 22, in _wrapped_view
    return view_func(request, *args, **kwargs)
  File "/usr/local/lib/python2.7/dist-packages/django/utils/decorators.py", line 25, in bound_func
    return func(self, *args2, **kwargs2)
  File "/home/mikhail/EclipseWorkspace/oncoFinder2/oncoFinder2/core/views.py", line 936, in dispatch
    return super(Test, self).dispatch(request, *args, **kwargs)
  File "/usr/local/lib/python2.7/dist-packages/django/views/generic/base.py", line 87, in dispatch
    return handler(request, *args, **kwargs)
  File "/usr/local/lib/python2.7/dist-packages/django/views/generic/base.py", line 154, in get
    context = self.get_context_data(**kwargs)
  File "/home/mikhail/EclipseWorkspace/oncoFinder2/oncoFinder2/core/views.py", line 961, in get_context_data
    raise Exception('test')
Exception: test
2015-09-22 11:59:04,035 ERROR base 28638 -1361052864 Internal Server Error: /test/
Traceback (most recent call last):
  File "/usr/local/lib/python2.7/dist-packages/django/core/handlers/base.py", line 112, in get_response
    response = wrapped_callback(request, *callback_args, **callback_kwargs)
  File "/usr/local/lib/python2.7/dist-packages/django/views/generic/base.py", line 69, in view
    return self.dispatch(request, *args, **kwargs)
  File "/usr/local/lib/python2.7/dist-packages/django/utils/decorators.py", line 29, in _wrapper
    return bound_func(*args, **kwargs)
  File "/usr/local/lib/python2.7/dist-packages/django/contrib/auth/decorators.py", line 22, in _wrapped_view
    return view_func(request, *args, **kwargs)
  File "/usr/local/lib/python2.7/dist-packages/django/utils/decorators.py", line 25, in bound_func
    return func(self, *args2, **kwargs2)
  File "/home/mikhail/EclipseWorkspace/oncoFinder2/oncoFinder2/core/views.py", line 936, in dispatch
    return super(Test, self).dispatch(request, *args, **kwargs)
  File "/usr/local/lib/python2.7/dist-packages/django/views/generic/base.py", line 87, in dispatch
    return handler(request, *args, **kwargs)
  File "/usr/local/lib/python2.7/dist-packages/django/views/generic/base.py", line 154, in get
    context = self.get_context_data(**kwargs)
  File "/home/mikhail/EclipseWorkspace/oncoFinder2/oncoFinder2/core/views.py", line 964, in get_context_data
    raise Exception('test')
Exception: test
2015-09-22 12:01:09,736 ERROR base 29456 -1359930560 Internal Server Error: /test/
Traceback (most recent call last):
  File "/usr/local/lib/python2.7/dist-packages/django/core/handlers/base.py", line 112, in get_response
    response = wrapped_callback(request, *callback_args, **callback_kwargs)
  File "/usr/local/lib/python2.7/dist-packages/django/views/generic/base.py", line 69, in view
    return self.dispatch(request, *args, **kwargs)
  File "/usr/local/lib/python2.7/dist-packages/django/utils/decorators.py", line 29, in _wrapper
    return bound_func(*args, **kwargs)
  File "/usr/local/lib/python2.7/dist-packages/django/contrib/auth/decorators.py", line 22, in _wrapped_view
    return view_func(request, *args, **kwargs)
  File "/usr/local/lib/python2.7/dist-packages/django/utils/decorators.py", line 25, in bound_func
    return func(self, *args2, **kwargs2)
  File "/home/mikhail/EclipseWorkspace/oncoFinder2/oncoFinder2/core/views.py", line 936, in dispatch
    return super(Test, self).dispatch(request, *args, **kwargs)
  File "/usr/local/lib/python2.7/dist-packages/django/views/generic/base.py", line 87, in dispatch
    return handler(request, *args, **kwargs)
  File "/usr/local/lib/python2.7/dist-packages/django/views/generic/base.py", line 154, in get
    context = self.get_context_data(**kwargs)
  File "/home/mikhail/EclipseWorkspace/oncoFinder2/oncoFinder2/core/views.py", line 965, in get_context_data
    raise Exception('test')
Exception: test
2015-09-22 12:01:34,019 ERROR base 29634 -1360004288 Internal Server Error: /test/
Traceback (most recent call last):
  File "/usr/local/lib/python2.7/dist-packages/django/core/handlers/base.py", line 112, in get_response
    response = wrapped_callback(request, *callback_args, **callback_kwargs)
  File "/usr/local/lib/python2.7/dist-packages/django/views/generic/base.py", line 69, in view
    return self.dispatch(request, *args, **kwargs)
  File "/usr/local/lib/python2.7/dist-packages/django/utils/decorators.py", line 29, in _wrapper
    return bound_func(*args, **kwargs)
  File "/usr/local/lib/python2.7/dist-packages/django/contrib/auth/decorators.py", line 22, in _wrapped_view
    return view_func(request, *args, **kwargs)
  File "/usr/local/lib/python2.7/dist-packages/django/utils/decorators.py", line 25, in bound_func
    return func(self, *args2, **kwargs2)
  File "/home/mikhail/EclipseWorkspace/oncoFinder2/oncoFinder2/core/views.py", line 936, in dispatch
    return super(Test, self).dispatch(request, *args, **kwargs)
  File "/usr/local/lib/python2.7/dist-packages/django/views/generic/base.py", line 87, in dispatch
    return handler(request, *args, **kwargs)
  File "/usr/local/lib/python2.7/dist-packages/django/views/generic/base.py", line 154, in get
    context = self.get_context_data(**kwargs)
  File "/home/mikhail/EclipseWorkspace/oncoFinder2/oncoFinder2/core/views.py", line 965, in get_context_data
    raise Exception('test')
Exception: test
2015-09-22 12:02:19,172 ERROR base 30009 -1360004288 Internal Server Error: /test/
Traceback (most recent call last):
  File "/usr/local/lib/python2.7/dist-packages/django/core/handlers/base.py", line 112, in get_response
    response = wrapped_callback(request, *callback_args, **callback_kwargs)
  File "/usr/local/lib/python2.7/dist-packages/django/views/generic/base.py", line 69, in view
    return self.dispatch(request, *args, **kwargs)
  File "/usr/local/lib/python2.7/dist-packages/django/utils/decorators.py", line 29, in _wrapper
    return bound_func(*args, **kwargs)
  File "/usr/local/lib/python2.7/dist-packages/django/contrib/auth/decorators.py", line 22, in _wrapped_view
    return view_func(request, *args, **kwargs)
  File "/usr/local/lib/python2.7/dist-packages/django/utils/decorators.py", line 25, in bound_func
    return func(self, *args2, **kwargs2)
  File "/home/mikhail/EclipseWorkspace/oncoFinder2/oncoFinder2/core/views.py", line 936, in dispatch
    return super(Test, self).dispatch(request, *args, **kwargs)
  File "/usr/local/lib/python2.7/dist-packages/django/views/generic/base.py", line 87, in dispatch
    return handler(request, *args, **kwargs)
  File "/usr/local/lib/python2.7/dist-packages/django/views/generic/base.py", line 154, in get
    context = self.get_context_data(**kwargs)
  File "/home/mikhail/EclipseWorkspace/oncoFinder2/oncoFinder2/core/views.py", line 965, in get_context_data
    raise Exception('test')
Exception: test
2015-09-22 12:03:19,538 ERROR base 30405 -1361052864 Internal Server Error: /test/
Traceback (most recent call last):
  File "/usr/local/lib/python2.7/dist-packages/django/core/handlers/base.py", line 112, in get_response
    response = wrapped_callback(request, *callback_args, **callback_kwargs)
  File "/usr/local/lib/python2.7/dist-packages/django/views/generic/base.py", line 69, in view
    return self.dispatch(request, *args, **kwargs)
  File "/usr/local/lib/python2.7/dist-packages/django/utils/decorators.py", line 29, in _wrapper
    return bound_func(*args, **kwargs)
  File "/usr/local/lib/python2.7/dist-packages/django/contrib/auth/decorators.py", line 22, in _wrapped_view
    return view_func(request, *args, **kwargs)
  File "/usr/local/lib/python2.7/dist-packages/django/utils/decorators.py", line 25, in bound_func
    return func(self, *args2, **kwargs2)
  File "/home/mikhail/EclipseWorkspace/oncoFinder2/oncoFinder2/core/views.py", line 936, in dispatch
    return super(Test, self).dispatch(request, *args, **kwargs)
  File "/usr/local/lib/python2.7/dist-packages/django/views/generic/base.py", line 87, in dispatch
    return handler(request, *args, **kwargs)
  File "/usr/local/lib/python2.7/dist-packages/django/views/generic/base.py", line 154, in get
    context = self.get_context_data(**kwargs)
  File "/home/mikhail/EclipseWorkspace/oncoFinder2/oncoFinder2/core/views.py", line 965, in get_context_data
    raise Exception('test')
Exception: test
2015-09-22 12:04:05,159 ERROR base 30720 -1361052864 Internal Server Error: /test/
Traceback (most recent call last):
  File "/usr/local/lib/python2.7/dist-packages/django/core/handlers/base.py", line 112, in get_response
    response = wrapped_callback(request, *callback_args, **callback_kwargs)
  File "/usr/local/lib/python2.7/dist-packages/django/views/generic/base.py", line 69, in view
    return self.dispatch(request, *args, **kwargs)
  File "/usr/local/lib/python2.7/dist-packages/django/utils/decorators.py", line 29, in _wrapper
    return bound_func(*args, **kwargs)
  File "/usr/local/lib/python2.7/dist-packages/django/contrib/auth/decorators.py", line 22, in _wrapped_view
    return view_func(request, *args, **kwargs)
  File "/usr/local/lib/python2.7/dist-packages/django/utils/decorators.py", line 25, in bound_func
    return func(self, *args2, **kwargs2)
  File "/home/mikhail/EclipseWorkspace/oncoFinder2/oncoFinder2/core/views.py", line 936, in dispatch
    return super(Test, self).dispatch(request, *args, **kwargs)
  File "/usr/local/lib/python2.7/dist-packages/django/views/generic/base.py", line 87, in dispatch
    return handler(request, *args, **kwargs)
  File "/usr/local/lib/python2.7/dist-packages/django/views/generic/base.py", line 154, in get
    context = self.get_context_data(**kwargs)
  File "/home/mikhail/EclipseWorkspace/oncoFinder2/oncoFinder2/core/views.py", line 965, in get_context_data
    raise Exception('test')
Exception: test
2015-09-22 12:04:36,367 ERROR base 30902 -1360004288 Internal Server Error: /test/
Traceback (most recent call last):
  File "/usr/local/lib/python2.7/dist-packages/django/core/handlers/base.py", line 112, in get_response
    response = wrapped_callback(request, *callback_args, **callback_kwargs)
  File "/usr/local/lib/python2.7/dist-packages/django/views/generic/base.py", line 69, in view
    return self.dispatch(request, *args, **kwargs)
  File "/usr/local/lib/python2.7/dist-packages/django/utils/decorators.py", line 29, in _wrapper
    return bound_func(*args, **kwargs)
  File "/usr/local/lib/python2.7/dist-packages/django/contrib/auth/decorators.py", line 22, in _wrapped_view
    return view_func(request, *args, **kwargs)
  File "/usr/local/lib/python2.7/dist-packages/django/utils/decorators.py", line 25, in bound_func
    return func(self, *args2, **kwargs2)
  File "/home/mikhail/EclipseWorkspace/oncoFinder2/oncoFinder2/core/views.py", line 936, in dispatch
    return super(Test, self).dispatch(request, *args, **kwargs)
  File "/usr/local/lib/python2.7/dist-packages/django/views/generic/base.py", line 87, in dispatch
    return handler(request, *args, **kwargs)
  File "/usr/local/lib/python2.7/dist-packages/django/views/generic/base.py", line 154, in get
    context = self.get_context_data(**kwargs)
  File "/home/mikhail/EclipseWorkspace/oncoFinder2/oncoFinder2/core/views.py", line 965, in get_context_data
    raise Exception('test')
Exception: test
2015-09-22 12:06:43,136 ERROR base 31692 -1361052864 Internal Server Error: /test/
Traceback (most recent call last):
  File "/usr/local/lib/python2.7/dist-packages/django/core/handlers/base.py", line 112, in get_response
    response = wrapped_callback(request, *callback_args, **callback_kwargs)
  File "/usr/local/lib/python2.7/dist-packages/django/views/generic/base.py", line 69, in view
    return self.dispatch(request, *args, **kwargs)
  File "/usr/local/lib/python2.7/dist-packages/django/utils/decorators.py", line 29, in _wrapper
    return bound_func(*args, **kwargs)
  File "/usr/local/lib/python2.7/dist-packages/django/contrib/auth/decorators.py", line 22, in _wrapped_view
    return view_func(request, *args, **kwargs)
  File "/usr/local/lib/python2.7/dist-packages/django/utils/decorators.py", line 25, in bound_func
    return func(self, *args2, **kwargs2)
  File "/home/mikhail/EclipseWorkspace/oncoFinder2/oncoFinder2/core/views.py", line 936, in dispatch
    return super(Test, self).dispatch(request, *args, **kwargs)
  File "/usr/local/lib/python2.7/dist-packages/django/views/generic/base.py", line 87, in dispatch
    return handler(request, *args, **kwargs)
  File "/usr/local/lib/python2.7/dist-packages/django/views/generic/base.py", line 154, in get
    context = self.get_context_data(**kwargs)
  File "/home/mikhail/EclipseWorkspace/oncoFinder2/oncoFinder2/core/views.py", line 965, in get_context_data
    raise Exception('test')
Exception: test
2015-09-22 12:07:19,169 ERROR base 32018 -1360004288 Internal Server Error: /test/
Traceback (most recent call last):
  File "/usr/local/lib/python2.7/dist-packages/django/core/handlers/base.py", line 112, in get_response
    response = wrapped_callback(request, *callback_args, **callback_kwargs)
  File "/usr/local/lib/python2.7/dist-packages/django/views/generic/base.py", line 69, in view
    return self.dispatch(request, *args, **kwargs)
  File "/usr/local/lib/python2.7/dist-packages/django/utils/decorators.py", line 29, in _wrapper
    return bound_func(*args, **kwargs)
  File "/usr/local/lib/python2.7/dist-packages/django/contrib/auth/decorators.py", line 22, in _wrapped_view
    return view_func(request, *args, **kwargs)
  File "/usr/local/lib/python2.7/dist-packages/django/utils/decorators.py", line 25, in bound_func
    return func(self, *args2, **kwargs2)
  File "/home/mikhail/EclipseWorkspace/oncoFinder2/oncoFinder2/core/views.py", line 936, in dispatch
    return super(Test, self).dispatch(request, *args, **kwargs)
  File "/usr/local/lib/python2.7/dist-packages/django/views/generic/base.py", line 87, in dispatch
    return handler(request, *args, **kwargs)
  File "/usr/local/lib/python2.7/dist-packages/django/views/generic/base.py", line 154, in get
    context = self.get_context_data(**kwargs)
  File "/home/mikhail/EclipseWorkspace/oncoFinder2/oncoFinder2/core/views.py", line 965, in get_context_data
    raise Exception('test')
Exception: test
2015-09-22 13:58:33,735 ERROR base 8721 -1360004288 Internal Server Error: /test/
Traceback (most recent call last):
  File "/usr/local/lib/python2.7/dist-packages/django/core/handlers/base.py", line 112, in get_response
    response = wrapped_callback(request, *callback_args, **callback_kwargs)
  File "/usr/local/lib/python2.7/dist-packages/django/views/generic/base.py", line 69, in view
    return self.dispatch(request, *args, **kwargs)
  File "/usr/local/lib/python2.7/dist-packages/django/utils/decorators.py", line 29, in _wrapper
    return bound_func(*args, **kwargs)
  File "/usr/local/lib/python2.7/dist-packages/django/contrib/auth/decorators.py", line 22, in _wrapped_view
    return view_func(request, *args, **kwargs)
  File "/usr/local/lib/python2.7/dist-packages/django/utils/decorators.py", line 25, in bound_func
    return func(self, *args2, **kwargs2)
  File "/home/mikhail/EclipseWorkspace/oncoFinder2/oncoFinder2/core/views.py", line 936, in dispatch
    return super(Test, self).dispatch(request, *args, **kwargs)
  File "/usr/local/lib/python2.7/dist-packages/django/views/generic/base.py", line 87, in dispatch
    return handler(request, *args, **kwargs)
  File "/usr/local/lib/python2.7/dist-packages/django/views/generic/base.py", line 154, in get
    context = self.get_context_data(**kwargs)
  File "/home/mikhail/EclipseWorkspace/oncoFinder2/oncoFinder2/core/views.py", line 943, in get_context_data
    raise Exception('stop')
Exception: stop
2015-09-22 14:01:52,434 ERROR base 10219 -1360176320 Internal Server Error: /test/
Traceback (most recent call last):
  File "/usr/local/lib/python2.7/dist-packages/django/core/handlers/base.py", line 112, in get_response
    response = wrapped_callback(request, *callback_args, **callback_kwargs)
  File "/usr/local/lib/python2.7/dist-packages/django/views/generic/base.py", line 69, in view
    return self.dispatch(request, *args, **kwargs)
  File "/usr/local/lib/python2.7/dist-packages/django/utils/decorators.py", line 29, in _wrapper
    return bound_func(*args, **kwargs)
  File "/usr/local/lib/python2.7/dist-packages/django/contrib/auth/decorators.py", line 22, in _wrapped_view
    return view_func(request, *args, **kwargs)
  File "/usr/local/lib/python2.7/dist-packages/django/utils/decorators.py", line 25, in bound_func
    return func(self, *args2, **kwargs2)
  File "/home/mikhail/EclipseWorkspace/oncoFinder2/oncoFinder2/core/views.py", line 936, in dispatch
    return super(Test, self).dispatch(request, *args, **kwargs)
  File "/usr/local/lib/python2.7/dist-packages/django/views/generic/base.py", line 87, in dispatch
    return handler(request, *args, **kwargs)
  File "/usr/local/lib/python2.7/dist-packages/django/views/generic/base.py", line 154, in get
    context = self.get_context_data(**kwargs)
  File "/home/mikhail/EclipseWorkspace/oncoFinder2/oncoFinder2/core/views.py", line 944, in get_context_data
    raise Exception('stop')
Exception: stop
2015-09-22 14:02:24,218 ERROR base 10436 -1360004288 Internal Server Error: /test/
Traceback (most recent call last):
  File "/usr/local/lib/python2.7/dist-packages/django/core/handlers/base.py", line 112, in get_response
    response = wrapped_callback(request, *callback_args, **callback_kwargs)
  File "/usr/local/lib/python2.7/dist-packages/django/views/generic/base.py", line 69, in view
    return self.dispatch(request, *args, **kwargs)
  File "/usr/local/lib/python2.7/dist-packages/django/utils/decorators.py", line 29, in _wrapper
    return bound_func(*args, **kwargs)
  File "/usr/local/lib/python2.7/dist-packages/django/contrib/auth/decorators.py", line 22, in _wrapped_view
    return view_func(request, *args, **kwargs)
  File "/usr/local/lib/python2.7/dist-packages/django/utils/decorators.py", line 25, in bound_func
    return func(self, *args2, **kwargs2)
  File "/home/mikhail/EclipseWorkspace/oncoFinder2/oncoFinder2/core/views.py", line 936, in dispatch
    return super(Test, self).dispatch(request, *args, **kwargs)
  File "/usr/local/lib/python2.7/dist-packages/django/views/generic/base.py", line 87, in dispatch
    return handler(request, *args, **kwargs)
  File "/usr/local/lib/python2.7/dist-packages/django/views/generic/base.py", line 154, in get
    context = self.get_context_data(**kwargs)
  File "/home/mikhail/EclipseWorkspace/oncoFinder2/oncoFinder2/core/views.py", line 943, in get_context_data
    drugs_ds = DataFrame(list(Drug.objects.all(using='old').values('name', 'db')))
TypeError: all() got an unexpected keyword argument 'using'
2015-09-22 14:02:50,753 ERROR base 10608 -1360176320 Internal Server Error: /test/
Traceback (most recent call last):
  File "/usr/local/lib/python2.7/dist-packages/django/core/handlers/base.py", line 112, in get_response
    response = wrapped_callback(request, *callback_args, **callback_kwargs)
  File "/usr/local/lib/python2.7/dist-packages/django/views/generic/base.py", line 69, in view
    return self.dispatch(request, *args, **kwargs)
  File "/usr/local/lib/python2.7/dist-packages/django/utils/decorators.py", line 29, in _wrapper
    return bound_func(*args, **kwargs)
  File "/usr/local/lib/python2.7/dist-packages/django/contrib/auth/decorators.py", line 22, in _wrapped_view
    return view_func(request, *args, **kwargs)
  File "/usr/local/lib/python2.7/dist-packages/django/utils/decorators.py", line 25, in bound_func
    return func(self, *args2, **kwargs2)
  File "/home/mikhail/EclipseWorkspace/oncoFinder2/oncoFinder2/core/views.py", line 936, in dispatch
    return super(Test, self).dispatch(request, *args, **kwargs)
  File "/usr/local/lib/python2.7/dist-packages/django/views/generic/base.py", line 87, in dispatch
    return handler(request, *args, **kwargs)
  File "/usr/local/lib/python2.7/dist-packages/django/views/generic/base.py", line 154, in get
    context = self.get_context_data(**kwargs)
  File "/home/mikhail/EclipseWorkspace/oncoFinder2/oncoFinder2/core/views.py", line 946, in get_context_data
    raise Exception('stop')
Exception: stop
2015-09-22 14:04:36,070 ERROR base 11406 -1360004288 Internal Server Error: /test/
Traceback (most recent call last):
  File "/usr/local/lib/python2.7/dist-packages/django/core/handlers/base.py", line 112, in get_response
    response = wrapped_callback(request, *callback_args, **callback_kwargs)
  File "/usr/local/lib/python2.7/dist-packages/django/views/generic/base.py", line 69, in view
    return self.dispatch(request, *args, **kwargs)
  File "/usr/local/lib/python2.7/dist-packages/django/utils/decorators.py", line 29, in _wrapper
    return bound_func(*args, **kwargs)
  File "/usr/local/lib/python2.7/dist-packages/django/contrib/auth/decorators.py", line 22, in _wrapped_view
    return view_func(request, *args, **kwargs)
  File "/usr/local/lib/python2.7/dist-packages/django/utils/decorators.py", line 25, in bound_func
    return func(self, *args2, **kwargs2)
  File "/home/mikhail/EclipseWorkspace/oncoFinder2/oncoFinder2/core/views.py", line 936, in dispatch
    return super(Test, self).dispatch(request, *args, **kwargs)
  File "/usr/local/lib/python2.7/dist-packages/django/views/generic/base.py", line 87, in dispatch
    return handler(request, *args, **kwargs)
  File "/usr/local/lib/python2.7/dist-packages/django/views/generic/base.py", line 154, in get
    context = self.get_context_data(**kwargs)
  File "/home/mikhail/EclipseWorkspace/oncoFinder2/oncoFinder2/core/views.py", line 943, in get_context_data
    n_of = drugs_of['name'].to_list()
  File "/usr/local/lib/python2.7/dist-packages/pandas/core/generic.py", line 1978, in __getattr__
    (type(self).__name__, name))
AttributeError: 'Series' object has no attribute 'to_list'
2015-09-22 14:05:07,567 ERROR base 11663 -1360004288 Internal Server Error: /test/
Traceback (most recent call last):
  File "/usr/local/lib/python2.7/dist-packages/django/core/handlers/base.py", line 112, in get_response
    response = wrapped_callback(request, *callback_args, **callback_kwargs)
  File "/usr/local/lib/python2.7/dist-packages/django/views/generic/base.py", line 69, in view
    return self.dispatch(request, *args, **kwargs)
  File "/usr/local/lib/python2.7/dist-packages/django/utils/decorators.py", line 29, in _wrapper
    return bound_func(*args, **kwargs)
  File "/usr/local/lib/python2.7/dist-packages/django/contrib/auth/decorators.py", line 22, in _wrapped_view
    return view_func(request, *args, **kwargs)
  File "/usr/local/lib/python2.7/dist-packages/django/utils/decorators.py", line 25, in bound_func
    return func(self, *args2, **kwargs2)
  File "/home/mikhail/EclipseWorkspace/oncoFinder2/oncoFinder2/core/views.py", line 936, in dispatch
    return super(Test, self).dispatch(request, *args, **kwargs)
  File "/usr/local/lib/python2.7/dist-packages/django/views/generic/base.py", line 87, in dispatch
    return handler(request, *args, **kwargs)
  File "/usr/local/lib/python2.7/dist-packages/django/views/generic/base.py", line 154, in get
    context = self.get_context_data(**kwargs)
  File "/home/mikhail/EclipseWorkspace/oncoFinder2/oncoFinder2/core/views.py", line 949, in get_context_data
    raise Exception('stop')
Exception: stop
2015-09-22 14:05:57,828 ERROR base 11994 -1361052864 Internal Server Error: /test/
Traceback (most recent call last):
  File "/usr/local/lib/python2.7/dist-packages/django/core/handlers/base.py", line 112, in get_response
    response = wrapped_callback(request, *callback_args, **callback_kwargs)
  File "/usr/local/lib/python2.7/dist-packages/django/views/generic/base.py", line 69, in view
    return self.dispatch(request, *args, **kwargs)
  File "/usr/local/lib/python2.7/dist-packages/django/utils/decorators.py", line 29, in _wrapper
    return bound_func(*args, **kwargs)
  File "/usr/local/lib/python2.7/dist-packages/django/contrib/auth/decorators.py", line 22, in _wrapped_view
    return view_func(request, *args, **kwargs)
  File "/usr/local/lib/python2.7/dist-packages/django/utils/decorators.py", line 25, in bound_func
    return func(self, *args2, **kwargs2)
  File "/home/mikhail/EclipseWorkspace/oncoFinder2/oncoFinder2/core/views.py", line 936, in dispatch
    return super(Test, self).dispatch(request, *args, **kwargs)
  File "/usr/local/lib/python2.7/dist-packages/django/views/generic/base.py", line 87, in dispatch
    return handler(request, *args, **kwargs)
  File "/usr/local/lib/python2.7/dist-packages/django/views/generic/base.py", line 154, in get
    context = self.get_context_data(**kwargs)
  File "/home/mikhail/EclipseWorkspace/oncoFinder2/oncoFinder2/core/views.py", line 951, in get_context_data
    raise Exception('stop')
Exception: stop
2015-09-22 14:07:10,224 ERROR base 12453 -1360176320 Internal Server Error: /test/
Traceback (most recent call last):
  File "/usr/local/lib/python2.7/dist-packages/django/core/handlers/base.py", line 112, in get_response
    response = wrapped_callback(request, *callback_args, **callback_kwargs)
  File "/usr/local/lib/python2.7/dist-packages/django/views/generic/base.py", line 69, in view
    return self.dispatch(request, *args, **kwargs)
  File "/usr/local/lib/python2.7/dist-packages/django/utils/decorators.py", line 29, in _wrapper
    return bound_func(*args, **kwargs)
  File "/usr/local/lib/python2.7/dist-packages/django/contrib/auth/decorators.py", line 22, in _wrapped_view
    return view_func(request, *args, **kwargs)
  File "/usr/local/lib/python2.7/dist-packages/django/utils/decorators.py", line 25, in bound_func
    return func(self, *args2, **kwargs2)
  File "/home/mikhail/EclipseWorkspace/oncoFinder2/oncoFinder2/core/views.py", line 936, in dispatch
    return super(Test, self).dispatch(request, *args, **kwargs)
  File "/usr/local/lib/python2.7/dist-packages/django/views/generic/base.py", line 87, in dispatch
    return handler(request, *args, **kwargs)
  File "/usr/local/lib/python2.7/dist-packages/django/views/generic/base.py", line 154, in get
    context = self.get_context_data(**kwargs)
  File "/home/mikhail/EclipseWorkspace/oncoFinder2/oncoFinder2/core/views.py", line 952, in get_context_data
    raise Exception('stop')
Exception: stop
2015-09-22 14:14:38,128 ERROR base 15317 -1361052864 Internal Server Error: /test/
Traceback (most recent call last):
  File "/usr/local/lib/python2.7/dist-packages/django/core/handlers/base.py", line 112, in get_response
    response = wrapped_callback(request, *callback_args, **callback_kwargs)
  File "/usr/local/lib/python2.7/dist-packages/django/views/generic/base.py", line 69, in view
    return self.dispatch(request, *args, **kwargs)
  File "/usr/local/lib/python2.7/dist-packages/django/utils/decorators.py", line 29, in _wrapper
    return bound_func(*args, **kwargs)
  File "/usr/local/lib/python2.7/dist-packages/django/contrib/auth/decorators.py", line 22, in _wrapped_view
    return view_func(request, *args, **kwargs)
  File "/usr/local/lib/python2.7/dist-packages/django/utils/decorators.py", line 25, in bound_func
    return func(self, *args2, **kwargs2)
  File "/home/mikhail/EclipseWorkspace/oncoFinder2/oncoFinder2/core/views.py", line 936, in dispatch
    return super(Test, self).dispatch(request, *args, **kwargs)
  File "/usr/local/lib/python2.7/dist-packages/django/views/generic/base.py", line 87, in dispatch
    return handler(request, *args, **kwargs)
  File "/usr/local/lib/python2.7/dist-packages/django/views/generic/base.py", line 154, in get
    context = self.get_context_data(**kwargs)
  File "/home/mikhail/EclipseWorkspace/oncoFinder2/oncoFinder2/core/views.py", line 951, in get_context_data
    d_gs = Drug.objects.using('old').get(name='drug_name')
  File "/usr/local/lib/python2.7/dist-packages/django/db/models/query.py", line 310, in get
    self.model._meta.object_name)
DoesNotExist: Drug matching query does not exist.
2015-09-22 14:16:46,028 ERROR base 16131 -1359930560 Internal Server Error: /test/
Traceback (most recent call last):
  File "/usr/local/lib/python2.7/dist-packages/django/core/handlers/base.py", line 112, in get_response
    response = wrapped_callback(request, *callback_args, **callback_kwargs)
  File "/usr/local/lib/python2.7/dist-packages/django/views/generic/base.py", line 69, in view
    return self.dispatch(request, *args, **kwargs)
  File "/usr/local/lib/python2.7/dist-packages/django/utils/decorators.py", line 29, in _wrapper
    return bound_func(*args, **kwargs)
  File "/usr/local/lib/python2.7/dist-packages/django/contrib/auth/decorators.py", line 22, in _wrapped_view
    return view_func(request, *args, **kwargs)
  File "/usr/local/lib/python2.7/dist-packages/django/utils/decorators.py", line 25, in bound_func
    return func(self, *args2, **kwargs2)
  File "/home/mikhail/EclipseWorkspace/oncoFinder2/oncoFinder2/core/views.py", line 936, in dispatch
    return super(Test, self).dispatch(request, *args, **kwargs)
  File "/usr/local/lib/python2.7/dist-packages/django/views/generic/base.py", line 87, in dispatch
    return handler(request, *args, **kwargs)
  File "/usr/local/lib/python2.7/dist-packages/django/views/generic/base.py", line 154, in get
    context = self.get_context_data(**kwargs)
  File "/home/mikhail/EclipseWorkspace/oncoFinder2/oncoFinder2/core/views.py", line 951, in get_context_data
    d_gs = Drug.objects.using('old').get(name=drug_name)
  File "/usr/local/lib/python2.7/dist-packages/django/db/models/query.py", line 313, in get
    (self.model._meta.object_name, num))
MultipleObjectsReturned: get() returned more than one Drug -- it returned 2!
2015-09-22 14:20:12,085 ERROR base 17473 -1361052864 Internal Server Error: /test/
Traceback (most recent call last):
  File "/usr/local/lib/python2.7/dist-packages/django/core/handlers/base.py", line 112, in get_response
    response = wrapped_callback(request, *callback_args, **callback_kwargs)
  File "/usr/local/lib/python2.7/dist-packages/django/views/generic/base.py", line 69, in view
    return self.dispatch(request, *args, **kwargs)
  File "/usr/local/lib/python2.7/dist-packages/django/utils/decorators.py", line 29, in _wrapper
    return bound_func(*args, **kwargs)
  File "/usr/local/lib/python2.7/dist-packages/django/contrib/auth/decorators.py", line 22, in _wrapped_view
    return view_func(request, *args, **kwargs)
  File "/usr/local/lib/python2.7/dist-packages/django/utils/decorators.py", line 25, in bound_func
    return func(self, *args2, **kwargs2)
  File "/home/mikhail/EclipseWorkspace/oncoFinder2/oncoFinder2/core/views.py", line 936, in dispatch
    return super(Test, self).dispatch(request, *args, **kwargs)
  File "/usr/local/lib/python2.7/dist-packages/django/views/generic/base.py", line 87, in dispatch
    return handler(request, *args, **kwargs)
  File "/usr/local/lib/python2.7/dist-packages/django/views/generic/base.py", line 154, in get
    context = self.get_context_data(**kwargs)
  File "/home/mikhail/EclipseWorkspace/oncoFinder2/oncoFinder2/core/views.py", line 957, in get_context_data
    raise Exception('stop')
Exception: stop
2015-09-22 14:26:58,747 ERROR base 20137 -1361052864 Internal Server Error: /test/
Traceback (most recent call last):
  File "/usr/local/lib/python2.7/dist-packages/django/core/handlers/base.py", line 112, in get_response
    response = wrapped_callback(request, *callback_args, **callback_kwargs)
  File "/usr/local/lib/python2.7/dist-packages/django/views/generic/base.py", line 69, in view
    return self.dispatch(request, *args, **kwargs)
  File "/usr/local/lib/python2.7/dist-packages/django/utils/decorators.py", line 29, in _wrapper
    return bound_func(*args, **kwargs)
  File "/usr/local/lib/python2.7/dist-packages/django/contrib/auth/decorators.py", line 22, in _wrapped_view
    return view_func(request, *args, **kwargs)
  File "/usr/local/lib/python2.7/dist-packages/django/utils/decorators.py", line 25, in bound_func
    return func(self, *args2, **kwargs2)
  File "/home/mikhail/EclipseWorkspace/oncoFinder2/oncoFinder2/core/views.py", line 936, in dispatch
    return super(Test, self).dispatch(request, *args, **kwargs)
  File "/usr/local/lib/python2.7/dist-packages/django/views/generic/base.py", line 87, in dispatch
    return handler(request, *args, **kwargs)
  File "/usr/local/lib/python2.7/dist-packages/django/views/generic/base.py", line 154, in get
    context = self.get_context_data(**kwargs)
  File "/home/mikhail/EclipseWorkspace/oncoFinder2/oncoFinder2/core/views.py", line 962, in get_context_data
    raise Exception('stop')
Exception: stop
2015-09-22 14:30:08,234 ERROR base 20897 -1360004288 Internal Server Error: /test/
Traceback (most recent call last):
  File "/usr/local/lib/python2.7/dist-packages/django/core/handlers/base.py", line 112, in get_response
    response = wrapped_callback(request, *callback_args, **callback_kwargs)
  File "/usr/local/lib/python2.7/dist-packages/django/views/generic/base.py", line 69, in view
    return self.dispatch(request, *args, **kwargs)
  File "/usr/local/lib/python2.7/dist-packages/django/utils/decorators.py", line 29, in _wrapper
    return bound_func(*args, **kwargs)
  File "/usr/local/lib/python2.7/dist-packages/django/contrib/auth/decorators.py", line 22, in _wrapped_view
    return view_func(request, *args, **kwargs)
  File "/usr/local/lib/python2.7/dist-packages/django/utils/decorators.py", line 25, in bound_func
    return func(self, *args2, **kwargs2)
  File "/home/mikhail/EclipseWorkspace/oncoFinder2/oncoFinder2/core/views.py", line 936, in dispatch
    return super(Test, self).dispatch(request, *args, **kwargs)
  File "/usr/local/lib/python2.7/dist-packages/django/views/generic/base.py", line 87, in dispatch
    return handler(request, *args, **kwargs)
  File "/usr/local/lib/python2.7/dist-packages/django/views/generic/base.py", line 154, in get
    context = self.get_context_data(**kwargs)
  File "/home/mikhail/EclipseWorkspace/oncoFinder2/oncoFinder2/core/views.py", line 964, in get_context_data
    raise Exception('stop')
Exception: stop
2015-09-22 14:36:50,075 ERROR base 23576 -1389368512 Internal Server Error: /test/
Traceback (most recent call last):
  File "/usr/local/lib/python2.7/dist-packages/django/core/handlers/base.py", line 112, in get_response
    response = wrapped_callback(request, *callback_args, **callback_kwargs)
  File "/usr/local/lib/python2.7/dist-packages/django/views/generic/base.py", line 69, in view
    return self.dispatch(request, *args, **kwargs)
  File "/usr/local/lib/python2.7/dist-packages/django/utils/decorators.py", line 29, in _wrapper
    return bound_func(*args, **kwargs)
  File "/usr/local/lib/python2.7/dist-packages/django/contrib/auth/decorators.py", line 22, in _wrapped_view
    return view_func(request, *args, **kwargs)
  File "/usr/local/lib/python2.7/dist-packages/django/utils/decorators.py", line 25, in bound_func
    return func(self, *args2, **kwargs2)
  File "/home/mikhail/EclipseWorkspace/oncoFinder2/oncoFinder2/core/views.py", line 936, in dispatch
    return super(Test, self).dispatch(request, *args, **kwargs)
  File "/usr/local/lib/python2.7/dist-packages/django/views/generic/base.py", line 87, in dispatch
    return handler(request, *args, **kwargs)
  File "/usr/local/lib/python2.7/dist-packages/django/views/generic/base.py", line 154, in get
    context = self.get_context_data(**kwargs)
  File "/home/mikhail/EclipseWorkspace/oncoFinder2/oncoFinder2/core/views.py", line 968, in get_context_data
    raise Exception('stop')
Exception: stop
2015-09-22 14:38:26,024 ERROR base 24621 -1370490048 Internal Server Error: /document/doc6973/
Traceback (most recent call last):
  File "/usr/local/lib/python2.7/dist-packages/django/core/handlers/base.py", line 112, in get_response
    response = wrapped_callback(request, *callback_args, **callback_kwargs)
  File "/usr/local/lib/python2.7/dist-packages/django/views/generic/base.py", line 69, in view
    return self.dispatch(request, *args, **kwargs)
  File "/usr/local/lib/python2.7/dist-packages/django/utils/decorators.py", line 29, in _wrapper
    return bound_func(*args, **kwargs)
  File "/usr/local/lib/python2.7/dist-packages/django/contrib/auth/decorators.py", line 22, in _wrapped_view
    return view_func(request, *args, **kwargs)
  File "/usr/local/lib/python2.7/dist-packages/django/utils/decorators.py", line 25, in bound_func
    return func(self, *args2, **kwargs2)
  File "/home/mikhail/EclipseWorkspace/oncoFinder2/oncoFinder2/profiles/views.py", line 301, in dispatch
    return super(DocumentDetail, self).dispatch(request, *args, **kwargs)
  File "/usr/local/lib/python2.7/dist-packages/django/views/generic/base.py", line 87, in dispatch
    return handler(request, *args, **kwargs)
  File "/usr/local/lib/python2.7/dist-packages/django/views/generic/detail.py", line 111, in get
    context = self.get_context_data(object=self.object)
  File "/home/mikhail/EclipseWorkspace/oncoFinder2/oncoFinder2/profiles/views.py", line 309, in get_context_data
    dialect = sniffer.sniff(open(filename, 'r').read(), delimiters='\t,;') # defining the separator of the csv file
IOError: [Errno 2] No such file or directory: u'/home/mikhail/EclipseWorkspace/oncoFinder2/oncoFinder2/oncoFinder2/media/users/admin/custom/input/gcrma11.csv'
2015-09-22 14:38:38,911 ERROR base 24621 -1370490048 Internal Server Error: /document/doc6984/
Traceback (most recent call last):
  File "/usr/local/lib/python2.7/dist-packages/django/core/handlers/base.py", line 112, in get_response
    response = wrapped_callback(request, *callback_args, **callback_kwargs)
  File "/usr/local/lib/python2.7/dist-packages/django/views/generic/base.py", line 69, in view
    return self.dispatch(request, *args, **kwargs)
  File "/usr/local/lib/python2.7/dist-packages/django/utils/decorators.py", line 29, in _wrapper
    return bound_func(*args, **kwargs)
  File "/usr/local/lib/python2.7/dist-packages/django/contrib/auth/decorators.py", line 22, in _wrapped_view
    return view_func(request, *args, **kwargs)
  File "/usr/local/lib/python2.7/dist-packages/django/utils/decorators.py", line 25, in bound_func
    return func(self, *args2, **kwargs2)
  File "/home/mikhail/EclipseWorkspace/oncoFinder2/oncoFinder2/profiles/views.py", line 301, in dispatch
    return super(DocumentDetail, self).dispatch(request, *args, **kwargs)
  File "/usr/local/lib/python2.7/dist-packages/django/views/generic/base.py", line 87, in dispatch
    return handler(request, *args, **kwargs)
  File "/usr/local/lib/python2.7/dist-packages/django/views/generic/detail.py", line 111, in get
    context = self.get_context_data(object=self.object)
  File "/home/mikhail/EclipseWorkspace/oncoFinder2/oncoFinder2/profiles/views.py", line 309, in get_context_data
    dialect = sniffer.sniff(open(filename, 'r').read(), delimiters='\t,;') # defining the separator of the csv file
IOError: [Errno 2] No such file or directory: u'/home/mikhail/EclipseWorkspace/oncoFinder2/oncoFinder2/oncoFinder2/media/users/admin/custom/input/3DRUGS_ILL_dif07_1.txt'
2015-09-22 15:00:59,915 ERROR base 1401 -1361052864 Internal Server Error: /calculation-parameters/doc7026/
Traceback (most recent call last):
  File "/usr/local/lib/python2.7/dist-packages/django/core/handlers/base.py", line 112, in get_response
    response = wrapped_callback(request, *callback_args, **callback_kwargs)
  File "/usr/local/lib/python2.7/dist-packages/django/views/generic/base.py", line 69, in view
    return self.dispatch(request, *args, **kwargs)
  File "/usr/local/lib/python2.7/dist-packages/django/utils/decorators.py", line 29, in _wrapper
    return bound_func(*args, **kwargs)
  File "/usr/local/lib/python2.7/dist-packages/django/contrib/auth/decorators.py", line 22, in _wrapped_view
    return view_func(request, *args, **kwargs)
  File "/usr/local/lib/python2.7/dist-packages/django/utils/decorators.py", line 25, in bound_func
    return func(self, *args2, **kwargs2)
  File "/home/mikhail/EclipseWorkspace/oncoFinder2/oncoFinder2/core/views.py", line 48, in dispatch
    return super(CoreSetCalculationParameters, self).dispatch(request, *args, **kwargs)
  File "/usr/local/lib/python2.7/dist-packages/django/views/generic/base.py", line 87, in dispatch
    return handler(request, *args, **kwargs)
  File "/usr/local/lib/python2.7/dist-packages/django/views/generic/edit.py", line 171, in post
    return self.form_valid(form)
  File "/home/mikhail/EclipseWorkspace/oncoFinder2/oncoFinder2/core/views.py", line 108, in form_valid
    raise Exception('drugs db')
Exception: ds db
2015-09-22 15:02:58,876 ERROR base 2378 -1360004288 Internal Server Error: /calculation-parameters/doc7026/
Traceback (most recent call last):
  File "/usr/local/lib/python2.7/dist-packages/django/core/handlers/base.py", line 112, in get_response
    response = wrapped_callback(request, *callback_args, **callback_kwargs)
  File "/usr/local/lib/python2.7/dist-packages/django/views/generic/base.py", line 69, in view
    return self.dispatch(request, *args, **kwargs)
  File "/usr/local/lib/python2.7/dist-packages/django/utils/decorators.py", line 29, in _wrapper
    return bound_func(*args, **kwargs)
  File "/usr/local/lib/python2.7/dist-packages/django/contrib/auth/decorators.py", line 22, in _wrapped_view
    return view_func(request, *args, **kwargs)
  File "/usr/local/lib/python2.7/dist-packages/django/utils/decorators.py", line 25, in bound_func
    return func(self, *args2, **kwargs2)
  File "/home/mikhail/EclipseWorkspace/oncoFinder2/oncoFinder2/core/views.py", line 48, in dispatch
    return super(CoreSetCalculationParameters, self).dispatch(request, *args, **kwargs)
  File "/usr/local/lib/python2.7/dist-packages/django/views/generic/base.py", line 87, in dispatch
    return handler(request, *args, **kwargs)
  File "/usr/local/lib/python2.7/dist-packages/django/views/generic/edit.py", line 171, in post
    return self.form_valid(form)
  File "/home/mikhail/EclipseWorkspace/oncoFinder2/oncoFinder2/core/views.py", line 113, in form_valid
    raise Exception('drugs db')
Exception: drugs db
2015-09-22 15:05:24,258 ERROR base 3528 -1360176320 Internal Server Error: /calculation-parameters/doc7026/
Traceback (most recent call last):
  File "/usr/local/lib/python2.7/dist-packages/django/core/handlers/base.py", line 112, in get_response
    response = wrapped_callback(request, *callback_args, **callback_kwargs)
  File "/usr/local/lib/python2.7/dist-packages/django/views/generic/base.py", line 69, in view
    return self.dispatch(request, *args, **kwargs)
  File "/usr/local/lib/python2.7/dist-packages/django/utils/decorators.py", line 29, in _wrapper
    return bound_func(*args, **kwargs)
  File "/usr/local/lib/python2.7/dist-packages/django/contrib/auth/decorators.py", line 22, in _wrapped_view
    return view_func(request, *args, **kwargs)
  File "/usr/local/lib/python2.7/dist-packages/django/utils/decorators.py", line 25, in bound_func
    return func(self, *args2, **kwargs2)
  File "/home/mikhail/EclipseWorkspace/oncoFinder2/oncoFinder2/core/views.py", line 48, in dispatch
    return super(CoreSetCalculationParameters, self).dispatch(request, *args, **kwargs)
  File "/usr/local/lib/python2.7/dist-packages/django/views/generic/base.py", line 87, in dispatch
    return handler(request, *args, **kwargs)
  File "/usr/local/lib/python2.7/dist-packages/django/views/generic/edit.py", line 171, in post
    return self.form_valid(form)
  File "/home/mikhail/EclipseWorkspace/oncoFinder2/oncoFinder2/core/views.py", line 115, in form_valid
    raise Exception('drugs db')
Exception: drugs db
2015-09-22 15:05:39,458 ERROR base 3528 -1370490048 Internal Server Error: /calculation-parameters/doc7026/
Traceback (most recent call last):
  File "/usr/local/lib/python2.7/dist-packages/django/core/handlers/base.py", line 112, in get_response
    response = wrapped_callback(request, *callback_args, **callback_kwargs)
  File "/usr/local/lib/python2.7/dist-packages/django/views/generic/base.py", line 69, in view
    return self.dispatch(request, *args, **kwargs)
  File "/usr/local/lib/python2.7/dist-packages/django/utils/decorators.py", line 29, in _wrapper
    return bound_func(*args, **kwargs)
  File "/usr/local/lib/python2.7/dist-packages/django/contrib/auth/decorators.py", line 22, in _wrapped_view
    return view_func(request, *args, **kwargs)
  File "/usr/local/lib/python2.7/dist-packages/django/utils/decorators.py", line 25, in bound_func
    return func(self, *args2, **kwargs2)
  File "/home/mikhail/EclipseWorkspace/oncoFinder2/oncoFinder2/core/views.py", line 48, in dispatch
    return super(CoreSetCalculationParameters, self).dispatch(request, *args, **kwargs)
  File "/usr/local/lib/python2.7/dist-packages/django/views/generic/base.py", line 87, in dispatch
    return handler(request, *args, **kwargs)
  File "/usr/local/lib/python2.7/dist-packages/django/views/generic/edit.py", line 171, in post
    return self.form_valid(form)
  File "/home/mikhail/EclipseWorkspace/oncoFinder2/oncoFinder2/core/views.py", line 115, in form_valid
    raise Exception('drugs db')
Exception: drugs db
2015-09-22 15:05:49,054 ERROR base 3528 -1370490048 Internal Server Error: /calculation-parameters/doc7026/
Traceback (most recent call last):
  File "/usr/local/lib/python2.7/dist-packages/django/core/handlers/base.py", line 112, in get_response
    response = wrapped_callback(request, *callback_args, **callback_kwargs)
  File "/usr/local/lib/python2.7/dist-packages/django/views/generic/base.py", line 69, in view
    return self.dispatch(request, *args, **kwargs)
  File "/usr/local/lib/python2.7/dist-packages/django/utils/decorators.py", line 29, in _wrapper
    return bound_func(*args, **kwargs)
  File "/usr/local/lib/python2.7/dist-packages/django/contrib/auth/decorators.py", line 22, in _wrapped_view
    return view_func(request, *args, **kwargs)
  File "/usr/local/lib/python2.7/dist-packages/django/utils/decorators.py", line 25, in bound_func
    return func(self, *args2, **kwargs2)
  File "/home/mikhail/EclipseWorkspace/oncoFinder2/oncoFinder2/core/views.py", line 48, in dispatch
    return super(CoreSetCalculationParameters, self).dispatch(request, *args, **kwargs)
  File "/usr/local/lib/python2.7/dist-packages/django/views/generic/base.py", line 87, in dispatch
    return handler(request, *args, **kwargs)
  File "/usr/local/lib/python2.7/dist-packages/django/views/generic/edit.py", line 171, in post
    return self.form_valid(form)
  File "/home/mikhail/EclipseWorkspace/oncoFinder2/oncoFinder2/core/views.py", line 115, in form_valid
    raise Exception('drugs db')
Exception: drugs db
2015-09-22 15:05:58,528 ERROR base 3528 -1370490048 Internal Server Error: /calculation-parameters/doc7026/
Traceback (most recent call last):
  File "/usr/local/lib/python2.7/dist-packages/django/core/handlers/base.py", line 112, in get_response
    response = wrapped_callback(request, *callback_args, **callback_kwargs)
  File "/usr/local/lib/python2.7/dist-packages/django/views/generic/base.py", line 69, in view
    return self.dispatch(request, *args, **kwargs)
  File "/usr/local/lib/python2.7/dist-packages/django/utils/decorators.py", line 29, in _wrapper
    return bound_func(*args, **kwargs)
  File "/usr/local/lib/python2.7/dist-packages/django/contrib/auth/decorators.py", line 22, in _wrapped_view
    return view_func(request, *args, **kwargs)
  File "/usr/local/lib/python2.7/dist-packages/django/utils/decorators.py", line 25, in bound_func
    return func(self, *args2, **kwargs2)
  File "/home/mikhail/EclipseWorkspace/oncoFinder2/oncoFinder2/core/views.py", line 48, in dispatch
    return super(CoreSetCalculationParameters, self).dispatch(request, *args, **kwargs)
  File "/usr/local/lib/python2.7/dist-packages/django/views/generic/base.py", line 87, in dispatch
    return handler(request, *args, **kwargs)
  File "/usr/local/lib/python2.7/dist-packages/django/views/generic/edit.py", line 171, in post
    return self.form_valid(form)
  File "/home/mikhail/EclipseWorkspace/oncoFinder2/oncoFinder2/core/views.py", line 115, in form_valid
    raise Exception('drugs db')
Exception: drugs db
