2014-11-21 17:01:52,699 ERROR base 10944 -1291289792 Internal Server Error: /document/doc2543/treat8/
Traceback (most recent call last):
  File "/usr/local/lib/python2.7/dist-packages/django/core/handlers/base.py", line 114, in get_response
    response = wrapped_callback(request, *callback_args, **callback_kwargs)
  File "/usr/local/lib/python2.7/dist-packages/django/views/generic/base.py", line 69, in view
    return self.dispatch(request, *args, **kwargs)
  File "/usr/local/lib/python2.7/dist-packages/django/utils/decorators.py", line 29, in _wrapper
    return bound_func(*args, **kwargs)
  File "/usr/local/lib/python2.7/dist-packages/django/contrib/auth/decorators.py", line 22, in _wrapped_view
    return view_func(request, *args, **kwargs)
  File "/usr/local/lib/python2.7/dist-packages/django/utils/decorators.py", line 25, in bound_func
    return func(self, *args2, **kwargs2)
  File "/home/mikhail/EclipseWorkspace/oncoFinder2/oncoFinder2/medic/views.py", line 142, in dispatch
    return super(PatientTreatmentDetail, self).dispatch(request, *args, **kwargs)
  File "/usr/local/lib/python2.7/dist-packages/django/views/generic/base.py", line 87, in dispatch
    return handler(request, *args, **kwargs)
  File "/home/mikhail/EclipseWorkspace/oncoFinder2/oncoFinder2/medic/views.py", line 288, in post
    context = self.get_context_data(object=self.object)
  File "/home/mikhail/EclipseWorkspace/oncoFinder2/oncoFinder2/medic/views.py", line 163, in get_context_data
    df_required_paths = df_pms1[path_cols]
  File "/usr/local/lib/python2.7/dist-packages/pandas/core/frame.py", line 1737, in __getitem__
    return self._getitem_array(key)
  File "/usr/local/lib/python2.7/dist-packages/pandas/core/frame.py", line 1781, in _getitem_array
    indexer = self.ix._convert_to_indexer(key, axis=1)
  File "/usr/local/lib/python2.7/dist-packages/pandas/core/indexing.py", line 1135, in _convert_to_indexer
    raise KeyError('%s not in index' % objarr[mask])
KeyError: "['L.kynurenine_degradation'] not in index"
2014-11-21 17:01:55,020 ERROR base 10944 -1437598912 Internal Server Error: /document/doc2543/treat11/
Traceback (most recent call last):
  File "/usr/local/lib/python2.7/dist-packages/django/core/handlers/base.py", line 114, in get_response
    response = wrapped_callback(request, *callback_args, **callback_kwargs)
  File "/usr/local/lib/python2.7/dist-packages/django/views/generic/base.py", line 69, in view
    return self.dispatch(request, *args, **kwargs)
  File "/usr/local/lib/python2.7/dist-packages/django/utils/decorators.py", line 29, in _wrapper
    return bound_func(*args, **kwargs)
  File "/usr/local/lib/python2.7/dist-packages/django/contrib/auth/decorators.py", line 22, in _wrapped_view
    return view_func(request, *args, **kwargs)
  File "/usr/local/lib/python2.7/dist-packages/django/utils/decorators.py", line 25, in bound_func
    return func(self, *args2, **kwargs2)
  File "/home/mikhail/EclipseWorkspace/oncoFinder2/oncoFinder2/medic/views.py", line 142, in dispatch
    return super(PatientTreatmentDetail, self).dispatch(request, *args, **kwargs)
  File "/usr/local/lib/python2.7/dist-packages/django/views/generic/base.py", line 87, in dispatch
    return handler(request, *args, **kwargs)
  File "/home/mikhail/EclipseWorkspace/oncoFinder2/oncoFinder2/medic/views.py", line 288, in post
    context = self.get_context_data(object=self.object)
  File "/home/mikhail/EclipseWorkspace/oncoFinder2/oncoFinder2/medic/views.py", line 163, in get_context_data
    df_required_paths = df_pms1[path_cols]
  File "/usr/local/lib/python2.7/dist-packages/pandas/core/frame.py", line 1737, in __getitem__
    return self._getitem_array(key)
  File "/usr/local/lib/python2.7/dist-packages/pandas/core/frame.py", line 1781, in _getitem_array
    indexer = self.ix._convert_to_indexer(key, axis=1)
  File "/usr/local/lib/python2.7/dist-packages/pandas/core/indexing.py", line 1135, in _convert_to_indexer
    raise KeyError('%s not in index' % objarr[mask])
KeyError: "['L.kynurenine_degradation'\n 'sphingosine_and_sphingosine.1.phosphate_metabolism'\n 'tryptophan_degradation_to_2.amino.3.carboxymuconate_semialdehyde'] not in index"
2014-11-21 17:02:16,765 ERROR base 10944 -1437598912 Internal Server Error: /document/doc2543/treat8/
Traceback (most recent call last):
  File "/usr/local/lib/python2.7/dist-packages/django/core/handlers/base.py", line 114, in get_response
    response = wrapped_callback(request, *callback_args, **callback_kwargs)
  File "/usr/local/lib/python2.7/dist-packages/django/views/generic/base.py", line 69, in view
    return self.dispatch(request, *args, **kwargs)
  File "/usr/local/lib/python2.7/dist-packages/django/utils/decorators.py", line 29, in _wrapper
    return bound_func(*args, **kwargs)
  File "/usr/local/lib/python2.7/dist-packages/django/contrib/auth/decorators.py", line 22, in _wrapped_view
    return view_func(request, *args, **kwargs)
  File "/usr/local/lib/python2.7/dist-packages/django/utils/decorators.py", line 25, in bound_func
    return func(self, *args2, **kwargs2)
  File "/home/mikhail/EclipseWorkspace/oncoFinder2/oncoFinder2/medic/views.py", line 142, in dispatch
    return super(PatientTreatmentDetail, self).dispatch(request, *args, **kwargs)
  File "/usr/local/lib/python2.7/dist-packages/django/views/generic/base.py", line 87, in dispatch
    return handler(request, *args, **kwargs)
  File "/usr/local/lib/python2.7/dist-packages/django/views/generic/detail.py", line 111, in get
    context = self.get_context_data(object=self.object)
  File "/home/mikhail/EclipseWorkspace/oncoFinder2/oncoFinder2/medic/views.py", line 163, in get_context_data
    df_required_paths = df_pms1[path_cols]
  File "/usr/local/lib/python2.7/dist-packages/pandas/core/frame.py", line 1737, in __getitem__
    return self._getitem_array(key)
  File "/usr/local/lib/python2.7/dist-packages/pandas/core/frame.py", line 1781, in _getitem_array
    indexer = self.ix._convert_to_indexer(key, axis=1)
  File "/usr/local/lib/python2.7/dist-packages/pandas/core/indexing.py", line 1135, in _convert_to_indexer
    raise KeyError('%s not in index' % objarr[mask])
KeyError: "['L.kynurenine_degradation'] not in index"
2014-11-21 17:06:22,927 ERROR base 10944 -1416627392 Internal Server Error: /document/doc2543/treat14/
Traceback (most recent call last):
  File "/usr/local/lib/python2.7/dist-packages/django/core/handlers/base.py", line 114, in get_response
    response = wrapped_callback(request, *callback_args, **callback_kwargs)
  File "/usr/local/lib/python2.7/dist-packages/django/views/generic/base.py", line 69, in view
    return self.dispatch(request, *args, **kwargs)
  File "/usr/local/lib/python2.7/dist-packages/django/utils/decorators.py", line 29, in _wrapper
    return bound_func(*args, **kwargs)
  File "/usr/local/lib/python2.7/dist-packages/django/contrib/auth/decorators.py", line 22, in _wrapped_view
    return view_func(request, *args, **kwargs)
  File "/usr/local/lib/python2.7/dist-packages/django/utils/decorators.py", line 25, in bound_func
    return func(self, *args2, **kwargs2)
  File "/home/mikhail/EclipseWorkspace/oncoFinder2/oncoFinder2/medic/views.py", line 142, in dispatch
    return super(PatientTreatmentDetail, self).dispatch(request, *args, **kwargs)
  File "/usr/local/lib/python2.7/dist-packages/django/views/generic/base.py", line 87, in dispatch
    return handler(request, *args, **kwargs)
  File "/home/mikhail/EclipseWorkspace/oncoFinder2/oncoFinder2/medic/views.py", line 288, in post
    context = self.get_context_data(object=self.object)
  File "/home/mikhail/EclipseWorkspace/oncoFinder2/oncoFinder2/medic/views.py", line 163, in get_context_data
    df_required_paths = df_pms1[path_cols]
  File "/usr/local/lib/python2.7/dist-packages/pandas/core/frame.py", line 1737, in __getitem__
    return self._getitem_array(key)
  File "/usr/local/lib/python2.7/dist-packages/pandas/core/frame.py", line 1781, in _getitem_array
    indexer = self.ix._convert_to_indexer(key, axis=1)
  File "/usr/local/lib/python2.7/dist-packages/pandas/core/indexing.py", line 1135, in _convert_to_indexer
    raise KeyError('%s not in index' % objarr[mask])
KeyError: "['sphingosine_and_sphingosine.1.phosphate_metabolism'] not in index"
2014-11-21 17:06:23,436 ERROR base 10944 -1445991616 Internal Server Error: /document/doc2543/treat12/
Traceback (most recent call last):
  File "/usr/local/lib/python2.7/dist-packages/django/core/handlers/base.py", line 114, in get_response
    response = wrapped_callback(request, *callback_args, **callback_kwargs)
  File "/usr/local/lib/python2.7/dist-packages/django/views/generic/base.py", line 69, in view
    return self.dispatch(request, *args, **kwargs)
  File "/usr/local/lib/python2.7/dist-packages/django/utils/decorators.py", line 29, in _wrapper
    return bound_func(*args, **kwargs)
  File "/usr/local/lib/python2.7/dist-packages/django/contrib/auth/decorators.py", line 22, in _wrapped_view
    return view_func(request, *args, **kwargs)
  File "/usr/local/lib/python2.7/dist-packages/django/utils/decorators.py", line 25, in bound_func
    return func(self, *args2, **kwargs2)
  File "/home/mikhail/EclipseWorkspace/oncoFinder2/oncoFinder2/medic/views.py", line 142, in dispatch
    return super(PatientTreatmentDetail, self).dispatch(request, *args, **kwargs)
  File "/usr/local/lib/python2.7/dist-packages/django/views/generic/base.py", line 87, in dispatch
    return handler(request, *args, **kwargs)
  File "/home/mikhail/EclipseWorkspace/oncoFinder2/oncoFinder2/medic/views.py", line 288, in post
    context = self.get_context_data(object=self.object)
  File "/home/mikhail/EclipseWorkspace/oncoFinder2/oncoFinder2/medic/views.py", line 163, in get_context_data
    df_required_paths = df_pms1[path_cols]
  File "/usr/local/lib/python2.7/dist-packages/pandas/core/frame.py", line 1737, in __getitem__
    return self._getitem_array(key)
  File "/usr/local/lib/python2.7/dist-packages/pandas/core/frame.py", line 1781, in _getitem_array
    indexer = self.ix._convert_to_indexer(key, axis=1)
  File "/usr/local/lib/python2.7/dist-packages/pandas/core/indexing.py", line 1135, in _convert_to_indexer
    raise KeyError('%s not in index' % objarr[mask])
KeyError: "['ATM_Pathway_G2.M_Checkpoint_Arrest'\n 'D.galactose_degradation_V_Leloir_pathway'] not in index"
2014-11-21 17:06:24,222 ERROR base 10944 -1437598912 Internal Server Error: /document/doc2543/treat8/
Traceback (most recent call last):
  File "/usr/local/lib/python2.7/dist-packages/django/core/handlers/base.py", line 114, in get_response
    response = wrapped_callback(request, *callback_args, **callback_kwargs)
  File "/usr/local/lib/python2.7/dist-packages/django/views/generic/base.py", line 69, in view
    return self.dispatch(request, *args, **kwargs)
  File "/usr/local/lib/python2.7/dist-packages/django/utils/decorators.py", line 29, in _wrapper
    return bound_func(*args, **kwargs)
  File "/usr/local/lib/python2.7/dist-packages/django/contrib/auth/decorators.py", line 22, in _wrapped_view
    return view_func(request, *args, **kwargs)
  File "/usr/local/lib/python2.7/dist-packages/django/utils/decorators.py", line 25, in bound_func
    return func(self, *args2, **kwargs2)
  File "/home/mikhail/EclipseWorkspace/oncoFinder2/oncoFinder2/medic/views.py", line 142, in dispatch
    return super(PatientTreatmentDetail, self).dispatch(request, *args, **kwargs)
  File "/usr/local/lib/python2.7/dist-packages/django/views/generic/base.py", line 87, in dispatch
    return handler(request, *args, **kwargs)
  File "/home/mikhail/EclipseWorkspace/oncoFinder2/oncoFinder2/medic/views.py", line 288, in post
    context = self.get_context_data(object=self.object)
  File "/home/mikhail/EclipseWorkspace/oncoFinder2/oncoFinder2/medic/views.py", line 163, in get_context_data
    df_required_paths = df_pms1[path_cols]
  File "/usr/local/lib/python2.7/dist-packages/pandas/core/frame.py", line 1737, in __getitem__
    return self._getitem_array(key)
  File "/usr/local/lib/python2.7/dist-packages/pandas/core/frame.py", line 1781, in _getitem_array
    indexer = self.ix._convert_to_indexer(key, axis=1)
  File "/usr/local/lib/python2.7/dist-packages/pandas/core/indexing.py", line 1135, in _convert_to_indexer
    raise KeyError('%s not in index' % objarr[mask])
KeyError: "['L.kynurenine_degradation'] not in index"
2014-11-21 17:06:25,487 ERROR base 10944 -1291289792 Internal Server Error: /document/doc2543/treat11/
Traceback (most recent call last):
  File "/usr/local/lib/python2.7/dist-packages/django/core/handlers/base.py", line 114, in get_response
    response = wrapped_callback(request, *callback_args, **callback_kwargs)
  File "/usr/local/lib/python2.7/dist-packages/django/views/generic/base.py", line 69, in view
    return self.dispatch(request, *args, **kwargs)
  File "/usr/local/lib/python2.7/dist-packages/django/utils/decorators.py", line 29, in _wrapper
    return bound_func(*args, **kwargs)
  File "/usr/local/lib/python2.7/dist-packages/django/contrib/auth/decorators.py", line 22, in _wrapped_view
    return view_func(request, *args, **kwargs)
  File "/usr/local/lib/python2.7/dist-packages/django/utils/decorators.py", line 25, in bound_func
    return func(self, *args2, **kwargs2)
  File "/home/mikhail/EclipseWorkspace/oncoFinder2/oncoFinder2/medic/views.py", line 142, in dispatch
    return super(PatientTreatmentDetail, self).dispatch(request, *args, **kwargs)
  File "/usr/local/lib/python2.7/dist-packages/django/views/generic/base.py", line 87, in dispatch
    return handler(request, *args, **kwargs)
  File "/home/mikhail/EclipseWorkspace/oncoFinder2/oncoFinder2/medic/views.py", line 288, in post
    context = self.get_context_data(object=self.object)
  File "/home/mikhail/EclipseWorkspace/oncoFinder2/oncoFinder2/medic/views.py", line 163, in get_context_data
    df_required_paths = df_pms1[path_cols]
  File "/usr/local/lib/python2.7/dist-packages/pandas/core/frame.py", line 1737, in __getitem__
    return self._getitem_array(key)
  File "/usr/local/lib/python2.7/dist-packages/pandas/core/frame.py", line 1781, in _getitem_array
    indexer = self.ix._convert_to_indexer(key, axis=1)
  File "/usr/local/lib/python2.7/dist-packages/pandas/core/indexing.py", line 1135, in _convert_to_indexer
    raise KeyError('%s not in index' % objarr[mask])
KeyError: "['L.kynurenine_degradation'\n 'sphingosine_and_sphingosine.1.phosphate_metabolism'\n 'tryptophan_degradation_to_2.amino.3.carboxymuconate_semialdehyde'] not in index"
2014-11-21 20:00:14,048 ERROR base 7601 -1250432192 Internal Server Error: /medic/generatereport/
Traceback (most recent call last):
  File "/usr/local/lib/python2.7/dist-packages/django/core/handlers/base.py", line 132, in get_response
    raise ValueError("The view %s.%s didn't return an HttpResponse object." % (callback.__module__, view_name))
ValueError: The view medic.views.MedicAjaxGenerateReport didn't return an HttpResponse object.
2014-11-21 22:36:06,083 ERROR base 3823 -1290237120 Internal Server Error: /medic/generatereport/
Traceback (most recent call last):
  File "/usr/local/lib/python2.7/dist-packages/django/core/handlers/base.py", line 114, in get_response
    response = wrapped_callback(request, *callback_args, **callback_kwargs)
  File "/usr/local/lib/python2.7/dist-packages/django/views/generic/base.py", line 69, in view
    return self.dispatch(request, *args, **kwargs)
  File "/home/mikhail/EclipseWorkspace/oncoFinder2/oncoFinder2/medic/views.py", line 393, in dispatch
    return super(MedicAjaxGenerateReport, self).dispatch(request, *args, **kwargs)
  File "/usr/local/lib/python2.7/dist-packages/django/views/generic/base.py", line 87, in dispatch
    return handler(request, *args, **kwargs)
  File "/home/mikhail/EclipseWorkspace/oncoFinder2/oncoFinder2/medic/views.py", line 365, in post
    cairosvg.svg2png(bytestring=svg,write_to=fout)
  File "/usr/local/lib/python2.7/dist-packages/cairosvg/__init__.py", line 43, in <lambda>
    surface_type.convert(*args, **kwargs))(_surface_type)
  File "/usr/local/lib/python2.7/dist-packages/cairosvg/surface/__init__.py", line 82, in convert
    tree = Tree(**kwargs)
  File "/usr/local/lib/python2.7/dist-packages/cairosvg/parser.py", line 270, in __init__
    tree = ElementTree.fromstring(bytestring)
  File "lxml.etree.pyx", line 2754, in lxml.etree.fromstring (src/lxml/lxml.etree.c:54631)
  File "parser.pxi", line 1578, in lxml.etree._parseMemoryDocument (src/lxml/lxml.etree.c:82748)
  File "parser.pxi", line 1450, in lxml.etree._parseDoc (src/lxml/lxml.etree.c:81481)
  File "parser.pxi", line 925, in lxml.etree._BaseParser._parseUnicodeDoc (src/lxml/lxml.etree.c:77905)
  File "parser.pxi", line 569, in lxml.etree._ParserContext._handleParseResultDoc (src/lxml/lxml.etree.c:74472)
  File "parser.pxi", line 650, in lxml.etree._handleParseResult (src/lxml/lxml.etree.c:75363)
  File "parser.pxi", line 590, in lxml.etree._raiseParseError (src/lxml/lxml.etree.c:74696)
XMLSyntaxError: AttValue: " or ' expected, line 1, column 17
2014-11-21 22:39:40,125 ERROR base 3823 -1278219456 Internal Server Error: /medic/generatereport/
Traceback (most recent call last):
  File "/usr/local/lib/python2.7/dist-packages/django/core/handlers/base.py", line 114, in get_response
    response = wrapped_callback(request, *callback_args, **callback_kwargs)
  File "/usr/local/lib/python2.7/dist-packages/django/views/generic/base.py", line 69, in view
    return self.dispatch(request, *args, **kwargs)
  File "/home/mikhail/EclipseWorkspace/oncoFinder2/oncoFinder2/medic/views.py", line 393, in dispatch
    return super(MedicAjaxGenerateReport, self).dispatch(request, *args, **kwargs)
  File "/usr/local/lib/python2.7/dist-packages/django/views/generic/base.py", line 87, in dispatch
    return handler(request, *args, **kwargs)
  File "/home/mikhail/EclipseWorkspace/oncoFinder2/oncoFinder2/medic/views.py", line 365, in post
    cairosvg.svg2png(bytestring=svg,write_to=fout)
  File "/usr/local/lib/python2.7/dist-packages/cairosvg/__init__.py", line 43, in <lambda>
    surface_type.convert(*args, **kwargs))(_surface_type)
  File "/usr/local/lib/python2.7/dist-packages/cairosvg/surface/__init__.py", line 82, in convert
    tree = Tree(**kwargs)
  File "/usr/local/lib/python2.7/dist-packages/cairosvg/parser.py", line 270, in __init__
    tree = ElementTree.fromstring(bytestring)
  File "lxml.etree.pyx", line 2754, in lxml.etree.fromstring (src/lxml/lxml.etree.c:54631)
  File "parser.pxi", line 1578, in lxml.etree._parseMemoryDocument (src/lxml/lxml.etree.c:82748)
  File "parser.pxi", line 1450, in lxml.etree._parseDoc (src/lxml/lxml.etree.c:81481)
  File "parser.pxi", line 925, in lxml.etree._BaseParser._parseUnicodeDoc (src/lxml/lxml.etree.c:77905)
  File "parser.pxi", line 569, in lxml.etree._ParserContext._handleParseResultDoc (src/lxml/lxml.etree.c:74472)
  File "parser.pxi", line 650, in lxml.etree._handleParseResult (src/lxml/lxml.etree.c:75363)
  File "parser.pxi", line 590, in lxml.etree._raiseParseError (src/lxml/lxml.etree.c:74696)
XMLSyntaxError: AttValue: ' expected, line 1, column 44
2014-11-21 22:41:38,035 ERROR base 3823 -1269826752 Internal Server Error: /medic/generatereport/
Traceback (most recent call last):
  File "/usr/local/lib/python2.7/dist-packages/django/core/handlers/base.py", line 114, in get_response
    response = wrapped_callback(request, *callback_args, **callback_kwargs)
  File "/usr/local/lib/python2.7/dist-packages/django/views/generic/base.py", line 69, in view
    return self.dispatch(request, *args, **kwargs)
  File "/home/mikhail/EclipseWorkspace/oncoFinder2/oncoFinder2/medic/views.py", line 393, in dispatch
    return super(MedicAjaxGenerateReport, self).dispatch(request, *args, **kwargs)
  File "/usr/local/lib/python2.7/dist-packages/django/views/generic/base.py", line 87, in dispatch
    return handler(request, *args, **kwargs)
  File "/home/mikhail/EclipseWorkspace/oncoFinder2/oncoFinder2/medic/views.py", line 365, in post
    cairosvg.svg2png(bytestring=svg,write_to=fout)
  File "/usr/local/lib/python2.7/dist-packages/cairosvg/__init__.py", line 43, in <lambda>
    surface_type.convert(*args, **kwargs))(_surface_type)
  File "/usr/local/lib/python2.7/dist-packages/cairosvg/surface/__init__.py", line 82, in convert
    tree = Tree(**kwargs)
  File "/usr/local/lib/python2.7/dist-packages/cairosvg/parser.py", line 270, in __init__
    tree = ElementTree.fromstring(bytestring)
  File "lxml.etree.pyx", line 2754, in lxml.etree.fromstring (src/lxml/lxml.etree.c:54631)
  File "parser.pxi", line 1578, in lxml.etree._parseMemoryDocument (src/lxml/lxml.etree.c:82748)
  File "parser.pxi", line 1450, in lxml.etree._parseDoc (src/lxml/lxml.etree.c:81481)
  File "parser.pxi", line 925, in lxml.etree._BaseParser._parseUnicodeDoc (src/lxml/lxml.etree.c:77905)
  File "parser.pxi", line 569, in lxml.etree._ParserContext._handleParseResultDoc (src/lxml/lxml.etree.c:74472)
  File "parser.pxi", line 650, in lxml.etree._handleParseResult (src/lxml/lxml.etree.c:75363)
  File "parser.pxi", line 590, in lxml.etree._raiseParseError (src/lxml/lxml.etree.c:74696)
XMLSyntaxError: AttValue: ' expected, line 1, column 44
2014-11-21 22:43:38,093 ERROR base 3823 -1290237120 Internal Server Error: /medic/generatereport/
Traceback (most recent call last):
  File "/usr/local/lib/python2.7/dist-packages/django/core/handlers/base.py", line 114, in get_response
    response = wrapped_callback(request, *callback_args, **callback_kwargs)
  File "/usr/local/lib/python2.7/dist-packages/django/views/generic/base.py", line 69, in view
    return self.dispatch(request, *args, **kwargs)
  File "/home/mikhail/EclipseWorkspace/oncoFinder2/oncoFinder2/medic/views.py", line 393, in dispatch
    return super(MedicAjaxGenerateReport, self).dispatch(request, *args, **kwargs)
  File "/usr/local/lib/python2.7/dist-packages/django/views/generic/base.py", line 87, in dispatch
    return handler(request, *args, **kwargs)
  File "/home/mikhail/EclipseWorkspace/oncoFinder2/oncoFinder2/medic/views.py", line 365, in post
    cairosvg.svg2png(bytestring=svg,write_to=fout)
  File "/usr/local/lib/python2.7/dist-packages/cairosvg/__init__.py", line 43, in <lambda>
    surface_type.convert(*args, **kwargs))(_surface_type)
  File "/usr/local/lib/python2.7/dist-packages/cairosvg/surface/__init__.py", line 82, in convert
    tree = Tree(**kwargs)
  File "/usr/local/lib/python2.7/dist-packages/cairosvg/parser.py", line 270, in __init__
    tree = ElementTree.fromstring(bytestring)
  File "lxml.etree.pyx", line 2754, in lxml.etree.fromstring (src/lxml/lxml.etree.c:54631)
  File "parser.pxi", line 1578, in lxml.etree._parseMemoryDocument (src/lxml/lxml.etree.c:82748)
  File "parser.pxi", line 1450, in lxml.etree._parseDoc (src/lxml/lxml.etree.c:81481)
  File "parser.pxi", line 925, in lxml.etree._BaseParser._parseUnicodeDoc (src/lxml/lxml.etree.c:77905)
  File "parser.pxi", line 569, in lxml.etree._ParserContext._handleParseResultDoc (src/lxml/lxml.etree.c:74472)
  File "parser.pxi", line 650, in lxml.etree._handleParseResult (src/lxml/lxml.etree.c:75363)
  File "parser.pxi", line 590, in lxml.etree._raiseParseError (src/lxml/lxml.etree.c:74696)
XMLSyntaxError: attributes construct error, line 1, column 31
2014-11-21 22:45:58,707 ERROR base 3823 -1278219456 Internal Server Error: /medic/generatereport/
Traceback (most recent call last):
  File "/usr/local/lib/python2.7/dist-packages/django/core/handlers/base.py", line 114, in get_response
    response = wrapped_callback(request, *callback_args, **callback_kwargs)
  File "/usr/local/lib/python2.7/dist-packages/django/views/generic/base.py", line 69, in view
    return self.dispatch(request, *args, **kwargs)
  File "/home/mikhail/EclipseWorkspace/oncoFinder2/oncoFinder2/medic/views.py", line 393, in dispatch
    return super(MedicAjaxGenerateReport, self).dispatch(request, *args, **kwargs)
  File "/usr/local/lib/python2.7/dist-packages/django/views/generic/base.py", line 87, in dispatch
    return handler(request, *args, **kwargs)
  File "/home/mikhail/EclipseWorkspace/oncoFinder2/oncoFinder2/medic/views.py", line 365, in post
    cairosvg.svg2png(bytestring=svg,write_to=fout)
  File "/usr/local/lib/python2.7/dist-packages/cairosvg/__init__.py", line 43, in <lambda>
    surface_type.convert(*args, **kwargs))(_surface_type)
  File "/usr/local/lib/python2.7/dist-packages/cairosvg/surface/__init__.py", line 82, in convert
    tree = Tree(**kwargs)
  File "/usr/local/lib/python2.7/dist-packages/cairosvg/parser.py", line 270, in __init__
    tree = ElementTree.fromstring(bytestring)
  File "lxml.etree.pyx", line 2754, in lxml.etree.fromstring (src/lxml/lxml.etree.c:54631)
  File "parser.pxi", line 1578, in lxml.etree._parseMemoryDocument (src/lxml/lxml.etree.c:82748)
  File "parser.pxi", line 1450, in lxml.etree._parseDoc (src/lxml/lxml.etree.c:81481)
  File "parser.pxi", line 925, in lxml.etree._BaseParser._parseUnicodeDoc (src/lxml/lxml.etree.c:77905)
  File "parser.pxi", line 569, in lxml.etree._ParserContext._handleParseResultDoc (src/lxml/lxml.etree.c:74472)
  File "parser.pxi", line 650, in lxml.etree._handleParseResult (src/lxml/lxml.etree.c:75363)
  File "parser.pxi", line 590, in lxml.etree._raiseParseError (src/lxml/lxml.etree.c:74696)
XMLSyntaxError: AttValue: " or ' expected, line 1, column 17
2014-11-21 22:49:20,321 ERROR base 3823 -1378886848 Internal Server Error: /medic/generatereport/
Traceback (most recent call last):
  File "/usr/local/lib/python2.7/dist-packages/django/core/handlers/base.py", line 114, in get_response
    response = wrapped_callback(request, *callback_args, **callback_kwargs)
  File "/usr/local/lib/python2.7/dist-packages/django/views/generic/base.py", line 69, in view
    return self.dispatch(request, *args, **kwargs)
  File "/home/mikhail/EclipseWorkspace/oncoFinder2/oncoFinder2/medic/views.py", line 393, in dispatch
    return super(MedicAjaxGenerateReport, self).dispatch(request, *args, **kwargs)
  File "/usr/local/lib/python2.7/dist-packages/django/views/generic/base.py", line 87, in dispatch
    return handler(request, *args, **kwargs)
  File "/home/mikhail/EclipseWorkspace/oncoFinder2/oncoFinder2/medic/views.py", line 365, in post
    cairosvg.svg2png(bytestring=svg,write_to=fout)
  File "/usr/local/lib/python2.7/dist-packages/cairosvg/__init__.py", line 43, in <lambda>
    surface_type.convert(*args, **kwargs))(_surface_type)
  File "/usr/local/lib/python2.7/dist-packages/cairosvg/surface/__init__.py", line 82, in convert
    tree = Tree(**kwargs)
  File "/usr/local/lib/python2.7/dist-packages/cairosvg/parser.py", line 270, in __init__
    tree = ElementTree.fromstring(bytestring)
  File "lxml.etree.pyx", line 2754, in lxml.etree.fromstring (src/lxml/lxml.etree.c:54631)
  File "parser.pxi", line 1578, in lxml.etree._parseMemoryDocument (src/lxml/lxml.etree.c:82748)
  File "parser.pxi", line 1450, in lxml.etree._parseDoc (src/lxml/lxml.etree.c:81481)
  File "parser.pxi", line 925, in lxml.etree._BaseParser._parseUnicodeDoc (src/lxml/lxml.etree.c:77905)
  File "parser.pxi", line 569, in lxml.etree._ParserContext._handleParseResultDoc (src/lxml/lxml.etree.c:74472)
  File "parser.pxi", line 650, in lxml.etree._handleParseResult (src/lxml/lxml.etree.c:75363)
  File "parser.pxi", line 590, in lxml.etree._raiseParseError (src/lxml/lxml.etree.c:74696)
XMLSyntaxError: AttValue: ' expected, line 1, column 44
2014-11-24 13:08:56,305 ERROR base 7512 -1271923904 Internal Server Error: /document/doc2543/treat14/
Traceback (most recent call last):
  File "/usr/local/lib/python2.7/dist-packages/django/core/handlers/base.py", line 114, in get_response
    response = wrapped_callback(request, *callback_args, **callback_kwargs)
  File "/usr/local/lib/python2.7/dist-packages/django/views/generic/base.py", line 69, in view
    return self.dispatch(request, *args, **kwargs)
  File "/usr/local/lib/python2.7/dist-packages/django/utils/decorators.py", line 29, in _wrapper
    return bound_func(*args, **kwargs)
  File "/usr/local/lib/python2.7/dist-packages/django/contrib/auth/decorators.py", line 22, in _wrapped_view
    return view_func(request, *args, **kwargs)
  File "/usr/local/lib/python2.7/dist-packages/django/utils/decorators.py", line 25, in bound_func
    return func(self, *args2, **kwargs2)
  File "/home/mikhail/EclipseWorkspace/oncoFinder2/oncoFinder2/medic/views.py", line 143, in dispatch
    return super(PatientTreatmentDetail, self).dispatch(request, *args, **kwargs)
  File "/usr/local/lib/python2.7/dist-packages/django/views/generic/base.py", line 87, in dispatch
    return handler(request, *args, **kwargs)
  File "/home/mikhail/EclipseWorkspace/oncoFinder2/oncoFinder2/medic/views.py", line 289, in post
    context = self.get_context_data(object=self.object)
  File "/home/mikhail/EclipseWorkspace/oncoFinder2/oncoFinder2/medic/views.py", line 164, in get_context_data
    df_required_paths = df_pms1[path_cols]
  File "/usr/local/lib/python2.7/dist-packages/pandas/core/frame.py", line 1737, in __getitem__
    return self._getitem_array(key)
  File "/usr/local/lib/python2.7/dist-packages/pandas/core/frame.py", line 1781, in _getitem_array
    indexer = self.ix._convert_to_indexer(key, axis=1)
  File "/usr/local/lib/python2.7/dist-packages/pandas/core/indexing.py", line 1135, in _convert_to_indexer
    raise KeyError('%s not in index' % objarr[mask])
KeyError: "['sphingosine_and_sphingosine.1.phosphate_metabolism'] not in index"
2014-11-24 13:08:56,438 ERROR base 7512 -1386218688 Internal Server Error: /document/doc2543/treat12/
Traceback (most recent call last):
  File "/usr/local/lib/python2.7/dist-packages/django/core/handlers/base.py", line 114, in get_response
    response = wrapped_callback(request, *callback_args, **callback_kwargs)
  File "/usr/local/lib/python2.7/dist-packages/django/views/generic/base.py", line 69, in view
    return self.dispatch(request, *args, **kwargs)
  File "/usr/local/lib/python2.7/dist-packages/django/utils/decorators.py", line 29, in _wrapper
    return bound_func(*args, **kwargs)
  File "/usr/local/lib/python2.7/dist-packages/django/contrib/auth/decorators.py", line 22, in _wrapped_view
    return view_func(request, *args, **kwargs)
  File "/usr/local/lib/python2.7/dist-packages/django/utils/decorators.py", line 25, in bound_func
    return func(self, *args2, **kwargs2)
  File "/home/mikhail/EclipseWorkspace/oncoFinder2/oncoFinder2/medic/views.py", line 143, in dispatch
    return super(PatientTreatmentDetail, self).dispatch(request, *args, **kwargs)
  File "/usr/local/lib/python2.7/dist-packages/django/views/generic/base.py", line 87, in dispatch
    return handler(request, *args, **kwargs)
  File "/home/mikhail/EclipseWorkspace/oncoFinder2/oncoFinder2/medic/views.py", line 289, in post
    context = self.get_context_data(object=self.object)
  File "/home/mikhail/EclipseWorkspace/oncoFinder2/oncoFinder2/medic/views.py", line 164, in get_context_data
    df_required_paths = df_pms1[path_cols]
  File "/usr/local/lib/python2.7/dist-packages/pandas/core/frame.py", line 1737, in __getitem__
    return self._getitem_array(key)
  File "/usr/local/lib/python2.7/dist-packages/pandas/core/frame.py", line 1781, in _getitem_array
    indexer = self.ix._convert_to_indexer(key, axis=1)
  File "/usr/local/lib/python2.7/dist-packages/pandas/core/indexing.py", line 1135, in _convert_to_indexer
    raise KeyError('%s not in index' % objarr[mask])
KeyError: "['ATM_Pathway_G2.M_Checkpoint_Arrest'\n 'D.galactose_degradation_V_Leloir_pathway'] not in index"
2014-11-24 13:08:57,390 ERROR base 7512 -1251480768 Internal Server Error: /document/doc2543/treat8/
Traceback (most recent call last):
  File "/usr/local/lib/python2.7/dist-packages/django/core/handlers/base.py", line 114, in get_response
    response = wrapped_callback(request, *callback_args, **callback_kwargs)
  File "/usr/local/lib/python2.7/dist-packages/django/views/generic/base.py", line 69, in view
    return self.dispatch(request, *args, **kwargs)
  File "/usr/local/lib/python2.7/dist-packages/django/utils/decorators.py", line 29, in _wrapper
    return bound_func(*args, **kwargs)
  File "/usr/local/lib/python2.7/dist-packages/django/contrib/auth/decorators.py", line 22, in _wrapped_view
    return view_func(request, *args, **kwargs)
  File "/usr/local/lib/python2.7/dist-packages/django/utils/decorators.py", line 25, in bound_func
    return func(self, *args2, **kwargs2)
  File "/home/mikhail/EclipseWorkspace/oncoFinder2/oncoFinder2/medic/views.py", line 143, in dispatch
    return super(PatientTreatmentDetail, self).dispatch(request, *args, **kwargs)
  File "/usr/local/lib/python2.7/dist-packages/django/views/generic/base.py", line 87, in dispatch
    return handler(request, *args, **kwargs)
  File "/home/mikhail/EclipseWorkspace/oncoFinder2/oncoFinder2/medic/views.py", line 289, in post
    context = self.get_context_data(object=self.object)
  File "/home/mikhail/EclipseWorkspace/oncoFinder2/oncoFinder2/medic/views.py", line 164, in get_context_data
    df_required_paths = df_pms1[path_cols]
  File "/usr/local/lib/python2.7/dist-packages/pandas/core/frame.py", line 1737, in __getitem__
    return self._getitem_array(key)
  File "/usr/local/lib/python2.7/dist-packages/pandas/core/frame.py", line 1781, in _getitem_array
    indexer = self.ix._convert_to_indexer(key, axis=1)
  File "/usr/local/lib/python2.7/dist-packages/pandas/core/indexing.py", line 1135, in _convert_to_indexer
    raise KeyError('%s not in index' % objarr[mask])
KeyError: "['L.kynurenine_degradation'] not in index"
2014-11-24 13:08:58,858 ERROR base 7512 -1280316608 Internal Server Error: /document/doc2543/treat11/
Traceback (most recent call last):
  File "/usr/local/lib/python2.7/dist-packages/django/core/handlers/base.py", line 114, in get_response
    response = wrapped_callback(request, *callback_args, **callback_kwargs)
  File "/usr/local/lib/python2.7/dist-packages/django/views/generic/base.py", line 69, in view
    return self.dispatch(request, *args, **kwargs)
  File "/usr/local/lib/python2.7/dist-packages/django/utils/decorators.py", line 29, in _wrapper
    return bound_func(*args, **kwargs)
  File "/usr/local/lib/python2.7/dist-packages/django/contrib/auth/decorators.py", line 22, in _wrapped_view
    return view_func(request, *args, **kwargs)
  File "/usr/local/lib/python2.7/dist-packages/django/utils/decorators.py", line 25, in bound_func
    return func(self, *args2, **kwargs2)
  File "/home/mikhail/EclipseWorkspace/oncoFinder2/oncoFinder2/medic/views.py", line 143, in dispatch
    return super(PatientTreatmentDetail, self).dispatch(request, *args, **kwargs)
  File "/usr/local/lib/python2.7/dist-packages/django/views/generic/base.py", line 87, in dispatch
    return handler(request, *args, **kwargs)
  File "/home/mikhail/EclipseWorkspace/oncoFinder2/oncoFinder2/medic/views.py", line 289, in post
    context = self.get_context_data(object=self.object)
  File "/home/mikhail/EclipseWorkspace/oncoFinder2/oncoFinder2/medic/views.py", line 164, in get_context_data
    df_required_paths = df_pms1[path_cols]
  File "/usr/local/lib/python2.7/dist-packages/pandas/core/frame.py", line 1737, in __getitem__
    return self._getitem_array(key)
  File "/usr/local/lib/python2.7/dist-packages/pandas/core/frame.py", line 1781, in _getitem_array
    indexer = self.ix._convert_to_indexer(key, axis=1)
  File "/usr/local/lib/python2.7/dist-packages/pandas/core/indexing.py", line 1135, in _convert_to_indexer
    raise KeyError('%s not in index' % objarr[mask])
KeyError: "['L.kynurenine_degradation'\n 'sphingosine_and_sphingosine.1.phosphate_metabolism'\n 'tryptophan_degradation_to_2.amino.3.carboxymuconate_semialdehyde'] not in index"
2014-11-24 13:22:22,437 ERROR base 21987 -1332741312 Internal Server Error: /document/doc2543/treat14/
Traceback (most recent call last):
  File "/usr/local/lib/python2.7/dist-packages/django/core/handlers/base.py", line 114, in get_response
    response = wrapped_callback(request, *callback_args, **callback_kwargs)
  File "/usr/local/lib/python2.7/dist-packages/django/views/generic/base.py", line 69, in view
    return self.dispatch(request, *args, **kwargs)
  File "/usr/local/lib/python2.7/dist-packages/django/utils/decorators.py", line 29, in _wrapper
    return bound_func(*args, **kwargs)
  File "/usr/local/lib/python2.7/dist-packages/django/contrib/auth/decorators.py", line 22, in _wrapped_view
    return view_func(request, *args, **kwargs)
  File "/usr/local/lib/python2.7/dist-packages/django/utils/decorators.py", line 25, in bound_func
    return func(self, *args2, **kwargs2)
  File "/home/mikhail/EclipseWorkspace/oncoFinder2/oncoFinder2/medic/views.py", line 143, in dispatch
    return super(PatientTreatmentDetail, self).dispatch(request, *args, **kwargs)
  File "/usr/local/lib/python2.7/dist-packages/django/views/generic/base.py", line 87, in dispatch
    return handler(request, *args, **kwargs)
  File "/home/mikhail/EclipseWorkspace/oncoFinder2/oncoFinder2/medic/views.py", line 289, in post
    context = self.get_context_data(object=self.object)
  File "/home/mikhail/EclipseWorkspace/oncoFinder2/oncoFinder2/medic/views.py", line 164, in get_context_data
    df_required_paths = df_pms1[path_cols]
  File "/usr/local/lib/python2.7/dist-packages/pandas/core/frame.py", line 1737, in __getitem__
    return self._getitem_array(key)
  File "/usr/local/lib/python2.7/dist-packages/pandas/core/frame.py", line 1781, in _getitem_array
    indexer = self.ix._convert_to_indexer(key, axis=1)
  File "/usr/local/lib/python2.7/dist-packages/pandas/core/indexing.py", line 1135, in _convert_to_indexer
    raise KeyError('%s not in index' % objarr[mask])
KeyError: "['sphingosine_and_sphingosine.1.phosphate_metabolism'] not in index"
2014-11-24 13:22:23,134 ERROR base 21987 -1277166784 Internal Server Error: /document/doc2543/treat12/
Traceback (most recent call last):
  File "/usr/local/lib/python2.7/dist-packages/django/core/handlers/base.py", line 114, in get_response
    response = wrapped_callback(request, *callback_args, **callback_kwargs)
  File "/usr/local/lib/python2.7/dist-packages/django/views/generic/base.py", line 69, in view
    return self.dispatch(request, *args, **kwargs)
  File "/usr/local/lib/python2.7/dist-packages/django/utils/decorators.py", line 29, in _wrapper
    return bound_func(*args, **kwargs)
  File "/usr/local/lib/python2.7/dist-packages/django/contrib/auth/decorators.py", line 22, in _wrapped_view
    return view_func(request, *args, **kwargs)
  File "/usr/local/lib/python2.7/dist-packages/django/utils/decorators.py", line 25, in bound_func
    return func(self, *args2, **kwargs2)
  File "/home/mikhail/EclipseWorkspace/oncoFinder2/oncoFinder2/medic/views.py", line 143, in dispatch
    return super(PatientTreatmentDetail, self).dispatch(request, *args, **kwargs)
  File "/usr/local/lib/python2.7/dist-packages/django/views/generic/base.py", line 87, in dispatch
    return handler(request, *args, **kwargs)
  File "/home/mikhail/EclipseWorkspace/oncoFinder2/oncoFinder2/medic/views.py", line 289, in post
    context = self.get_context_data(object=self.object)
  File "/home/mikhail/EclipseWorkspace/oncoFinder2/oncoFinder2/medic/views.py", line 164, in get_context_data
    df_required_paths = df_pms1[path_cols]
  File "/usr/local/lib/python2.7/dist-packages/pandas/core/frame.py", line 1737, in __getitem__
    return self._getitem_array(key)
  File "/usr/local/lib/python2.7/dist-packages/pandas/core/frame.py", line 1781, in _getitem_array
    indexer = self.ix._convert_to_indexer(key, axis=1)
  File "/usr/local/lib/python2.7/dist-packages/pandas/core/indexing.py", line 1135, in _convert_to_indexer
    raise KeyError('%s not in index' % objarr[mask])
KeyError: "['ATM_Pathway_G2.M_Checkpoint_Arrest'\n 'D.galactose_degradation_V_Leloir_pathway'] not in index"
2014-11-24 13:22:23,830 ERROR base 21987 -1261438144 Internal Server Error: /document/doc2543/treat8/
Traceback (most recent call last):
  File "/usr/local/lib/python2.7/dist-packages/django/core/handlers/base.py", line 114, in get_response
    response = wrapped_callback(request, *callback_args, **callback_kwargs)
  File "/usr/local/lib/python2.7/dist-packages/django/views/generic/base.py", line 69, in view
    return self.dispatch(request, *args, **kwargs)
  File "/usr/local/lib/python2.7/dist-packages/django/utils/decorators.py", line 29, in _wrapper
    return bound_func(*args, **kwargs)
  File "/usr/local/lib/python2.7/dist-packages/django/contrib/auth/decorators.py", line 22, in _wrapped_view
    return view_func(request, *args, **kwargs)
  File "/usr/local/lib/python2.7/dist-packages/django/utils/decorators.py", line 25, in bound_func
    return func(self, *args2, **kwargs2)
  File "/home/mikhail/EclipseWorkspace/oncoFinder2/oncoFinder2/medic/views.py", line 143, in dispatch
    return super(PatientTreatmentDetail, self).dispatch(request, *args, **kwargs)
  File "/usr/local/lib/python2.7/dist-packages/django/views/generic/base.py", line 87, in dispatch
    return handler(request, *args, **kwargs)
  File "/home/mikhail/EclipseWorkspace/oncoFinder2/oncoFinder2/medic/views.py", line 289, in post
    context = self.get_context_data(object=self.object)
  File "/home/mikhail/EclipseWorkspace/oncoFinder2/oncoFinder2/medic/views.py", line 164, in get_context_data
    df_required_paths = df_pms1[path_cols]
  File "/usr/local/lib/python2.7/dist-packages/pandas/core/frame.py", line 1737, in __getitem__
    return self._getitem_array(key)
  File "/usr/local/lib/python2.7/dist-packages/pandas/core/frame.py", line 1781, in _getitem_array
    indexer = self.ix._convert_to_indexer(key, axis=1)
  File "/usr/local/lib/python2.7/dist-packages/pandas/core/indexing.py", line 1135, in _convert_to_indexer
    raise KeyError('%s not in index' % objarr[mask])
KeyError: "['L.kynurenine_degradation'] not in index"
2014-11-24 13:22:25,018 ERROR base 21987 -1293944000 Internal Server Error: /document/doc2543/treat11/
Traceback (most recent call last):
  File "/usr/local/lib/python2.7/dist-packages/django/core/handlers/base.py", line 114, in get_response
    response = wrapped_callback(request, *callback_args, **callback_kwargs)
  File "/usr/local/lib/python2.7/dist-packages/django/views/generic/base.py", line 69, in view
    return self.dispatch(request, *args, **kwargs)
  File "/usr/local/lib/python2.7/dist-packages/django/utils/decorators.py", line 29, in _wrapper
    return bound_func(*args, **kwargs)
  File "/usr/local/lib/python2.7/dist-packages/django/contrib/auth/decorators.py", line 22, in _wrapped_view
    return view_func(request, *args, **kwargs)
  File "/usr/local/lib/python2.7/dist-packages/django/utils/decorators.py", line 25, in bound_func
    return func(self, *args2, **kwargs2)
  File "/home/mikhail/EclipseWorkspace/oncoFinder2/oncoFinder2/medic/views.py", line 143, in dispatch
    return super(PatientTreatmentDetail, self).dispatch(request, *args, **kwargs)
  File "/usr/local/lib/python2.7/dist-packages/django/views/generic/base.py", line 87, in dispatch
    return handler(request, *args, **kwargs)
  File "/home/mikhail/EclipseWorkspace/oncoFinder2/oncoFinder2/medic/views.py", line 289, in post
    context = self.get_context_data(object=self.object)
  File "/home/mikhail/EclipseWorkspace/oncoFinder2/oncoFinder2/medic/views.py", line 164, in get_context_data
    df_required_paths = df_pms1[path_cols]
  File "/usr/local/lib/python2.7/dist-packages/pandas/core/frame.py", line 1737, in __getitem__
    return self._getitem_array(key)
  File "/usr/local/lib/python2.7/dist-packages/pandas/core/frame.py", line 1781, in _getitem_array
    indexer = self.ix._convert_to_indexer(key, axis=1)
  File "/usr/local/lib/python2.7/dist-packages/pandas/core/indexing.py", line 1135, in _convert_to_indexer
    raise KeyError('%s not in index' % objarr[mask])
KeyError: "['L.kynurenine_degradation'\n 'sphingosine_and_sphingosine.1.phosphate_metabolism'\n 'tryptophan_degradation_to_2.amino.3.carboxymuconate_semialdehyde'] not in index"
2014-11-24 13:23:10,331 ERROR base 21987 -1293944000 Internal Server Error: /document/doc2543/treat14/
Traceback (most recent call last):
  File "/usr/local/lib/python2.7/dist-packages/django/core/handlers/base.py", line 114, in get_response
    response = wrapped_callback(request, *callback_args, **callback_kwargs)
  File "/usr/local/lib/python2.7/dist-packages/django/views/generic/base.py", line 69, in view
    return self.dispatch(request, *args, **kwargs)
  File "/usr/local/lib/python2.7/dist-packages/django/utils/decorators.py", line 29, in _wrapper
    return bound_func(*args, **kwargs)
  File "/usr/local/lib/python2.7/dist-packages/django/contrib/auth/decorators.py", line 22, in _wrapped_view
    return view_func(request, *args, **kwargs)
  File "/usr/local/lib/python2.7/dist-packages/django/utils/decorators.py", line 25, in bound_func
    return func(self, *args2, **kwargs2)
  File "/home/mikhail/EclipseWorkspace/oncoFinder2/oncoFinder2/medic/views.py", line 143, in dispatch
    return super(PatientTreatmentDetail, self).dispatch(request, *args, **kwargs)
  File "/usr/local/lib/python2.7/dist-packages/django/views/generic/base.py", line 87, in dispatch
    return handler(request, *args, **kwargs)
  File "/home/mikhail/EclipseWorkspace/oncoFinder2/oncoFinder2/medic/views.py", line 289, in post
    context = self.get_context_data(object=self.object)
  File "/home/mikhail/EclipseWorkspace/oncoFinder2/oncoFinder2/medic/views.py", line 164, in get_context_data
    df_required_paths = df_pms1[path_cols]
  File "/usr/local/lib/python2.7/dist-packages/pandas/core/frame.py", line 1737, in __getitem__
    return self._getitem_array(key)
  File "/usr/local/lib/python2.7/dist-packages/pandas/core/frame.py", line 1781, in _getitem_array
    indexer = self.ix._convert_to_indexer(key, axis=1)
  File "/usr/local/lib/python2.7/dist-packages/pandas/core/indexing.py", line 1135, in _convert_to_indexer
    raise KeyError('%s not in index' % objarr[mask])
KeyError: "['sphingosine_and_sphingosine.1.phosphate_metabolism'] not in index"
2014-11-24 13:23:11,164 ERROR base 21987 -1411384512 Internal Server Error: /document/doc2543/treat12/
Traceback (most recent call last):
  File "/usr/local/lib/python2.7/dist-packages/django/core/handlers/base.py", line 114, in get_response
    response = wrapped_callback(request, *callback_args, **callback_kwargs)
  File "/usr/local/lib/python2.7/dist-packages/django/views/generic/base.py", line 69, in view
    return self.dispatch(request, *args, **kwargs)
  File "/usr/local/lib/python2.7/dist-packages/django/utils/decorators.py", line 29, in _wrapper
    return bound_func(*args, **kwargs)
  File "/usr/local/lib/python2.7/dist-packages/django/contrib/auth/decorators.py", line 22, in _wrapped_view
    return view_func(request, *args, **kwargs)
  File "/usr/local/lib/python2.7/dist-packages/django/utils/decorators.py", line 25, in bound_func
    return func(self, *args2, **kwargs2)
  File "/home/mikhail/EclipseWorkspace/oncoFinder2/oncoFinder2/medic/views.py", line 143, in dispatch
    return super(PatientTreatmentDetail, self).dispatch(request, *args, **kwargs)
  File "/usr/local/lib/python2.7/dist-packages/django/views/generic/base.py", line 87, in dispatch
    return handler(request, *args, **kwargs)
  File "/home/mikhail/EclipseWorkspace/oncoFinder2/oncoFinder2/medic/views.py", line 289, in post
    context = self.get_context_data(object=self.object)
  File "/home/mikhail/EclipseWorkspace/oncoFinder2/oncoFinder2/medic/views.py", line 164, in get_context_data
    df_required_paths = df_pms1[path_cols]
  File "/usr/local/lib/python2.7/dist-packages/pandas/core/frame.py", line 1737, in __getitem__
    return self._getitem_array(key)
  File "/usr/local/lib/python2.7/dist-packages/pandas/core/frame.py", line 1781, in _getitem_array
    indexer = self.ix._convert_to_indexer(key, axis=1)
  File "/usr/local/lib/python2.7/dist-packages/pandas/core/indexing.py", line 1135, in _convert_to_indexer
    raise KeyError('%s not in index' % objarr[mask])
KeyError: "['ATM_Pathway_G2.M_Checkpoint_Arrest'\n 'D.galactose_degradation_V_Leloir_pathway'] not in index"
2014-11-24 13:23:12,131 ERROR base 21987 -1261438144 Internal Server Error: /document/doc2543/treat8/
Traceback (most recent call last):
  File "/usr/local/lib/python2.7/dist-packages/django/core/handlers/base.py", line 114, in get_response
    response = wrapped_callback(request, *callback_args, **callback_kwargs)
  File "/usr/local/lib/python2.7/dist-packages/django/views/generic/base.py", line 69, in view
    return self.dispatch(request, *args, **kwargs)
  File "/usr/local/lib/python2.7/dist-packages/django/utils/decorators.py", line 29, in _wrapper
    return bound_func(*args, **kwargs)
  File "/usr/local/lib/python2.7/dist-packages/django/contrib/auth/decorators.py", line 22, in _wrapped_view
    return view_func(request, *args, **kwargs)
  File "/usr/local/lib/python2.7/dist-packages/django/utils/decorators.py", line 25, in bound_func
    return func(self, *args2, **kwargs2)
  File "/home/mikhail/EclipseWorkspace/oncoFinder2/oncoFinder2/medic/views.py", line 143, in dispatch
    return super(PatientTreatmentDetail, self).dispatch(request, *args, **kwargs)
  File "/usr/local/lib/python2.7/dist-packages/django/views/generic/base.py", line 87, in dispatch
    return handler(request, *args, **kwargs)
  File "/home/mikhail/EclipseWorkspace/oncoFinder2/oncoFinder2/medic/views.py", line 289, in post
    context = self.get_context_data(object=self.object)
  File "/home/mikhail/EclipseWorkspace/oncoFinder2/oncoFinder2/medic/views.py", line 164, in get_context_data
    df_required_paths = df_pms1[path_cols]
  File "/usr/local/lib/python2.7/dist-packages/pandas/core/frame.py", line 1737, in __getitem__
    return self._getitem_array(key)
  File "/usr/local/lib/python2.7/dist-packages/pandas/core/frame.py", line 1781, in _getitem_array
    indexer = self.ix._convert_to_indexer(key, axis=1)
  File "/usr/local/lib/python2.7/dist-packages/pandas/core/indexing.py", line 1135, in _convert_to_indexer
    raise KeyError('%s not in index' % objarr[mask])
KeyError: "['L.kynurenine_degradation'] not in index"
2014-11-24 13:23:13,268 ERROR base 21987 -1277166784 Internal Server Error: /document/doc2543/treat11/
Traceback (most recent call last):
  File "/usr/local/lib/python2.7/dist-packages/django/core/handlers/base.py", line 114, in get_response
    response = wrapped_callback(request, *callback_args, **callback_kwargs)
  File "/usr/local/lib/python2.7/dist-packages/django/views/generic/base.py", line 69, in view
    return self.dispatch(request, *args, **kwargs)
  File "/usr/local/lib/python2.7/dist-packages/django/utils/decorators.py", line 29, in _wrapper
    return bound_func(*args, **kwargs)
  File "/usr/local/lib/python2.7/dist-packages/django/contrib/auth/decorators.py", line 22, in _wrapped_view
    return view_func(request, *args, **kwargs)
  File "/usr/local/lib/python2.7/dist-packages/django/utils/decorators.py", line 25, in bound_func
    return func(self, *args2, **kwargs2)
  File "/home/mikhail/EclipseWorkspace/oncoFinder2/oncoFinder2/medic/views.py", line 143, in dispatch
    return super(PatientTreatmentDetail, self).dispatch(request, *args, **kwargs)
  File "/usr/local/lib/python2.7/dist-packages/django/views/generic/base.py", line 87, in dispatch
    return handler(request, *args, **kwargs)
  File "/home/mikhail/EclipseWorkspace/oncoFinder2/oncoFinder2/medic/views.py", line 289, in post
    context = self.get_context_data(object=self.object)
  File "/home/mikhail/EclipseWorkspace/oncoFinder2/oncoFinder2/medic/views.py", line 164, in get_context_data
    df_required_paths = df_pms1[path_cols]
  File "/usr/local/lib/python2.7/dist-packages/pandas/core/frame.py", line 1737, in __getitem__
    return self._getitem_array(key)
  File "/usr/local/lib/python2.7/dist-packages/pandas/core/frame.py", line 1781, in _getitem_array
    indexer = self.ix._convert_to_indexer(key, axis=1)
  File "/usr/local/lib/python2.7/dist-packages/pandas/core/indexing.py", line 1135, in _convert_to_indexer
    raise KeyError('%s not in index' % objarr[mask])
KeyError: "['L.kynurenine_degradation'\n 'sphingosine_and_sphingosine.1.phosphate_metabolism'\n 'tryptophan_degradation_to_2.amino.3.carboxymuconate_semialdehyde'] not in index"
2014-11-24 13:25:58,568 ERROR base 25109 -1271923904 Internal Server Error: /document/doc2543/treat14/
Traceback (most recent call last):
  File "/usr/local/lib/python2.7/dist-packages/django/core/handlers/base.py", line 114, in get_response
    response = wrapped_callback(request, *callback_args, **callback_kwargs)
  File "/usr/local/lib/python2.7/dist-packages/django/views/generic/base.py", line 69, in view
    return self.dispatch(request, *args, **kwargs)
  File "/usr/local/lib/python2.7/dist-packages/django/utils/decorators.py", line 29, in _wrapper
    return bound_func(*args, **kwargs)
  File "/usr/local/lib/python2.7/dist-packages/django/contrib/auth/decorators.py", line 22, in _wrapped_view
    return view_func(request, *args, **kwargs)
  File "/usr/local/lib/python2.7/dist-packages/django/utils/decorators.py", line 25, in bound_func
    return func(self, *args2, **kwargs2)
  File "/home/mikhail/EclipseWorkspace/oncoFinder2/oncoFinder2/medic/views.py", line 143, in dispatch
    return super(PatientTreatmentDetail, self).dispatch(request, *args, **kwargs)
  File "/usr/local/lib/python2.7/dist-packages/django/views/generic/base.py", line 87, in dispatch
    return handler(request, *args, **kwargs)
  File "/home/mikhail/EclipseWorkspace/oncoFinder2/oncoFinder2/medic/views.py", line 289, in post
    context = self.get_context_data(object=self.object)
  File "/home/mikhail/EclipseWorkspace/oncoFinder2/oncoFinder2/medic/views.py", line 164, in get_context_data
    df_required_paths = df_pms1[path_cols]
  File "/usr/local/lib/python2.7/dist-packages/pandas/core/frame.py", line 1737, in __getitem__
    return self._getitem_array(key)
  File "/usr/local/lib/python2.7/dist-packages/pandas/core/frame.py", line 1781, in _getitem_array
    indexer = self.ix._convert_to_indexer(key, axis=1)
  File "/usr/local/lib/python2.7/dist-packages/pandas/core/indexing.py", line 1135, in _convert_to_indexer
    raise KeyError('%s not in index' % objarr[mask])
KeyError: "['sphingosine_and_sphingosine.1.phosphate_metabolism'] not in index"
2014-11-24 13:25:59,490 ERROR base 25109 -1297102016 Internal Server Error: /document/doc2543/treat12/
Traceback (most recent call last):
  File "/usr/local/lib/python2.7/dist-packages/django/core/handlers/base.py", line 114, in get_response
    response = wrapped_callback(request, *callback_args, **callback_kwargs)
  File "/usr/local/lib/python2.7/dist-packages/django/views/generic/base.py", line 69, in view
    return self.dispatch(request, *args, **kwargs)
  File "/usr/local/lib/python2.7/dist-packages/django/utils/decorators.py", line 29, in _wrapper
    return bound_func(*args, **kwargs)
  File "/usr/local/lib/python2.7/dist-packages/django/contrib/auth/decorators.py", line 22, in _wrapped_view
    return view_func(request, *args, **kwargs)
  File "/usr/local/lib/python2.7/dist-packages/django/utils/decorators.py", line 25, in bound_func
    return func(self, *args2, **kwargs2)
  File "/home/mikhail/EclipseWorkspace/oncoFinder2/oncoFinder2/medic/views.py", line 143, in dispatch
    return super(PatientTreatmentDetail, self).dispatch(request, *args, **kwargs)
  File "/usr/local/lib/python2.7/dist-packages/django/views/generic/base.py", line 87, in dispatch
    return handler(request, *args, **kwargs)
  File "/home/mikhail/EclipseWorkspace/oncoFinder2/oncoFinder2/medic/views.py", line 289, in post
    context = self.get_context_data(object=self.object)
  File "/home/mikhail/EclipseWorkspace/oncoFinder2/oncoFinder2/medic/views.py", line 164, in get_context_data
    df_required_paths = df_pms1[path_cols]
  File "/usr/local/lib/python2.7/dist-packages/pandas/core/frame.py", line 1737, in __getitem__
    return self._getitem_array(key)
  File "/usr/local/lib/python2.7/dist-packages/pandas/core/frame.py", line 1781, in _getitem_array
    indexer = self.ix._convert_to_indexer(key, axis=1)
  File "/usr/local/lib/python2.7/dist-packages/pandas/core/indexing.py", line 1135, in _convert_to_indexer
    raise KeyError('%s not in index' % objarr[mask])
KeyError: "['ATM_Pathway_G2.M_Checkpoint_Arrest'\n 'D.galactose_degradation_V_Leloir_pathway'] not in index"
2014-11-24 13:26:00,001 ERROR base 25109 -1364198592 Internal Server Error: /document/doc2543/treat8/
Traceback (most recent call last):
  File "/usr/local/lib/python2.7/dist-packages/django/core/handlers/base.py", line 114, in get_response
    response = wrapped_callback(request, *callback_args, **callback_kwargs)
  File "/usr/local/lib/python2.7/dist-packages/django/views/generic/base.py", line 69, in view
    return self.dispatch(request, *args, **kwargs)
  File "/usr/local/lib/python2.7/dist-packages/django/utils/decorators.py", line 29, in _wrapper
    return bound_func(*args, **kwargs)
  File "/usr/local/lib/python2.7/dist-packages/django/contrib/auth/decorators.py", line 22, in _wrapped_view
    return view_func(request, *args, **kwargs)
  File "/usr/local/lib/python2.7/dist-packages/django/utils/decorators.py", line 25, in bound_func
    return func(self, *args2, **kwargs2)
  File "/home/mikhail/EclipseWorkspace/oncoFinder2/oncoFinder2/medic/views.py", line 143, in dispatch
    return super(PatientTreatmentDetail, self).dispatch(request, *args, **kwargs)
  File "/usr/local/lib/python2.7/dist-packages/django/views/generic/base.py", line 87, in dispatch
    return handler(request, *args, **kwargs)
  File "/home/mikhail/EclipseWorkspace/oncoFinder2/oncoFinder2/medic/views.py", line 289, in post
    context = self.get_context_data(object=self.object)
  File "/home/mikhail/EclipseWorkspace/oncoFinder2/oncoFinder2/medic/views.py", line 164, in get_context_data
    df_required_paths = df_pms1[path_cols]
  File "/usr/local/lib/python2.7/dist-packages/pandas/core/frame.py", line 1737, in __getitem__
    return self._getitem_array(key)
  File "/usr/local/lib/python2.7/dist-packages/pandas/core/frame.py", line 1781, in _getitem_array
    indexer = self.ix._convert_to_indexer(key, axis=1)
  File "/usr/local/lib/python2.7/dist-packages/pandas/core/indexing.py", line 1135, in _convert_to_indexer
    raise KeyError('%s not in index' % objarr[mask])
KeyError: "['L.kynurenine_degradation'] not in index"
2014-11-24 13:26:01,242 ERROR base 25109 -1280316608 Internal Server Error: /document/doc2543/treat11/
Traceback (most recent call last):
  File "/usr/local/lib/python2.7/dist-packages/django/core/handlers/base.py", line 114, in get_response
    response = wrapped_callback(request, *callback_args, **callback_kwargs)
  File "/usr/local/lib/python2.7/dist-packages/django/views/generic/base.py", line 69, in view
    return self.dispatch(request, *args, **kwargs)
  File "/usr/local/lib/python2.7/dist-packages/django/utils/decorators.py", line 29, in _wrapper
    return bound_func(*args, **kwargs)
  File "/usr/local/lib/python2.7/dist-packages/django/contrib/auth/decorators.py", line 22, in _wrapped_view
    return view_func(request, *args, **kwargs)
  File "/usr/local/lib/python2.7/dist-packages/django/utils/decorators.py", line 25, in bound_func
    return func(self, *args2, **kwargs2)
  File "/home/mikhail/EclipseWorkspace/oncoFinder2/oncoFinder2/medic/views.py", line 143, in dispatch
    return super(PatientTreatmentDetail, self).dispatch(request, *args, **kwargs)
  File "/usr/local/lib/python2.7/dist-packages/django/views/generic/base.py", line 87, in dispatch
    return handler(request, *args, **kwargs)
  File "/home/mikhail/EclipseWorkspace/oncoFinder2/oncoFinder2/medic/views.py", line 289, in post
    context = self.get_context_data(object=self.object)
  File "/home/mikhail/EclipseWorkspace/oncoFinder2/oncoFinder2/medic/views.py", line 164, in get_context_data
    df_required_paths = df_pms1[path_cols]
  File "/usr/local/lib/python2.7/dist-packages/pandas/core/frame.py", line 1737, in __getitem__
    return self._getitem_array(key)
  File "/usr/local/lib/python2.7/dist-packages/pandas/core/frame.py", line 1781, in _getitem_array
    indexer = self.ix._convert_to_indexer(key, axis=1)
  File "/usr/local/lib/python2.7/dist-packages/pandas/core/indexing.py", line 1135, in _convert_to_indexer
    raise KeyError('%s not in index' % objarr[mask])
KeyError: "['L.kynurenine_degradation'\n 'sphingosine_and_sphingosine.1.phosphate_metabolism'\n 'tryptophan_degradation_to_2.amino.3.carboxymuconate_semialdehyde'] not in index"
2014-11-24 13:34:33,083 ERROR base 25109 -1280316608 Internal Server Error: /document/doc2543/treat14/
Traceback (most recent call last):
  File "/usr/local/lib/python2.7/dist-packages/django/core/handlers/base.py", line 114, in get_response
    response = wrapped_callback(request, *callback_args, **callback_kwargs)
  File "/usr/local/lib/python2.7/dist-packages/django/views/generic/base.py", line 69, in view
    return self.dispatch(request, *args, **kwargs)
  File "/usr/local/lib/python2.7/dist-packages/django/utils/decorators.py", line 29, in _wrapper
    return bound_func(*args, **kwargs)
  File "/usr/local/lib/python2.7/dist-packages/django/contrib/auth/decorators.py", line 22, in _wrapped_view
    return view_func(request, *args, **kwargs)
  File "/usr/local/lib/python2.7/dist-packages/django/utils/decorators.py", line 25, in bound_func
    return func(self, *args2, **kwargs2)
  File "/home/mikhail/EclipseWorkspace/oncoFinder2/oncoFinder2/medic/views.py", line 143, in dispatch
    return super(PatientTreatmentDetail, self).dispatch(request, *args, **kwargs)
  File "/usr/local/lib/python2.7/dist-packages/django/views/generic/base.py", line 87, in dispatch
    return handler(request, *args, **kwargs)
  File "/home/mikhail/EclipseWorkspace/oncoFinder2/oncoFinder2/medic/views.py", line 289, in post
    context = self.get_context_data(object=self.object)
  File "/home/mikhail/EclipseWorkspace/oncoFinder2/oncoFinder2/medic/views.py", line 164, in get_context_data
    df_required_paths = df_pms1[path_cols]
  File "/usr/local/lib/python2.7/dist-packages/pandas/core/frame.py", line 1737, in __getitem__
    return self._getitem_array(key)
  File "/usr/local/lib/python2.7/dist-packages/pandas/core/frame.py", line 1781, in _getitem_array
    indexer = self.ix._convert_to_indexer(key, axis=1)
  File "/usr/local/lib/python2.7/dist-packages/pandas/core/indexing.py", line 1135, in _convert_to_indexer
    raise KeyError('%s not in index' % objarr[mask])
KeyError: "['sphingosine_and_sphingosine.1.phosphate_metabolism'] not in index"
2014-11-24 13:34:33,636 ERROR base 25109 -1364198592 Internal Server Error: /document/doc2543/treat12/
Traceback (most recent call last):
  File "/usr/local/lib/python2.7/dist-packages/django/core/handlers/base.py", line 114, in get_response
    response = wrapped_callback(request, *callback_args, **callback_kwargs)
  File "/usr/local/lib/python2.7/dist-packages/django/views/generic/base.py", line 69, in view
    return self.dispatch(request, *args, **kwargs)
  File "/usr/local/lib/python2.7/dist-packages/django/utils/decorators.py", line 29, in _wrapper
    return bound_func(*args, **kwargs)
  File "/usr/local/lib/python2.7/dist-packages/django/contrib/auth/decorators.py", line 22, in _wrapped_view
    return view_func(request, *args, **kwargs)
  File "/usr/local/lib/python2.7/dist-packages/django/utils/decorators.py", line 25, in bound_func
    return func(self, *args2, **kwargs2)
  File "/home/mikhail/EclipseWorkspace/oncoFinder2/oncoFinder2/medic/views.py", line 143, in dispatch
    return super(PatientTreatmentDetail, self).dispatch(request, *args, **kwargs)
  File "/usr/local/lib/python2.7/dist-packages/django/views/generic/base.py", line 87, in dispatch
    return handler(request, *args, **kwargs)
  File "/home/mikhail/EclipseWorkspace/oncoFinder2/oncoFinder2/medic/views.py", line 289, in post
    context = self.get_context_data(object=self.object)
  File "/home/mikhail/EclipseWorkspace/oncoFinder2/oncoFinder2/medic/views.py", line 164, in get_context_data
    df_required_paths = df_pms1[path_cols]
  File "/usr/local/lib/python2.7/dist-packages/pandas/core/frame.py", line 1737, in __getitem__
    return self._getitem_array(key)
  File "/usr/local/lib/python2.7/dist-packages/pandas/core/frame.py", line 1781, in _getitem_array
    indexer = self.ix._convert_to_indexer(key, axis=1)
  File "/usr/local/lib/python2.7/dist-packages/pandas/core/indexing.py", line 1135, in _convert_to_indexer
    raise KeyError('%s not in index' % objarr[mask])
KeyError: "['ATM_Pathway_G2.M_Checkpoint_Arrest'\n 'D.galactose_degradation_V_Leloir_pathway'] not in index"
2014-11-24 13:34:34,097 ERROR base 25109 -1297102016 Internal Server Error: /document/doc2543/treat8/
Traceback (most recent call last):
  File "/usr/local/lib/python2.7/dist-packages/django/core/handlers/base.py", line 114, in get_response
    response = wrapped_callback(request, *callback_args, **callback_kwargs)
  File "/usr/local/lib/python2.7/dist-packages/django/views/generic/base.py", line 69, in view
    return self.dispatch(request, *args, **kwargs)
  File "/usr/local/lib/python2.7/dist-packages/django/utils/decorators.py", line 29, in _wrapper
    return bound_func(*args, **kwargs)
  File "/usr/local/lib/python2.7/dist-packages/django/contrib/auth/decorators.py", line 22, in _wrapped_view
    return view_func(request, *args, **kwargs)
  File "/usr/local/lib/python2.7/dist-packages/django/utils/decorators.py", line 25, in bound_func
    return func(self, *args2, **kwargs2)
  File "/home/mikhail/EclipseWorkspace/oncoFinder2/oncoFinder2/medic/views.py", line 143, in dispatch
    return super(PatientTreatmentDetail, self).dispatch(request, *args, **kwargs)
  File "/usr/local/lib/python2.7/dist-packages/django/views/generic/base.py", line 87, in dispatch
    return handler(request, *args, **kwargs)
  File "/home/mikhail/EclipseWorkspace/oncoFinder2/oncoFinder2/medic/views.py", line 289, in post
    context = self.get_context_data(object=self.object)
  File "/home/mikhail/EclipseWorkspace/oncoFinder2/oncoFinder2/medic/views.py", line 164, in get_context_data
    df_required_paths = df_pms1[path_cols]
  File "/usr/local/lib/python2.7/dist-packages/pandas/core/frame.py", line 1737, in __getitem__
    return self._getitem_array(key)
  File "/usr/local/lib/python2.7/dist-packages/pandas/core/frame.py", line 1781, in _getitem_array
    indexer = self.ix._convert_to_indexer(key, axis=1)
  File "/usr/local/lib/python2.7/dist-packages/pandas/core/indexing.py", line 1135, in _convert_to_indexer
    raise KeyError('%s not in index' % objarr[mask])
KeyError: "['L.kynurenine_degradation'] not in index"
2014-11-24 13:34:36,061 ERROR base 25109 -1405093056 Internal Server Error: /document/doc2543/treat11/
Traceback (most recent call last):
  File "/usr/local/lib/python2.7/dist-packages/django/core/handlers/base.py", line 114, in get_response
    response = wrapped_callback(request, *callback_args, **callback_kwargs)
  File "/usr/local/lib/python2.7/dist-packages/django/views/generic/base.py", line 69, in view
    return self.dispatch(request, *args, **kwargs)
  File "/usr/local/lib/python2.7/dist-packages/django/utils/decorators.py", line 29, in _wrapper
    return bound_func(*args, **kwargs)
  File "/usr/local/lib/python2.7/dist-packages/django/contrib/auth/decorators.py", line 22, in _wrapped_view
    return view_func(request, *args, **kwargs)
  File "/usr/local/lib/python2.7/dist-packages/django/utils/decorators.py", line 25, in bound_func
    return func(self, *args2, **kwargs2)
  File "/home/mikhail/EclipseWorkspace/oncoFinder2/oncoFinder2/medic/views.py", line 143, in dispatch
    return super(PatientTreatmentDetail, self).dispatch(request, *args, **kwargs)
  File "/usr/local/lib/python2.7/dist-packages/django/views/generic/base.py", line 87, in dispatch
    return handler(request, *args, **kwargs)
  File "/home/mikhail/EclipseWorkspace/oncoFinder2/oncoFinder2/medic/views.py", line 289, in post
    context = self.get_context_data(object=self.object)
  File "/home/mikhail/EclipseWorkspace/oncoFinder2/oncoFinder2/medic/views.py", line 164, in get_context_data
    df_required_paths = df_pms1[path_cols]
  File "/usr/local/lib/python2.7/dist-packages/pandas/core/frame.py", line 1737, in __getitem__
    return self._getitem_array(key)
  File "/usr/local/lib/python2.7/dist-packages/pandas/core/frame.py", line 1781, in _getitem_array
    indexer = self.ix._convert_to_indexer(key, axis=1)
  File "/usr/local/lib/python2.7/dist-packages/pandas/core/indexing.py", line 1135, in _convert_to_indexer
    raise KeyError('%s not in index' % objarr[mask])
KeyError: "['L.kynurenine_degradation'\n 'sphingosine_and_sphingosine.1.phosphate_metabolism'\n 'tryptophan_degradation_to_2.amino.3.carboxymuconate_semialdehyde'] not in index"
2014-11-24 13:35:10,361 ERROR base 25109 -1297102016 Internal Server Error: /document/doc2543/treat14/
Traceback (most recent call last):
  File "/usr/local/lib/python2.7/dist-packages/django/core/handlers/base.py", line 114, in get_response
    response = wrapped_callback(request, *callback_args, **callback_kwargs)
  File "/usr/local/lib/python2.7/dist-packages/django/views/generic/base.py", line 69, in view
    return self.dispatch(request, *args, **kwargs)
  File "/usr/local/lib/python2.7/dist-packages/django/utils/decorators.py", line 29, in _wrapper
    return bound_func(*args, **kwargs)
  File "/usr/local/lib/python2.7/dist-packages/django/contrib/auth/decorators.py", line 22, in _wrapped_view
    return view_func(request, *args, **kwargs)
  File "/usr/local/lib/python2.7/dist-packages/django/utils/decorators.py", line 25, in bound_func
    return func(self, *args2, **kwargs2)
  File "/home/mikhail/EclipseWorkspace/oncoFinder2/oncoFinder2/medic/views.py", line 143, in dispatch
    return super(PatientTreatmentDetail, self).dispatch(request, *args, **kwargs)
  File "/usr/local/lib/python2.7/dist-packages/django/views/generic/base.py", line 87, in dispatch
    return handler(request, *args, **kwargs)
  File "/home/mikhail/EclipseWorkspace/oncoFinder2/oncoFinder2/medic/views.py", line 289, in post
    context = self.get_context_data(object=self.object)
  File "/home/mikhail/EclipseWorkspace/oncoFinder2/oncoFinder2/medic/views.py", line 164, in get_context_data
    df_required_paths = df_pms1[path_cols]
  File "/usr/local/lib/python2.7/dist-packages/pandas/core/frame.py", line 1737, in __getitem__
    return self._getitem_array(key)
  File "/usr/local/lib/python2.7/dist-packages/pandas/core/frame.py", line 1781, in _getitem_array
    indexer = self.ix._convert_to_indexer(key, axis=1)
  File "/usr/local/lib/python2.7/dist-packages/pandas/core/indexing.py", line 1135, in _convert_to_indexer
    raise KeyError('%s not in index' % objarr[mask])
KeyError: "['sphingosine_and_sphingosine.1.phosphate_metabolism'] not in index"
2014-11-24 13:35:10,835 ERROR base 25109 -1444938944 Internal Server Error: /document/doc2543/treat12/
Traceback (most recent call last):
  File "/usr/local/lib/python2.7/dist-packages/django/core/handlers/base.py", line 114, in get_response
    response = wrapped_callback(request, *callback_args, **callback_kwargs)
  File "/usr/local/lib/python2.7/dist-packages/django/views/generic/base.py", line 69, in view
    return self.dispatch(request, *args, **kwargs)
  File "/usr/local/lib/python2.7/dist-packages/django/utils/decorators.py", line 29, in _wrapper
    return bound_func(*args, **kwargs)
  File "/usr/local/lib/python2.7/dist-packages/django/contrib/auth/decorators.py", line 22, in _wrapped_view
    return view_func(request, *args, **kwargs)
  File "/usr/local/lib/python2.7/dist-packages/django/utils/decorators.py", line 25, in bound_func
    return func(self, *args2, **kwargs2)
  File "/home/mikhail/EclipseWorkspace/oncoFinder2/oncoFinder2/medic/views.py", line 143, in dispatch
    return super(PatientTreatmentDetail, self).dispatch(request, *args, **kwargs)
  File "/usr/local/lib/python2.7/dist-packages/django/views/generic/base.py", line 87, in dispatch
    return handler(request, *args, **kwargs)
  File "/home/mikhail/EclipseWorkspace/oncoFinder2/oncoFinder2/medic/views.py", line 289, in post
    context = self.get_context_data(object=self.object)
  File "/home/mikhail/EclipseWorkspace/oncoFinder2/oncoFinder2/medic/views.py", line 164, in get_context_data
    df_required_paths = df_pms1[path_cols]
  File "/usr/local/lib/python2.7/dist-packages/pandas/core/frame.py", line 1737, in __getitem__
    return self._getitem_array(key)
  File "/usr/local/lib/python2.7/dist-packages/pandas/core/frame.py", line 1781, in _getitem_array
    indexer = self.ix._convert_to_indexer(key, axis=1)
  File "/usr/local/lib/python2.7/dist-packages/pandas/core/indexing.py", line 1135, in _convert_to_indexer
    raise KeyError('%s not in index' % objarr[mask])
KeyError: "['ATM_Pathway_G2.M_Checkpoint_Arrest'\n 'D.galactose_degradation_V_Leloir_pathway'] not in index"
2014-11-24 13:35:11,407 ERROR base 25109 -1288709312 Internal Server Error: /document/doc2543/treat8/
Traceback (most recent call last):
  File "/usr/local/lib/python2.7/dist-packages/django/core/handlers/base.py", line 114, in get_response
    response = wrapped_callback(request, *callback_args, **callback_kwargs)
  File "/usr/local/lib/python2.7/dist-packages/django/views/generic/base.py", line 69, in view
    return self.dispatch(request, *args, **kwargs)
  File "/usr/local/lib/python2.7/dist-packages/django/utils/decorators.py", line 29, in _wrapper
    return bound_func(*args, **kwargs)
  File "/usr/local/lib/python2.7/dist-packages/django/contrib/auth/decorators.py", line 22, in _wrapped_view
    return view_func(request, *args, **kwargs)
  File "/usr/local/lib/python2.7/dist-packages/django/utils/decorators.py", line 25, in bound_func
    return func(self, *args2, **kwargs2)
  File "/home/mikhail/EclipseWorkspace/oncoFinder2/oncoFinder2/medic/views.py", line 143, in dispatch
    return super(PatientTreatmentDetail, self).dispatch(request, *args, **kwargs)
  File "/usr/local/lib/python2.7/dist-packages/django/views/generic/base.py", line 87, in dispatch
    return handler(request, *args, **kwargs)
  File "/home/mikhail/EclipseWorkspace/oncoFinder2/oncoFinder2/medic/views.py", line 289, in post
    context = self.get_context_data(object=self.object)
  File "/home/mikhail/EclipseWorkspace/oncoFinder2/oncoFinder2/medic/views.py", line 164, in get_context_data
    df_required_paths = df_pms1[path_cols]
  File "/usr/local/lib/python2.7/dist-packages/pandas/core/frame.py", line 1737, in __getitem__
    return self._getitem_array(key)
  File "/usr/local/lib/python2.7/dist-packages/pandas/core/frame.py", line 1781, in _getitem_array
    indexer = self.ix._convert_to_indexer(key, axis=1)
  File "/usr/local/lib/python2.7/dist-packages/pandas/core/indexing.py", line 1135, in _convert_to_indexer
    raise KeyError('%s not in index' % objarr[mask])
KeyError: "['L.kynurenine_degradation'] not in index"
2014-11-24 13:35:12,694 ERROR base 25109 -1364198592 Internal Server Error: /document/doc2543/treat11/
Traceback (most recent call last):
  File "/usr/local/lib/python2.7/dist-packages/django/core/handlers/base.py", line 114, in get_response
    response = wrapped_callback(request, *callback_args, **callback_kwargs)
  File "/usr/local/lib/python2.7/dist-packages/django/views/generic/base.py", line 69, in view
    return self.dispatch(request, *args, **kwargs)
  File "/usr/local/lib/python2.7/dist-packages/django/utils/decorators.py", line 29, in _wrapper
    return bound_func(*args, **kwargs)
  File "/usr/local/lib/python2.7/dist-packages/django/contrib/auth/decorators.py", line 22, in _wrapped_view
    return view_func(request, *args, **kwargs)
  File "/usr/local/lib/python2.7/dist-packages/django/utils/decorators.py", line 25, in bound_func
    return func(self, *args2, **kwargs2)
  File "/home/mikhail/EclipseWorkspace/oncoFinder2/oncoFinder2/medic/views.py", line 143, in dispatch
    return super(PatientTreatmentDetail, self).dispatch(request, *args, **kwargs)
  File "/usr/local/lib/python2.7/dist-packages/django/views/generic/base.py", line 87, in dispatch
    return handler(request, *args, **kwargs)
  File "/home/mikhail/EclipseWorkspace/oncoFinder2/oncoFinder2/medic/views.py", line 289, in post
    context = self.get_context_data(object=self.object)
  File "/home/mikhail/EclipseWorkspace/oncoFinder2/oncoFinder2/medic/views.py", line 164, in get_context_data
    df_required_paths = df_pms1[path_cols]
  File "/usr/local/lib/python2.7/dist-packages/pandas/core/frame.py", line 1737, in __getitem__
    return self._getitem_array(key)
  File "/usr/local/lib/python2.7/dist-packages/pandas/core/frame.py", line 1781, in _getitem_array
    indexer = self.ix._convert_to_indexer(key, axis=1)
  File "/usr/local/lib/python2.7/dist-packages/pandas/core/indexing.py", line 1135, in _convert_to_indexer
    raise KeyError('%s not in index' % objarr[mask])
KeyError: "['L.kynurenine_degradation'\n 'sphingosine_and_sphingosine.1.phosphate_metabolism'\n 'tryptophan_degradation_to_2.amino.3.carboxymuconate_semialdehyde'] not in index"
2014-11-24 13:36:43,957 ERROR base 25109 -1288709312 Internal Server Error: /document/doc2543/treat14/
Traceback (most recent call last):
  File "/usr/local/lib/python2.7/dist-packages/django/core/handlers/base.py", line 114, in get_response
    response = wrapped_callback(request, *callback_args, **callback_kwargs)
  File "/usr/local/lib/python2.7/dist-packages/django/views/generic/base.py", line 69, in view
    return self.dispatch(request, *args, **kwargs)
  File "/usr/local/lib/python2.7/dist-packages/django/utils/decorators.py", line 29, in _wrapper
    return bound_func(*args, **kwargs)
  File "/usr/local/lib/python2.7/dist-packages/django/contrib/auth/decorators.py", line 22, in _wrapped_view
    return view_func(request, *args, **kwargs)
  File "/usr/local/lib/python2.7/dist-packages/django/utils/decorators.py", line 25, in bound_func
    return func(self, *args2, **kwargs2)
  File "/home/mikhail/EclipseWorkspace/oncoFinder2/oncoFinder2/medic/views.py", line 143, in dispatch
    return super(PatientTreatmentDetail, self).dispatch(request, *args, **kwargs)
  File "/usr/local/lib/python2.7/dist-packages/django/views/generic/base.py", line 87, in dispatch
    return handler(request, *args, **kwargs)
  File "/home/mikhail/EclipseWorkspace/oncoFinder2/oncoFinder2/medic/views.py", line 289, in post
    context = self.get_context_data(object=self.object)
  File "/home/mikhail/EclipseWorkspace/oncoFinder2/oncoFinder2/medic/views.py", line 164, in get_context_data
    df_required_paths = df_pms1[path_cols]
  File "/usr/local/lib/python2.7/dist-packages/pandas/core/frame.py", line 1737, in __getitem__
    return self._getitem_array(key)
  File "/usr/local/lib/python2.7/dist-packages/pandas/core/frame.py", line 1781, in _getitem_array
    indexer = self.ix._convert_to_indexer(key, axis=1)
  File "/usr/local/lib/python2.7/dist-packages/pandas/core/indexing.py", line 1135, in _convert_to_indexer
    raise KeyError('%s not in index' % objarr[mask])
KeyError: "['sphingosine_and_sphingosine.1.phosphate_metabolism'] not in index"
2014-11-24 13:36:44,188 ERROR base 25109 -1405093056 Internal Server Error: /document/doc2543/treat12/
Traceback (most recent call last):
  File "/usr/local/lib/python2.7/dist-packages/django/core/handlers/base.py", line 114, in get_response
    response = wrapped_callback(request, *callback_args, **callback_kwargs)
  File "/usr/local/lib/python2.7/dist-packages/django/views/generic/base.py", line 69, in view
    return self.dispatch(request, *args, **kwargs)
  File "/usr/local/lib/python2.7/dist-packages/django/utils/decorators.py", line 29, in _wrapper
    return bound_func(*args, **kwargs)
  File "/usr/local/lib/python2.7/dist-packages/django/contrib/auth/decorators.py", line 22, in _wrapped_view
    return view_func(request, *args, **kwargs)
  File "/usr/local/lib/python2.7/dist-packages/django/utils/decorators.py", line 25, in bound_func
    return func(self, *args2, **kwargs2)
  File "/home/mikhail/EclipseWorkspace/oncoFinder2/oncoFinder2/medic/views.py", line 143, in dispatch
    return super(PatientTreatmentDetail, self).dispatch(request, *args, **kwargs)
  File "/usr/local/lib/python2.7/dist-packages/django/views/generic/base.py", line 87, in dispatch
    return handler(request, *args, **kwargs)
  File "/home/mikhail/EclipseWorkspace/oncoFinder2/oncoFinder2/medic/views.py", line 289, in post
    context = self.get_context_data(object=self.object)
  File "/home/mikhail/EclipseWorkspace/oncoFinder2/oncoFinder2/medic/views.py", line 164, in get_context_data
    df_required_paths = df_pms1[path_cols]
  File "/usr/local/lib/python2.7/dist-packages/pandas/core/frame.py", line 1737, in __getitem__
    return self._getitem_array(key)
  File "/usr/local/lib/python2.7/dist-packages/pandas/core/frame.py", line 1781, in _getitem_array
    indexer = self.ix._convert_to_indexer(key, axis=1)
  File "/usr/local/lib/python2.7/dist-packages/pandas/core/indexing.py", line 1135, in _convert_to_indexer
    raise KeyError('%s not in index' % objarr[mask])
KeyError: "['ATM_Pathway_G2.M_Checkpoint_Arrest'\n 'D.galactose_degradation_V_Leloir_pathway'] not in index"
2014-11-24 13:36:44,942 ERROR base 25109 -1364198592 Internal Server Error: /document/doc2543/treat8/
Traceback (most recent call last):
  File "/usr/local/lib/python2.7/dist-packages/django/core/handlers/base.py", line 114, in get_response
    response = wrapped_callback(request, *callback_args, **callback_kwargs)
  File "/usr/local/lib/python2.7/dist-packages/django/views/generic/base.py", line 69, in view
    return self.dispatch(request, *args, **kwargs)
  File "/usr/local/lib/python2.7/dist-packages/django/utils/decorators.py", line 29, in _wrapper
    return bound_func(*args, **kwargs)
  File "/usr/local/lib/python2.7/dist-packages/django/contrib/auth/decorators.py", line 22, in _wrapped_view
    return view_func(request, *args, **kwargs)
  File "/usr/local/lib/python2.7/dist-packages/django/utils/decorators.py", line 25, in bound_func
    return func(self, *args2, **kwargs2)
  File "/home/mikhail/EclipseWorkspace/oncoFinder2/oncoFinder2/medic/views.py", line 143, in dispatch
    return super(PatientTreatmentDetail, self).dispatch(request, *args, **kwargs)
  File "/usr/local/lib/python2.7/dist-packages/django/views/generic/base.py", line 87, in dispatch
    return handler(request, *args, **kwargs)
  File "/home/mikhail/EclipseWorkspace/oncoFinder2/oncoFinder2/medic/views.py", line 289, in post
    context = self.get_context_data(object=self.object)
  File "/home/mikhail/EclipseWorkspace/oncoFinder2/oncoFinder2/medic/views.py", line 164, in get_context_data
    df_required_paths = df_pms1[path_cols]
  File "/usr/local/lib/python2.7/dist-packages/pandas/core/frame.py", line 1737, in __getitem__
    return self._getitem_array(key)
  File "/usr/local/lib/python2.7/dist-packages/pandas/core/frame.py", line 1781, in _getitem_array
    indexer = self.ix._convert_to_indexer(key, axis=1)
  File "/usr/local/lib/python2.7/dist-packages/pandas/core/indexing.py", line 1135, in _convert_to_indexer
    raise KeyError('%s not in index' % objarr[mask])
KeyError: "['L.kynurenine_degradation'] not in index"
2014-11-24 13:36:46,117 ERROR base 25109 -1444938944 Internal Server Error: /document/doc2543/treat11/
Traceback (most recent call last):
  File "/usr/local/lib/python2.7/dist-packages/django/core/handlers/base.py", line 114, in get_response
    response = wrapped_callback(request, *callback_args, **callback_kwargs)
  File "/usr/local/lib/python2.7/dist-packages/django/views/generic/base.py", line 69, in view
    return self.dispatch(request, *args, **kwargs)
  File "/usr/local/lib/python2.7/dist-packages/django/utils/decorators.py", line 29, in _wrapper
    return bound_func(*args, **kwargs)
  File "/usr/local/lib/python2.7/dist-packages/django/contrib/auth/decorators.py", line 22, in _wrapped_view
    return view_func(request, *args, **kwargs)
  File "/usr/local/lib/python2.7/dist-packages/django/utils/decorators.py", line 25, in bound_func
    return func(self, *args2, **kwargs2)
  File "/home/mikhail/EclipseWorkspace/oncoFinder2/oncoFinder2/medic/views.py", line 143, in dispatch
    return super(PatientTreatmentDetail, self).dispatch(request, *args, **kwargs)
  File "/usr/local/lib/python2.7/dist-packages/django/views/generic/base.py", line 87, in dispatch
    return handler(request, *args, **kwargs)
  File "/home/mikhail/EclipseWorkspace/oncoFinder2/oncoFinder2/medic/views.py", line 289, in post
    context = self.get_context_data(object=self.object)
  File "/home/mikhail/EclipseWorkspace/oncoFinder2/oncoFinder2/medic/views.py", line 164, in get_context_data
    df_required_paths = df_pms1[path_cols]
  File "/usr/local/lib/python2.7/dist-packages/pandas/core/frame.py", line 1737, in __getitem__
    return self._getitem_array(key)
  File "/usr/local/lib/python2.7/dist-packages/pandas/core/frame.py", line 1781, in _getitem_array
    indexer = self.ix._convert_to_indexer(key, axis=1)
  File "/usr/local/lib/python2.7/dist-packages/pandas/core/indexing.py", line 1135, in _convert_to_indexer
    raise KeyError('%s not in index' % objarr[mask])
KeyError: "['L.kynurenine_degradation'\n 'sphingosine_and_sphingosine.1.phosphate_metabolism'\n 'tryptophan_degradation_to_2.amino.3.carboxymuconate_semialdehyde'] not in index"
2014-11-24 13:37:18,375 ERROR base 25109 -1276118208 Internal Server Error: /document/doc2543/treat14/
Traceback (most recent call last):
  File "/usr/local/lib/python2.7/dist-packages/django/core/handlers/base.py", line 114, in get_response
    response = wrapped_callback(request, *callback_args, **callback_kwargs)
  File "/usr/local/lib/python2.7/dist-packages/django/views/generic/base.py", line 69, in view
    return self.dispatch(request, *args, **kwargs)
  File "/usr/local/lib/python2.7/dist-packages/django/utils/decorators.py", line 29, in _wrapper
    return bound_func(*args, **kwargs)
  File "/usr/local/lib/python2.7/dist-packages/django/contrib/auth/decorators.py", line 22, in _wrapped_view
    return view_func(request, *args, **kwargs)
  File "/usr/local/lib/python2.7/dist-packages/django/utils/decorators.py", line 25, in bound_func
    return func(self, *args2, **kwargs2)
  File "/home/mikhail/EclipseWorkspace/oncoFinder2/oncoFinder2/medic/views.py", line 143, in dispatch
    return super(PatientTreatmentDetail, self).dispatch(request, *args, **kwargs)
  File "/usr/local/lib/python2.7/dist-packages/django/views/generic/base.py", line 87, in dispatch
    return handler(request, *args, **kwargs)
  File "/home/mikhail/EclipseWorkspace/oncoFinder2/oncoFinder2/medic/views.py", line 289, in post
    context = self.get_context_data(object=self.object)
  File "/home/mikhail/EclipseWorkspace/oncoFinder2/oncoFinder2/medic/views.py", line 164, in get_context_data
    df_required_paths = df_pms1[path_cols]
  File "/usr/local/lib/python2.7/dist-packages/pandas/core/frame.py", line 1737, in __getitem__
    return self._getitem_array(key)
  File "/usr/local/lib/python2.7/dist-packages/pandas/core/frame.py", line 1781, in _getitem_array
    indexer = self.ix._convert_to_indexer(key, axis=1)
  File "/usr/local/lib/python2.7/dist-packages/pandas/core/indexing.py", line 1135, in _convert_to_indexer
    raise KeyError('%s not in index' % objarr[mask])
KeyError: "['sphingosine_and_sphingosine.1.phosphate_metabolism'] not in index"
2014-11-24 13:37:18,589 ERROR base 25109 -1444938944 Internal Server Error: /document/doc2543/treat12/
Traceback (most recent call last):
  File "/usr/local/lib/python2.7/dist-packages/django/core/handlers/base.py", line 114, in get_response
    response = wrapped_callback(request, *callback_args, **callback_kwargs)
  File "/usr/local/lib/python2.7/dist-packages/django/views/generic/base.py", line 69, in view
    return self.dispatch(request, *args, **kwargs)
  File "/usr/local/lib/python2.7/dist-packages/django/utils/decorators.py", line 29, in _wrapper
    return bound_func(*args, **kwargs)
  File "/usr/local/lib/python2.7/dist-packages/django/contrib/auth/decorators.py", line 22, in _wrapped_view
    return view_func(request, *args, **kwargs)
  File "/usr/local/lib/python2.7/dist-packages/django/utils/decorators.py", line 25, in bound_func
    return func(self, *args2, **kwargs2)
  File "/home/mikhail/EclipseWorkspace/oncoFinder2/oncoFinder2/medic/views.py", line 143, in dispatch
    return super(PatientTreatmentDetail, self).dispatch(request, *args, **kwargs)
  File "/usr/local/lib/python2.7/dist-packages/django/views/generic/base.py", line 87, in dispatch
    return handler(request, *args, **kwargs)
  File "/home/mikhail/EclipseWorkspace/oncoFinder2/oncoFinder2/medic/views.py", line 289, in post
    context = self.get_context_data(object=self.object)
  File "/home/mikhail/EclipseWorkspace/oncoFinder2/oncoFinder2/medic/views.py", line 164, in get_context_data
    df_required_paths = df_pms1[path_cols]
  File "/usr/local/lib/python2.7/dist-packages/pandas/core/frame.py", line 1737, in __getitem__
    return self._getitem_array(key)
  File "/usr/local/lib/python2.7/dist-packages/pandas/core/frame.py", line 1781, in _getitem_array
    indexer = self.ix._convert_to_indexer(key, axis=1)
  File "/usr/local/lib/python2.7/dist-packages/pandas/core/indexing.py", line 1135, in _convert_to_indexer
    raise KeyError('%s not in index' % objarr[mask])
KeyError: "['ATM_Pathway_G2.M_Checkpoint_Arrest'\n 'D.galactose_degradation_V_Leloir_pathway'] not in index"
2014-11-24 13:37:19,382 ERROR base 25109 -1364198592 Internal Server Error: /document/doc2543/treat8/
Traceback (most recent call last):
  File "/usr/local/lib/python2.7/dist-packages/django/core/handlers/base.py", line 114, in get_response
    response = wrapped_callback(request, *callback_args, **callback_kwargs)
  File "/usr/local/lib/python2.7/dist-packages/django/views/generic/base.py", line 69, in view
    return self.dispatch(request, *args, **kwargs)
  File "/usr/local/lib/python2.7/dist-packages/django/utils/decorators.py", line 29, in _wrapper
    return bound_func(*args, **kwargs)
  File "/usr/local/lib/python2.7/dist-packages/django/contrib/auth/decorators.py", line 22, in _wrapped_view
    return view_func(request, *args, **kwargs)
  File "/usr/local/lib/python2.7/dist-packages/django/utils/decorators.py", line 25, in bound_func
    return func(self, *args2, **kwargs2)
  File "/home/mikhail/EclipseWorkspace/oncoFinder2/oncoFinder2/medic/views.py", line 143, in dispatch
    return super(PatientTreatmentDetail, self).dispatch(request, *args, **kwargs)
  File "/usr/local/lib/python2.7/dist-packages/django/views/generic/base.py", line 87, in dispatch
    return handler(request, *args, **kwargs)
  File "/home/mikhail/EclipseWorkspace/oncoFinder2/oncoFinder2/medic/views.py", line 289, in post
    context = self.get_context_data(object=self.object)
  File "/home/mikhail/EclipseWorkspace/oncoFinder2/oncoFinder2/medic/views.py", line 164, in get_context_data
    df_required_paths = df_pms1[path_cols]
  File "/usr/local/lib/python2.7/dist-packages/pandas/core/frame.py", line 1737, in __getitem__
    return self._getitem_array(key)
  File "/usr/local/lib/python2.7/dist-packages/pandas/core/frame.py", line 1781, in _getitem_array
    indexer = self.ix._convert_to_indexer(key, axis=1)
  File "/usr/local/lib/python2.7/dist-packages/pandas/core/indexing.py", line 1135, in _convert_to_indexer
    raise KeyError('%s not in index' % objarr[mask])
KeyError: "['L.kynurenine_degradation'] not in index"
2014-11-24 13:37:20,445 ERROR base 25109 -1297102016 Internal Server Error: /document/doc2543/treat11/
Traceback (most recent call last):
  File "/usr/local/lib/python2.7/dist-packages/django/core/handlers/base.py", line 114, in get_response
    response = wrapped_callback(request, *callback_args, **callback_kwargs)
  File "/usr/local/lib/python2.7/dist-packages/django/views/generic/base.py", line 69, in view
    return self.dispatch(request, *args, **kwargs)
  File "/usr/local/lib/python2.7/dist-packages/django/utils/decorators.py", line 29, in _wrapper
    return bound_func(*args, **kwargs)
  File "/usr/local/lib/python2.7/dist-packages/django/contrib/auth/decorators.py", line 22, in _wrapped_view
    return view_func(request, *args, **kwargs)
  File "/usr/local/lib/python2.7/dist-packages/django/utils/decorators.py", line 25, in bound_func
    return func(self, *args2, **kwargs2)
  File "/home/mikhail/EclipseWorkspace/oncoFinder2/oncoFinder2/medic/views.py", line 143, in dispatch
    return super(PatientTreatmentDetail, self).dispatch(request, *args, **kwargs)
  File "/usr/local/lib/python2.7/dist-packages/django/views/generic/base.py", line 87, in dispatch
    return handler(request, *args, **kwargs)
  File "/home/mikhail/EclipseWorkspace/oncoFinder2/oncoFinder2/medic/views.py", line 289, in post
    context = self.get_context_data(object=self.object)
  File "/home/mikhail/EclipseWorkspace/oncoFinder2/oncoFinder2/medic/views.py", line 164, in get_context_data
    df_required_paths = df_pms1[path_cols]
  File "/usr/local/lib/python2.7/dist-packages/pandas/core/frame.py", line 1737, in __getitem__
    return self._getitem_array(key)
  File "/usr/local/lib/python2.7/dist-packages/pandas/core/frame.py", line 1781, in _getitem_array
    indexer = self.ix._convert_to_indexer(key, axis=1)
  File "/usr/local/lib/python2.7/dist-packages/pandas/core/indexing.py", line 1135, in _convert_to_indexer
    raise KeyError('%s not in index' % objarr[mask])
KeyError: "['L.kynurenine_degradation'\n 'sphingosine_and_sphingosine.1.phosphate_metabolism'\n 'tryptophan_degradation_to_2.amino.3.carboxymuconate_semialdehyde'] not in index"
2014-11-24 14:04:37,927 ERROR base 25109 -1405093056 Internal Server Error: /document/doc2543/treat14/
Traceback (most recent call last):
  File "/usr/local/lib/python2.7/dist-packages/django/core/handlers/base.py", line 114, in get_response
    response = wrapped_callback(request, *callback_args, **callback_kwargs)
  File "/usr/local/lib/python2.7/dist-packages/django/views/generic/base.py", line 69, in view
    return self.dispatch(request, *args, **kwargs)
  File "/usr/local/lib/python2.7/dist-packages/django/utils/decorators.py", line 29, in _wrapper
    return bound_func(*args, **kwargs)
  File "/usr/local/lib/python2.7/dist-packages/django/contrib/auth/decorators.py", line 22, in _wrapped_view
    return view_func(request, *args, **kwargs)
  File "/usr/local/lib/python2.7/dist-packages/django/utils/decorators.py", line 25, in bound_func
    return func(self, *args2, **kwargs2)
  File "/home/mikhail/EclipseWorkspace/oncoFinder2/oncoFinder2/medic/views.py", line 143, in dispatch
    return super(PatientTreatmentDetail, self).dispatch(request, *args, **kwargs)
  File "/usr/local/lib/python2.7/dist-packages/django/views/generic/base.py", line 87, in dispatch
    return handler(request, *args, **kwargs)
  File "/home/mikhail/EclipseWorkspace/oncoFinder2/oncoFinder2/medic/views.py", line 289, in post
    context = self.get_context_data(object=self.object)
  File "/home/mikhail/EclipseWorkspace/oncoFinder2/oncoFinder2/medic/views.py", line 164, in get_context_data
    df_required_paths = df_pms1[path_cols]
  File "/usr/local/lib/python2.7/dist-packages/pandas/core/frame.py", line 1737, in __getitem__
    return self._getitem_array(key)
  File "/usr/local/lib/python2.7/dist-packages/pandas/core/frame.py", line 1781, in _getitem_array
    indexer = self.ix._convert_to_indexer(key, axis=1)
  File "/usr/local/lib/python2.7/dist-packages/pandas/core/indexing.py", line 1135, in _convert_to_indexer
    raise KeyError('%s not in index' % objarr[mask])
KeyError: "['sphingosine_and_sphingosine.1.phosphate_metabolism'] not in index"
2014-11-24 14:04:38,472 ERROR base 25109 -1333789888 Internal Server Error: /document/doc2543/treat12/
Traceback (most recent call last):
  File "/usr/local/lib/python2.7/dist-packages/django/core/handlers/base.py", line 114, in get_response
    response = wrapped_callback(request, *callback_args, **callback_kwargs)
  File "/usr/local/lib/python2.7/dist-packages/django/views/generic/base.py", line 69, in view
    return self.dispatch(request, *args, **kwargs)
  File "/usr/local/lib/python2.7/dist-packages/django/utils/decorators.py", line 29, in _wrapper
    return bound_func(*args, **kwargs)
  File "/usr/local/lib/python2.7/dist-packages/django/contrib/auth/decorators.py", line 22, in _wrapped_view
    return view_func(request, *args, **kwargs)
  File "/usr/local/lib/python2.7/dist-packages/django/utils/decorators.py", line 25, in bound_func
    return func(self, *args2, **kwargs2)
  File "/home/mikhail/EclipseWorkspace/oncoFinder2/oncoFinder2/medic/views.py", line 143, in dispatch
    return super(PatientTreatmentDetail, self).dispatch(request, *args, **kwargs)
  File "/usr/local/lib/python2.7/dist-packages/django/views/generic/base.py", line 87, in dispatch
    return handler(request, *args, **kwargs)
  File "/home/mikhail/EclipseWorkspace/oncoFinder2/oncoFinder2/medic/views.py", line 289, in post
    context = self.get_context_data(object=self.object)
  File "/home/mikhail/EclipseWorkspace/oncoFinder2/oncoFinder2/medic/views.py", line 164, in get_context_data
    df_required_paths = df_pms1[path_cols]
  File "/usr/local/lib/python2.7/dist-packages/pandas/core/frame.py", line 1737, in __getitem__
    return self._getitem_array(key)
  File "/usr/local/lib/python2.7/dist-packages/pandas/core/frame.py", line 1781, in _getitem_array
    indexer = self.ix._convert_to_indexer(key, axis=1)
  File "/usr/local/lib/python2.7/dist-packages/pandas/core/indexing.py", line 1135, in _convert_to_indexer
    raise KeyError('%s not in index' % objarr[mask])
KeyError: "['ATM_Pathway_G2.M_Checkpoint_Arrest'\n 'D.galactose_degradation_V_Leloir_pathway'] not in index"
2014-11-24 14:04:39,066 ERROR base 25109 -1297102016 Internal Server Error: /document/doc2543/treat8/
Traceback (most recent call last):
  File "/usr/local/lib/python2.7/dist-packages/django/core/handlers/base.py", line 114, in get_response
    response = wrapped_callback(request, *callback_args, **callback_kwargs)
  File "/usr/local/lib/python2.7/dist-packages/django/views/generic/base.py", line 69, in view
    return self.dispatch(request, *args, **kwargs)
  File "/usr/local/lib/python2.7/dist-packages/django/utils/decorators.py", line 29, in _wrapper
    return bound_func(*args, **kwargs)
  File "/usr/local/lib/python2.7/dist-packages/django/contrib/auth/decorators.py", line 22, in _wrapped_view
    return view_func(request, *args, **kwargs)
  File "/usr/local/lib/python2.7/dist-packages/django/utils/decorators.py", line 25, in bound_func
    return func(self, *args2, **kwargs2)
  File "/home/mikhail/EclipseWorkspace/oncoFinder2/oncoFinder2/medic/views.py", line 143, in dispatch
    return super(PatientTreatmentDetail, self).dispatch(request, *args, **kwargs)
  File "/usr/local/lib/python2.7/dist-packages/django/views/generic/base.py", line 87, in dispatch
    return handler(request, *args, **kwargs)
  File "/home/mikhail/EclipseWorkspace/oncoFinder2/oncoFinder2/medic/views.py", line 289, in post
    context = self.get_context_data(object=self.object)
  File "/home/mikhail/EclipseWorkspace/oncoFinder2/oncoFinder2/medic/views.py", line 164, in get_context_data
    df_required_paths = df_pms1[path_cols]
  File "/usr/local/lib/python2.7/dist-packages/pandas/core/frame.py", line 1737, in __getitem__
    return self._getitem_array(key)
  File "/usr/local/lib/python2.7/dist-packages/pandas/core/frame.py", line 1781, in _getitem_array
    indexer = self.ix._convert_to_indexer(key, axis=1)
  File "/usr/local/lib/python2.7/dist-packages/pandas/core/indexing.py", line 1135, in _convert_to_indexer
    raise KeyError('%s not in index' % objarr[mask])
KeyError: "['L.kynurenine_degradation'] not in index"
2014-11-24 14:04:41,079 ERROR base 25109 -1288701120 Internal Server Error: /document/doc2543/treat11/
Traceback (most recent call last):
  File "/usr/local/lib/python2.7/dist-packages/django/core/handlers/base.py", line 114, in get_response
    response = wrapped_callback(request, *callback_args, **callback_kwargs)
  File "/usr/local/lib/python2.7/dist-packages/django/views/generic/base.py", line 69, in view
    return self.dispatch(request, *args, **kwargs)
  File "/usr/local/lib/python2.7/dist-packages/django/utils/decorators.py", line 29, in _wrapper
    return bound_func(*args, **kwargs)
  File "/usr/local/lib/python2.7/dist-packages/django/contrib/auth/decorators.py", line 22, in _wrapped_view
    return view_func(request, *args, **kwargs)
  File "/usr/local/lib/python2.7/dist-packages/django/utils/decorators.py", line 25, in bound_func
    return func(self, *args2, **kwargs2)
  File "/home/mikhail/EclipseWorkspace/oncoFinder2/oncoFinder2/medic/views.py", line 143, in dispatch
    return super(PatientTreatmentDetail, self).dispatch(request, *args, **kwargs)
  File "/usr/local/lib/python2.7/dist-packages/django/views/generic/base.py", line 87, in dispatch
    return handler(request, *args, **kwargs)
  File "/home/mikhail/EclipseWorkspace/oncoFinder2/oncoFinder2/medic/views.py", line 289, in post
    context = self.get_context_data(object=self.object)
  File "/home/mikhail/EclipseWorkspace/oncoFinder2/oncoFinder2/medic/views.py", line 164, in get_context_data
    df_required_paths = df_pms1[path_cols]
  File "/usr/local/lib/python2.7/dist-packages/pandas/core/frame.py", line 1737, in __getitem__
    return self._getitem_array(key)
  File "/usr/local/lib/python2.7/dist-packages/pandas/core/frame.py", line 1781, in _getitem_array
    indexer = self.ix._convert_to_indexer(key, axis=1)
  File "/usr/local/lib/python2.7/dist-packages/pandas/core/indexing.py", line 1135, in _convert_to_indexer
    raise KeyError('%s not in index' % objarr[mask])
KeyError: "['L.kynurenine_degradation'\n 'sphingosine_and_sphingosine.1.phosphate_metabolism'\n 'tryptophan_degradation_to_2.amino.3.carboxymuconate_semialdehyde'] not in index"
2014-11-24 14:05:27,226 ERROR base 25109 -1333789888 Internal Server Error: /document/doc2543/treat14/
Traceback (most recent call last):
  File "/usr/local/lib/python2.7/dist-packages/django/core/handlers/base.py", line 114, in get_response
    response = wrapped_callback(request, *callback_args, **callback_kwargs)
  File "/usr/local/lib/python2.7/dist-packages/django/views/generic/base.py", line 69, in view
    return self.dispatch(request, *args, **kwargs)
  File "/usr/local/lib/python2.7/dist-packages/django/utils/decorators.py", line 29, in _wrapper
    return bound_func(*args, **kwargs)
  File "/usr/local/lib/python2.7/dist-packages/django/contrib/auth/decorators.py", line 22, in _wrapped_view
    return view_func(request, *args, **kwargs)
  File "/usr/local/lib/python2.7/dist-packages/django/utils/decorators.py", line 25, in bound_func
    return func(self, *args2, **kwargs2)
  File "/home/mikhail/EclipseWorkspace/oncoFinder2/oncoFinder2/medic/views.py", line 143, in dispatch
    return super(PatientTreatmentDetail, self).dispatch(request, *args, **kwargs)
  File "/usr/local/lib/python2.7/dist-packages/django/views/generic/base.py", line 87, in dispatch
    return handler(request, *args, **kwargs)
  File "/home/mikhail/EclipseWorkspace/oncoFinder2/oncoFinder2/medic/views.py", line 289, in post
    context = self.get_context_data(object=self.object)
  File "/home/mikhail/EclipseWorkspace/oncoFinder2/oncoFinder2/medic/views.py", line 164, in get_context_data
    df_required_paths = df_pms1[path_cols]
  File "/usr/local/lib/python2.7/dist-packages/pandas/core/frame.py", line 1737, in __getitem__
    return self._getitem_array(key)
  File "/usr/local/lib/python2.7/dist-packages/pandas/core/frame.py", line 1781, in _getitem_array
    indexer = self.ix._convert_to_indexer(key, axis=1)
  File "/usr/local/lib/python2.7/dist-packages/pandas/core/indexing.py", line 1135, in _convert_to_indexer
    raise KeyError('%s not in index' % objarr[mask])
KeyError: "['sphingosine_and_sphingosine.1.phosphate_metabolism'] not in index"
2014-11-24 14:05:27,917 ERROR base 25109 -1364198592 Internal Server Error: /document/doc2543/treat12/
Traceback (most recent call last):
  File "/usr/local/lib/python2.7/dist-packages/django/core/handlers/base.py", line 114, in get_response
    response = wrapped_callback(request, *callback_args, **callback_kwargs)
  File "/usr/local/lib/python2.7/dist-packages/django/views/generic/base.py", line 69, in view
    return self.dispatch(request, *args, **kwargs)
  File "/usr/local/lib/python2.7/dist-packages/django/utils/decorators.py", line 29, in _wrapper
    return bound_func(*args, **kwargs)
  File "/usr/local/lib/python2.7/dist-packages/django/contrib/auth/decorators.py", line 22, in _wrapped_view
    return view_func(request, *args, **kwargs)
  File "/usr/local/lib/python2.7/dist-packages/django/utils/decorators.py", line 25, in bound_func
    return func(self, *args2, **kwargs2)
  File "/home/mikhail/EclipseWorkspace/oncoFinder2/oncoFinder2/medic/views.py", line 143, in dispatch
    return super(PatientTreatmentDetail, self).dispatch(request, *args, **kwargs)
  File "/usr/local/lib/python2.7/dist-packages/django/views/generic/base.py", line 87, in dispatch
    return handler(request, *args, **kwargs)
  File "/home/mikhail/EclipseWorkspace/oncoFinder2/oncoFinder2/medic/views.py", line 289, in post
    context = self.get_context_data(object=self.object)
  File "/home/mikhail/EclipseWorkspace/oncoFinder2/oncoFinder2/medic/views.py", line 164, in get_context_data
    df_required_paths = df_pms1[path_cols]
  File "/usr/local/lib/python2.7/dist-packages/pandas/core/frame.py", line 1737, in __getitem__
    return self._getitem_array(key)
  File "/usr/local/lib/python2.7/dist-packages/pandas/core/frame.py", line 1781, in _getitem_array
    indexer = self.ix._convert_to_indexer(key, axis=1)
  File "/usr/local/lib/python2.7/dist-packages/pandas/core/indexing.py", line 1135, in _convert_to_indexer
    raise KeyError('%s not in index' % objarr[mask])
KeyError: "['ATM_Pathway_G2.M_Checkpoint_Arrest'\n 'D.galactose_degradation_V_Leloir_pathway'] not in index"
2014-11-24 14:05:28,688 ERROR base 25109 -1444938944 Internal Server Error: /document/doc2543/treat8/
Traceback (most recent call last):
  File "/usr/local/lib/python2.7/dist-packages/django/core/handlers/base.py", line 114, in get_response
    response = wrapped_callback(request, *callback_args, **callback_kwargs)
  File "/usr/local/lib/python2.7/dist-packages/django/views/generic/base.py", line 69, in view
    return self.dispatch(request, *args, **kwargs)
  File "/usr/local/lib/python2.7/dist-packages/django/utils/decorators.py", line 29, in _wrapper
    return bound_func(*args, **kwargs)
  File "/usr/local/lib/python2.7/dist-packages/django/contrib/auth/decorators.py", line 22, in _wrapped_view
    return view_func(request, *args, **kwargs)
  File "/usr/local/lib/python2.7/dist-packages/django/utils/decorators.py", line 25, in bound_func
    return func(self, *args2, **kwargs2)
  File "/home/mikhail/EclipseWorkspace/oncoFinder2/oncoFinder2/medic/views.py", line 143, in dispatch
    return super(PatientTreatmentDetail, self).dispatch(request, *args, **kwargs)
  File "/usr/local/lib/python2.7/dist-packages/django/views/generic/base.py", line 87, in dispatch
    return handler(request, *args, **kwargs)
  File "/home/mikhail/EclipseWorkspace/oncoFinder2/oncoFinder2/medic/views.py", line 289, in post
    context = self.get_context_data(object=self.object)
  File "/home/mikhail/EclipseWorkspace/oncoFinder2/oncoFinder2/medic/views.py", line 164, in get_context_data
    df_required_paths = df_pms1[path_cols]
  File "/usr/local/lib/python2.7/dist-packages/pandas/core/frame.py", line 1737, in __getitem__
    return self._getitem_array(key)
  File "/usr/local/lib/python2.7/dist-packages/pandas/core/frame.py", line 1781, in _getitem_array
    indexer = self.ix._convert_to_indexer(key, axis=1)
  File "/usr/local/lib/python2.7/dist-packages/pandas/core/indexing.py", line 1135, in _convert_to_indexer
    raise KeyError('%s not in index' % objarr[mask])
KeyError: "['L.kynurenine_degradation'] not in index"
2014-11-24 14:05:29,855 ERROR base 25109 -1405093056 Internal Server Error: /document/doc2543/treat11/
Traceback (most recent call last):
  File "/usr/local/lib/python2.7/dist-packages/django/core/handlers/base.py", line 114, in get_response
    response = wrapped_callback(request, *callback_args, **callback_kwargs)
  File "/usr/local/lib/python2.7/dist-packages/django/views/generic/base.py", line 69, in view
    return self.dispatch(request, *args, **kwargs)
  File "/usr/local/lib/python2.7/dist-packages/django/utils/decorators.py", line 29, in _wrapper
    return bound_func(*args, **kwargs)
  File "/usr/local/lib/python2.7/dist-packages/django/contrib/auth/decorators.py", line 22, in _wrapped_view
    return view_func(request, *args, **kwargs)
  File "/usr/local/lib/python2.7/dist-packages/django/utils/decorators.py", line 25, in bound_func
    return func(self, *args2, **kwargs2)
  File "/home/mikhail/EclipseWorkspace/oncoFinder2/oncoFinder2/medic/views.py", line 143, in dispatch
    return super(PatientTreatmentDetail, self).dispatch(request, *args, **kwargs)
  File "/usr/local/lib/python2.7/dist-packages/django/views/generic/base.py", line 87, in dispatch
    return handler(request, *args, **kwargs)
  File "/home/mikhail/EclipseWorkspace/oncoFinder2/oncoFinder2/medic/views.py", line 289, in post
    context = self.get_context_data(object=self.object)
  File "/home/mikhail/EclipseWorkspace/oncoFinder2/oncoFinder2/medic/views.py", line 164, in get_context_data
    df_required_paths = df_pms1[path_cols]
  File "/usr/local/lib/python2.7/dist-packages/pandas/core/frame.py", line 1737, in __getitem__
    return self._getitem_array(key)
  File "/usr/local/lib/python2.7/dist-packages/pandas/core/frame.py", line 1781, in _getitem_array
    indexer = self.ix._convert_to_indexer(key, axis=1)
  File "/usr/local/lib/python2.7/dist-packages/pandas/core/indexing.py", line 1135, in _convert_to_indexer
    raise KeyError('%s not in index' % objarr[mask])
KeyError: "['L.kynurenine_degradation'\n 'sphingosine_and_sphingosine.1.phosphate_metabolism'\n 'tryptophan_degradation_to_2.amino.3.carboxymuconate_semialdehyde'] not in index"
2014-11-24 14:06:18,423 ERROR base 25109 -1543505088 Internal Server Error: /document/doc2543/treat14/
Traceback (most recent call last):
  File "/usr/local/lib/python2.7/dist-packages/django/core/handlers/base.py", line 114, in get_response
    response = wrapped_callback(request, *callback_args, **callback_kwargs)
  File "/usr/local/lib/python2.7/dist-packages/django/views/generic/base.py", line 69, in view
    return self.dispatch(request, *args, **kwargs)
  File "/usr/local/lib/python2.7/dist-packages/django/utils/decorators.py", line 29, in _wrapper
    return bound_func(*args, **kwargs)
  File "/usr/local/lib/python2.7/dist-packages/django/contrib/auth/decorators.py", line 22, in _wrapped_view
    return view_func(request, *args, **kwargs)
  File "/usr/local/lib/python2.7/dist-packages/django/utils/decorators.py", line 25, in bound_func
    return func(self, *args2, **kwargs2)
  File "/home/mikhail/EclipseWorkspace/oncoFinder2/oncoFinder2/medic/views.py", line 143, in dispatch
    return super(PatientTreatmentDetail, self).dispatch(request, *args, **kwargs)
  File "/usr/local/lib/python2.7/dist-packages/django/views/generic/base.py", line 87, in dispatch
    return handler(request, *args, **kwargs)
  File "/home/mikhail/EclipseWorkspace/oncoFinder2/oncoFinder2/medic/views.py", line 289, in post
    context = self.get_context_data(object=self.object)
  File "/home/mikhail/EclipseWorkspace/oncoFinder2/oncoFinder2/medic/views.py", line 164, in get_context_data
    df_required_paths = df_pms1[path_cols]
  File "/usr/local/lib/python2.7/dist-packages/pandas/core/frame.py", line 1737, in __getitem__
    return self._getitem_array(key)
  File "/usr/local/lib/python2.7/dist-packages/pandas/core/frame.py", line 1781, in _getitem_array
    indexer = self.ix._convert_to_indexer(key, axis=1)
  File "/usr/local/lib/python2.7/dist-packages/pandas/core/indexing.py", line 1135, in _convert_to_indexer
    raise KeyError('%s not in index' % objarr[mask])
KeyError: "['sphingosine_and_sphingosine.1.phosphate_metabolism'] not in index"
2014-11-24 14:06:19,244 ERROR base 25109 -1333789888 Internal Server Error: /document/doc2543/treat12/
Traceback (most recent call last):
  File "/usr/local/lib/python2.7/dist-packages/django/core/handlers/base.py", line 114, in get_response
    response = wrapped_callback(request, *callback_args, **callback_kwargs)
  File "/usr/local/lib/python2.7/dist-packages/django/views/generic/base.py", line 69, in view
    return self.dispatch(request, *args, **kwargs)
  File "/usr/local/lib/python2.7/dist-packages/django/utils/decorators.py", line 29, in _wrapper
    return bound_func(*args, **kwargs)
  File "/usr/local/lib/python2.7/dist-packages/django/contrib/auth/decorators.py", line 22, in _wrapped_view
    return view_func(request, *args, **kwargs)
  File "/usr/local/lib/python2.7/dist-packages/django/utils/decorators.py", line 25, in bound_func
    return func(self, *args2, **kwargs2)
  File "/home/mikhail/EclipseWorkspace/oncoFinder2/oncoFinder2/medic/views.py", line 143, in dispatch
    return super(PatientTreatmentDetail, self).dispatch(request, *args, **kwargs)
  File "/usr/local/lib/python2.7/dist-packages/django/views/generic/base.py", line 87, in dispatch
    return handler(request, *args, **kwargs)
  File "/home/mikhail/EclipseWorkspace/oncoFinder2/oncoFinder2/medic/views.py", line 289, in post
    context = self.get_context_data(object=self.object)
  File "/home/mikhail/EclipseWorkspace/oncoFinder2/oncoFinder2/medic/views.py", line 164, in get_context_data
    df_required_paths = df_pms1[path_cols]
  File "/usr/local/lib/python2.7/dist-packages/pandas/core/frame.py", line 1737, in __getitem__
    return self._getitem_array(key)
  File "/usr/local/lib/python2.7/dist-packages/pandas/core/frame.py", line 1781, in _getitem_array
    indexer = self.ix._convert_to_indexer(key, axis=1)
  File "/usr/local/lib/python2.7/dist-packages/pandas/core/indexing.py", line 1135, in _convert_to_indexer
    raise KeyError('%s not in index' % objarr[mask])
KeyError: "['ATM_Pathway_G2.M_Checkpoint_Arrest'\n 'D.galactose_degradation_V_Leloir_pathway'] not in index"
2014-11-24 14:06:19,933 ERROR base 25109 -1364198592 Internal Server Error: /document/doc2543/treat8/
Traceback (most recent call last):
  File "/usr/local/lib/python2.7/dist-packages/django/core/handlers/base.py", line 114, in get_response
    response = wrapped_callback(request, *callback_args, **callback_kwargs)
  File "/usr/local/lib/python2.7/dist-packages/django/views/generic/base.py", line 69, in view
    return self.dispatch(request, *args, **kwargs)
  File "/usr/local/lib/python2.7/dist-packages/django/utils/decorators.py", line 29, in _wrapper
    return bound_func(*args, **kwargs)
  File "/usr/local/lib/python2.7/dist-packages/django/contrib/auth/decorators.py", line 22, in _wrapped_view
    return view_func(request, *args, **kwargs)
  File "/usr/local/lib/python2.7/dist-packages/django/utils/decorators.py", line 25, in bound_func
    return func(self, *args2, **kwargs2)
  File "/home/mikhail/EclipseWorkspace/oncoFinder2/oncoFinder2/medic/views.py", line 143, in dispatch
    return super(PatientTreatmentDetail, self).dispatch(request, *args, **kwargs)
  File "/usr/local/lib/python2.7/dist-packages/django/views/generic/base.py", line 87, in dispatch
    return handler(request, *args, **kwargs)
  File "/home/mikhail/EclipseWorkspace/oncoFinder2/oncoFinder2/medic/views.py", line 289, in post
    context = self.get_context_data(object=self.object)
  File "/home/mikhail/EclipseWorkspace/oncoFinder2/oncoFinder2/medic/views.py", line 164, in get_context_data
    df_required_paths = df_pms1[path_cols]
  File "/usr/local/lib/python2.7/dist-packages/pandas/core/frame.py", line 1737, in __getitem__
    return self._getitem_array(key)
  File "/usr/local/lib/python2.7/dist-packages/pandas/core/frame.py", line 1781, in _getitem_array
    indexer = self.ix._convert_to_indexer(key, axis=1)
  File "/usr/local/lib/python2.7/dist-packages/pandas/core/indexing.py", line 1135, in _convert_to_indexer
    raise KeyError('%s not in index' % objarr[mask])
KeyError: "['L.kynurenine_degradation'] not in index"
2014-11-24 14:06:21,087 ERROR base 25109 -1290798272 Internal Server Error: /document/doc2543/treat11/
Traceback (most recent call last):
  File "/usr/local/lib/python2.7/dist-packages/django/core/handlers/base.py", line 114, in get_response
    response = wrapped_callback(request, *callback_args, **callback_kwargs)
  File "/usr/local/lib/python2.7/dist-packages/django/views/generic/base.py", line 69, in view
    return self.dispatch(request, *args, **kwargs)
  File "/usr/local/lib/python2.7/dist-packages/django/utils/decorators.py", line 29, in _wrapper
    return bound_func(*args, **kwargs)
  File "/usr/local/lib/python2.7/dist-packages/django/contrib/auth/decorators.py", line 22, in _wrapped_view
    return view_func(request, *args, **kwargs)
  File "/usr/local/lib/python2.7/dist-packages/django/utils/decorators.py", line 25, in bound_func
    return func(self, *args2, **kwargs2)
  File "/home/mikhail/EclipseWorkspace/oncoFinder2/oncoFinder2/medic/views.py", line 143, in dispatch
    return super(PatientTreatmentDetail, self).dispatch(request, *args, **kwargs)
  File "/usr/local/lib/python2.7/dist-packages/django/views/generic/base.py", line 87, in dispatch
    return handler(request, *args, **kwargs)
  File "/home/mikhail/EclipseWorkspace/oncoFinder2/oncoFinder2/medic/views.py", line 289, in post
    context = self.get_context_data(object=self.object)
  File "/home/mikhail/EclipseWorkspace/oncoFinder2/oncoFinder2/medic/views.py", line 164, in get_context_data
    df_required_paths = df_pms1[path_cols]
  File "/usr/local/lib/python2.7/dist-packages/pandas/core/frame.py", line 1737, in __getitem__
    return self._getitem_array(key)
  File "/usr/local/lib/python2.7/dist-packages/pandas/core/frame.py", line 1781, in _getitem_array
    indexer = self.ix._convert_to_indexer(key, axis=1)
  File "/usr/local/lib/python2.7/dist-packages/pandas/core/indexing.py", line 1135, in _convert_to_indexer
    raise KeyError('%s not in index' % objarr[mask])
KeyError: "['L.kynurenine_degradation'\n 'sphingosine_and_sphingosine.1.phosphate_metabolism'\n 'tryptophan_degradation_to_2.amino.3.carboxymuconate_semialdehyde'] not in index"
2014-11-24 14:06:47,198 ERROR base 25109 -1543505088 Internal Server Error: /document/doc2543/treat14/
Traceback (most recent call last):
  File "/usr/local/lib/python2.7/dist-packages/django/core/handlers/base.py", line 114, in get_response
    response = wrapped_callback(request, *callback_args, **callback_kwargs)
  File "/usr/local/lib/python2.7/dist-packages/django/views/generic/base.py", line 69, in view
    return self.dispatch(request, *args, **kwargs)
  File "/usr/local/lib/python2.7/dist-packages/django/utils/decorators.py", line 29, in _wrapper
    return bound_func(*args, **kwargs)
  File "/usr/local/lib/python2.7/dist-packages/django/contrib/auth/decorators.py", line 22, in _wrapped_view
    return view_func(request, *args, **kwargs)
  File "/usr/local/lib/python2.7/dist-packages/django/utils/decorators.py", line 25, in bound_func
    return func(self, *args2, **kwargs2)
  File "/home/mikhail/EclipseWorkspace/oncoFinder2/oncoFinder2/medic/views.py", line 143, in dispatch
    return super(PatientTreatmentDetail, self).dispatch(request, *args, **kwargs)
  File "/usr/local/lib/python2.7/dist-packages/django/views/generic/base.py", line 87, in dispatch
    return handler(request, *args, **kwargs)
  File "/home/mikhail/EclipseWorkspace/oncoFinder2/oncoFinder2/medic/views.py", line 289, in post
    context = self.get_context_data(object=self.object)
  File "/home/mikhail/EclipseWorkspace/oncoFinder2/oncoFinder2/medic/views.py", line 164, in get_context_data
    df_required_paths = df_pms1[path_cols]
  File "/usr/local/lib/python2.7/dist-packages/pandas/core/frame.py", line 1737, in __getitem__
    return self._getitem_array(key)
  File "/usr/local/lib/python2.7/dist-packages/pandas/core/frame.py", line 1781, in _getitem_array
    indexer = self.ix._convert_to_indexer(key, axis=1)
  File "/usr/local/lib/python2.7/dist-packages/pandas/core/indexing.py", line 1135, in _convert_to_indexer
    raise KeyError('%s not in index' % objarr[mask])
KeyError: "['sphingosine_and_sphingosine.1.phosphate_metabolism'] not in index"
2014-11-24 14:06:48,034 ERROR base 25109 -1333789888 Internal Server Error: /document/doc2543/treat12/
Traceback (most recent call last):
  File "/usr/local/lib/python2.7/dist-packages/django/core/handlers/base.py", line 114, in get_response
    response = wrapped_callback(request, *callback_args, **callback_kwargs)
  File "/usr/local/lib/python2.7/dist-packages/django/views/generic/base.py", line 69, in view
    return self.dispatch(request, *args, **kwargs)
  File "/usr/local/lib/python2.7/dist-packages/django/utils/decorators.py", line 29, in _wrapper
    return bound_func(*args, **kwargs)
  File "/usr/local/lib/python2.7/dist-packages/django/contrib/auth/decorators.py", line 22, in _wrapped_view
    return view_func(request, *args, **kwargs)
  File "/usr/local/lib/python2.7/dist-packages/django/utils/decorators.py", line 25, in bound_func
    return func(self, *args2, **kwargs2)
  File "/home/mikhail/EclipseWorkspace/oncoFinder2/oncoFinder2/medic/views.py", line 143, in dispatch
    return super(PatientTreatmentDetail, self).dispatch(request, *args, **kwargs)
  File "/usr/local/lib/python2.7/dist-packages/django/views/generic/base.py", line 87, in dispatch
    return handler(request, *args, **kwargs)
  File "/home/mikhail/EclipseWorkspace/oncoFinder2/oncoFinder2/medic/views.py", line 289, in post
    context = self.get_context_data(object=self.object)
  File "/home/mikhail/EclipseWorkspace/oncoFinder2/oncoFinder2/medic/views.py", line 164, in get_context_data
    df_required_paths = df_pms1[path_cols]
  File "/usr/local/lib/python2.7/dist-packages/pandas/core/frame.py", line 1737, in __getitem__
    return self._getitem_array(key)
  File "/usr/local/lib/python2.7/dist-packages/pandas/core/frame.py", line 1781, in _getitem_array
    indexer = self.ix._convert_to_indexer(key, axis=1)
  File "/usr/local/lib/python2.7/dist-packages/pandas/core/indexing.py", line 1135, in _convert_to_indexer
    raise KeyError('%s not in index' % objarr[mask])
KeyError: "['ATM_Pathway_G2.M_Checkpoint_Arrest'\n 'D.galactose_degradation_V_Leloir_pathway'] not in index"
2014-11-24 14:06:49,003 ERROR base 25109 -1581253824 Internal Server Error: /document/doc2543/treat8/
Traceback (most recent call last):
  File "/usr/local/lib/python2.7/dist-packages/django/core/handlers/base.py", line 114, in get_response
    response = wrapped_callback(request, *callback_args, **callback_kwargs)
  File "/usr/local/lib/python2.7/dist-packages/django/views/generic/base.py", line 69, in view
    return self.dispatch(request, *args, **kwargs)
  File "/usr/local/lib/python2.7/dist-packages/django/utils/decorators.py", line 29, in _wrapper
    return bound_func(*args, **kwargs)
  File "/usr/local/lib/python2.7/dist-packages/django/contrib/auth/decorators.py", line 22, in _wrapped_view
    return view_func(request, *args, **kwargs)
  File "/usr/local/lib/python2.7/dist-packages/django/utils/decorators.py", line 25, in bound_func
    return func(self, *args2, **kwargs2)
  File "/home/mikhail/EclipseWorkspace/oncoFinder2/oncoFinder2/medic/views.py", line 143, in dispatch
    return super(PatientTreatmentDetail, self).dispatch(request, *args, **kwargs)
  File "/usr/local/lib/python2.7/dist-packages/django/views/generic/base.py", line 87, in dispatch
    return handler(request, *args, **kwargs)
  File "/home/mikhail/EclipseWorkspace/oncoFinder2/oncoFinder2/medic/views.py", line 289, in post
    context = self.get_context_data(object=self.object)
  File "/home/mikhail/EclipseWorkspace/oncoFinder2/oncoFinder2/medic/views.py", line 164, in get_context_data
    df_required_paths = df_pms1[path_cols]
  File "/usr/local/lib/python2.7/dist-packages/pandas/core/frame.py", line 1737, in __getitem__
    return self._getitem_array(key)
  File "/usr/local/lib/python2.7/dist-packages/pandas/core/frame.py", line 1781, in _getitem_array
    indexer = self.ix._convert_to_indexer(key, axis=1)
  File "/usr/local/lib/python2.7/dist-packages/pandas/core/indexing.py", line 1135, in _convert_to_indexer
    raise KeyError('%s not in index' % objarr[mask])
KeyError: "['L.kynurenine_degradation'] not in index"
2014-11-24 14:06:50,051 ERROR base 25109 -1444938944 Internal Server Error: /document/doc2543/treat11/
Traceback (most recent call last):
  File "/usr/local/lib/python2.7/dist-packages/django/core/handlers/base.py", line 114, in get_response
    response = wrapped_callback(request, *callback_args, **callback_kwargs)
  File "/usr/local/lib/python2.7/dist-packages/django/views/generic/base.py", line 69, in view
    return self.dispatch(request, *args, **kwargs)
  File "/usr/local/lib/python2.7/dist-packages/django/utils/decorators.py", line 29, in _wrapper
    return bound_func(*args, **kwargs)
  File "/usr/local/lib/python2.7/dist-packages/django/contrib/auth/decorators.py", line 22, in _wrapped_view
    return view_func(request, *args, **kwargs)
  File "/usr/local/lib/python2.7/dist-packages/django/utils/decorators.py", line 25, in bound_func
    return func(self, *args2, **kwargs2)
  File "/home/mikhail/EclipseWorkspace/oncoFinder2/oncoFinder2/medic/views.py", line 143, in dispatch
    return super(PatientTreatmentDetail, self).dispatch(request, *args, **kwargs)
  File "/usr/local/lib/python2.7/dist-packages/django/views/generic/base.py", line 87, in dispatch
    return handler(request, *args, **kwargs)
  File "/home/mikhail/EclipseWorkspace/oncoFinder2/oncoFinder2/medic/views.py", line 289, in post
    context = self.get_context_data(object=self.object)
  File "/home/mikhail/EclipseWorkspace/oncoFinder2/oncoFinder2/medic/views.py", line 164, in get_context_data
    df_required_paths = df_pms1[path_cols]
  File "/usr/local/lib/python2.7/dist-packages/pandas/core/frame.py", line 1737, in __getitem__
    return self._getitem_array(key)
  File "/usr/local/lib/python2.7/dist-packages/pandas/core/frame.py", line 1781, in _getitem_array
    indexer = self.ix._convert_to_indexer(key, axis=1)
  File "/usr/local/lib/python2.7/dist-packages/pandas/core/indexing.py", line 1135, in _convert_to_indexer
    raise KeyError('%s not in index' % objarr[mask])
KeyError: "['L.kynurenine_degradation'\n 'sphingosine_and_sphingosine.1.phosphate_metabolism'\n 'tryptophan_degradation_to_2.amino.3.carboxymuconate_semialdehyde'] not in index"
2014-11-24 14:08:47,317 ERROR base 25109 -1616905408 Internal Server Error: /document/doc2543/treat14/
Traceback (most recent call last):
  File "/usr/local/lib/python2.7/dist-packages/django/core/handlers/base.py", line 114, in get_response
    response = wrapped_callback(request, *callback_args, **callback_kwargs)
  File "/usr/local/lib/python2.7/dist-packages/django/views/generic/base.py", line 69, in view
    return self.dispatch(request, *args, **kwargs)
  File "/usr/local/lib/python2.7/dist-packages/django/utils/decorators.py", line 29, in _wrapper
    return bound_func(*args, **kwargs)
  File "/usr/local/lib/python2.7/dist-packages/django/contrib/auth/decorators.py", line 22, in _wrapped_view
    return view_func(request, *args, **kwargs)
  File "/usr/local/lib/python2.7/dist-packages/django/utils/decorators.py", line 25, in bound_func
    return func(self, *args2, **kwargs2)
  File "/home/mikhail/EclipseWorkspace/oncoFinder2/oncoFinder2/medic/views.py", line 143, in dispatch
    return super(PatientTreatmentDetail, self).dispatch(request, *args, **kwargs)
  File "/usr/local/lib/python2.7/dist-packages/django/views/generic/base.py", line 87, in dispatch
    return handler(request, *args, **kwargs)
  File "/home/mikhail/EclipseWorkspace/oncoFinder2/oncoFinder2/medic/views.py", line 289, in post
    context = self.get_context_data(object=self.object)
  File "/home/mikhail/EclipseWorkspace/oncoFinder2/oncoFinder2/medic/views.py", line 164, in get_context_data
    df_required_paths = df_pms1[path_cols]
  File "/usr/local/lib/python2.7/dist-packages/pandas/core/frame.py", line 1737, in __getitem__
    return self._getitem_array(key)
  File "/usr/local/lib/python2.7/dist-packages/pandas/core/frame.py", line 1781, in _getitem_array
    indexer = self.ix._convert_to_indexer(key, axis=1)
  File "/usr/local/lib/python2.7/dist-packages/pandas/core/indexing.py", line 1135, in _convert_to_indexer
    raise KeyError('%s not in index' % objarr[mask])
KeyError: "['sphingosine_and_sphingosine.1.phosphate_metabolism'] not in index"
2014-11-24 14:08:48,052 ERROR base 25109 -1543505088 Internal Server Error: /document/doc2543/treat12/
Traceback (most recent call last):
  File "/usr/local/lib/python2.7/dist-packages/django/core/handlers/base.py", line 114, in get_response
    response = wrapped_callback(request, *callback_args, **callback_kwargs)
  File "/usr/local/lib/python2.7/dist-packages/django/views/generic/base.py", line 69, in view
    return self.dispatch(request, *args, **kwargs)
  File "/usr/local/lib/python2.7/dist-packages/django/utils/decorators.py", line 29, in _wrapper
    return bound_func(*args, **kwargs)
  File "/usr/local/lib/python2.7/dist-packages/django/contrib/auth/decorators.py", line 22, in _wrapped_view
    return view_func(request, *args, **kwargs)
  File "/usr/local/lib/python2.7/dist-packages/django/utils/decorators.py", line 25, in bound_func
    return func(self, *args2, **kwargs2)
  File "/home/mikhail/EclipseWorkspace/oncoFinder2/oncoFinder2/medic/views.py", line 143, in dispatch
    return super(PatientTreatmentDetail, self).dispatch(request, *args, **kwargs)
  File "/usr/local/lib/python2.7/dist-packages/django/views/generic/base.py", line 87, in dispatch
    return handler(request, *args, **kwargs)
  File "/home/mikhail/EclipseWorkspace/oncoFinder2/oncoFinder2/medic/views.py", line 289, in post
    context = self.get_context_data(object=self.object)
  File "/home/mikhail/EclipseWorkspace/oncoFinder2/oncoFinder2/medic/views.py", line 164, in get_context_data
    df_required_paths = df_pms1[path_cols]
  File "/usr/local/lib/python2.7/dist-packages/pandas/core/frame.py", line 1737, in __getitem__
    return self._getitem_array(key)
  File "/usr/local/lib/python2.7/dist-packages/pandas/core/frame.py", line 1781, in _getitem_array
    indexer = self.ix._convert_to_indexer(key, axis=1)
  File "/usr/local/lib/python2.7/dist-packages/pandas/core/indexing.py", line 1135, in _convert_to_indexer
    raise KeyError('%s not in index' % objarr[mask])
KeyError: "['ATM_Pathway_G2.M_Checkpoint_Arrest'\n 'D.galactose_degradation_V_Leloir_pathway'] not in index"
2014-11-24 14:08:49,052 ERROR base 25109 -1333789888 Internal Server Error: /document/doc2543/treat8/
Traceback (most recent call last):
  File "/usr/local/lib/python2.7/dist-packages/django/core/handlers/base.py", line 114, in get_response
    response = wrapped_callback(request, *callback_args, **callback_kwargs)
  File "/usr/local/lib/python2.7/dist-packages/django/views/generic/base.py", line 69, in view
    return self.dispatch(request, *args, **kwargs)
  File "/usr/local/lib/python2.7/dist-packages/django/utils/decorators.py", line 29, in _wrapper
    return bound_func(*args, **kwargs)
  File "/usr/local/lib/python2.7/dist-packages/django/contrib/auth/decorators.py", line 22, in _wrapped_view
    return view_func(request, *args, **kwargs)
  File "/usr/local/lib/python2.7/dist-packages/django/utils/decorators.py", line 25, in bound_func
    return func(self, *args2, **kwargs2)
  File "/home/mikhail/EclipseWorkspace/oncoFinder2/oncoFinder2/medic/views.py", line 143, in dispatch
    return super(PatientTreatmentDetail, self).dispatch(request, *args, **kwargs)
  File "/usr/local/lib/python2.7/dist-packages/django/views/generic/base.py", line 87, in dispatch
    return handler(request, *args, **kwargs)
  File "/home/mikhail/EclipseWorkspace/oncoFinder2/oncoFinder2/medic/views.py", line 289, in post
    context = self.get_context_data(object=self.object)
  File "/home/mikhail/EclipseWorkspace/oncoFinder2/oncoFinder2/medic/views.py", line 164, in get_context_data
    df_required_paths = df_pms1[path_cols]
  File "/usr/local/lib/python2.7/dist-packages/pandas/core/frame.py", line 1737, in __getitem__
    return self._getitem_array(key)
  File "/usr/local/lib/python2.7/dist-packages/pandas/core/frame.py", line 1781, in _getitem_array
    indexer = self.ix._convert_to_indexer(key, axis=1)
  File "/usr/local/lib/python2.7/dist-packages/pandas/core/indexing.py", line 1135, in _convert_to_indexer
    raise KeyError('%s not in index' % objarr[mask])
KeyError: "['L.kynurenine_degradation'] not in index"
2014-11-24 14:08:50,620 ERROR base 25109 -1364198592 Internal Server Error: /document/doc2543/treat11/
Traceback (most recent call last):
  File "/usr/local/lib/python2.7/dist-packages/django/core/handlers/base.py", line 114, in get_response
    response = wrapped_callback(request, *callback_args, **callback_kwargs)
  File "/usr/local/lib/python2.7/dist-packages/django/views/generic/base.py", line 69, in view
    return self.dispatch(request, *args, **kwargs)
  File "/usr/local/lib/python2.7/dist-packages/django/utils/decorators.py", line 29, in _wrapper
    return bound_func(*args, **kwargs)
  File "/usr/local/lib/python2.7/dist-packages/django/contrib/auth/decorators.py", line 22, in _wrapped_view
    return view_func(request, *args, **kwargs)
  File "/usr/local/lib/python2.7/dist-packages/django/utils/decorators.py", line 25, in bound_func
    return func(self, *args2, **kwargs2)
  File "/home/mikhail/EclipseWorkspace/oncoFinder2/oncoFinder2/medic/views.py", line 143, in dispatch
    return super(PatientTreatmentDetail, self).dispatch(request, *args, **kwargs)
  File "/usr/local/lib/python2.7/dist-packages/django/views/generic/base.py", line 87, in dispatch
    return handler(request, *args, **kwargs)
  File "/home/mikhail/EclipseWorkspace/oncoFinder2/oncoFinder2/medic/views.py", line 289, in post
    context = self.get_context_data(object=self.object)
  File "/home/mikhail/EclipseWorkspace/oncoFinder2/oncoFinder2/medic/views.py", line 164, in get_context_data
    df_required_paths = df_pms1[path_cols]
  File "/usr/local/lib/python2.7/dist-packages/pandas/core/frame.py", line 1737, in __getitem__
    return self._getitem_array(key)
  File "/usr/local/lib/python2.7/dist-packages/pandas/core/frame.py", line 1781, in _getitem_array
    indexer = self.ix._convert_to_indexer(key, axis=1)
  File "/usr/local/lib/python2.7/dist-packages/pandas/core/indexing.py", line 1135, in _convert_to_indexer
    raise KeyError('%s not in index' % objarr[mask])
KeyError: "['L.kynurenine_degradation'\n 'sphingosine_and_sphingosine.1.phosphate_metabolism'\n 'tryptophan_degradation_to_2.amino.3.carboxymuconate_semialdehyde'] not in index"
2014-11-24 14:09:37,762 ERROR base 25109 -1581253824 Internal Server Error: /document/doc2543/treat14/
Traceback (most recent call last):
  File "/usr/local/lib/python2.7/dist-packages/django/core/handlers/base.py", line 114, in get_response
    response = wrapped_callback(request, *callback_args, **callback_kwargs)
  File "/usr/local/lib/python2.7/dist-packages/django/views/generic/base.py", line 69, in view
    return self.dispatch(request, *args, **kwargs)
  File "/usr/local/lib/python2.7/dist-packages/django/utils/decorators.py", line 29, in _wrapper
    return bound_func(*args, **kwargs)
  File "/usr/local/lib/python2.7/dist-packages/django/contrib/auth/decorators.py", line 22, in _wrapped_view
    return view_func(request, *args, **kwargs)
  File "/usr/local/lib/python2.7/dist-packages/django/utils/decorators.py", line 25, in bound_func
    return func(self, *args2, **kwargs2)
  File "/home/mikhail/EclipseWorkspace/oncoFinder2/oncoFinder2/medic/views.py", line 143, in dispatch
    return super(PatientTreatmentDetail, self).dispatch(request, *args, **kwargs)
  File "/usr/local/lib/python2.7/dist-packages/django/views/generic/base.py", line 87, in dispatch
    return handler(request, *args, **kwargs)
  File "/home/mikhail/EclipseWorkspace/oncoFinder2/oncoFinder2/medic/views.py", line 289, in post
    context = self.get_context_data(object=self.object)
  File "/home/mikhail/EclipseWorkspace/oncoFinder2/oncoFinder2/medic/views.py", line 164, in get_context_data
    df_required_paths = df_pms1[path_cols]
  File "/usr/local/lib/python2.7/dist-packages/pandas/core/frame.py", line 1737, in __getitem__
    return self._getitem_array(key)
  File "/usr/local/lib/python2.7/dist-packages/pandas/core/frame.py", line 1781, in _getitem_array
    indexer = self.ix._convert_to_indexer(key, axis=1)
  File "/usr/local/lib/python2.7/dist-packages/pandas/core/indexing.py", line 1135, in _convert_to_indexer
    raise KeyError('%s not in index' % objarr[mask])
KeyError: "['sphingosine_and_sphingosine.1.phosphate_metabolism'] not in index"
2014-11-24 14:09:38,484 ERROR base 25109 -1616905408 Internal Server Error: /document/doc2543/treat12/
Traceback (most recent call last):
  File "/usr/local/lib/python2.7/dist-packages/django/core/handlers/base.py", line 114, in get_response
    response = wrapped_callback(request, *callback_args, **callback_kwargs)
  File "/usr/local/lib/python2.7/dist-packages/django/views/generic/base.py", line 69, in view
    return self.dispatch(request, *args, **kwargs)
  File "/usr/local/lib/python2.7/dist-packages/django/utils/decorators.py", line 29, in _wrapper
    return bound_func(*args, **kwargs)
  File "/usr/local/lib/python2.7/dist-packages/django/contrib/auth/decorators.py", line 22, in _wrapped_view
    return view_func(request, *args, **kwargs)
  File "/usr/local/lib/python2.7/dist-packages/django/utils/decorators.py", line 25, in bound_func
    return func(self, *args2, **kwargs2)
  File "/home/mikhail/EclipseWorkspace/oncoFinder2/oncoFinder2/medic/views.py", line 143, in dispatch
    return super(PatientTreatmentDetail, self).dispatch(request, *args, **kwargs)
  File "/usr/local/lib/python2.7/dist-packages/django/views/generic/base.py", line 87, in dispatch
    return handler(request, *args, **kwargs)
  File "/home/mikhail/EclipseWorkspace/oncoFinder2/oncoFinder2/medic/views.py", line 289, in post
    context = self.get_context_data(object=self.object)
  File "/home/mikhail/EclipseWorkspace/oncoFinder2/oncoFinder2/medic/views.py", line 164, in get_context_data
    df_required_paths = df_pms1[path_cols]
  File "/usr/local/lib/python2.7/dist-packages/pandas/core/frame.py", line 1737, in __getitem__
    return self._getitem_array(key)
  File "/usr/local/lib/python2.7/dist-packages/pandas/core/frame.py", line 1781, in _getitem_array
    indexer = self.ix._convert_to_indexer(key, axis=1)
  File "/usr/local/lib/python2.7/dist-packages/pandas/core/indexing.py", line 1135, in _convert_to_indexer
    raise KeyError('%s not in index' % objarr[mask])
KeyError: "['ATM_Pathway_G2.M_Checkpoint_Arrest'\n 'D.galactose_degradation_V_Leloir_pathway'] not in index"
2014-11-24 14:09:39,444 ERROR base 25109 -1625298112 Internal Server Error: /document/doc2543/treat8/
Traceback (most recent call last):
  File "/usr/local/lib/python2.7/dist-packages/django/core/handlers/base.py", line 114, in get_response
    response = wrapped_callback(request, *callback_args, **callback_kwargs)
  File "/usr/local/lib/python2.7/dist-packages/django/views/generic/base.py", line 69, in view
    return self.dispatch(request, *args, **kwargs)
  File "/usr/local/lib/python2.7/dist-packages/django/utils/decorators.py", line 29, in _wrapper
    return bound_func(*args, **kwargs)
  File "/usr/local/lib/python2.7/dist-packages/django/contrib/auth/decorators.py", line 22, in _wrapped_view
    return view_func(request, *args, **kwargs)
  File "/usr/local/lib/python2.7/dist-packages/django/utils/decorators.py", line 25, in bound_func
    return func(self, *args2, **kwargs2)
  File "/home/mikhail/EclipseWorkspace/oncoFinder2/oncoFinder2/medic/views.py", line 143, in dispatch
    return super(PatientTreatmentDetail, self).dispatch(request, *args, **kwargs)
  File "/usr/local/lib/python2.7/dist-packages/django/views/generic/base.py", line 87, in dispatch
    return handler(request, *args, **kwargs)
  File "/home/mikhail/EclipseWorkspace/oncoFinder2/oncoFinder2/medic/views.py", line 289, in post
    context = self.get_context_data(object=self.object)
  File "/home/mikhail/EclipseWorkspace/oncoFinder2/oncoFinder2/medic/views.py", line 164, in get_context_data
    df_required_paths = df_pms1[path_cols]
  File "/usr/local/lib/python2.7/dist-packages/pandas/core/frame.py", line 1737, in __getitem__
    return self._getitem_array(key)
  File "/usr/local/lib/python2.7/dist-packages/pandas/core/frame.py", line 1781, in _getitem_array
    indexer = self.ix._convert_to_indexer(key, axis=1)
  File "/usr/local/lib/python2.7/dist-packages/pandas/core/indexing.py", line 1135, in _convert_to_indexer
    raise KeyError('%s not in index' % objarr[mask])
KeyError: "['L.kynurenine_degradation'] not in index"
2014-11-24 14:09:40,582 ERROR base 25109 -1543505088 Internal Server Error: /document/doc2543/treat11/
Traceback (most recent call last):
  File "/usr/local/lib/python2.7/dist-packages/django/core/handlers/base.py", line 114, in get_response
    response = wrapped_callback(request, *callback_args, **callback_kwargs)
  File "/usr/local/lib/python2.7/dist-packages/django/views/generic/base.py", line 69, in view
    return self.dispatch(request, *args, **kwargs)
  File "/usr/local/lib/python2.7/dist-packages/django/utils/decorators.py", line 29, in _wrapper
    return bound_func(*args, **kwargs)
  File "/usr/local/lib/python2.7/dist-packages/django/contrib/auth/decorators.py", line 22, in _wrapped_view
    return view_func(request, *args, **kwargs)
  File "/usr/local/lib/python2.7/dist-packages/django/utils/decorators.py", line 25, in bound_func
    return func(self, *args2, **kwargs2)
  File "/home/mikhail/EclipseWorkspace/oncoFinder2/oncoFinder2/medic/views.py", line 143, in dispatch
    return super(PatientTreatmentDetail, self).dispatch(request, *args, **kwargs)
  File "/usr/local/lib/python2.7/dist-packages/django/views/generic/base.py", line 87, in dispatch
    return handler(request, *args, **kwargs)
  File "/home/mikhail/EclipseWorkspace/oncoFinder2/oncoFinder2/medic/views.py", line 289, in post
    context = self.get_context_data(object=self.object)
  File "/home/mikhail/EclipseWorkspace/oncoFinder2/oncoFinder2/medic/views.py", line 164, in get_context_data
    df_required_paths = df_pms1[path_cols]
  File "/usr/local/lib/python2.7/dist-packages/pandas/core/frame.py", line 1737, in __getitem__
    return self._getitem_array(key)
  File "/usr/local/lib/python2.7/dist-packages/pandas/core/frame.py", line 1781, in _getitem_array
    indexer = self.ix._convert_to_indexer(key, axis=1)
  File "/usr/local/lib/python2.7/dist-packages/pandas/core/indexing.py", line 1135, in _convert_to_indexer
    raise KeyError('%s not in index' % objarr[mask])
KeyError: "['L.kynurenine_degradation'\n 'sphingosine_and_sphingosine.1.phosphate_metabolism'\n 'tryptophan_degradation_to_2.amino.3.carboxymuconate_semialdehyde'] not in index"
2014-11-24 14:11:57,679 ERROR base 25109 -1364198592 Internal Server Error: /document/doc2543/treat14/
Traceback (most recent call last):
  File "/usr/local/lib/python2.7/dist-packages/django/core/handlers/base.py", line 114, in get_response
    response = wrapped_callback(request, *callback_args, **callback_kwargs)
  File "/usr/local/lib/python2.7/dist-packages/django/views/generic/base.py", line 69, in view
    return self.dispatch(request, *args, **kwargs)
  File "/usr/local/lib/python2.7/dist-packages/django/utils/decorators.py", line 29, in _wrapper
    return bound_func(*args, **kwargs)
  File "/usr/local/lib/python2.7/dist-packages/django/contrib/auth/decorators.py", line 22, in _wrapped_view
    return view_func(request, *args, **kwargs)
  File "/usr/local/lib/python2.7/dist-packages/django/utils/decorators.py", line 25, in bound_func
    return func(self, *args2, **kwargs2)
  File "/home/mikhail/EclipseWorkspace/oncoFinder2/oncoFinder2/medic/views.py", line 143, in dispatch
    return super(PatientTreatmentDetail, self).dispatch(request, *args, **kwargs)
  File "/usr/local/lib/python2.7/dist-packages/django/views/generic/base.py", line 87, in dispatch
    return handler(request, *args, **kwargs)
  File "/home/mikhail/EclipseWorkspace/oncoFinder2/oncoFinder2/medic/views.py", line 289, in post
    context = self.get_context_data(object=self.object)
  File "/home/mikhail/EclipseWorkspace/oncoFinder2/oncoFinder2/medic/views.py", line 164, in get_context_data
    df_required_paths = df_pms1[path_cols]
  File "/usr/local/lib/python2.7/dist-packages/pandas/core/frame.py", line 1737, in __getitem__
    return self._getitem_array(key)
  File "/usr/local/lib/python2.7/dist-packages/pandas/core/frame.py", line 1781, in _getitem_array
    indexer = self.ix._convert_to_indexer(key, axis=1)
  File "/usr/local/lib/python2.7/dist-packages/pandas/core/indexing.py", line 1135, in _convert_to_indexer
    raise KeyError('%s not in index' % objarr[mask])
KeyError: "['sphingosine_and_sphingosine.1.phosphate_metabolism'] not in index"
2014-11-24 14:11:58,468 ERROR base 25109 -1616905408 Internal Server Error: /document/doc2543/treat12/
Traceback (most recent call last):
  File "/usr/local/lib/python2.7/dist-packages/django/core/handlers/base.py", line 114, in get_response
    response = wrapped_callback(request, *callback_args, **callback_kwargs)
  File "/usr/local/lib/python2.7/dist-packages/django/views/generic/base.py", line 69, in view
    return self.dispatch(request, *args, **kwargs)
  File "/usr/local/lib/python2.7/dist-packages/django/utils/decorators.py", line 29, in _wrapper
    return bound_func(*args, **kwargs)
  File "/usr/local/lib/python2.7/dist-packages/django/contrib/auth/decorators.py", line 22, in _wrapped_view
    return view_func(request, *args, **kwargs)
  File "/usr/local/lib/python2.7/dist-packages/django/utils/decorators.py", line 25, in bound_func
    return func(self, *args2, **kwargs2)
  File "/home/mikhail/EclipseWorkspace/oncoFinder2/oncoFinder2/medic/views.py", line 143, in dispatch
    return super(PatientTreatmentDetail, self).dispatch(request, *args, **kwargs)
  File "/usr/local/lib/python2.7/dist-packages/django/views/generic/base.py", line 87, in dispatch
    return handler(request, *args, **kwargs)
  File "/home/mikhail/EclipseWorkspace/oncoFinder2/oncoFinder2/medic/views.py", line 289, in post
    context = self.get_context_data(object=self.object)
  File "/home/mikhail/EclipseWorkspace/oncoFinder2/oncoFinder2/medic/views.py", line 164, in get_context_data
    df_required_paths = df_pms1[path_cols]
  File "/usr/local/lib/python2.7/dist-packages/pandas/core/frame.py", line 1737, in __getitem__
    return self._getitem_array(key)
  File "/usr/local/lib/python2.7/dist-packages/pandas/core/frame.py", line 1781, in _getitem_array
    indexer = self.ix._convert_to_indexer(key, axis=1)
  File "/usr/local/lib/python2.7/dist-packages/pandas/core/indexing.py", line 1135, in _convert_to_indexer
    raise KeyError('%s not in index' % objarr[mask])
KeyError: "['ATM_Pathway_G2.M_Checkpoint_Arrest'\n 'D.galactose_degradation_V_Leloir_pathway'] not in index"
2014-11-24 14:11:58,990 ERROR base 25109 -1625298112 Internal Server Error: /document/doc2543/treat8/
Traceback (most recent call last):
  File "/usr/local/lib/python2.7/dist-packages/django/core/handlers/base.py", line 114, in get_response
    response = wrapped_callback(request, *callback_args, **callback_kwargs)
  File "/usr/local/lib/python2.7/dist-packages/django/views/generic/base.py", line 69, in view
    return self.dispatch(request, *args, **kwargs)
  File "/usr/local/lib/python2.7/dist-packages/django/utils/decorators.py", line 29, in _wrapper
    return bound_func(*args, **kwargs)
  File "/usr/local/lib/python2.7/dist-packages/django/contrib/auth/decorators.py", line 22, in _wrapped_view
    return view_func(request, *args, **kwargs)
  File "/usr/local/lib/python2.7/dist-packages/django/utils/decorators.py", line 25, in bound_func
    return func(self, *args2, **kwargs2)
  File "/home/mikhail/EclipseWorkspace/oncoFinder2/oncoFinder2/medic/views.py", line 143, in dispatch
    return super(PatientTreatmentDetail, self).dispatch(request, *args, **kwargs)
  File "/usr/local/lib/python2.7/dist-packages/django/views/generic/base.py", line 87, in dispatch
    return handler(request, *args, **kwargs)
  File "/home/mikhail/EclipseWorkspace/oncoFinder2/oncoFinder2/medic/views.py", line 289, in post
    context = self.get_context_data(object=self.object)
  File "/home/mikhail/EclipseWorkspace/oncoFinder2/oncoFinder2/medic/views.py", line 164, in get_context_data
    df_required_paths = df_pms1[path_cols]
  File "/usr/local/lib/python2.7/dist-packages/pandas/core/frame.py", line 1737, in __getitem__
    return self._getitem_array(key)
  File "/usr/local/lib/python2.7/dist-packages/pandas/core/frame.py", line 1781, in _getitem_array
    indexer = self.ix._convert_to_indexer(key, axis=1)
  File "/usr/local/lib/python2.7/dist-packages/pandas/core/indexing.py", line 1135, in _convert_to_indexer
    raise KeyError('%s not in index' % objarr[mask])
KeyError: "['L.kynurenine_degradation'] not in index"
2014-11-24 14:12:00,385 ERROR base 25109 -1690305728 Internal Server Error: /document/doc2543/treat11/
Traceback (most recent call last):
  File "/usr/local/lib/python2.7/dist-packages/django/core/handlers/base.py", line 114, in get_response
    response = wrapped_callback(request, *callback_args, **callback_kwargs)
  File "/usr/local/lib/python2.7/dist-packages/django/views/generic/base.py", line 69, in view
    return self.dispatch(request, *args, **kwargs)
  File "/usr/local/lib/python2.7/dist-packages/django/utils/decorators.py", line 29, in _wrapper
    return bound_func(*args, **kwargs)
  File "/usr/local/lib/python2.7/dist-packages/django/contrib/auth/decorators.py", line 22, in _wrapped_view
    return view_func(request, *args, **kwargs)
  File "/usr/local/lib/python2.7/dist-packages/django/utils/decorators.py", line 25, in bound_func
    return func(self, *args2, **kwargs2)
  File "/home/mikhail/EclipseWorkspace/oncoFinder2/oncoFinder2/medic/views.py", line 143, in dispatch
    return super(PatientTreatmentDetail, self).dispatch(request, *args, **kwargs)
  File "/usr/local/lib/python2.7/dist-packages/django/views/generic/base.py", line 87, in dispatch
    return handler(request, *args, **kwargs)
  File "/home/mikhail/EclipseWorkspace/oncoFinder2/oncoFinder2/medic/views.py", line 289, in post
    context = self.get_context_data(object=self.object)
  File "/home/mikhail/EclipseWorkspace/oncoFinder2/oncoFinder2/medic/views.py", line 164, in get_context_data
    df_required_paths = df_pms1[path_cols]
  File "/usr/local/lib/python2.7/dist-packages/pandas/core/frame.py", line 1737, in __getitem__
    return self._getitem_array(key)
  File "/usr/local/lib/python2.7/dist-packages/pandas/core/frame.py", line 1781, in _getitem_array
    indexer = self.ix._convert_to_indexer(key, axis=1)
  File "/usr/local/lib/python2.7/dist-packages/pandas/core/indexing.py", line 1135, in _convert_to_indexer
    raise KeyError('%s not in index' % objarr[mask])
KeyError: "['L.kynurenine_degradation'\n 'sphingosine_and_sphingosine.1.phosphate_metabolism'\n 'tryptophan_degradation_to_2.amino.3.carboxymuconate_semialdehyde'] not in index"
2014-11-24 14:13:09,976 ERROR base 25109 -1736443072 Internal Server Error: /document/doc2543/treat14/
Traceback (most recent call last):
  File "/usr/local/lib/python2.7/dist-packages/django/core/handlers/base.py", line 114, in get_response
    response = wrapped_callback(request, *callback_args, **callback_kwargs)
  File "/usr/local/lib/python2.7/dist-packages/django/views/generic/base.py", line 69, in view
    return self.dispatch(request, *args, **kwargs)
  File "/usr/local/lib/python2.7/dist-packages/django/utils/decorators.py", line 29, in _wrapper
    return bound_func(*args, **kwargs)
  File "/usr/local/lib/python2.7/dist-packages/django/contrib/auth/decorators.py", line 22, in _wrapped_view
    return view_func(request, *args, **kwargs)
  File "/usr/local/lib/python2.7/dist-packages/django/utils/decorators.py", line 25, in bound_func
    return func(self, *args2, **kwargs2)
  File "/home/mikhail/EclipseWorkspace/oncoFinder2/oncoFinder2/medic/views.py", line 143, in dispatch
    return super(PatientTreatmentDetail, self).dispatch(request, *args, **kwargs)
  File "/usr/local/lib/python2.7/dist-packages/django/views/generic/base.py", line 87, in dispatch
    return handler(request, *args, **kwargs)
  File "/home/mikhail/EclipseWorkspace/oncoFinder2/oncoFinder2/medic/views.py", line 289, in post
    context = self.get_context_data(object=self.object)
  File "/home/mikhail/EclipseWorkspace/oncoFinder2/oncoFinder2/medic/views.py", line 164, in get_context_data
    df_required_paths = df_pms1[path_cols]
  File "/usr/local/lib/python2.7/dist-packages/pandas/core/frame.py", line 1737, in __getitem__
    return self._getitem_array(key)
  File "/usr/local/lib/python2.7/dist-packages/pandas/core/frame.py", line 1781, in _getitem_array
    indexer = self.ix._convert_to_indexer(key, axis=1)
  File "/usr/local/lib/python2.7/dist-packages/pandas/core/indexing.py", line 1135, in _convert_to_indexer
    raise KeyError('%s not in index' % objarr[mask])
KeyError: "['sphingosine_and_sphingosine.1.phosphate_metabolism'] not in index"
2014-11-24 14:13:10,810 ERROR base 25109 -1581253824 Internal Server Error: /document/doc2543/treat12/
Traceback (most recent call last):
  File "/usr/local/lib/python2.7/dist-packages/django/core/handlers/base.py", line 114, in get_response
    response = wrapped_callback(request, *callback_args, **callback_kwargs)
  File "/usr/local/lib/python2.7/dist-packages/django/views/generic/base.py", line 69, in view
    return self.dispatch(request, *args, **kwargs)
  File "/usr/local/lib/python2.7/dist-packages/django/utils/decorators.py", line 29, in _wrapper
    return bound_func(*args, **kwargs)
  File "/usr/local/lib/python2.7/dist-packages/django/contrib/auth/decorators.py", line 22, in _wrapped_view
    return view_func(request, *args, **kwargs)
  File "/usr/local/lib/python2.7/dist-packages/django/utils/decorators.py", line 25, in bound_func
    return func(self, *args2, **kwargs2)
  File "/home/mikhail/EclipseWorkspace/oncoFinder2/oncoFinder2/medic/views.py", line 143, in dispatch
    return super(PatientTreatmentDetail, self).dispatch(request, *args, **kwargs)
  File "/usr/local/lib/python2.7/dist-packages/django/views/generic/base.py", line 87, in dispatch
    return handler(request, *args, **kwargs)
  File "/home/mikhail/EclipseWorkspace/oncoFinder2/oncoFinder2/medic/views.py", line 289, in post
    context = self.get_context_data(object=self.object)
  File "/home/mikhail/EclipseWorkspace/oncoFinder2/oncoFinder2/medic/views.py", line 164, in get_context_data
    df_required_paths = df_pms1[path_cols]
  File "/usr/local/lib/python2.7/dist-packages/pandas/core/frame.py", line 1737, in __getitem__
    return self._getitem_array(key)
  File "/usr/local/lib/python2.7/dist-packages/pandas/core/frame.py", line 1781, in _getitem_array
    indexer = self.ix._convert_to_indexer(key, axis=1)
  File "/usr/local/lib/python2.7/dist-packages/pandas/core/indexing.py", line 1135, in _convert_to_indexer
    raise KeyError('%s not in index' % objarr[mask])
KeyError: "['ATM_Pathway_G2.M_Checkpoint_Arrest'\n 'D.galactose_degradation_V_Leloir_pathway'] not in index"
2014-11-24 14:13:11,494 ERROR base 25109 -1616905408 Internal Server Error: /document/doc2543/treat8/
Traceback (most recent call last):
  File "/usr/local/lib/python2.7/dist-packages/django/core/handlers/base.py", line 114, in get_response
    response = wrapped_callback(request, *callback_args, **callback_kwargs)
  File "/usr/local/lib/python2.7/dist-packages/django/views/generic/base.py", line 69, in view
    return self.dispatch(request, *args, **kwargs)
  File "/usr/local/lib/python2.7/dist-packages/django/utils/decorators.py", line 29, in _wrapper
    return bound_func(*args, **kwargs)
  File "/usr/local/lib/python2.7/dist-packages/django/contrib/auth/decorators.py", line 22, in _wrapped_view
    return view_func(request, *args, **kwargs)
  File "/usr/local/lib/python2.7/dist-packages/django/utils/decorators.py", line 25, in bound_func
    return func(self, *args2, **kwargs2)
  File "/home/mikhail/EclipseWorkspace/oncoFinder2/oncoFinder2/medic/views.py", line 143, in dispatch
    return super(PatientTreatmentDetail, self).dispatch(request, *args, **kwargs)
  File "/usr/local/lib/python2.7/dist-packages/django/views/generic/base.py", line 87, in dispatch
    return handler(request, *args, **kwargs)
  File "/home/mikhail/EclipseWorkspace/oncoFinder2/oncoFinder2/medic/views.py", line 289, in post
    context = self.get_context_data(object=self.object)
  File "/home/mikhail/EclipseWorkspace/oncoFinder2/oncoFinder2/medic/views.py", line 164, in get_context_data
    df_required_paths = df_pms1[path_cols]
  File "/usr/local/lib/python2.7/dist-packages/pandas/core/frame.py", line 1737, in __getitem__
    return self._getitem_array(key)
  File "/usr/local/lib/python2.7/dist-packages/pandas/core/frame.py", line 1781, in _getitem_array
    indexer = self.ix._convert_to_indexer(key, axis=1)
  File "/usr/local/lib/python2.7/dist-packages/pandas/core/indexing.py", line 1135, in _convert_to_indexer
    raise KeyError('%s not in index' % objarr[mask])
KeyError: "['L.kynurenine_degradation'] not in index"
2014-11-24 14:13:13,005 ERROR base 25109 -1364198592 Internal Server Error: /document/doc2543/treat11/
Traceback (most recent call last):
  File "/usr/local/lib/python2.7/dist-packages/django/core/handlers/base.py", line 114, in get_response
    response = wrapped_callback(request, *callback_args, **callback_kwargs)
  File "/usr/local/lib/python2.7/dist-packages/django/views/generic/base.py", line 69, in view
    return self.dispatch(request, *args, **kwargs)
  File "/usr/local/lib/python2.7/dist-packages/django/utils/decorators.py", line 29, in _wrapper
    return bound_func(*args, **kwargs)
  File "/usr/local/lib/python2.7/dist-packages/django/contrib/auth/decorators.py", line 22, in _wrapped_view
    return view_func(request, *args, **kwargs)
  File "/usr/local/lib/python2.7/dist-packages/django/utils/decorators.py", line 25, in bound_func
    return func(self, *args2, **kwargs2)
  File "/home/mikhail/EclipseWorkspace/oncoFinder2/oncoFinder2/medic/views.py", line 143, in dispatch
    return super(PatientTreatmentDetail, self).dispatch(request, *args, **kwargs)
  File "/usr/local/lib/python2.7/dist-packages/django/views/generic/base.py", line 87, in dispatch
    return handler(request, *args, **kwargs)
  File "/home/mikhail/EclipseWorkspace/oncoFinder2/oncoFinder2/medic/views.py", line 289, in post
    context = self.get_context_data(object=self.object)
  File "/home/mikhail/EclipseWorkspace/oncoFinder2/oncoFinder2/medic/views.py", line 164, in get_context_data
    df_required_paths = df_pms1[path_cols]
  File "/usr/local/lib/python2.7/dist-packages/pandas/core/frame.py", line 1737, in __getitem__
    return self._getitem_array(key)
  File "/usr/local/lib/python2.7/dist-packages/pandas/core/frame.py", line 1781, in _getitem_array
    indexer = self.ix._convert_to_indexer(key, axis=1)
  File "/usr/local/lib/python2.7/dist-packages/pandas/core/indexing.py", line 1135, in _convert_to_indexer
    raise KeyError('%s not in index' % objarr[mask])
KeyError: "['L.kynurenine_degradation'\n 'sphingosine_and_sphingosine.1.phosphate_metabolism'\n 'tryptophan_degradation_to_2.amino.3.carboxymuconate_semialdehyde'] not in index"
2014-11-24 14:13:57,085 ERROR base 25109 -1788871872 Internal Server Error: /document/doc2543/treat14/
Traceback (most recent call last):
  File "/usr/local/lib/python2.7/dist-packages/django/core/handlers/base.py", line 114, in get_response
    response = wrapped_callback(request, *callback_args, **callback_kwargs)
  File "/usr/local/lib/python2.7/dist-packages/django/views/generic/base.py", line 69, in view
    return self.dispatch(request, *args, **kwargs)
  File "/usr/local/lib/python2.7/dist-packages/django/utils/decorators.py", line 29, in _wrapper
    return bound_func(*args, **kwargs)
  File "/usr/local/lib/python2.7/dist-packages/django/contrib/auth/decorators.py", line 22, in _wrapped_view
    return view_func(request, *args, **kwargs)
  File "/usr/local/lib/python2.7/dist-packages/django/utils/decorators.py", line 25, in bound_func
    return func(self, *args2, **kwargs2)
  File "/home/mikhail/EclipseWorkspace/oncoFinder2/oncoFinder2/medic/views.py", line 143, in dispatch
    return super(PatientTreatmentDetail, self).dispatch(request, *args, **kwargs)
  File "/usr/local/lib/python2.7/dist-packages/django/views/generic/base.py", line 87, in dispatch
    return handler(request, *args, **kwargs)
  File "/home/mikhail/EclipseWorkspace/oncoFinder2/oncoFinder2/medic/views.py", line 289, in post
    context = self.get_context_data(object=self.object)
  File "/home/mikhail/EclipseWorkspace/oncoFinder2/oncoFinder2/medic/views.py", line 164, in get_context_data
    df_required_paths = df_pms1[path_cols]
  File "/usr/local/lib/python2.7/dist-packages/pandas/core/frame.py", line 1737, in __getitem__
    return self._getitem_array(key)
  File "/usr/local/lib/python2.7/dist-packages/pandas/core/frame.py", line 1781, in _getitem_array
    indexer = self.ix._convert_to_indexer(key, axis=1)
  File "/usr/local/lib/python2.7/dist-packages/pandas/core/indexing.py", line 1135, in _convert_to_indexer
    raise KeyError('%s not in index' % objarr[mask])
KeyError: "['sphingosine_and_sphingosine.1.phosphate_metabolism'] not in index"
2014-11-24 14:13:57,639 ERROR base 25109 -1797264576 Internal Server Error: /document/doc2543/treat12/
Traceback (most recent call last):
  File "/usr/local/lib/python2.7/dist-packages/django/core/handlers/base.py", line 114, in get_response
    response = wrapped_callback(request, *callback_args, **callback_kwargs)
  File "/usr/local/lib/python2.7/dist-packages/django/views/generic/base.py", line 69, in view
    return self.dispatch(request, *args, **kwargs)
  File "/usr/local/lib/python2.7/dist-packages/django/utils/decorators.py", line 29, in _wrapper
    return bound_func(*args, **kwargs)
  File "/usr/local/lib/python2.7/dist-packages/django/contrib/auth/decorators.py", line 22, in _wrapped_view
    return view_func(request, *args, **kwargs)
  File "/usr/local/lib/python2.7/dist-packages/django/utils/decorators.py", line 25, in bound_func
    return func(self, *args2, **kwargs2)
  File "/home/mikhail/EclipseWorkspace/oncoFinder2/oncoFinder2/medic/views.py", line 143, in dispatch
    return super(PatientTreatmentDetail, self).dispatch(request, *args, **kwargs)
  File "/usr/local/lib/python2.7/dist-packages/django/views/generic/base.py", line 87, in dispatch
    return handler(request, *args, **kwargs)
  File "/home/mikhail/EclipseWorkspace/oncoFinder2/oncoFinder2/medic/views.py", line 289, in post
    context = self.get_context_data(object=self.object)
  File "/home/mikhail/EclipseWorkspace/oncoFinder2/oncoFinder2/medic/views.py", line 164, in get_context_data
    df_required_paths = df_pms1[path_cols]
  File "/usr/local/lib/python2.7/dist-packages/pandas/core/frame.py", line 1737, in __getitem__
    return self._getitem_array(key)
  File "/usr/local/lib/python2.7/dist-packages/pandas/core/frame.py", line 1781, in _getitem_array
    indexer = self.ix._convert_to_indexer(key, axis=1)
  File "/usr/local/lib/python2.7/dist-packages/pandas/core/indexing.py", line 1135, in _convert_to_indexer
    raise KeyError('%s not in index' % objarr[mask])
KeyError: "['ATM_Pathway_G2.M_Checkpoint_Arrest'\n 'D.galactose_degradation_V_Leloir_pathway'] not in index"
2014-11-24 14:13:58,201 ERROR base 25109 -1581253824 Internal Server Error: /document/doc2543/treat8/
Traceback (most recent call last):
  File "/usr/local/lib/python2.7/dist-packages/django/core/handlers/base.py", line 114, in get_response
    response = wrapped_callback(request, *callback_args, **callback_kwargs)
  File "/usr/local/lib/python2.7/dist-packages/django/views/generic/base.py", line 69, in view
    return self.dispatch(request, *args, **kwargs)
  File "/usr/local/lib/python2.7/dist-packages/django/utils/decorators.py", line 29, in _wrapper
    return bound_func(*args, **kwargs)
  File "/usr/local/lib/python2.7/dist-packages/django/contrib/auth/decorators.py", line 22, in _wrapped_view
    return view_func(request, *args, **kwargs)
  File "/usr/local/lib/python2.7/dist-packages/django/utils/decorators.py", line 25, in bound_func
    return func(self, *args2, **kwargs2)
  File "/home/mikhail/EclipseWorkspace/oncoFinder2/oncoFinder2/medic/views.py", line 143, in dispatch
    return super(PatientTreatmentDetail, self).dispatch(request, *args, **kwargs)
  File "/usr/local/lib/python2.7/dist-packages/django/views/generic/base.py", line 87, in dispatch
    return handler(request, *args, **kwargs)
  File "/home/mikhail/EclipseWorkspace/oncoFinder2/oncoFinder2/medic/views.py", line 289, in post
    context = self.get_context_data(object=self.object)
  File "/home/mikhail/EclipseWorkspace/oncoFinder2/oncoFinder2/medic/views.py", line 164, in get_context_data
    df_required_paths = df_pms1[path_cols]
  File "/usr/local/lib/python2.7/dist-packages/pandas/core/frame.py", line 1737, in __getitem__
    return self._getitem_array(key)
  File "/usr/local/lib/python2.7/dist-packages/pandas/core/frame.py", line 1781, in _getitem_array
    indexer = self.ix._convert_to_indexer(key, axis=1)
  File "/usr/local/lib/python2.7/dist-packages/pandas/core/indexing.py", line 1135, in _convert_to_indexer
    raise KeyError('%s not in index' % objarr[mask])
KeyError: "['L.kynurenine_degradation'] not in index"
2014-11-24 14:13:59,590 ERROR base 25109 -1690305728 Internal Server Error: /document/doc2543/treat11/
Traceback (most recent call last):
  File "/usr/local/lib/python2.7/dist-packages/django/core/handlers/base.py", line 114, in get_response
    response = wrapped_callback(request, *callback_args, **callback_kwargs)
  File "/usr/local/lib/python2.7/dist-packages/django/views/generic/base.py", line 69, in view
    return self.dispatch(request, *args, **kwargs)
  File "/usr/local/lib/python2.7/dist-packages/django/utils/decorators.py", line 29, in _wrapper
    return bound_func(*args, **kwargs)
  File "/usr/local/lib/python2.7/dist-packages/django/contrib/auth/decorators.py", line 22, in _wrapped_view
    return view_func(request, *args, **kwargs)
  File "/usr/local/lib/python2.7/dist-packages/django/utils/decorators.py", line 25, in bound_func
    return func(self, *args2, **kwargs2)
  File "/home/mikhail/EclipseWorkspace/oncoFinder2/oncoFinder2/medic/views.py", line 143, in dispatch
    return super(PatientTreatmentDetail, self).dispatch(request, *args, **kwargs)
  File "/usr/local/lib/python2.7/dist-packages/django/views/generic/base.py", line 87, in dispatch
    return handler(request, *args, **kwargs)
  File "/home/mikhail/EclipseWorkspace/oncoFinder2/oncoFinder2/medic/views.py", line 289, in post
    context = self.get_context_data(object=self.object)
  File "/home/mikhail/EclipseWorkspace/oncoFinder2/oncoFinder2/medic/views.py", line 164, in get_context_data
    df_required_paths = df_pms1[path_cols]
  File "/usr/local/lib/python2.7/dist-packages/pandas/core/frame.py", line 1737, in __getitem__
    return self._getitem_array(key)
  File "/usr/local/lib/python2.7/dist-packages/pandas/core/frame.py", line 1781, in _getitem_array
    indexer = self.ix._convert_to_indexer(key, axis=1)
  File "/usr/local/lib/python2.7/dist-packages/pandas/core/indexing.py", line 1135, in _convert_to_indexer
    raise KeyError('%s not in index' % objarr[mask])
KeyError: "['L.kynurenine_degradation'\n 'sphingosine_and_sphingosine.1.phosphate_metabolism'\n 'tryptophan_degradation_to_2.amino.3.carboxymuconate_semialdehyde'] not in index"
2014-11-24 14:14:44,635 ERROR base 25109 -1690305728 Internal Server Error: /document/doc2543/treat14/
Traceback (most recent call last):
  File "/usr/local/lib/python2.7/dist-packages/django/core/handlers/base.py", line 114, in get_response
    response = wrapped_callback(request, *callback_args, **callback_kwargs)
  File "/usr/local/lib/python2.7/dist-packages/django/views/generic/base.py", line 69, in view
    return self.dispatch(request, *args, **kwargs)
  File "/usr/local/lib/python2.7/dist-packages/django/utils/decorators.py", line 29, in _wrapper
    return bound_func(*args, **kwargs)
  File "/usr/local/lib/python2.7/dist-packages/django/contrib/auth/decorators.py", line 22, in _wrapped_view
    return view_func(request, *args, **kwargs)
  File "/usr/local/lib/python2.7/dist-packages/django/utils/decorators.py", line 25, in bound_func
    return func(self, *args2, **kwargs2)
  File "/home/mikhail/EclipseWorkspace/oncoFinder2/oncoFinder2/medic/views.py", line 143, in dispatch
    return super(PatientTreatmentDetail, self).dispatch(request, *args, **kwargs)
  File "/usr/local/lib/python2.7/dist-packages/django/views/generic/base.py", line 87, in dispatch
    return handler(request, *args, **kwargs)
  File "/home/mikhail/EclipseWorkspace/oncoFinder2/oncoFinder2/medic/views.py", line 289, in post
    context = self.get_context_data(object=self.object)
  File "/home/mikhail/EclipseWorkspace/oncoFinder2/oncoFinder2/medic/views.py", line 164, in get_context_data
    df_required_paths = df_pms1[path_cols]
  File "/usr/local/lib/python2.7/dist-packages/pandas/core/frame.py", line 1737, in __getitem__
    return self._getitem_array(key)
  File "/usr/local/lib/python2.7/dist-packages/pandas/core/frame.py", line 1781, in _getitem_array
    indexer = self.ix._convert_to_indexer(key, axis=1)
  File "/usr/local/lib/python2.7/dist-packages/pandas/core/indexing.py", line 1135, in _convert_to_indexer
    raise KeyError('%s not in index' % objarr[mask])
KeyError: "['sphingosine_and_sphingosine.1.phosphate_metabolism'] not in index"
2014-11-24 14:14:45,395 ERROR base 25109 -1364198592 Internal Server Error: /document/doc2543/treat12/
Traceback (most recent call last):
  File "/usr/local/lib/python2.7/dist-packages/django/core/handlers/base.py", line 114, in get_response
    response = wrapped_callback(request, *callback_args, **callback_kwargs)
  File "/usr/local/lib/python2.7/dist-packages/django/views/generic/base.py", line 69, in view
    return self.dispatch(request, *args, **kwargs)
  File "/usr/local/lib/python2.7/dist-packages/django/utils/decorators.py", line 29, in _wrapper
    return bound_func(*args, **kwargs)
  File "/usr/local/lib/python2.7/dist-packages/django/contrib/auth/decorators.py", line 22, in _wrapped_view
    return view_func(request, *args, **kwargs)
  File "/usr/local/lib/python2.7/dist-packages/django/utils/decorators.py", line 25, in bound_func
    return func(self, *args2, **kwargs2)
  File "/home/mikhail/EclipseWorkspace/oncoFinder2/oncoFinder2/medic/views.py", line 143, in dispatch
    return super(PatientTreatmentDetail, self).dispatch(request, *args, **kwargs)
  File "/usr/local/lib/python2.7/dist-packages/django/views/generic/base.py", line 87, in dispatch
    return handler(request, *args, **kwargs)
  File "/home/mikhail/EclipseWorkspace/oncoFinder2/oncoFinder2/medic/views.py", line 289, in post
    context = self.get_context_data(object=self.object)
  File "/home/mikhail/EclipseWorkspace/oncoFinder2/oncoFinder2/medic/views.py", line 164, in get_context_data
    df_required_paths = df_pms1[path_cols]
  File "/usr/local/lib/python2.7/dist-packages/pandas/core/frame.py", line 1737, in __getitem__
    return self._getitem_array(key)
  File "/usr/local/lib/python2.7/dist-packages/pandas/core/frame.py", line 1781, in _getitem_array
    indexer = self.ix._convert_to_indexer(key, axis=1)
  File "/usr/local/lib/python2.7/dist-packages/pandas/core/indexing.py", line 1135, in _convert_to_indexer
    raise KeyError('%s not in index' % objarr[mask])
KeyError: "['ATM_Pathway_G2.M_Checkpoint_Arrest'\n 'D.galactose_degradation_V_Leloir_pathway'] not in index"
2014-11-24 14:14:46,393 ERROR base 25109 -1581253824 Internal Server Error: /document/doc2543/treat8/
Traceback (most recent call last):
  File "/usr/local/lib/python2.7/dist-packages/django/core/handlers/base.py", line 114, in get_response
    response = wrapped_callback(request, *callback_args, **callback_kwargs)
  File "/usr/local/lib/python2.7/dist-packages/django/views/generic/base.py", line 69, in view
    return self.dispatch(request, *args, **kwargs)
  File "/usr/local/lib/python2.7/dist-packages/django/utils/decorators.py", line 29, in _wrapper
    return bound_func(*args, **kwargs)
  File "/usr/local/lib/python2.7/dist-packages/django/contrib/auth/decorators.py", line 22, in _wrapped_view
    return view_func(request, *args, **kwargs)
  File "/usr/local/lib/python2.7/dist-packages/django/utils/decorators.py", line 25, in bound_func
    return func(self, *args2, **kwargs2)
  File "/home/mikhail/EclipseWorkspace/oncoFinder2/oncoFinder2/medic/views.py", line 143, in dispatch
    return super(PatientTreatmentDetail, self).dispatch(request, *args, **kwargs)
  File "/usr/local/lib/python2.7/dist-packages/django/views/generic/base.py", line 87, in dispatch
    return handler(request, *args, **kwargs)
  File "/home/mikhail/EclipseWorkspace/oncoFinder2/oncoFinder2/medic/views.py", line 289, in post
    context = self.get_context_data(object=self.object)
  File "/home/mikhail/EclipseWorkspace/oncoFinder2/oncoFinder2/medic/views.py", line 164, in get_context_data
    df_required_paths = df_pms1[path_cols]
  File "/usr/local/lib/python2.7/dist-packages/pandas/core/frame.py", line 1737, in __getitem__
    return self._getitem_array(key)
  File "/usr/local/lib/python2.7/dist-packages/pandas/core/frame.py", line 1781, in _getitem_array
    indexer = self.ix._convert_to_indexer(key, axis=1)
  File "/usr/local/lib/python2.7/dist-packages/pandas/core/indexing.py", line 1135, in _convert_to_indexer
    raise KeyError('%s not in index' % objarr[mask])
KeyError: "['L.kynurenine_degradation'] not in index"
2014-11-24 14:14:47,662 ERROR base 25109 -1616905408 Internal Server Error: /document/doc2543/treat11/
Traceback (most recent call last):
  File "/usr/local/lib/python2.7/dist-packages/django/core/handlers/base.py", line 114, in get_response
    response = wrapped_callback(request, *callback_args, **callback_kwargs)
  File "/usr/local/lib/python2.7/dist-packages/django/views/generic/base.py", line 69, in view
    return self.dispatch(request, *args, **kwargs)
  File "/usr/local/lib/python2.7/dist-packages/django/utils/decorators.py", line 29, in _wrapper
    return bound_func(*args, **kwargs)
  File "/usr/local/lib/python2.7/dist-packages/django/contrib/auth/decorators.py", line 22, in _wrapped_view
    return view_func(request, *args, **kwargs)
  File "/usr/local/lib/python2.7/dist-packages/django/utils/decorators.py", line 25, in bound_func
    return func(self, *args2, **kwargs2)
  File "/home/mikhail/EclipseWorkspace/oncoFinder2/oncoFinder2/medic/views.py", line 143, in dispatch
    return super(PatientTreatmentDetail, self).dispatch(request, *args, **kwargs)
  File "/usr/local/lib/python2.7/dist-packages/django/views/generic/base.py", line 87, in dispatch
    return handler(request, *args, **kwargs)
  File "/home/mikhail/EclipseWorkspace/oncoFinder2/oncoFinder2/medic/views.py", line 289, in post
    context = self.get_context_data(object=self.object)
  File "/home/mikhail/EclipseWorkspace/oncoFinder2/oncoFinder2/medic/views.py", line 164, in get_context_data
    df_required_paths = df_pms1[path_cols]
  File "/usr/local/lib/python2.7/dist-packages/pandas/core/frame.py", line 1737, in __getitem__
    return self._getitem_array(key)
  File "/usr/local/lib/python2.7/dist-packages/pandas/core/frame.py", line 1781, in _getitem_array
    indexer = self.ix._convert_to_indexer(key, axis=1)
  File "/usr/local/lib/python2.7/dist-packages/pandas/core/indexing.py", line 1135, in _convert_to_indexer
    raise KeyError('%s not in index' % objarr[mask])
KeyError: "['L.kynurenine_degradation'\n 'sphingosine_and_sphingosine.1.phosphate_metabolism'\n 'tryptophan_degradation_to_2.amino.3.carboxymuconate_semialdehyde'] not in index"
2014-11-24 14:16:28,209 ERROR base 25109 -1364198592 Internal Server Error: /document/doc2543/treat14/
Traceback (most recent call last):
  File "/usr/local/lib/python2.7/dist-packages/django/core/handlers/base.py", line 114, in get_response
    response = wrapped_callback(request, *callback_args, **callback_kwargs)
  File "/usr/local/lib/python2.7/dist-packages/django/views/generic/base.py", line 69, in view
    return self.dispatch(request, *args, **kwargs)
  File "/usr/local/lib/python2.7/dist-packages/django/utils/decorators.py", line 29, in _wrapper
    return bound_func(*args, **kwargs)
  File "/usr/local/lib/python2.7/dist-packages/django/contrib/auth/decorators.py", line 22, in _wrapped_view
    return view_func(request, *args, **kwargs)
  File "/usr/local/lib/python2.7/dist-packages/django/utils/decorators.py", line 25, in bound_func
    return func(self, *args2, **kwargs2)
  File "/home/mikhail/EclipseWorkspace/oncoFinder2/oncoFinder2/medic/views.py", line 143, in dispatch
    return super(PatientTreatmentDetail, self).dispatch(request, *args, **kwargs)
  File "/usr/local/lib/python2.7/dist-packages/django/views/generic/base.py", line 87, in dispatch
    return handler(request, *args, **kwargs)
  File "/home/mikhail/EclipseWorkspace/oncoFinder2/oncoFinder2/medic/views.py", line 289, in post
    context = self.get_context_data(object=self.object)
  File "/home/mikhail/EclipseWorkspace/oncoFinder2/oncoFinder2/medic/views.py", line 164, in get_context_data
    df_required_paths = df_pms1[path_cols]
  File "/usr/local/lib/python2.7/dist-packages/pandas/core/frame.py", line 1737, in __getitem__
    return self._getitem_array(key)
  File "/usr/local/lib/python2.7/dist-packages/pandas/core/frame.py", line 1781, in _getitem_array
    indexer = self.ix._convert_to_indexer(key, axis=1)
  File "/usr/local/lib/python2.7/dist-packages/pandas/core/indexing.py", line 1135, in _convert_to_indexer
    raise KeyError('%s not in index' % objarr[mask])
KeyError: "['sphingosine_and_sphingosine.1.phosphate_metabolism'] not in index"
2014-11-24 14:16:29,085 ERROR base 25109 -1581253824 Internal Server Error: /document/doc2543/treat12/
Traceback (most recent call last):
  File "/usr/local/lib/python2.7/dist-packages/django/core/handlers/base.py", line 114, in get_response
    response = wrapped_callback(request, *callback_args, **callback_kwargs)
  File "/usr/local/lib/python2.7/dist-packages/django/views/generic/base.py", line 69, in view
    return self.dispatch(request, *args, **kwargs)
  File "/usr/local/lib/python2.7/dist-packages/django/utils/decorators.py", line 29, in _wrapper
    return bound_func(*args, **kwargs)
  File "/usr/local/lib/python2.7/dist-packages/django/contrib/auth/decorators.py", line 22, in _wrapped_view
    return view_func(request, *args, **kwargs)
  File "/usr/local/lib/python2.7/dist-packages/django/utils/decorators.py", line 25, in bound_func
    return func(self, *args2, **kwargs2)
  File "/home/mikhail/EclipseWorkspace/oncoFinder2/oncoFinder2/medic/views.py", line 143, in dispatch
    return super(PatientTreatmentDetail, self).dispatch(request, *args, **kwargs)
  File "/usr/local/lib/python2.7/dist-packages/django/views/generic/base.py", line 87, in dispatch
    return handler(request, *args, **kwargs)
  File "/home/mikhail/EclipseWorkspace/oncoFinder2/oncoFinder2/medic/views.py", line 289, in post
    context = self.get_context_data(object=self.object)
  File "/home/mikhail/EclipseWorkspace/oncoFinder2/oncoFinder2/medic/views.py", line 164, in get_context_data
    df_required_paths = df_pms1[path_cols]
  File "/usr/local/lib/python2.7/dist-packages/pandas/core/frame.py", line 1737, in __getitem__
    return self._getitem_array(key)
  File "/usr/local/lib/python2.7/dist-packages/pandas/core/frame.py", line 1781, in _getitem_array
    indexer = self.ix._convert_to_indexer(key, axis=1)
  File "/usr/local/lib/python2.7/dist-packages/pandas/core/indexing.py", line 1135, in _convert_to_indexer
    raise KeyError('%s not in index' % objarr[mask])
KeyError: "['ATM_Pathway_G2.M_Checkpoint_Arrest'\n 'D.galactose_degradation_V_Leloir_pathway'] not in index"
2014-11-24 14:16:29,888 ERROR base 25109 -1736443072 Internal Server Error: /document/doc2543/treat8/
Traceback (most recent call last):
  File "/usr/local/lib/python2.7/dist-packages/django/core/handlers/base.py", line 114, in get_response
    response = wrapped_callback(request, *callback_args, **callback_kwargs)
  File "/usr/local/lib/python2.7/dist-packages/django/views/generic/base.py", line 69, in view
    return self.dispatch(request, *args, **kwargs)
  File "/usr/local/lib/python2.7/dist-packages/django/utils/decorators.py", line 29, in _wrapper
    return bound_func(*args, **kwargs)
  File "/usr/local/lib/python2.7/dist-packages/django/contrib/auth/decorators.py", line 22, in _wrapped_view
    return view_func(request, *args, **kwargs)
  File "/usr/local/lib/python2.7/dist-packages/django/utils/decorators.py", line 25, in bound_func
    return func(self, *args2, **kwargs2)
  File "/home/mikhail/EclipseWorkspace/oncoFinder2/oncoFinder2/medic/views.py", line 143, in dispatch
    return super(PatientTreatmentDetail, self).dispatch(request, *args, **kwargs)
  File "/usr/local/lib/python2.7/dist-packages/django/views/generic/base.py", line 87, in dispatch
    return handler(request, *args, **kwargs)
  File "/home/mikhail/EclipseWorkspace/oncoFinder2/oncoFinder2/medic/views.py", line 289, in post
    context = self.get_context_data(object=self.object)
  File "/home/mikhail/EclipseWorkspace/oncoFinder2/oncoFinder2/medic/views.py", line 164, in get_context_data
    df_required_paths = df_pms1[path_cols]
  File "/usr/local/lib/python2.7/dist-packages/pandas/core/frame.py", line 1737, in __getitem__
    return self._getitem_array(key)
  File "/usr/local/lib/python2.7/dist-packages/pandas/core/frame.py", line 1781, in _getitem_array
    indexer = self.ix._convert_to_indexer(key, axis=1)
  File "/usr/local/lib/python2.7/dist-packages/pandas/core/indexing.py", line 1135, in _convert_to_indexer
    raise KeyError('%s not in index' % objarr[mask])
KeyError: "['L.kynurenine_degradation'] not in index"
2014-11-24 14:16:30,826 ERROR base 25109 -1690305728 Internal Server Error: /document/doc2543/treat11/
Traceback (most recent call last):
  File "/usr/local/lib/python2.7/dist-packages/django/core/handlers/base.py", line 114, in get_response
    response = wrapped_callback(request, *callback_args, **callback_kwargs)
  File "/usr/local/lib/python2.7/dist-packages/django/views/generic/base.py", line 69, in view
    return self.dispatch(request, *args, **kwargs)
  File "/usr/local/lib/python2.7/dist-packages/django/utils/decorators.py", line 29, in _wrapper
    return bound_func(*args, **kwargs)
  File "/usr/local/lib/python2.7/dist-packages/django/contrib/auth/decorators.py", line 22, in _wrapped_view
    return view_func(request, *args, **kwargs)
  File "/usr/local/lib/python2.7/dist-packages/django/utils/decorators.py", line 25, in bound_func
    return func(self, *args2, **kwargs2)
  File "/home/mikhail/EclipseWorkspace/oncoFinder2/oncoFinder2/medic/views.py", line 143, in dispatch
    return super(PatientTreatmentDetail, self).dispatch(request, *args, **kwargs)
  File "/usr/local/lib/python2.7/dist-packages/django/views/generic/base.py", line 87, in dispatch
    return handler(request, *args, **kwargs)
  File "/home/mikhail/EclipseWorkspace/oncoFinder2/oncoFinder2/medic/views.py", line 289, in post
    context = self.get_context_data(object=self.object)
  File "/home/mikhail/EclipseWorkspace/oncoFinder2/oncoFinder2/medic/views.py", line 164, in get_context_data
    df_required_paths = df_pms1[path_cols]
  File "/usr/local/lib/python2.7/dist-packages/pandas/core/frame.py", line 1737, in __getitem__
    return self._getitem_array(key)
  File "/usr/local/lib/python2.7/dist-packages/pandas/core/frame.py", line 1781, in _getitem_array
    indexer = self.ix._convert_to_indexer(key, axis=1)
  File "/usr/local/lib/python2.7/dist-packages/pandas/core/indexing.py", line 1135, in _convert_to_indexer
    raise KeyError('%s not in index' % objarr[mask])
KeyError: "['L.kynurenine_degradation'\n 'sphingosine_and_sphingosine.1.phosphate_metabolism'\n 'tryptophan_degradation_to_2.amino.3.carboxymuconate_semialdehyde'] not in index"
2014-11-24 14:16:53,026 ERROR base 25109 -1364198592 Internal Server Error: /document/doc2543/treat8/
Traceback (most recent call last):
  File "/usr/local/lib/python2.7/dist-packages/django/core/handlers/base.py", line 114, in get_response
    response = wrapped_callback(request, *callback_args, **callback_kwargs)
  File "/usr/local/lib/python2.7/dist-packages/django/views/generic/base.py", line 69, in view
    return self.dispatch(request, *args, **kwargs)
  File "/usr/local/lib/python2.7/dist-packages/django/utils/decorators.py", line 29, in _wrapper
    return bound_func(*args, **kwargs)
  File "/usr/local/lib/python2.7/dist-packages/django/contrib/auth/decorators.py", line 22, in _wrapped_view
    return view_func(request, *args, **kwargs)
  File "/usr/local/lib/python2.7/dist-packages/django/utils/decorators.py", line 25, in bound_func
    return func(self, *args2, **kwargs2)
  File "/home/mikhail/EclipseWorkspace/oncoFinder2/oncoFinder2/medic/views.py", line 143, in dispatch
    return super(PatientTreatmentDetail, self).dispatch(request, *args, **kwargs)
  File "/usr/local/lib/python2.7/dist-packages/django/views/generic/base.py", line 87, in dispatch
    return handler(request, *args, **kwargs)
  File "/home/mikhail/EclipseWorkspace/oncoFinder2/oncoFinder2/medic/views.py", line 289, in post
    context = self.get_context_data(object=self.object)
  File "/home/mikhail/EclipseWorkspace/oncoFinder2/oncoFinder2/medic/views.py", line 164, in get_context_data
    df_required_paths = df_pms1[path_cols]
  File "/usr/local/lib/python2.7/dist-packages/pandas/core/frame.py", line 1737, in __getitem__
    return self._getitem_array(key)
  File "/usr/local/lib/python2.7/dist-packages/pandas/core/frame.py", line 1781, in _getitem_array
    indexer = self.ix._convert_to_indexer(key, axis=1)
  File "/usr/local/lib/python2.7/dist-packages/pandas/core/indexing.py", line 1135, in _convert_to_indexer
    raise KeyError('%s not in index' % objarr[mask])
KeyError: "['L.kynurenine_degradation'] not in index"
2014-11-24 14:33:58,395 ERROR base 12278 -1251480768 Internal Server Error: /medic/generatefullreport/
Traceback (most recent call last):
  File "/usr/local/lib/python2.7/dist-packages/django/core/handlers/base.py", line 114, in get_response
    response = wrapped_callback(request, *callback_args, **callback_kwargs)
  File "/usr/local/lib/python2.7/dist-packages/django/views/generic/base.py", line 69, in view
    return self.dispatch(request, *args, **kwargs)
  File "/home/mikhail/EclipseWorkspace/oncoFinder2/oncoFinder2/medic/views.py", line 489, in dispatch
    return super(MedicAjaxGenerateReport, self).dispatch(request, *args, **kwargs)
TypeError: super(type, obj): obj must be an instance or subtype of type
2014-11-24 14:34:24,533 ERROR base 15532 -1251480768 Internal Server Error: /medic/generatefullreport/
Traceback (most recent call last):
  File "/usr/local/lib/python2.7/dist-packages/django/core/handlers/base.py", line 114, in get_response
    response = wrapped_callback(request, *callback_args, **callback_kwargs)
  File "/usr/local/lib/python2.7/dist-packages/django/views/generic/base.py", line 69, in view
    return self.dispatch(request, *args, **kwargs)
  File "/home/mikhail/EclipseWorkspace/oncoFinder2/oncoFinder2/medic/views.py", line 489, in dispatch
    return super(MedicAjaxGenerateFullReport, self).dispatch(request, *args, **kwargs)
  File "/usr/local/lib/python2.7/dist-packages/django/views/generic/base.py", line 87, in dispatch
    return handler(request, *args, **kwargs)
  File "/home/mikhail/EclipseWorkspace/oncoFinder2/oncoFinder2/medic/views.py", line 441, in post
    t_n_patients = request.POST.get('t_n_patients'+treat.id)
TypeError: cannot concatenate 'str' and 'long' objects
2014-11-24 14:42:29,225 ERROR base 18262 -1251480768 Internal Server Error: /medic/generatefullreport/
Traceback (most recent call last):
  File "/usr/local/lib/python2.7/dist-packages/django/core/handlers/base.py", line 114, in get_response
    response = wrapped_callback(request, *callback_args, **callback_kwargs)
  File "/usr/local/lib/python2.7/dist-packages/django/views/generic/base.py", line 69, in view
    return self.dispatch(request, *args, **kwargs)
  File "/home/mikhail/EclipseWorkspace/oncoFinder2/oncoFinder2/medic/views.py", line 492, in dispatch
    return super(MedicAjaxGenerateFullReport, self).dispatch(request, *args, **kwargs)
  File "/usr/local/lib/python2.7/dist-packages/django/views/generic/base.py", line 87, in dispatch
    return handler(request, *args, **kwargs)
  File "/home/mikhail/EclipseWorkspace/oncoFinder2/oncoFinder2/medic/views.py", line 471, in post
    document.add_paragraph('Organization name: '+o_org)
TypeError: cannot concatenate 'str' and 'NoneType' objects
2014-11-24 14:53:45,105 ERROR base 21167 -1252529344 Internal Server Error: /medic/generatefullreport/
Traceback (most recent call last):
  File "/usr/local/lib/python2.7/dist-packages/django/core/handlers/base.py", line 114, in get_response
    response = wrapped_callback(request, *callback_args, **callback_kwargs)
  File "/usr/local/lib/python2.7/dist-packages/django/views/generic/base.py", line 69, in view
    return self.dispatch(request, *args, **kwargs)
  File "/home/mikhail/EclipseWorkspace/oncoFinder2/oncoFinder2/medic/views.py", line 508, in dispatch
    return super(MedicAjaxGenerateFullReport, self).dispatch(request, *args, **kwargs)
  File "/usr/local/lib/python2.7/dist-packages/django/views/generic/base.py", line 87, in dispatch
    return handler(request, *args, **kwargs)
  File "/home/mikhail/EclipseWorkspace/oncoFinder2/oncoFinder2/medic/views.py", line 452, in post
    cells[1].text = request.POST.get('t_responder'+treat_id)
  File "/usr/local/lib/python2.7/dist-packages/docx/table.py", line 154, in text
    r.text = text
  File "/usr/local/lib/python2.7/dist-packages/docx/oxml/text.py", line 251, in text
    _RunContentAppender.append_to_run_from_text(self, text)
  File "/usr/local/lib/python2.7/dist-packages/docx/oxml/text.py", line 399, in append_to_run_from_text
    appender.add_text(text)
  File "/usr/local/lib/python2.7/dist-packages/docx/oxml/text.py", line 406, in add_text
    for char in text:
TypeError: 'NoneType' object is not iterable
2014-11-24 14:54:46,315 ERROR base 22265 -1251480768 Internal Server Error: /medic/generatefullreport/
Traceback (most recent call last):
  File "/usr/local/lib/python2.7/dist-packages/django/core/handlers/base.py", line 114, in get_response
    response = wrapped_callback(request, *callback_args, **callback_kwargs)
  File "/usr/local/lib/python2.7/dist-packages/django/views/generic/base.py", line 69, in view
    return self.dispatch(request, *args, **kwargs)
  File "/home/mikhail/EclipseWorkspace/oncoFinder2/oncoFinder2/medic/views.py", line 508, in dispatch
    return super(MedicAjaxGenerateFullReport, self).dispatch(request, *args, **kwargs)
  File "/usr/local/lib/python2.7/dist-packages/django/views/generic/base.py", line 87, in dispatch
    return handler(request, *args, **kwargs)
  File "/home/mikhail/EclipseWorkspace/oncoFinder2/oncoFinder2/medic/views.py", line 451, in post
    cells[0].text = str(request.POST.get('t_treatment'+treat_id))
UnicodeEncodeError: 'ascii' codec can't encode character u'\u2014' in position 3: ordinal not in range(128)
2014-11-24 14:55:34,803 ERROR base 22426 -1251480768 Internal Server Error: /medic/generatefullreport/
Traceback (most recent call last):
  File "/usr/local/lib/python2.7/dist-packages/django/core/handlers/base.py", line 114, in get_response
    response = wrapped_callback(request, *callback_args, **callback_kwargs)
  File "/usr/local/lib/python2.7/dist-packages/django/views/generic/base.py", line 69, in view
    return self.dispatch(request, *args, **kwargs)
  File "/home/mikhail/EclipseWorkspace/oncoFinder2/oncoFinder2/medic/views.py", line 508, in dispatch
    return super(MedicAjaxGenerateFullReport, self).dispatch(request, *args, **kwargs)
  File "/usr/local/lib/python2.7/dist-packages/django/views/generic/base.py", line 87, in dispatch
    return handler(request, *args, **kwargs)
  File "/home/mikhail/EclipseWorkspace/oncoFinder2/oncoFinder2/medic/views.py", line 452, in post
    cells[1].text = request.POST.get('t_responder'+treat_id)
  File "/usr/local/lib/python2.7/dist-packages/docx/table.py", line 154, in text
    r.text = text
  File "/usr/local/lib/python2.7/dist-packages/docx/oxml/text.py", line 251, in text
    _RunContentAppender.append_to_run_from_text(self, text)
  File "/usr/local/lib/python2.7/dist-packages/docx/oxml/text.py", line 399, in append_to_run_from_text
    appender.add_text(text)
  File "/usr/local/lib/python2.7/dist-packages/docx/oxml/text.py", line 406, in add_text
    for char in text:
TypeError: 'NoneType' object is not iterable
