2014-05-28 18:02:17,176 ERROR base 9221 -1272534208 Internal Server Error: /test/
Traceback (most recent call last):
  File "/usr/local/lib/python2.7/dist-packages/django/core/handlers/base.py", line 114, in get_response
    response = wrapped_callback(request, *callback_args, **callback_kwargs)
  File "/usr/local/lib/python2.7/dist-packages/django/views/generic/base.py", line 69, in view
    return self.dispatch(request, *args, **kwargs)
  File "/usr/local/lib/python2.7/dist-packages/django/utils/decorators.py", line 29, in _wrapper
    return bound_func(*args, **kwargs)
  File "/usr/local/lib/python2.7/dist-packages/django/contrib/auth/decorators.py", line 22, in _wrapped_view
    return view_func(request, *args, **kwargs)
  File "/usr/local/lib/python2.7/dist-packages/django/utils/decorators.py", line 25, in bound_func
    return func(self, *args2, **kwargs2)
  File "/home/mikhail/EclipseWorkspace/oncoFinder2/core/views.py", line 272, in dispatch
    return super(Test, self).dispatch(request, *args, **kwargs)
  File "/usr/local/lib/python2.7/dist-packages/django/views/generic/base.py", line 87, in dispatch
    return handler(request, *args, **kwargs)
  File "/usr/local/lib/python2.7/dist-packages/django/views/generic/base.py", line 154, in get
    context = self.get_context_data(**kwargs)
  File "/home/mikhail/EclipseWorkspace/oncoFinder2/core/views.py", line 289, in get_context_data
    df1 = read_csv(filename1, delimeter='\t')
TypeError: parser_f() got an unexpected keyword argument 'delimeter'
2014-05-28 18:04:41,327 ERROR base 9296 -1304429760 Internal Server Error: /document/new/
Traceback (most recent call last):
  File "/usr/local/lib/python2.7/dist-packages/django/core/handlers/base.py", line 114, in get_response
    response = wrapped_callback(request, *callback_args, **callback_kwargs)
  File "/usr/local/lib/python2.7/dist-packages/django/views/generic/base.py", line 69, in view
    return self.dispatch(request, *args, **kwargs)
  File "/usr/local/lib/python2.7/dist-packages/django/utils/decorators.py", line 29, in _wrapper
    return bound_func(*args, **kwargs)
  File "/usr/local/lib/python2.7/dist-packages/django/contrib/auth/decorators.py", line 22, in _wrapped_view
    return view_func(request, *args, **kwargs)
  File "/usr/local/lib/python2.7/dist-packages/django/utils/decorators.py", line 25, in bound_func
    return func(self, *args2, **kwargs2)
  File "/home/mikhail/EclipseWorkspace/oncoFinder2/profiles/views.py", line 154, in dispatch
    return super(CreateDocument, self).dispatch(request, *args, **kwargs)
  File "/usr/local/lib/python2.7/dist-packages/django/views/generic/base.py", line 87, in dispatch
    return handler(request, *args, **kwargs)
  File "/usr/local/lib/python2.7/dist-packages/django/views/generic/edit.py", line 205, in post
    return super(BaseCreateView, self).post(request, *args, **kwargs)
  File "/usr/local/lib/python2.7/dist-packages/django/views/generic/edit.py", line 171, in post
    return self.form_valid(form)
  File "/home/mikhail/EclipseWorkspace/oncoFinder2/profiles/views.py", line 199, in form_valid
    df = df.div(df.Mean_norm, axis='index')
  File "/usr/local/lib/python2.7/dist-packages/pandas-0.13.1_674_g95090fd-py2.7-linux-i686.egg/pandas/core/ops.py", line 761, in f
    return self._combine_series(other, na_op, fill_value, axis, level)
  File "/usr/local/lib/python2.7/dist-packages/pandas-0.13.1_674_g95090fd-py2.7-linux-i686.egg/pandas/core/frame.py", line 2796, in _combine_series
    return self._combine_match_index(other, func, level=level, fill_value=fill_value)
  File "/usr/local/lib/python2.7/dist-packages/pandas-0.13.1_674_g95090fd-py2.7-linux-i686.egg/pandas/core/frame.py", line 2826, in _combine_match_index
    return self._constructor(func(left.values.T, right.values).T,
  File "/usr/local/lib/python2.7/dist-packages/pandas-0.13.1_674_g95090fd-py2.7-linux-i686.egg/pandas/core/ops.py", line 737, in na_op
    mask = notnull(xrav) & notnull(yrav)
ValueError: operands could not be broadcast together with shapes (598976,) (18718,) 
2014-05-28 18:06:50,748 ERROR base 9330 -1304429760 Internal Server Error: /document/new/
Traceback (most recent call last):
  File "/usr/local/lib/python2.7/dist-packages/django/core/handlers/base.py", line 114, in get_response
    response = wrapped_callback(request, *callback_args, **callback_kwargs)
  File "/usr/local/lib/python2.7/dist-packages/django/views/generic/base.py", line 69, in view
    return self.dispatch(request, *args, **kwargs)
  File "/usr/local/lib/python2.7/dist-packages/django/utils/decorators.py", line 29, in _wrapper
    return bound_func(*args, **kwargs)
  File "/usr/local/lib/python2.7/dist-packages/django/contrib/auth/decorators.py", line 22, in _wrapped_view
    return view_func(request, *args, **kwargs)
  File "/usr/local/lib/python2.7/dist-packages/django/utils/decorators.py", line 25, in bound_func
    return func(self, *args2, **kwargs2)
  File "/home/mikhail/EclipseWorkspace/oncoFinder2/profiles/views.py", line 154, in dispatch
    return super(CreateDocument, self).dispatch(request, *args, **kwargs)
  File "/usr/local/lib/python2.7/dist-packages/django/views/generic/base.py", line 87, in dispatch
    return handler(request, *args, **kwargs)
  File "/usr/local/lib/python2.7/dist-packages/django/views/generic/edit.py", line 205, in post
    return super(BaseCreateView, self).post(request, *args, **kwargs)
  File "/usr/local/lib/python2.7/dist-packages/django/views/generic/edit.py", line 171, in post
    return self.form_valid(form)
  File "/home/mikhail/EclipseWorkspace/oncoFinder2/profiles/views.py", line 205, in form_valid
    df.to_csv(new_file, sep='\t', encoding='utf-8')
  File "/usr/local/lib/python2.7/dist-packages/pandas-0.13.1_674_g95090fd-py2.7-linux-i686.egg/pandas/util/decorators.py", line 60, in wrapper
    return func(*args, **kwargs)
  File "/usr/local/lib/python2.7/dist-packages/pandas-0.13.1_674_g95090fd-py2.7-linux-i686.egg/pandas/core/frame.py", line 1139, in to_csv
    formatter.save()
  File "/usr/local/lib/python2.7/dist-packages/pandas-0.13.1_674_g95090fd-py2.7-linux-i686.egg/pandas/core/format.py", line 1182, in save
    self._save()
  File "/usr/local/lib/python2.7/dist-packages/pandas-0.13.1_674_g95090fd-py2.7-linux-i686.egg/pandas/core/format.py", line 1282, in _save
    self._save_chunk(start_i, end_i)
  File "/usr/local/lib/python2.7/dist-packages/pandas-0.13.1_674_g95090fd-py2.7-linux-i686.egg/pandas/core/format.py", line 1305, in _save_chunk
    lib.write_csv_rows(self.data, ix, self.nlevels, self.cols, self.writer)
  File "lib.pyx", line 858, in pandas.lib.write_csv_rows (pandas/lib.c:15047)
  File "/usr/local/lib/python2.7/dist-packages/pandas-0.13.1_674_g95090fd-py2.7-linux-i686.egg/pandas/core/common.py", line 2430, in writerows
    data = data.decode("utf-8")
  File "/usr/lib/python2.7/encodings/utf_8.py", line 16, in decode
    return codecs.utf_8_decode(input, errors, True)
UnicodeDecodeError: 'utf8' codec can't decode byte 0xd1 in position 33491: invalid continuation byte
