2015-12-04 00:17:51,809 ERROR base 3695 -1407198400 Internal Server Error: /shambhala/prevfiles/
Traceback (most recent call last):
  File "/usr/local/lib/python2.7/dist-packages/django/core/handlers/base.py", line 112, in get_response
    response = wrapped_callback(request, *callback_args, **callback_kwargs)
  File "/usr/local/lib/python2.7/dist-packages/django/views/generic/base.py", line 69, in view
    return self.dispatch(request, *args, **kwargs)
  File "/usr/local/lib/python2.7/dist-packages/django/utils/decorators.py", line 29, in _wrapper
    return bound_func(*args, **kwargs)
  File "/usr/local/lib/python2.7/dist-packages/django/contrib/auth/decorators.py", line 22, in _wrapped_view
    return view_func(request, *args, **kwargs)
  File "/usr/local/lib/python2.7/dist-packages/django/utils/decorators.py", line 25, in bound_func
    return func(self, *args2, **kwargs2)
  File "/home/mikhail/EclipseWorkspace/oncoFinder2/oncoFinder2/core/harmony_views.py", line 236, in dispatch
    return super(HarmonyPrevFiles, self).dispatch(request, *args, **kwargs)
  File "/usr/local/lib/python2.7/dist-packages/django/views/generic/base.py", line 87, in dispatch
    return handler(request, *args, **kwargs)
  File "/usr/local/lib/python2.7/dist-packages/django/views/generic/base.py", line 154, in get
    context = self.get_context_data(**kwargs)
  File "/home/mikhail/EclipseWorkspace/oncoFinder2/oncoFinder2/core/harmony_views.py", line 243, in get_context_data
    dirs = os.listdir(path)
OSError: [Errno 2] No such file or directory: '/home/mikhail/EclipseWorkspace/oncoFinder2/oncoFinder2/oncoFinder2/media/XPN/'
2015-12-04 00:19:18,826 ERROR base 3695 -1423983808 Internal Server Error: /shambhala/prevfiles/
Traceback (most recent call last):
  File "/usr/local/lib/python2.7/dist-packages/django/core/handlers/base.py", line 112, in get_response
    response = wrapped_callback(request, *callback_args, **callback_kwargs)
  File "/usr/local/lib/python2.7/dist-packages/django/views/generic/base.py", line 69, in view
    return self.dispatch(request, *args, **kwargs)
  File "/usr/local/lib/python2.7/dist-packages/django/utils/decorators.py", line 29, in _wrapper
    return bound_func(*args, **kwargs)
  File "/usr/local/lib/python2.7/dist-packages/django/contrib/auth/decorators.py", line 22, in _wrapped_view
    return view_func(request, *args, **kwargs)
  File "/usr/local/lib/python2.7/dist-packages/django/utils/decorators.py", line 25, in bound_func
    return func(self, *args2, **kwargs2)
  File "/home/mikhail/EclipseWorkspace/oncoFinder2/oncoFinder2/core/harmony_views.py", line 236, in dispatch
    return super(HarmonyPrevFiles, self).dispatch(request, *args, **kwargs)
  File "/usr/local/lib/python2.7/dist-packages/django/views/generic/base.py", line 87, in dispatch
    return handler(request, *args, **kwargs)
  File "/usr/local/lib/python2.7/dist-packages/django/views/generic/base.py", line 154, in get
    context = self.get_context_data(**kwargs)
  File "/home/mikhail/EclipseWorkspace/oncoFinder2/oncoFinder2/core/harmony_views.py", line 243, in get_context_data
    dirs = os.listdir(path)
OSError: [Errno 2] No such file or directory: '/home/mikhail/EclipseWorkspace/oncoFinder2/oncoFinder2/oncoFinder2/media/XPN/'
2015-12-04 00:20:45,796 ERROR base 6118 -1357833408 Internal Server Error: /shambhala/done/
Traceback (most recent call last):
  File "/usr/local/lib/python2.7/dist-packages/django/core/handlers/base.py", line 112, in get_response
    response = wrapped_callback(request, *callback_args, **callback_kwargs)
  File "/usr/local/lib/python2.7/dist-packages/django/views/generic/base.py", line 69, in view
    return self.dispatch(request, *args, **kwargs)
  File "/usr/local/lib/python2.7/dist-packages/django/utils/decorators.py", line 29, in _wrapper
    return bound_func(*args, **kwargs)
  File "/usr/local/lib/python2.7/dist-packages/django/contrib/auth/decorators.py", line 22, in _wrapped_view
    return view_func(request, *args, **kwargs)
  File "/usr/local/lib/python2.7/dist-packages/django/utils/decorators.py", line 25, in bound_func
    return func(self, *args2, **kwargs2)
  File "/home/mikhail/EclipseWorkspace/oncoFinder2/oncoFinder2/core/harmony_views.py", line 121, in dispatch
    return super(ShambalaDone, self).dispatch(request, *args, **kwargs)
  File "/usr/local/lib/python2.7/dist-packages/django/views/generic/base.py", line 87, in dispatch
    return handler(request, *args, **kwargs)
  File "/usr/local/lib/python2.7/dist-packages/django/views/generic/base.py", line 154, in get
    context = self.get_context_data(**kwargs)
  File "/home/mikhail/EclipseWorkspace/oncoFinder2/oncoFinder2/core/harmony_views.py", line 127, in get_context_data
    raise
TypeError: exceptions must be old-style classes or derived from BaseException, not NoneType
2015-12-04 00:26:57,367 ERROR base 6204 -1357833408 Internal Server Error: /shambhala/done/
Traceback (most recent call last):
  File "/usr/local/lib/python2.7/dist-packages/django/core/handlers/base.py", line 137, in get_response
    response = response.render()
  File "/usr/local/lib/python2.7/dist-packages/django/template/response.py", line 105, in render
    self.content = self.rendered_content
  File "/usr/local/lib/python2.7/dist-packages/django/template/response.py", line 80, in rendered_content
    template = self.resolve_template(self.template_name)
  File "/usr/local/lib/python2.7/dist-packages/django/template/response.py", line 56, in resolve_template
    return loader.select_template(template)
  File "/usr/local/lib/python2.7/dist-packages/django/template/loader.py", line 180, in select_template
    return get_template(template_name)
  File "/usr/local/lib/python2.7/dist-packages/django/template/loader.py", line 138, in get_template
    template, origin = find_template(template_name)
  File "/usr/local/lib/python2.7/dist-packages/django/template/loader.py", line 127, in find_template
    source, display_name = loader(name, dirs)
  File "/usr/local/lib/python2.7/dist-packages/django/template/loader.py", line 43, in __call__
    return self.load_template(template_name, template_dirs)
  File "/usr/local/lib/python2.7/dist-packages/django/template/loader.py", line 49, in load_template
    template = get_template_from_string(source, origin, template_name)
  File "/usr/local/lib/python2.7/dist-packages/django/template/loader.py", line 149, in get_template_from_string
    return Template(source, origin, name)
  File "/usr/local/lib/python2.7/dist-packages/debug_toolbar/panels/templates/panel.py", line 101, in new_template_init
    old_template_init(self, template_string, origin, name)
  File "/usr/local/lib/python2.7/dist-packages/django/template/base.py", line 125, in __init__
    self.nodelist = compile_string(template_string, origin)
  File "/usr/local/lib/python2.7/dist-packages/django/template/base.py", line 153, in compile_string
    return parser.parse()
  File "/usr/local/lib/python2.7/dist-packages/django/template/base.py", line 278, in parse
    compiled_result = compile_func(self, token)
  File "/usr/local/lib/python2.7/dist-packages/django/template/loader_tags.py", line 215, in do_extends
    nodelist = parser.parse()
  File "/usr/local/lib/python2.7/dist-packages/django/template/base.py", line 278, in parse
    compiled_result = compile_func(self, token)
  File "/usr/local/lib/python2.7/dist-packages/django/template/loader_tags.py", line 190, in do_block
    nodelist = parser.parse(('endblock',))
  File "/usr/local/lib/python2.7/dist-packages/django/template/base.py", line 278, in parse
    compiled_result = compile_func(self, token)
  File "/usr/local/lib/python2.7/dist-packages/django/template/defaulttags.py", line 806, in do_for
    nodelist_loop = parser.parse(('empty', 'endfor',))
  File "/usr/local/lib/python2.7/dist-packages/django/template/base.py", line 276, in parse
    self.invalid_block_tag(token, command, parse_until)
  File "/usr/local/lib/python2.7/dist-packages/django/template/base.py", line 331, in invalid_block_tag
    (command, get_text_list(["'%s'" % p for p in parse_until])))
TemplateSyntaxError: Invalid block tag: 'endif', expected 'empty' or 'endfor'
2015-12-04 00:29:17,338 ERROR base 9508 -1357833408 Internal Server Error: /shambhala/done/
Traceback (most recent call last):
  File "/usr/local/lib/python2.7/dist-packages/django/core/handlers/base.py", line 112, in get_response
    response = wrapped_callback(request, *callback_args, **callback_kwargs)
  File "/usr/local/lib/python2.7/dist-packages/django/views/generic/base.py", line 69, in view
    return self.dispatch(request, *args, **kwargs)
  File "/usr/local/lib/python2.7/dist-packages/django/utils/decorators.py", line 29, in _wrapper
    return bound_func(*args, **kwargs)
  File "/usr/local/lib/python2.7/dist-packages/django/contrib/auth/decorators.py", line 22, in _wrapped_view
    return view_func(request, *args, **kwargs)
  File "/usr/local/lib/python2.7/dist-packages/django/utils/decorators.py", line 25, in bound_func
    return func(self, *args2, **kwargs2)
  File "/home/mikhail/EclipseWorkspace/oncoFinder2/oncoFinder2/core/harmony_views.py", line 121, in dispatch
    return super(ShambalaDone, self).dispatch(request, *args, **kwargs)
  File "/usr/local/lib/python2.7/dist-packages/django/views/generic/base.py", line 87, in dispatch
    return handler(request, *args, **kwargs)
  File "/usr/local/lib/python2.7/dist-packages/django/views/generic/base.py", line 154, in get
    context = self.get_context_data(**kwargs)
  File "/home/mikhail/EclipseWorkspace/oncoFinder2/oncoFinder2/core/harmony_views.py", line 126, in get_context_data
    context['documents'] =  ShambalaDocument.objects.all().orderby('created_at')
AttributeError: 'QuerySet' object has no attribute 'orderby'
2015-12-04 00:30:58,233 ERROR base 9669 -1367344320 Internal Server Error: /shambhala/done/
Traceback (most recent call last):
  File "/usr/local/lib/python2.7/dist-packages/django/core/handlers/base.py", line 137, in get_response
    response = response.render()
  File "/usr/local/lib/python2.7/dist-packages/django/template/response.py", line 105, in render
    self.content = self.rendered_content
  File "/usr/local/lib/python2.7/dist-packages/django/template/response.py", line 80, in rendered_content
    template = self.resolve_template(self.template_name)
  File "/usr/local/lib/python2.7/dist-packages/django/template/response.py", line 56, in resolve_template
    return loader.select_template(template)
  File "/usr/local/lib/python2.7/dist-packages/django/template/loader.py", line 180, in select_template
    return get_template(template_name)
  File "/usr/local/lib/python2.7/dist-packages/django/template/loader.py", line 138, in get_template
    template, origin = find_template(template_name)
  File "/usr/local/lib/python2.7/dist-packages/django/template/loader.py", line 127, in find_template
    source, display_name = loader(name, dirs)
  File "/usr/local/lib/python2.7/dist-packages/django/template/loader.py", line 43, in __call__
    return self.load_template(template_name, template_dirs)
  File "/usr/local/lib/python2.7/dist-packages/django/template/loader.py", line 49, in load_template
    template = get_template_from_string(source, origin, template_name)
  File "/usr/local/lib/python2.7/dist-packages/django/template/loader.py", line 149, in get_template_from_string
    return Template(source, origin, name)
  File "/usr/local/lib/python2.7/dist-packages/debug_toolbar/panels/templates/panel.py", line 101, in new_template_init
    old_template_init(self, template_string, origin, name)
  File "/usr/local/lib/python2.7/dist-packages/django/template/base.py", line 125, in __init__
    self.nodelist = compile_string(template_string, origin)
  File "/usr/local/lib/python2.7/dist-packages/django/template/base.py", line 153, in compile_string
    return parser.parse()
  File "/usr/local/lib/python2.7/dist-packages/django/template/base.py", line 278, in parse
    compiled_result = compile_func(self, token)
  File "/usr/local/lib/python2.7/dist-packages/django/template/loader_tags.py", line 215, in do_extends
    nodelist = parser.parse()
  File "/usr/local/lib/python2.7/dist-packages/django/template/base.py", line 278, in parse
    compiled_result = compile_func(self, token)
  File "/usr/local/lib/python2.7/dist-packages/django/template/loader_tags.py", line 190, in do_block
    nodelist = parser.parse(('endblock',))
  File "/usr/local/lib/python2.7/dist-packages/django/template/base.py", line 278, in parse
    compiled_result = compile_func(self, token)
  File "/usr/local/lib/python2.7/dist-packages/django/template/defaulttags.py", line 806, in do_for
    nodelist_loop = parser.parse(('empty', 'endfor',))
  File "/usr/local/lib/python2.7/dist-packages/django/template/base.py", line 276, in parse
    self.invalid_block_tag(token, command, parse_until)
  File "/usr/local/lib/python2.7/dist-packages/django/template/base.py", line 331, in invalid_block_tag
    (command, get_text_list(["'%s'" % p for p in parse_until])))
TemplateSyntaxError: Invalid block tag: 'endif', expected 'empty' or 'endfor'
2015-12-04 00:31:01,849 ERROR base 9669 -1386222784 Internal Server Error: /shambhala/done/
Traceback (most recent call last):
  File "/usr/local/lib/python2.7/dist-packages/django/core/handlers/base.py", line 137, in get_response
    response = response.render()
  File "/usr/local/lib/python2.7/dist-packages/django/template/response.py", line 105, in render
    self.content = self.rendered_content
  File "/usr/local/lib/python2.7/dist-packages/django/template/response.py", line 80, in rendered_content
    template = self.resolve_template(self.template_name)
  File "/usr/local/lib/python2.7/dist-packages/django/template/response.py", line 56, in resolve_template
    return loader.select_template(template)
  File "/usr/local/lib/python2.7/dist-packages/django/template/loader.py", line 180, in select_template
    return get_template(template_name)
  File "/usr/local/lib/python2.7/dist-packages/django/template/loader.py", line 138, in get_template
    template, origin = find_template(template_name)
  File "/usr/local/lib/python2.7/dist-packages/django/template/loader.py", line 127, in find_template
    source, display_name = loader(name, dirs)
  File "/usr/local/lib/python2.7/dist-packages/django/template/loader.py", line 43, in __call__
    return self.load_template(template_name, template_dirs)
  File "/usr/local/lib/python2.7/dist-packages/django/template/loader.py", line 49, in load_template
    template = get_template_from_string(source, origin, template_name)
  File "/usr/local/lib/python2.7/dist-packages/django/template/loader.py", line 149, in get_template_from_string
    return Template(source, origin, name)
  File "/usr/local/lib/python2.7/dist-packages/debug_toolbar/panels/templates/panel.py", line 101, in new_template_init
    old_template_init(self, template_string, origin, name)
  File "/usr/local/lib/python2.7/dist-packages/django/template/base.py", line 125, in __init__
    self.nodelist = compile_string(template_string, origin)
  File "/usr/local/lib/python2.7/dist-packages/django/template/base.py", line 153, in compile_string
    return parser.parse()
  File "/usr/local/lib/python2.7/dist-packages/django/template/base.py", line 278, in parse
    compiled_result = compile_func(self, token)
  File "/usr/local/lib/python2.7/dist-packages/django/template/loader_tags.py", line 215, in do_extends
    nodelist = parser.parse()
  File "/usr/local/lib/python2.7/dist-packages/django/template/base.py", line 278, in parse
    compiled_result = compile_func(self, token)
  File "/usr/local/lib/python2.7/dist-packages/django/template/loader_tags.py", line 190, in do_block
    nodelist = parser.parse(('endblock',))
  File "/usr/local/lib/python2.7/dist-packages/django/template/base.py", line 278, in parse
    compiled_result = compile_func(self, token)
  File "/usr/local/lib/python2.7/dist-packages/django/template/defaulttags.py", line 806, in do_for
    nodelist_loop = parser.parse(('empty', 'endfor',))
  File "/usr/local/lib/python2.7/dist-packages/django/template/base.py", line 276, in parse
    self.invalid_block_tag(token, command, parse_until)
  File "/usr/local/lib/python2.7/dist-packages/django/template/base.py", line 331, in invalid_block_tag
    (command, get_text_list(["'%s'" % p for p in parse_until])))
TemplateSyntaxError: Invalid block tag: 'endif', expected 'empty' or 'endfor'
2015-12-08 14:40:46,255 ERROR base 5749 -1403008192 Internal Server Error: /document/doc8948/
Traceback (most recent call last):
  File "/usr/local/lib/python2.7/dist-packages/django/core/handlers/base.py", line 112, in get_response
    response = wrapped_callback(request, *callback_args, **callback_kwargs)
  File "/usr/local/lib/python2.7/dist-packages/django/views/generic/base.py", line 69, in view
    return self.dispatch(request, *args, **kwargs)
  File "/usr/local/lib/python2.7/dist-packages/django/utils/decorators.py", line 29, in _wrapper
    return bound_func(*args, **kwargs)
  File "/usr/local/lib/python2.7/dist-packages/django/contrib/auth/decorators.py", line 22, in _wrapped_view
    return view_func(request, *args, **kwargs)
  File "/usr/local/lib/python2.7/dist-packages/django/utils/decorators.py", line 25, in bound_func
    return func(self, *args2, **kwargs2)
  File "/home/mikhail/EclipseWorkspace/oncoFinder2/oncoFinder2/profiles/views.py", line 300, in dispatch
    return super(DocumentDetail, self).dispatch(request, *args, **kwargs)
  File "/usr/local/lib/python2.7/dist-packages/django/views/generic/base.py", line 87, in dispatch
    return handler(request, *args, **kwargs)
  File "/usr/local/lib/python2.7/dist-packages/django/views/generic/detail.py", line 111, in get
    context = self.get_context_data(object=self.object)
  File "/home/mikhail/EclipseWorkspace/oncoFinder2/oncoFinder2/profiles/views.py", line 308, in get_context_data
    dialect = sniffer.sniff(open(filename, 'r').read(), delimiters='\t,;') # defining the separator of the csv file
IOError: [Errno 2] No such file or directory: u'/home/mikhail/EclipseWorkspace/oncoFinder2/oncoFinder2/oncoFinder2/media/users/admin/customarray-test/input/gcrma6.csv'
2015-12-10 18:31:27,011 ERROR base 12811 -1412445376 Internal Server Error: /document/doc10091/Tumour_X5500024052861011409506.H02.CEL/
Traceback (most recent call last):
  File "/usr/local/lib/python2.7/dist-packages/django/core/handlers/base.py", line 112, in get_response
    response = wrapped_callback(request, *callback_args, **callback_kwargs)
  File "/usr/local/lib/python2.7/dist-packages/django/views/generic/base.py", line 69, in view
    return self.dispatch(request, *args, **kwargs)
  File "/usr/local/lib/python2.7/dist-packages/django/utils/decorators.py", line 29, in _wrapper
    return bound_func(*args, **kwargs)
  File "/usr/local/lib/python2.7/dist-packages/django/contrib/auth/decorators.py", line 22, in _wrapped_view
    return view_func(request, *args, **kwargs)
  File "/usr/local/lib/python2.7/dist-packages/django/utils/decorators.py", line 25, in bound_func
    return func(self, *args2, **kwargs2)
  File "/home/mikhail/EclipseWorkspace/oncoFinder2/oncoFinder2/profiles/views.py", line 401, in dispatch
    return super(SampleDetail, self).dispatch(request, *args, **kwargs)
  File "/usr/local/lib/python2.7/dist-packages/django/views/generic/base.py", line 87, in dispatch
    return handler(request, *args, **kwargs)
  File "/usr/local/lib/python2.7/dist-packages/django/views/generic/detail.py", line 111, in get
    context = self.get_context_data(object=self.object)
  File "/home/mikhail/EclipseWorkspace/oncoFinder2/oncoFinder2/profiles/views.py", line 422, in get_context_data
    raise Exception('sample')
Exception: sample
2015-12-10 18:34:37,757 ERROR base 14418 -1358881984 Internal Server Error: /document/ajaxpathdetail/
Traceback (most recent call last):
  File "/usr/local/lib/python2.7/dist-packages/django/core/handlers/base.py", line 112, in get_response
    response = wrapped_callback(request, *callback_args, **callback_kwargs)
  File "/usr/local/lib/python2.7/dist-packages/django/views/generic/base.py", line 69, in view
    return self.dispatch(request, *args, **kwargs)
  File "/usr/local/lib/python2.7/dist-packages/django/utils/decorators.py", line 29, in _wrapper
    return bound_func(*args, **kwargs)
  File "/usr/local/lib/python2.7/dist-packages/django/contrib/auth/decorators.py", line 22, in _wrapped_view
    return view_func(request, *args, **kwargs)
  File "/usr/local/lib/python2.7/dist-packages/django/utils/decorators.py", line 25, in bound_func
    return func(self, *args2, **kwargs2)
  File "/home/mikhail/EclipseWorkspace/oncoFinder2/oncoFinder2/profiles/views.py", line 682, in dispatch
    return super(AjaxPathDetail, self).dispatch(request, *args, **kwargs)
  File "/usr/local/lib/python2.7/dist-packages/django/views/generic/base.py", line 87, in dispatch
    return handler(request, *args, **kwargs)
  File "/home/mikhail/EclipseWorkspace/oncoFinder2/oncoFinder2/profiles/views.py", line 676, in post
    return self.render_to_response(self.get_context_data( request, **kwargs), **kwargs)
  File "/home/mikhail/EclipseWorkspace/oncoFinder2/oncoFinder2/profiles/views.py", line 703, in get_context_data
    df_file_cnr = read_excel(request.POST['docpath'], index_col='SYMBOL')
  File "/usr/local/lib/python2.7/dist-packages/pandas/io/excel.py", line 151, in read_excel
    return ExcelFile(io, engine=engine).parse(sheetname=sheetname, **kwds)
  File "/usr/local/lib/python2.7/dist-packages/pandas/io/excel.py", line 287, in parse
    **kwds)
  File "/usr/local/lib/python2.7/dist-packages/pandas/io/excel.py", line 435, in _parse_excel
    output[asheetname] = parser.read()
  File "/usr/local/lib/python2.7/dist-packages/pandas/io/parsers.py", line 715, in read
    ret = self._engine.read(nrows)
  File "/usr/local/lib/python2.7/dist-packages/pandas/io/parsers.py", line 1569, in read
    index, columns = self._make_index(data, alldata, columns, indexnamerow)
  File "/usr/local/lib/python2.7/dist-packages/pandas/io/parsers.py", line 882, in _make_index
    index = self._get_simple_index(alldata, columns)
  File "/usr/local/lib/python2.7/dist-packages/pandas/io/parsers.py", line 916, in _get_simple_index
    i = ix(idx)
  File "/usr/local/lib/python2.7/dist-packages/pandas/io/parsers.py", line 910, in ix
    raise ValueError('Index %s invalid' % col)
ValueError: Index SYMBOL invalid
2015-12-10 18:35:00,074 ERROR base 14418 -1358881984 Internal Server Error: /document/ajaxpathdetail/
Traceback (most recent call last):
  File "/usr/local/lib/python2.7/dist-packages/django/core/handlers/base.py", line 112, in get_response
    response = wrapped_callback(request, *callback_args, **callback_kwargs)
  File "/usr/local/lib/python2.7/dist-packages/django/views/generic/base.py", line 69, in view
    return self.dispatch(request, *args, **kwargs)
  File "/usr/local/lib/python2.7/dist-packages/django/utils/decorators.py", line 29, in _wrapper
    return bound_func(*args, **kwargs)
  File "/usr/local/lib/python2.7/dist-packages/django/contrib/auth/decorators.py", line 22, in _wrapped_view
    return view_func(request, *args, **kwargs)
  File "/usr/local/lib/python2.7/dist-packages/django/utils/decorators.py", line 25, in bound_func
    return func(self, *args2, **kwargs2)
  File "/home/mikhail/EclipseWorkspace/oncoFinder2/oncoFinder2/profiles/views.py", line 682, in dispatch
    return super(AjaxPathDetail, self).dispatch(request, *args, **kwargs)
  File "/usr/local/lib/python2.7/dist-packages/django/views/generic/base.py", line 87, in dispatch
    return handler(request, *args, **kwargs)
  File "/home/mikhail/EclipseWorkspace/oncoFinder2/oncoFinder2/profiles/views.py", line 676, in post
    return self.render_to_response(self.get_context_data( request, **kwargs), **kwargs)
  File "/home/mikhail/EclipseWorkspace/oncoFinder2/oncoFinder2/profiles/views.py", line 703, in get_context_data
    df_file_cnr = read_excel(request.POST['docpath'], index_col='SYMBOL')
  File "/usr/local/lib/python2.7/dist-packages/pandas/io/excel.py", line 151, in read_excel
    return ExcelFile(io, engine=engine).parse(sheetname=sheetname, **kwds)
  File "/usr/local/lib/python2.7/dist-packages/pandas/io/excel.py", line 287, in parse
    **kwds)
  File "/usr/local/lib/python2.7/dist-packages/pandas/io/excel.py", line 435, in _parse_excel
    output[asheetname] = parser.read()
  File "/usr/local/lib/python2.7/dist-packages/pandas/io/parsers.py", line 715, in read
    ret = self._engine.read(nrows)
  File "/usr/local/lib/python2.7/dist-packages/pandas/io/parsers.py", line 1569, in read
    index, columns = self._make_index(data, alldata, columns, indexnamerow)
  File "/usr/local/lib/python2.7/dist-packages/pandas/io/parsers.py", line 882, in _make_index
    index = self._get_simple_index(alldata, columns)
  File "/usr/local/lib/python2.7/dist-packages/pandas/io/parsers.py", line 916, in _get_simple_index
    i = ix(idx)
  File "/usr/local/lib/python2.7/dist-packages/pandas/io/parsers.py", line 910, in ix
    raise ValueError('Index %s invalid' % col)
ValueError: Index SYMBOL invalid
2015-12-10 18:35:47,908 ERROR base 14933 -1358881984 Internal Server Error: /document/ajaxpathdetail/
Traceback (most recent call last):
  File "/usr/local/lib/python2.7/dist-packages/django/core/handlers/base.py", line 112, in get_response
    response = wrapped_callback(request, *callback_args, **callback_kwargs)
  File "/usr/local/lib/python2.7/dist-packages/django/views/generic/base.py", line 69, in view
    return self.dispatch(request, *args, **kwargs)
  File "/usr/local/lib/python2.7/dist-packages/django/utils/decorators.py", line 29, in _wrapper
    return bound_func(*args, **kwargs)
  File "/usr/local/lib/python2.7/dist-packages/django/contrib/auth/decorators.py", line 22, in _wrapped_view
    return view_func(request, *args, **kwargs)
  File "/usr/local/lib/python2.7/dist-packages/django/utils/decorators.py", line 25, in bound_func
    return func(self, *args2, **kwargs2)
  File "/home/mikhail/EclipseWorkspace/oncoFinder2/oncoFinder2/profiles/views.py", line 682, in dispatch
    return super(AjaxPathDetail, self).dispatch(request, *args, **kwargs)
  File "/usr/local/lib/python2.7/dist-packages/django/views/generic/base.py", line 87, in dispatch
    return handler(request, *args, **kwargs)
  File "/home/mikhail/EclipseWorkspace/oncoFinder2/oncoFinder2/profiles/views.py", line 676, in post
    return self.render_to_response(self.get_context_data( request, **kwargs), **kwargs)
  File "/home/mikhail/EclipseWorkspace/oncoFinder2/oncoFinder2/profiles/views.py", line 703, in get_context_data
    df_file_cnr = read_excel(request.POST['docpath'], index_col='SYMBOL')
  File "/usr/local/lib/python2.7/dist-packages/pandas/io/excel.py", line 151, in read_excel
    return ExcelFile(io, engine=engine).parse(sheetname=sheetname, **kwds)
  File "/usr/local/lib/python2.7/dist-packages/pandas/io/excel.py", line 287, in parse
    **kwds)
  File "/usr/local/lib/python2.7/dist-packages/pandas/io/excel.py", line 435, in _parse_excel
    output[asheetname] = parser.read()
  File "/usr/local/lib/python2.7/dist-packages/pandas/io/parsers.py", line 715, in read
    ret = self._engine.read(nrows)
  File "/usr/local/lib/python2.7/dist-packages/pandas/io/parsers.py", line 1569, in read
    index, columns = self._make_index(data, alldata, columns, indexnamerow)
  File "/usr/local/lib/python2.7/dist-packages/pandas/io/parsers.py", line 882, in _make_index
    index = self._get_simple_index(alldata, columns)
  File "/usr/local/lib/python2.7/dist-packages/pandas/io/parsers.py", line 916, in _get_simple_index
    i = ix(idx)
  File "/usr/local/lib/python2.7/dist-packages/pandas/io/parsers.py", line 910, in ix
    raise ValueError('Index %s invalid' % col)
ValueError: Index SYMBOL invalid
2015-12-10 18:36:44,326 ERROR base 15368 -1358881984 Internal Server Error: /document/ajaxpathdetail/
Traceback (most recent call last):
  File "/usr/local/lib/python2.7/dist-packages/django/core/handlers/base.py", line 112, in get_response
    response = wrapped_callback(request, *callback_args, **callback_kwargs)
  File "/usr/local/lib/python2.7/dist-packages/django/views/generic/base.py", line 69, in view
    return self.dispatch(request, *args, **kwargs)
  File "/usr/local/lib/python2.7/dist-packages/django/utils/decorators.py", line 29, in _wrapper
    return bound_func(*args, **kwargs)
  File "/usr/local/lib/python2.7/dist-packages/django/contrib/auth/decorators.py", line 22, in _wrapped_view
    return view_func(request, *args, **kwargs)
  File "/usr/local/lib/python2.7/dist-packages/django/utils/decorators.py", line 25, in bound_func
    return func(self, *args2, **kwargs2)
  File "/home/mikhail/EclipseWorkspace/oncoFinder2/oncoFinder2/profiles/views.py", line 682, in dispatch
    return super(AjaxPathDetail, self).dispatch(request, *args, **kwargs)
  File "/usr/local/lib/python2.7/dist-packages/django/views/generic/base.py", line 87, in dispatch
    return handler(request, *args, **kwargs)
  File "/home/mikhail/EclipseWorkspace/oncoFinder2/oncoFinder2/profiles/views.py", line 676, in post
    return self.render_to_response(self.get_context_data( request, **kwargs), **kwargs)
  File "/home/mikhail/EclipseWorkspace/oncoFinder2/oncoFinder2/profiles/views.py", line 704, in get_context_data
    raise Exception(request.POST['docpath'])
Exception: /home/mikhail/EclipseWorkspace/oncoFinder2/oncoFinder2/oncoFinder2/media/users/admin/aliper/process/cnr_output_gcrma11.csv.xlsx
2015-12-10 18:37:21,282 ERROR base 15571 -1358955712 Internal Server Error: /document/ajaxpathdetail/
Traceback (most recent call last):
  File "/usr/local/lib/python2.7/dist-packages/django/core/handlers/base.py", line 112, in get_response
    response = wrapped_callback(request, *callback_args, **callback_kwargs)
  File "/usr/local/lib/python2.7/dist-packages/django/views/generic/base.py", line 69, in view
    return self.dispatch(request, *args, **kwargs)
  File "/usr/local/lib/python2.7/dist-packages/django/utils/decorators.py", line 29, in _wrapper
    return bound_func(*args, **kwargs)
  File "/usr/local/lib/python2.7/dist-packages/django/contrib/auth/decorators.py", line 22, in _wrapped_view
    return view_func(request, *args, **kwargs)
  File "/usr/local/lib/python2.7/dist-packages/django/utils/decorators.py", line 25, in bound_func
    return func(self, *args2, **kwargs2)
  File "/home/mikhail/EclipseWorkspace/oncoFinder2/oncoFinder2/profiles/views.py", line 682, in dispatch
    return super(AjaxPathDetail, self).dispatch(request, *args, **kwargs)
  File "/usr/local/lib/python2.7/dist-packages/django/views/generic/base.py", line 87, in dispatch
    return handler(request, *args, **kwargs)
  File "/home/mikhail/EclipseWorkspace/oncoFinder2/oncoFinder2/profiles/views.py", line 676, in post
    return self.render_to_response(self.get_context_data( request, **kwargs), **kwargs)
  File "/home/mikhail/EclipseWorkspace/oncoFinder2/oncoFinder2/profiles/views.py", line 704, in get_context_data
    raise Exception(df_file_cnr.columns)
Exception: Index([u'Normal_GSM370578.CEL', u'Normal_GSM370579.CEL', u'Normal_GSM370580.CEL', u'Normal_GSM370581.CEL', u'Tumour_X5500024052861011409506.H02.CEL', u'Tumour_X5500024052861011409506.H03.CEL', u'Tumour_X5500024052861011409506.H04.CEL', u'Tumour_X5500024052861011409506.H05.CEL', u'Tumour_X5500024052861011409506.H06.CEL', u'Tumour_X5500024052861011409506.H07.CEL', u'Tumour_X5500024052861011409506.H08.CEL', u'Tumour_X5500024052861011409506.H09.CEL', u'Tumour_X5500024052861011409506.H10.CEL', u'Tumour_X5500024052861011409506.H11.CEL', u'gMean_norm', u'mean', u'p_value', u'q_value', u'std'], dtype='object')
2015-12-10 18:42:49,604 ERROR base 17780 -1358955712 Internal Server Error: /document/doc10091/Tumour_X5500024052861011409506.H02.CEL/
Traceback (most recent call last):
  File "/usr/local/lib/python2.7/dist-packages/django/core/handlers/base.py", line 112, in get_response
    response = wrapped_callback(request, *callback_args, **callback_kwargs)
  File "/usr/local/lib/python2.7/dist-packages/django/views/generic/base.py", line 69, in view
    return self.dispatch(request, *args, **kwargs)
  File "/usr/local/lib/python2.7/dist-packages/django/utils/decorators.py", line 29, in _wrapper
    return bound_func(*args, **kwargs)
  File "/usr/local/lib/python2.7/dist-packages/django/contrib/auth/decorators.py", line 22, in _wrapped_view
    return view_func(request, *args, **kwargs)
  File "/usr/local/lib/python2.7/dist-packages/django/utils/decorators.py", line 25, in bound_func
    return func(self, *args2, **kwargs2)
  File "/home/mikhail/EclipseWorkspace/oncoFinder2/oncoFinder2/profiles/views.py", line 401, in dispatch
    return super(SampleDetail, self).dispatch(request, *args, **kwargs)
  File "/usr/local/lib/python2.7/dist-packages/django/views/generic/base.py", line 87, in dispatch
    return handler(request, *args, **kwargs)
  File "/usr/local/lib/python2.7/dist-packages/django/views/generic/detail.py", line 111, in get
    context = self.get_context_data(object=self.object)
  File "/home/mikhail/EclipseWorkspace/oncoFinder2/oncoFinder2/profiles/views.py", line 417, in get_context_data
    index_col='SYMBOL')
  File "/usr/local/lib/python2.7/dist-packages/pandas/io/excel.py", line 151, in read_excel
    return ExcelFile(io, engine=engine).parse(sheetname=sheetname, **kwds)
  File "/usr/local/lib/python2.7/dist-packages/pandas/io/excel.py", line 287, in parse
    **kwds)
  File "/usr/local/lib/python2.7/dist-packages/pandas/io/excel.py", line 435, in _parse_excel
    output[asheetname] = parser.read()
  File "/usr/local/lib/python2.7/dist-packages/pandas/io/parsers.py", line 715, in read
    ret = self._engine.read(nrows)
  File "/usr/local/lib/python2.7/dist-packages/pandas/io/parsers.py", line 1569, in read
    index, columns = self._make_index(data, alldata, columns, indexnamerow)
  File "/usr/local/lib/python2.7/dist-packages/pandas/io/parsers.py", line 882, in _make_index
    index = self._get_simple_index(alldata, columns)
  File "/usr/local/lib/python2.7/dist-packages/pandas/io/parsers.py", line 916, in _get_simple_index
    i = ix(idx)
  File "/usr/local/lib/python2.7/dist-packages/pandas/io/parsers.py", line 910, in ix
    raise ValueError('Index %s invalid' % col)
ValueError: Index SYMBOL invalid
2015-12-15 18:16:22,546 ERROR base 10659 -1369441472 Internal Server Error: /test/
Traceback (most recent call last):
  File "/usr/local/lib/python2.7/dist-packages/django/core/handlers/base.py", line 112, in get_response
    response = wrapped_callback(request, *callback_args, **callback_kwargs)
  File "/usr/local/lib/python2.7/dist-packages/django/views/generic/base.py", line 69, in view
    return self.dispatch(request, *args, **kwargs)
  File "/usr/local/lib/python2.7/dist-packages/django/utils/decorators.py", line 29, in _wrapper
    return bound_func(*args, **kwargs)
  File "/usr/local/lib/python2.7/dist-packages/django/contrib/auth/decorators.py", line 22, in _wrapped_view
    return view_func(request, *args, **kwargs)
  File "/usr/local/lib/python2.7/dist-packages/django/utils/decorators.py", line 25, in bound_func
    return func(self, *args2, **kwargs2)
  File "/home/mikhail/EclipseWorkspace/oncoFinder2/oncoFinder2/core/views.py", line 953, in dispatch
    return super(Test, self).dispatch(request, *args, **kwargs)
  File "/usr/local/lib/python2.7/dist-packages/django/views/generic/base.py", line 87, in dispatch
    return handler(request, *args, **kwargs)
  File "/usr/local/lib/python2.7/dist-packages/django/views/generic/base.py", line 154, in get
    context = self.get_context_data(**kwargs)
  File "/home/mikhail/EclipseWorkspace/oncoFinder2/oncoFinder2/core/views.py", line 962, in get_context_data
    raise Exception('stop')
Exception: stop
2015-12-15 18:18:39,820 ERROR base 11852 -1358881984 Internal Server Error: /test/
Traceback (most recent call last):
  File "/usr/local/lib/python2.7/dist-packages/django/core/handlers/base.py", line 112, in get_response
    response = wrapped_callback(request, *callback_args, **callback_kwargs)
  File "/usr/local/lib/python2.7/dist-packages/django/views/generic/base.py", line 69, in view
    return self.dispatch(request, *args, **kwargs)
  File "/usr/local/lib/python2.7/dist-packages/django/utils/decorators.py", line 29, in _wrapper
    return bound_func(*args, **kwargs)
  File "/usr/local/lib/python2.7/dist-packages/django/contrib/auth/decorators.py", line 22, in _wrapped_view
    return view_func(request, *args, **kwargs)
  File "/usr/local/lib/python2.7/dist-packages/django/utils/decorators.py", line 25, in bound_func
    return func(self, *args2, **kwargs2)
  File "/home/mikhail/EclipseWorkspace/oncoFinder2/oncoFinder2/core/views.py", line 953, in dispatch
    return super(Test, self).dispatch(request, *args, **kwargs)
  File "/usr/local/lib/python2.7/dist-packages/django/views/generic/base.py", line 87, in dispatch
    return handler(request, *args, **kwargs)
  File "/usr/local/lib/python2.7/dist-packages/django/views/generic/base.py", line 154, in get
    context = self.get_context_data(**kwargs)
  File "/home/mikhail/EclipseWorkspace/oncoFinder2/oncoFinder2/core/views.py", line 962, in get_context_data
    raise Exception('stop')
Exception: stop
2015-12-15 18:19:07,781 ERROR base 12035 -1358881984 Internal Server Error: /test/
Traceback (most recent call last):
  File "/usr/local/lib/python2.7/dist-packages/django/core/handlers/base.py", line 112, in get_response
    response = wrapped_callback(request, *callback_args, **callback_kwargs)
  File "/usr/local/lib/python2.7/dist-packages/django/views/generic/base.py", line 69, in view
    return self.dispatch(request, *args, **kwargs)
  File "/usr/local/lib/python2.7/dist-packages/django/utils/decorators.py", line 29, in _wrapper
    return bound_func(*args, **kwargs)
  File "/usr/local/lib/python2.7/dist-packages/django/contrib/auth/decorators.py", line 22, in _wrapped_view
    return view_func(request, *args, **kwargs)
  File "/usr/local/lib/python2.7/dist-packages/django/utils/decorators.py", line 25, in bound_func
    return func(self, *args2, **kwargs2)
  File "/home/mikhail/EclipseWorkspace/oncoFinder2/oncoFinder2/core/views.py", line 953, in dispatch
    return super(Test, self).dispatch(request, *args, **kwargs)
  File "/usr/local/lib/python2.7/dist-packages/django/views/generic/base.py", line 87, in dispatch
    return handler(request, *args, **kwargs)
  File "/usr/local/lib/python2.7/dist-packages/django/views/generic/base.py", line 154, in get
    context = self.get_context_data(**kwargs)
  File "/home/mikhail/EclipseWorkspace/oncoFinder2/oncoFinder2/core/views.py", line 962, in get_context_data
    raise Exception('stop')
Exception: stop
2015-12-15 18:19:44,050 ERROR base 12340 -1358881984 Internal Server Error: /test/
Traceback (most recent call last):
  File "/usr/local/lib/python2.7/dist-packages/django/core/handlers/base.py", line 112, in get_response
    response = wrapped_callback(request, *callback_args, **callback_kwargs)
  File "/usr/local/lib/python2.7/dist-packages/django/views/generic/base.py", line 69, in view
    return self.dispatch(request, *args, **kwargs)
  File "/usr/local/lib/python2.7/dist-packages/django/utils/decorators.py", line 29, in _wrapper
    return bound_func(*args, **kwargs)
  File "/usr/local/lib/python2.7/dist-packages/django/contrib/auth/decorators.py", line 22, in _wrapped_view
    return view_func(request, *args, **kwargs)
  File "/usr/local/lib/python2.7/dist-packages/django/utils/decorators.py", line 25, in bound_func
    return func(self, *args2, **kwargs2)
  File "/home/mikhail/EclipseWorkspace/oncoFinder2/oncoFinder2/core/views.py", line 953, in dispatch
    return super(Test, self).dispatch(request, *args, **kwargs)
  File "/usr/local/lib/python2.7/dist-packages/django/views/generic/base.py", line 87, in dispatch
    return handler(request, *args, **kwargs)
  File "/usr/local/lib/python2.7/dist-packages/django/views/generic/base.py", line 154, in get
    context = self.get_context_data(**kwargs)
  File "/home/mikhail/EclipseWorkspace/oncoFinder2/oncoFinder2/core/views.py", line 961, in get_context_data
    pp = pathws['name', 'amcf']
  File "/usr/local/lib/python2.7/dist-packages/pandas/core/frame.py", line 1969, in __getitem__
    return self._getitem_column(key)
  File "/usr/local/lib/python2.7/dist-packages/pandas/core/frame.py", line 1976, in _getitem_column
    return self._get_item_cache(key)
  File "/usr/local/lib/python2.7/dist-packages/pandas/core/generic.py", line 1091, in _get_item_cache
    values = self._data.get(item)
  File "/usr/local/lib/python2.7/dist-packages/pandas/core/internals.py", line 3211, in get
    loc = self.items.get_loc(item)
  File "/usr/local/lib/python2.7/dist-packages/pandas/core/index.py", line 1759, in get_loc
    return self._engine.get_loc(key)
  File "pandas/index.pyx", line 137, in pandas.index.IndexEngine.get_loc (pandas/index.c:3979)
  File "pandas/index.pyx", line 157, in pandas.index.IndexEngine.get_loc (pandas/index.c:3843)
  File "pandas/hashtable.pyx", line 668, in pandas.hashtable.PyObjectHashTable.get_item (pandas/hashtable.c:12265)
  File "pandas/hashtable.pyx", line 676, in pandas.hashtable.PyObjectHashTable.get_item (pandas/hashtable.c:12216)
KeyError: ('name', 'amcf')
2015-12-15 18:19:58,592 ERROR base 12440 -1359381696 Internal Server Error: /test/
Traceback (most recent call last):
  File "/usr/local/lib/python2.7/dist-packages/django/core/handlers/base.py", line 112, in get_response
    response = wrapped_callback(request, *callback_args, **callback_kwargs)
  File "/usr/local/lib/python2.7/dist-packages/django/views/generic/base.py", line 69, in view
    return self.dispatch(request, *args, **kwargs)
  File "/usr/local/lib/python2.7/dist-packages/django/utils/decorators.py", line 29, in _wrapper
    return bound_func(*args, **kwargs)
  File "/usr/local/lib/python2.7/dist-packages/django/contrib/auth/decorators.py", line 22, in _wrapped_view
    return view_func(request, *args, **kwargs)
  File "/usr/local/lib/python2.7/dist-packages/django/utils/decorators.py", line 25, in bound_func
    return func(self, *args2, **kwargs2)
  File "/home/mikhail/EclipseWorkspace/oncoFinder2/oncoFinder2/core/views.py", line 953, in dispatch
    return super(Test, self).dispatch(request, *args, **kwargs)
  File "/usr/local/lib/python2.7/dist-packages/django/views/generic/base.py", line 87, in dispatch
    return handler(request, *args, **kwargs)
  File "/usr/local/lib/python2.7/dist-packages/django/views/generic/base.py", line 154, in get
    context = self.get_context_data(**kwargs)
  File "/home/mikhail/EclipseWorkspace/oncoFinder2/oncoFinder2/core/views.py", line 962, in get_context_data
    raise Exception('stop')
Exception: stop
2015-12-15 18:20:56,040 ERROR base 12869 -1359930560 Internal Server Error: /test/
Traceback (most recent call last):
  File "/usr/local/lib/python2.7/dist-packages/django/core/handlers/base.py", line 112, in get_response
    response = wrapped_callback(request, *callback_args, **callback_kwargs)
  File "/usr/local/lib/python2.7/dist-packages/django/views/generic/base.py", line 69, in view
    return self.dispatch(request, *args, **kwargs)
  File "/usr/local/lib/python2.7/dist-packages/django/utils/decorators.py", line 29, in _wrapper
    return bound_func(*args, **kwargs)
  File "/usr/local/lib/python2.7/dist-packages/django/contrib/auth/decorators.py", line 22, in _wrapped_view
    return view_func(request, *args, **kwargs)
  File "/usr/local/lib/python2.7/dist-packages/django/utils/decorators.py", line 25, in bound_func
    return func(self, *args2, **kwargs2)
  File "/home/mikhail/EclipseWorkspace/oncoFinder2/oncoFinder2/core/views.py", line 953, in dispatch
    return super(Test, self).dispatch(request, *args, **kwargs)
  File "/usr/local/lib/python2.7/dist-packages/django/views/generic/base.py", line 87, in dispatch
    return handler(request, *args, **kwargs)
  File "/usr/local/lib/python2.7/dist-packages/django/views/generic/base.py", line 154, in get
    context = self.get_context_data(**kwargs)
  File "/home/mikhail/EclipseWorkspace/oncoFinder2/oncoFinder2/core/views.py", line 963, in get_context_data
    raise Exception('stop')
Exception: stop
2015-12-16 14:53:26,063 ERROR base 5017 -1401951424 Internal Server Error: /utils/path
Traceback (most recent call last):
  File "/usr/local/lib/python2.7/dist-packages/django/core/handlers/base.py", line 112, in get_response
    response = wrapped_callback(request, *callback_args, **callback_kwargs)
  File "/usr/local/lib/python2.7/dist-packages/django/views/generic/base.py", line 69, in view
    return self.dispatch(request, *args, **kwargs)
  File "/usr/local/lib/python2.7/dist-packages/django/utils/decorators.py", line 29, in _wrapper
    return bound_func(*args, **kwargs)
  File "/usr/local/lib/python2.7/dist-packages/django/contrib/auth/decorators.py", line 22, in _wrapped_view
    return view_func(request, *args, **kwargs)
  File "/usr/local/lib/python2.7/dist-packages/django/utils/decorators.py", line 25, in bound_func
    return func(self, *args2, **kwargs2)
  File "/home/mikhail/EclipseWorkspace/oncoFinder2/oncoFinder2/core/utils_views.py", line 185, in dispatch
    return super(ConvertPath, self).dispatch(request, *args, **kwargs)
  File "/usr/local/lib/python2.7/dist-packages/django/views/generic/base.py", line 87, in dispatch
    return handler(request, *args, **kwargs)
  File "/usr/local/lib/python2.7/dist-packages/django/views/generic/base.py", line 154, in get
    context = self.get_context_data(**kwargs)
  File "/home/mikhail/EclipseWorkspace/oncoFinder2/oncoFinder2/core/utils_views.py", line 193, in get_context_data
    raise Exception('just stop exception. Check view!')
Exception: just stop exception. Check view!
2015-12-16 14:56:59,023 ERROR base 8992 -1405105344 Internal Server Error: /utils/path
Traceback (most recent call last):
  File "/usr/local/lib/python2.7/dist-packages/django/core/handlers/base.py", line 112, in get_response
    response = wrapped_callback(request, *callback_args, **callback_kwargs)
  File "/usr/local/lib/python2.7/dist-packages/django/views/generic/base.py", line 69, in view
    return self.dispatch(request, *args, **kwargs)
  File "/usr/local/lib/python2.7/dist-packages/django/utils/decorators.py", line 29, in _wrapper
    return bound_func(*args, **kwargs)
  File "/usr/local/lib/python2.7/dist-packages/django/contrib/auth/decorators.py", line 22, in _wrapped_view
    return view_func(request, *args, **kwargs)
  File "/usr/local/lib/python2.7/dist-packages/django/utils/decorators.py", line 25, in bound_func
    return func(self, *args2, **kwargs2)
  File "/home/mikhail/EclipseWorkspace/oncoFinder2/oncoFinder2/core/utils_views.py", line 185, in dispatch
    return super(ConvertPath, self).dispatch(request, *args, **kwargs)
  File "/usr/local/lib/python2.7/dist-packages/django/views/generic/base.py", line 87, in dispatch
    return handler(request, *args, **kwargs)
  File "/usr/local/lib/python2.7/dist-packages/django/views/generic/base.py", line 154, in get
    context = self.get_context_data(**kwargs)
  File "/home/mikhail/EclipseWorkspace/oncoFinder2/oncoFinder2/core/utils_views.py", line 193, in get_context_data
    raise Exception('just stop exception. Check view!')
Exception: just stop exception. Check view!
2015-12-16 15:13:08,518 ERROR base 9602 -1358881984 Internal Server Error: /utils/path
Traceback (most recent call last):
  File "/usr/local/lib/python2.7/dist-packages/django/core/handlers/base.py", line 112, in get_response
    response = wrapped_callback(request, *callback_args, **callback_kwargs)
  File "/usr/local/lib/python2.7/dist-packages/django/views/generic/base.py", line 69, in view
    return self.dispatch(request, *args, **kwargs)
  File "/usr/local/lib/python2.7/dist-packages/django/utils/decorators.py", line 29, in _wrapper
    return bound_func(*args, **kwargs)
  File "/usr/local/lib/python2.7/dist-packages/django/contrib/auth/decorators.py", line 22, in _wrapped_view
    return view_func(request, *args, **kwargs)
  File "/usr/local/lib/python2.7/dist-packages/django/utils/decorators.py", line 25, in bound_func
    return func(self, *args2, **kwargs2)
  File "/home/mikhail/EclipseWorkspace/oncoFinder2/oncoFinder2/core/utils_views.py", line 185, in dispatch
    return super(ConvertPath, self).dispatch(request, *args, **kwargs)
  File "/usr/local/lib/python2.7/dist-packages/django/views/generic/base.py", line 87, in dispatch
    return handler(request, *args, **kwargs)
  File "/usr/local/lib/python2.7/dist-packages/django/views/generic/base.py", line 154, in get
    context = self.get_context_data(**kwargs)
  File "/home/mikhail/EclipseWorkspace/oncoFinder2/oncoFinder2/core/utils_views.py", line 361, in get_context_data
    raise Exception('Biocarta Done')
Exception: Biocarta Done
2015-12-16 15:24:29,084 ERROR base 18472 -1422931136 Internal Server Error: /db/pathways/human/biocarta/biocarta_actions_of_nitric_oxide_in_the_heart_main_pathway/5159/
Traceback (most recent call last):
  File "/usr/local/lib/python2.7/dist-packages/django/core/handlers/base.py", line 112, in get_response
    response = wrapped_callback(request, *callback_args, **callback_kwargs)
  File "/usr/local/lib/python2.7/dist-packages/django/views/generic/base.py", line 69, in view
    return self.dispatch(request, *args, **kwargs)
  File "/usr/local/lib/python2.7/dist-packages/django/utils/decorators.py", line 29, in _wrapper
    return bound_func(*args, **kwargs)
  File "/usr/local/lib/python2.7/dist-packages/django/contrib/auth/decorators.py", line 22, in _wrapped_view
    return view_func(request, *args, **kwargs)
  File "/usr/local/lib/python2.7/dist-packages/django/utils/decorators.py", line 25, in bound_func
    return func(self, *args2, **kwargs2)
  File "/usr/local/lib/python2.7/dist-packages/django/utils/decorators.py", line 29, in _wrapper
    return bound_func(*args, **kwargs)
  File "/usr/local/lib/python2.7/dist-packages/django/contrib/admin/views/decorators.py", line 17, in _checklogin
    return view_func(request, *args, **kwargs)
  File "/usr/local/lib/python2.7/dist-packages/django/utils/decorators.py", line 25, in bound_func
    return func(self, *args2, **kwargs2)
  File "/home/mikhail/EclipseWorkspace/oncoFinder2/oncoFinder2/database/views.py", line 54, in dispatch
    return super(PathwayDetail, self).dispatch(request, *args, **kwargs)
  File "/usr/local/lib/python2.7/dist-packages/django/views/generic/base.py", line 87, in dispatch
    return handler(request, *args, **kwargs)
  File "/usr/local/lib/python2.7/dist-packages/django/views/generic/detail.py", line 111, in get
    context = self.get_context_data(object=self.object)
  File "/home/mikhail/EclipseWorkspace/oncoFinder2/oncoFinder2/database/views.py", line 109, in get_context_data
    A.draw(settings.MEDIA_ROOT+"/pathway_pics/"+self.object.organism+"/"+self.object.database+"/"+self.object.name+".svg")
  File "/usr/local/lib/python2.7/dist-packages/pygraphviz-1.3rc2-py2.7-linux-i686.egg/pygraphviz/agraph.py", line 1471, in draw
    fh = self._get_fh(path, 'w+b')
  File "/usr/local/lib/python2.7/dist-packages/pygraphviz-1.3rc2-py2.7-linux-i686.egg/pygraphviz/agraph.py", line 1500, in _get_fh
    fh = open(path, mode=mode)
IOError: [Errno 2] No such file or directory: u'/home/mikhail/EclipseWorkspace/oncoFinder2/oncoFinder2/oncoFinder2/media/pathway_pics/human/biocarta/biocarta_actions_of_nitric_oxide_in_the_heart_Main_Pathway.svg'
2015-12-17 17:32:17,413 ERROR base 29207 -1361224896 Internal Server Error: /test/
Traceback (most recent call last):
  File "/usr/local/lib/python2.7/dist-packages/django/core/handlers/base.py", line 112, in get_response
    response = wrapped_callback(request, *callback_args, **callback_kwargs)
  File "/usr/local/lib/python2.7/dist-packages/django/views/generic/base.py", line 69, in view
    return self.dispatch(request, *args, **kwargs)
  File "/usr/local/lib/python2.7/dist-packages/django/utils/decorators.py", line 29, in _wrapper
    return bound_func(*args, **kwargs)
  File "/usr/local/lib/python2.7/dist-packages/django/contrib/auth/decorators.py", line 22, in _wrapped_view
    return view_func(request, *args, **kwargs)
  File "/usr/local/lib/python2.7/dist-packages/django/utils/decorators.py", line 25, in bound_func
    return func(self, *args2, **kwargs2)
  File "/home/mikhail/EclipseWorkspace/oncoFinder2/oncoFinder2/core/views.py", line 953, in dispatch
    return super(Test, self).dispatch(request, *args, **kwargs)
  File "/usr/local/lib/python2.7/dist-packages/django/views/generic/base.py", line 87, in dispatch
    return handler(request, *args, **kwargs)
  File "/usr/local/lib/python2.7/dist-packages/django/views/generic/base.py", line 154, in get
    context = self.get_context_data(**kwargs)
  File "/home/mikhail/EclipseWorkspace/oncoFinder2/oncoFinder2/core/views.py", line 960, in get_context_data
    raise Exception('stop')
Exception: stop
2015-12-17 17:35:39,227 ERROR base 1356 -1360979136 Internal Server Error: /test/
Traceback (most recent call last):
  File "/usr/local/lib/python2.7/dist-packages/django/core/handlers/base.py", line 112, in get_response
    response = wrapped_callback(request, *callback_args, **callback_kwargs)
  File "/usr/local/lib/python2.7/dist-packages/django/views/generic/base.py", line 69, in view
    return self.dispatch(request, *args, **kwargs)
  File "/usr/local/lib/python2.7/dist-packages/django/utils/decorators.py", line 29, in _wrapper
    return bound_func(*args, **kwargs)
  File "/usr/local/lib/python2.7/dist-packages/django/contrib/auth/decorators.py", line 22, in _wrapped_view
    return view_func(request, *args, **kwargs)
  File "/usr/local/lib/python2.7/dist-packages/django/utils/decorators.py", line 25, in bound_func
    return func(self, *args2, **kwargs2)
  File "/home/mikhail/EclipseWorkspace/oncoFinder2/oncoFinder2/core/views.py", line 953, in dispatch
    return super(Test, self).dispatch(request, *args, **kwargs)
  File "/usr/local/lib/python2.7/dist-packages/django/views/generic/base.py", line 87, in dispatch
    return handler(request, *args, **kwargs)
  File "/usr/local/lib/python2.7/dist-packages/django/views/generic/base.py", line 154, in get
    context = self.get_context_data(**kwargs)
  File "/home/mikhail/EclipseWorkspace/oncoFinder2/oncoFinder2/core/views.py", line 971, in get_context_data
    raise Exception('stop')
Exception: stop
2015-12-17 17:37:20,399 ERROR base 2233 -1362027712 Internal Server Error: /test/
Traceback (most recent call last):
  File "/usr/local/lib/python2.7/dist-packages/django/core/handlers/base.py", line 112, in get_response
    response = wrapped_callback(request, *callback_args, **callback_kwargs)
  File "/usr/local/lib/python2.7/dist-packages/django/views/generic/base.py", line 69, in view
    return self.dispatch(request, *args, **kwargs)
  File "/usr/local/lib/python2.7/dist-packages/django/utils/decorators.py", line 29, in _wrapper
    return bound_func(*args, **kwargs)
  File "/usr/local/lib/python2.7/dist-packages/django/contrib/auth/decorators.py", line 22, in _wrapped_view
    return view_func(request, *args, **kwargs)
  File "/usr/local/lib/python2.7/dist-packages/django/utils/decorators.py", line 25, in bound_func
    return func(self, *args2, **kwargs2)
  File "/home/mikhail/EclipseWorkspace/oncoFinder2/oncoFinder2/core/views.py", line 953, in dispatch
    return super(Test, self).dispatch(request, *args, **kwargs)
  File "/usr/local/lib/python2.7/dist-packages/django/views/generic/base.py", line 87, in dispatch
    return handler(request, *args, **kwargs)
  File "/usr/local/lib/python2.7/dist-packages/django/views/generic/base.py", line 154, in get
    context = self.get_context_data(**kwargs)
  File "/home/mikhail/EclipseWorkspace/oncoFinder2/oncoFinder2/core/views.py", line 971, in get_context_data
    raise Exception('stop')
Exception: stop
2015-12-17 17:37:47,541 ERROR base 2418 -1360979136 Internal Server Error: /test/
Traceback (most recent call last):
  File "/usr/local/lib/python2.7/dist-packages/django/core/handlers/base.py", line 112, in get_response
    response = wrapped_callback(request, *callback_args, **callback_kwargs)
  File "/usr/local/lib/python2.7/dist-packages/django/views/generic/base.py", line 69, in view
    return self.dispatch(request, *args, **kwargs)
  File "/usr/local/lib/python2.7/dist-packages/django/utils/decorators.py", line 29, in _wrapper
    return bound_func(*args, **kwargs)
  File "/usr/local/lib/python2.7/dist-packages/django/contrib/auth/decorators.py", line 22, in _wrapped_view
    return view_func(request, *args, **kwargs)
  File "/usr/local/lib/python2.7/dist-packages/django/utils/decorators.py", line 25, in bound_func
    return func(self, *args2, **kwargs2)
  File "/home/mikhail/EclipseWorkspace/oncoFinder2/oncoFinder2/core/views.py", line 953, in dispatch
    return super(Test, self).dispatch(request, *args, **kwargs)
  File "/usr/local/lib/python2.7/dist-packages/django/views/generic/base.py", line 87, in dispatch
    return handler(request, *args, **kwargs)
  File "/usr/local/lib/python2.7/dist-packages/django/views/generic/base.py", line 154, in get
    context = self.get_context_data(**kwargs)
  File "/home/mikhail/EclipseWorkspace/oncoFinder2/oncoFinder2/core/views.py", line 972, in get_context_data
    raise Exception('stop')
Exception: stop
2015-12-17 17:37:58,818 ERROR base 2418 -1406153920 Internal Server Error: /test/
Traceback (most recent call last):
  File "/usr/local/lib/python2.7/dist-packages/django/core/handlers/base.py", line 112, in get_response
    response = wrapped_callback(request, *callback_args, **callback_kwargs)
  File "/usr/local/lib/python2.7/dist-packages/django/views/generic/base.py", line 69, in view
    return self.dispatch(request, *args, **kwargs)
  File "/usr/local/lib/python2.7/dist-packages/django/utils/decorators.py", line 29, in _wrapper
    return bound_func(*args, **kwargs)
  File "/usr/local/lib/python2.7/dist-packages/django/contrib/auth/decorators.py", line 22, in _wrapped_view
    return view_func(request, *args, **kwargs)
  File "/usr/local/lib/python2.7/dist-packages/django/utils/decorators.py", line 25, in bound_func
    return func(self, *args2, **kwargs2)
  File "/home/mikhail/EclipseWorkspace/oncoFinder2/oncoFinder2/core/views.py", line 953, in dispatch
    return super(Test, self).dispatch(request, *args, **kwargs)
  File "/usr/local/lib/python2.7/dist-packages/django/views/generic/base.py", line 87, in dispatch
    return handler(request, *args, **kwargs)
  File "/usr/local/lib/python2.7/dist-packages/django/views/generic/base.py", line 154, in get
    context = self.get_context_data(**kwargs)
  File "/home/mikhail/EclipseWorkspace/oncoFinder2/oncoFinder2/core/views.py", line 972, in get_context_data
    raise Exception('stop')
Exception: stop
2015-12-17 17:38:20,987 ERROR base 2802 -1361478848 Internal Server Error: /test/
Traceback (most recent call last):
  File "/usr/local/lib/python2.7/dist-packages/django/core/handlers/base.py", line 112, in get_response
    response = wrapped_callback(request, *callback_args, **callback_kwargs)
  File "/usr/local/lib/python2.7/dist-packages/django/views/generic/base.py", line 69, in view
    return self.dispatch(request, *args, **kwargs)
  File "/usr/local/lib/python2.7/dist-packages/django/utils/decorators.py", line 29, in _wrapper
    return bound_func(*args, **kwargs)
  File "/usr/local/lib/python2.7/dist-packages/django/contrib/auth/decorators.py", line 22, in _wrapped_view
    return view_func(request, *args, **kwargs)
  File "/usr/local/lib/python2.7/dist-packages/django/utils/decorators.py", line 25, in bound_func
    return func(self, *args2, **kwargs2)
  File "/home/mikhail/EclipseWorkspace/oncoFinder2/oncoFinder2/core/views.py", line 953, in dispatch
    return super(Test, self).dispatch(request, *args, **kwargs)
  File "/usr/local/lib/python2.7/dist-packages/django/views/generic/base.py", line 87, in dispatch
    return handler(request, *args, **kwargs)
  File "/usr/local/lib/python2.7/dist-packages/django/views/generic/base.py", line 154, in get
    context = self.get_context_data(**kwargs)
  File "/home/mikhail/EclipseWorkspace/oncoFinder2/oncoFinder2/core/views.py", line 972, in get_context_data
    raise Exception('stop')
Exception: stop
2015-12-17 17:38:34,573 ERROR base 2935 -1362027712 Internal Server Error: /test/
Traceback (most recent call last):
  File "/usr/local/lib/python2.7/dist-packages/django/core/handlers/base.py", line 112, in get_response
    response = wrapped_callback(request, *callback_args, **callback_kwargs)
  File "/usr/local/lib/python2.7/dist-packages/django/views/generic/base.py", line 69, in view
    return self.dispatch(request, *args, **kwargs)
  File "/usr/local/lib/python2.7/dist-packages/django/utils/decorators.py", line 29, in _wrapper
    return bound_func(*args, **kwargs)
  File "/usr/local/lib/python2.7/dist-packages/django/contrib/auth/decorators.py", line 22, in _wrapped_view
    return view_func(request, *args, **kwargs)
  File "/usr/local/lib/python2.7/dist-packages/django/utils/decorators.py", line 25, in bound_func
    return func(self, *args2, **kwargs2)
  File "/home/mikhail/EclipseWorkspace/oncoFinder2/oncoFinder2/core/views.py", line 953, in dispatch
    return super(Test, self).dispatch(request, *args, **kwargs)
  File "/usr/local/lib/python2.7/dist-packages/django/views/generic/base.py", line 87, in dispatch
    return handler(request, *args, **kwargs)
  File "/usr/local/lib/python2.7/dist-packages/django/views/generic/base.py", line 154, in get
    context = self.get_context_data(**kwargs)
  File "/home/mikhail/EclipseWorkspace/oncoFinder2/oncoFinder2/core/views.py", line 972, in get_context_data
    raise Exception('stop')
Exception: stop
2015-12-17 17:39:52,856 ERROR base 3043 -1362027712 Internal Server Error: /test/
Traceback (most recent call last):
  File "/usr/local/lib/python2.7/dist-packages/django/core/handlers/base.py", line 112, in get_response
    response = wrapped_callback(request, *callback_args, **callback_kwargs)
  File "/usr/local/lib/python2.7/dist-packages/django/views/generic/base.py", line 69, in view
    return self.dispatch(request, *args, **kwargs)
  File "/usr/local/lib/python2.7/dist-packages/django/utils/decorators.py", line 29, in _wrapper
    return bound_func(*args, **kwargs)
  File "/usr/local/lib/python2.7/dist-packages/django/contrib/auth/decorators.py", line 22, in _wrapped_view
    return view_func(request, *args, **kwargs)
  File "/usr/local/lib/python2.7/dist-packages/django/utils/decorators.py", line 25, in bound_func
    return func(self, *args2, **kwargs2)
  File "/home/mikhail/EclipseWorkspace/oncoFinder2/oncoFinder2/core/views.py", line 953, in dispatch
    return super(Test, self).dispatch(request, *args, **kwargs)
  File "/usr/local/lib/python2.7/dist-packages/django/views/generic/base.py", line 87, in dispatch
    return handler(request, *args, **kwargs)
  File "/usr/local/lib/python2.7/dist-packages/django/views/generic/base.py", line 154, in get
    context = self.get_context_data(**kwargs)
  File "/home/mikhail/EclipseWorkspace/oncoFinder2/oncoFinder2/core/views.py", line 972, in get_context_data
    raise Exception('stop')
Exception: stop
2015-12-17 17:44:34,257 ERROR base 5177 -1362027712 Internal Server Error: /test/
Traceback (most recent call last):
  File "/usr/local/lib/python2.7/dist-packages/django/core/handlers/base.py", line 112, in get_response
    response = wrapped_callback(request, *callback_args, **callback_kwargs)
  File "/usr/local/lib/python2.7/dist-packages/django/views/generic/base.py", line 69, in view
    return self.dispatch(request, *args, **kwargs)
  File "/usr/local/lib/python2.7/dist-packages/django/utils/decorators.py", line 29, in _wrapper
    return bound_func(*args, **kwargs)
  File "/usr/local/lib/python2.7/dist-packages/django/contrib/auth/decorators.py", line 22, in _wrapped_view
    return view_func(request, *args, **kwargs)
  File "/usr/local/lib/python2.7/dist-packages/django/utils/decorators.py", line 25, in bound_func
    return func(self, *args2, **kwargs2)
  File "/home/mikhail/EclipseWorkspace/oncoFinder2/oncoFinder2/core/views.py", line 953, in dispatch
    return super(Test, self).dispatch(request, *args, **kwargs)
  File "/usr/local/lib/python2.7/dist-packages/django/views/generic/base.py", line 87, in dispatch
    return handler(request, *args, **kwargs)
  File "/usr/local/lib/python2.7/dist-packages/django/views/generic/base.py", line 154, in get
    context = self.get_context_data(**kwargs)
  File "/home/mikhail/EclipseWorkspace/oncoFinder2/oncoFinder2/core/views.py", line 971, in get_context_data
    df = DataFrame(dict([ (k,Series(v)) for k,v in pn.iteritems() ]))
UnboundLocalError: local variable 'dict' referenced before assignment
2015-12-17 17:49:01,505 ERROR base 5177 -1390417088 Internal Server Error: /test/
Traceback (most recent call last):
  File "/usr/local/lib/python2.7/dist-packages/django/core/handlers/base.py", line 112, in get_response
    response = wrapped_callback(request, *callback_args, **callback_kwargs)
  File "/usr/local/lib/python2.7/dist-packages/django/views/generic/base.py", line 69, in view
    return self.dispatch(request, *args, **kwargs)
  File "/usr/local/lib/python2.7/dist-packages/django/utils/decorators.py", line 29, in _wrapper
    return bound_func(*args, **kwargs)
  File "/usr/local/lib/python2.7/dist-packages/django/contrib/auth/decorators.py", line 22, in _wrapped_view
    return view_func(request, *args, **kwargs)
  File "/usr/local/lib/python2.7/dist-packages/django/utils/decorators.py", line 25, in bound_func
    return func(self, *args2, **kwargs2)
  File "/home/mikhail/EclipseWorkspace/oncoFinder2/oncoFinder2/core/views.py", line 953, in dispatch
    return super(Test, self).dispatch(request, *args, **kwargs)
  File "/usr/local/lib/python2.7/dist-packages/django/views/generic/base.py", line 87, in dispatch
    return handler(request, *args, **kwargs)
  File "/usr/local/lib/python2.7/dist-packages/django/views/generic/base.py", line 154, in get
    context = self.get_context_data(**kwargs)
  File "/home/mikhail/EclipseWorkspace/oncoFinder2/oncoFinder2/core/views.py", line 971, in get_context_data
    df = DataFrame(dict([ (k,Series(v)) for k,v in pn.iteritems() ]))
UnboundLocalError: local variable 'dict' referenced before assignment
2015-12-17 17:50:53,806 ERROR base 8138 -1360979136 Internal Server Error: /test/
Traceback (most recent call last):
  File "/usr/local/lib/python2.7/dist-packages/django/core/handlers/base.py", line 112, in get_response
    response = wrapped_callback(request, *callback_args, **callback_kwargs)
  File "/usr/local/lib/python2.7/dist-packages/django/views/generic/base.py", line 69, in view
    return self.dispatch(request, *args, **kwargs)
  File "/usr/local/lib/python2.7/dist-packages/django/utils/decorators.py", line 29, in _wrapper
    return bound_func(*args, **kwargs)
  File "/usr/local/lib/python2.7/dist-packages/django/contrib/auth/decorators.py", line 22, in _wrapped_view
    return view_func(request, *args, **kwargs)
  File "/usr/local/lib/python2.7/dist-packages/django/utils/decorators.py", line 25, in bound_func
    return func(self, *args2, **kwargs2)
  File "/home/mikhail/EclipseWorkspace/oncoFinder2/oncoFinder2/core/views.py", line 953, in dispatch
    return super(Test, self).dispatch(request, *args, **kwargs)
  File "/usr/local/lib/python2.7/dist-packages/django/views/generic/base.py", line 87, in dispatch
    return handler(request, *args, **kwargs)
  File "/usr/local/lib/python2.7/dist-packages/django/views/generic/base.py", line 154, in get
    context = self.get_context_data(**kwargs)
  File "/home/mikhail/EclipseWorkspace/oncoFinder2/oncoFinder2/core/views.py", line 958, in get_context_data
    d = dict( A = np.array([1,2]), B = np.array([1,2,3,4]) )
UnboundLocalError: local variable 'dict' referenced before assignment
2015-12-17 17:53:14,440 ERROR base 8699 -1360979136 Internal Server Error: /test/
Traceback (most recent call last):
  File "/usr/local/lib/python2.7/dist-packages/django/core/handlers/base.py", line 112, in get_response
    response = wrapped_callback(request, *callback_args, **callback_kwargs)
  File "/usr/local/lib/python2.7/dist-packages/django/views/generic/base.py", line 69, in view
    return self.dispatch(request, *args, **kwargs)
  File "/usr/local/lib/python2.7/dist-packages/django/utils/decorators.py", line 29, in _wrapper
    return bound_func(*args, **kwargs)
  File "/usr/local/lib/python2.7/dist-packages/django/contrib/auth/decorators.py", line 22, in _wrapped_view
    return view_func(request, *args, **kwargs)
  File "/usr/local/lib/python2.7/dist-packages/django/utils/decorators.py", line 25, in bound_func
    return func(self, *args2, **kwargs2)
  File "/home/mikhail/EclipseWorkspace/oncoFinder2/oncoFinder2/core/views.py", line 953, in dispatch
    return super(Test, self).dispatch(request, *args, **kwargs)
  File "/usr/local/lib/python2.7/dist-packages/django/views/generic/base.py", line 87, in dispatch
    return handler(request, *args, **kwargs)
  File "/usr/local/lib/python2.7/dist-packages/django/views/generic/base.py", line 154, in get
    context = self.get_context_data(**kwargs)
  File "/home/mikhail/EclipseWorkspace/oncoFinder2/oncoFinder2/core/views.py", line 975, in get_context_data
    raise Exception('stop')
Exception: stop
2015-12-17 17:57:23,871 ERROR base 10400 -1360979136 Internal Server Error: /test/
Traceback (most recent call last):
  File "/usr/local/lib/python2.7/dist-packages/django/core/handlers/base.py", line 112, in get_response
    response = wrapped_callback(request, *callback_args, **callback_kwargs)
  File "/usr/local/lib/python2.7/dist-packages/django/views/generic/base.py", line 69, in view
    return self.dispatch(request, *args, **kwargs)
  File "/usr/local/lib/python2.7/dist-packages/django/utils/decorators.py", line 29, in _wrapper
    return bound_func(*args, **kwargs)
  File "/usr/local/lib/python2.7/dist-packages/django/contrib/auth/decorators.py", line 22, in _wrapped_view
    return view_func(request, *args, **kwargs)
  File "/usr/local/lib/python2.7/dist-packages/django/utils/decorators.py", line 25, in bound_func
    return func(self, *args2, **kwargs2)
  File "/home/mikhail/EclipseWorkspace/oncoFinder2/oncoFinder2/core/views.py", line 953, in dispatch
    return super(Test, self).dispatch(request, *args, **kwargs)
  File "/usr/local/lib/python2.7/dist-packages/django/views/generic/base.py", line 87, in dispatch
    return handler(request, *args, **kwargs)
  File "/usr/local/lib/python2.7/dist-packages/django/views/generic/base.py", line 154, in get
    context = self.get_context_data(**kwargs)
  File "/home/mikhail/EclipseWorkspace/oncoFinder2/oncoFinder2/core/views.py", line 976, in get_context_data
    raise Exception('stop')
Exception: stop
2015-12-19 13:07:16,737 ERROR base 4324 -1404056768 Internal Server Error: /admin/database/target/
Traceback (most recent call last):
  File "/usr/local/lib/python2.7/dist-packages/django/core/handlers/base.py", line 112, in get_response
    response = wrapped_callback(request, *callback_args, **callback_kwargs)
  File "/usr/local/lib/python2.7/dist-packages/django/contrib/admin/options.py", line 432, in wrapper
    return self.admin_site.admin_view(view)(*args, **kwargs)
  File "/usr/local/lib/python2.7/dist-packages/django/utils/decorators.py", line 99, in _wrapped_view
    response = view_func(request, *args, **kwargs)
  File "/usr/local/lib/python2.7/dist-packages/django/views/decorators/cache.py", line 52, in _wrapped_view_func
    response = view_func(request, *args, **kwargs)
  File "/usr/local/lib/python2.7/dist-packages/django/contrib/admin/sites.py", line 198, in inner
    return view(request, *args, **kwargs)
  File "/usr/local/lib/python2.7/dist-packages/django/utils/decorators.py", line 29, in _wrapper
    return bound_func(*args, **kwargs)
  File "/usr/local/lib/python2.7/dist-packages/django/utils/decorators.py", line 99, in _wrapped_view
    response = view_func(request, *args, **kwargs)
  File "/usr/local/lib/python2.7/dist-packages/django/utils/decorators.py", line 25, in bound_func
    return func(self, *args2, **kwargs2)
  File "/usr/local/lib/python2.7/dist-packages/django/contrib/admin/options.py", line 1306, in changelist_view
    self)
  File "/usr/local/lib/python2.7/dist-packages/django/contrib/admin/views/main.py", line 105, in __init__
    self.queryset = self.get_queryset(request)
  File "/usr/local/lib/python2.7/dist-packages/django/contrib/admin/views/main.py", line 391, in get_queryset
    request, qs, self.query)
  File "/usr/local/lib/python2.7/dist-packages/django/contrib/admin/options.py", line 771, in get_search_results
    queryset = queryset.filter(reduce(operator.or_, or_queries))
  File "/usr/local/lib/python2.7/dist-packages/django/db/models/query.py", line 593, in filter
    return self._filter_or_exclude(False, *args, **kwargs)
  File "/usr/local/lib/python2.7/dist-packages/django/db/models/query.py", line 611, in _filter_or_exclude
    clone.query.add_q(Q(*args, **kwargs))
  File "/usr/local/lib/python2.7/dist-packages/django/db/models/sql/query.py", line 1204, in add_q
    clause = self._add_q(where_part, used_aliases)
  File "/usr/local/lib/python2.7/dist-packages/django/db/models/sql/query.py", line 1236, in _add_q
    current_negated)
  File "/usr/local/lib/python2.7/dist-packages/django/db/models/sql/query.py", line 1240, in _add_q
    current_negated=current_negated)
  File "/usr/local/lib/python2.7/dist-packages/django/db/models/sql/query.py", line 1128, in build_filter
    lookup_type, value)
  File "/usr/local/lib/python2.7/dist-packages/django/db/models/fields/related.py", line 1123, in get_lookup_constraint
    raise TypeError('Related Field got invalid lookup: %s' % lookup_type)
TypeError: Related Field got invalid lookup: icontains
