2015-03-12 19:37:45,994 ERROR base 3050 -1250432192 Internal Server Error: /calculation-parameters/doc4872/
Traceback (most recent call last):
  File "/usr/local/lib/python2.7/dist-packages/django/core/handlers/base.py", line 114, in get_response
    response = wrapped_callback(request, *callback_args, **callback_kwargs)
  File "/usr/local/lib/python2.7/dist-packages/django/views/generic/base.py", line 69, in view
    return self.dispatch(request, *args, **kwargs)
  File "/usr/local/lib/python2.7/dist-packages/django/utils/decorators.py", line 29, in _wrapper
    return bound_func(*args, **kwargs)
  File "/usr/local/lib/python2.7/dist-packages/django/contrib/auth/decorators.py", line 22, in _wrapped_view
    return view_func(request, *args, **kwargs)
  File "/usr/local/lib/python2.7/dist-packages/django/utils/decorators.py", line 25, in bound_func
    return func(self, *args2, **kwargs2)
  File "/home/mikhail/EclipseWorkspace/oncoFinder2/oncoFinder2/core/views.py", line 45, in dispatch
    return super(CoreSetCalculationParameters, self).dispatch(request, *args, **kwargs)
  File "/usr/local/lib/python2.7/dist-packages/django/views/generic/base.py", line 87, in dispatch
    return handler(request, *args, **kwargs)
  File "/usr/local/lib/python2.7/dist-packages/django/views/generic/edit.py", line 171, in post
    return self.form_valid(form)
  File "/home/mikhail/EclipseWorkspace/oncoFinder2/oncoFinder2/core/views.py", line 505, in form_valid
    if target.name in differential_genes[tumour]:
KeyError: 'Tumour_X5500024052861011409506.H02.CEL'
2015-03-12 19:38:47,594 ERROR base 3577 -1250432192 Internal Server Error: /calculation-parameters/doc4872/
Traceback (most recent call last):
  File "/usr/local/lib/python2.7/dist-packages/django/core/handlers/base.py", line 114, in get_response
    response = wrapped_callback(request, *callback_args, **callback_kwargs)
  File "/usr/local/lib/python2.7/dist-packages/django/views/generic/base.py", line 69, in view
    return self.dispatch(request, *args, **kwargs)
  File "/usr/local/lib/python2.7/dist-packages/django/utils/decorators.py", line 29, in _wrapper
    return bound_func(*args, **kwargs)
  File "/usr/local/lib/python2.7/dist-packages/django/contrib/auth/decorators.py", line 22, in _wrapped_view
    return view_func(request, *args, **kwargs)
  File "/usr/local/lib/python2.7/dist-packages/django/utils/decorators.py", line 25, in bound_func
    return func(self, *args2, **kwargs2)
  File "/home/mikhail/EclipseWorkspace/oncoFinder2/oncoFinder2/core/views.py", line 45, in dispatch
    return super(CoreSetCalculationParameters, self).dispatch(request, *args, **kwargs)
  File "/usr/local/lib/python2.7/dist-packages/django/views/generic/base.py", line 87, in dispatch
    return handler(request, *args, **kwargs)
  File "/usr/local/lib/python2.7/dist-packages/django/views/generic/edit.py", line 171, in post
    return self.form_valid(form)
  File "/home/mikhail/EclipseWorkspace/oncoFinder2/oncoFinder2/core/views.py", line 248, in form_valid
    raise Exception('123')
Exception: 123
2015-03-12 19:40:41,165 ERROR base 4339 -1250432192 Internal Server Error: /calculation-parameters/doc4872/
Traceback (most recent call last):
  File "/usr/local/lib/python2.7/dist-packages/django/core/handlers/base.py", line 114, in get_response
    response = wrapped_callback(request, *callback_args, **callback_kwargs)
  File "/usr/local/lib/python2.7/dist-packages/django/views/generic/base.py", line 69, in view
    return self.dispatch(request, *args, **kwargs)
  File "/usr/local/lib/python2.7/dist-packages/django/utils/decorators.py", line 29, in _wrapper
    return bound_func(*args, **kwargs)
  File "/usr/local/lib/python2.7/dist-packages/django/contrib/auth/decorators.py", line 22, in _wrapped_view
    return view_func(request, *args, **kwargs)
  File "/usr/local/lib/python2.7/dist-packages/django/utils/decorators.py", line 25, in bound_func
    return func(self, *args2, **kwargs2)
  File "/home/mikhail/EclipseWorkspace/oncoFinder2/oncoFinder2/core/views.py", line 45, in dispatch
    return super(CoreSetCalculationParameters, self).dispatch(request, *args, **kwargs)
  File "/usr/local/lib/python2.7/dist-packages/django/views/generic/base.py", line 87, in dispatch
    return handler(request, *args, **kwargs)
  File "/usr/local/lib/python2.7/dist-packages/django/views/generic/edit.py", line 171, in post
    return self.form_valid(form)
  File "/home/mikhail/EclipseWorkspace/oncoFinder2/oncoFinder2/core/views.py", line 359, in form_valid
    raise Exception('exp')
Exception: exp
2015-03-12 19:52:39,051 ERROR base 7151 -1249903808 Internal Server Error: /calculation-parameters/doc4872/
Traceback (most recent call last):
  File "/usr/local/lib/python2.7/dist-packages/django/core/handlers/base.py", line 114, in get_response
    response = wrapped_callback(request, *callback_args, **callback_kwargs)
  File "/usr/local/lib/python2.7/dist-packages/django/views/generic/base.py", line 69, in view
    return self.dispatch(request, *args, **kwargs)
  File "/usr/local/lib/python2.7/dist-packages/django/utils/decorators.py", line 29, in _wrapper
    return bound_func(*args, **kwargs)
  File "/usr/local/lib/python2.7/dist-packages/django/contrib/auth/decorators.py", line 22, in _wrapped_view
    return view_func(request, *args, **kwargs)
  File "/usr/local/lib/python2.7/dist-packages/django/utils/decorators.py", line 25, in bound_func
    return func(self, *args2, **kwargs2)
  File "/home/mikhail/EclipseWorkspace/oncoFinder2/oncoFinder2/core/views.py", line 45, in dispatch
    return super(CoreSetCalculationParameters, self).dispatch(request, *args, **kwargs)
  File "/usr/local/lib/python2.7/dist-packages/django/views/generic/base.py", line 87, in dispatch
    return handler(request, *args, **kwargs)
  File "/usr/local/lib/python2.7/dist-packages/django/views/generic/edit.py", line 171, in post
    return self.form_valid(form)
  File "/home/mikhail/EclipseWorkspace/oncoFinder2/oncoFinder2/core/views.py", line 366, in form_valid
    raise Exception('exp')
Exception: exp
2015-03-12 19:54:42,767 ERROR base 9692 -1250432192 Internal Server Error: /calculation-parameters/doc4872/
Traceback (most recent call last):
  File "/usr/local/lib/python2.7/dist-packages/django/core/handlers/base.py", line 114, in get_response
    response = wrapped_callback(request, *callback_args, **callback_kwargs)
  File "/usr/local/lib/python2.7/dist-packages/django/views/generic/base.py", line 69, in view
    return self.dispatch(request, *args, **kwargs)
  File "/usr/local/lib/python2.7/dist-packages/django/utils/decorators.py", line 29, in _wrapper
    return bound_func(*args, **kwargs)
  File "/usr/local/lib/python2.7/dist-packages/django/contrib/auth/decorators.py", line 22, in _wrapped_view
    return view_func(request, *args, **kwargs)
  File "/usr/local/lib/python2.7/dist-packages/django/utils/decorators.py", line 25, in bound_func
    return func(self, *args2, **kwargs2)
  File "/home/mikhail/EclipseWorkspace/oncoFinder2/oncoFinder2/core/views.py", line 45, in dispatch
    return super(CoreSetCalculationParameters, self).dispatch(request, *args, **kwargs)
  File "/usr/local/lib/python2.7/dist-packages/django/views/generic/base.py", line 87, in dispatch
    return handler(request, *args, **kwargs)
  File "/usr/local/lib/python2.7/dist-packages/django/views/generic/edit.py", line 171, in post
    return self.form_valid(form)
  File "/home/mikhail/EclipseWorkspace/oncoFinder2/oncoFinder2/core/views.py", line 366, in form_valid
    raise Exception('exp')
Exception: exp
2015-03-12 19:56:22,131 ERROR base 10309 -1252000960 Internal Server Error: /calculation-parameters/doc4872/
Traceback (most recent call last):
  File "/usr/local/lib/python2.7/dist-packages/django/core/handlers/base.py", line 114, in get_response
    response = wrapped_callback(request, *callback_args, **callback_kwargs)
  File "/usr/local/lib/python2.7/dist-packages/django/views/generic/base.py", line 69, in view
    return self.dispatch(request, *args, **kwargs)
  File "/usr/local/lib/python2.7/dist-packages/django/utils/decorators.py", line 29, in _wrapper
    return bound_func(*args, **kwargs)
  File "/usr/local/lib/python2.7/dist-packages/django/contrib/auth/decorators.py", line 22, in _wrapped_view
    return view_func(request, *args, **kwargs)
  File "/usr/local/lib/python2.7/dist-packages/django/utils/decorators.py", line 25, in bound_func
    return func(self, *args2, **kwargs2)
  File "/home/mikhail/EclipseWorkspace/oncoFinder2/oncoFinder2/core/views.py", line 45, in dispatch
    return super(CoreSetCalculationParameters, self).dispatch(request, *args, **kwargs)
  File "/usr/local/lib/python2.7/dist-packages/django/views/generic/base.py", line 87, in dispatch
    return handler(request, *args, **kwargs)
  File "/usr/local/lib/python2.7/dist-packages/django/views/generic/edit.py", line 171, in post
    return self.form_valid(form)
  File "/home/mikhail/EclipseWorkspace/oncoFinder2/oncoFinder2/core/views.py", line 367, in form_valid
    raise Exception('exp')
Exception: exp
2015-03-12 19:57:41,435 ERROR base 10744 -1251480768 Internal Server Error: /calculation-parameters/doc4872/
Traceback (most recent call last):
  File "/usr/local/lib/python2.7/dist-packages/django/core/handlers/base.py", line 114, in get_response
    response = wrapped_callback(request, *callback_args, **callback_kwargs)
  File "/usr/local/lib/python2.7/dist-packages/django/views/generic/base.py", line 69, in view
    return self.dispatch(request, *args, **kwargs)
  File "/usr/local/lib/python2.7/dist-packages/django/utils/decorators.py", line 29, in _wrapper
    return bound_func(*args, **kwargs)
  File "/usr/local/lib/python2.7/dist-packages/django/contrib/auth/decorators.py", line 22, in _wrapped_view
    return view_func(request, *args, **kwargs)
  File "/usr/local/lib/python2.7/dist-packages/django/utils/decorators.py", line 25, in bound_func
    return func(self, *args2, **kwargs2)
  File "/home/mikhail/EclipseWorkspace/oncoFinder2/oncoFinder2/core/views.py", line 45, in dispatch
    return super(CoreSetCalculationParameters, self).dispatch(request, *args, **kwargs)
  File "/usr/local/lib/python2.7/dist-packages/django/views/generic/base.py", line 87, in dispatch
    return handler(request, *args, **kwargs)
  File "/usr/local/lib/python2.7/dist-packages/django/views/generic/edit.py", line 171, in post
    return self.form_valid(form)
  File "/home/mikhail/EclipseWorkspace/oncoFinder2/oncoFinder2/core/views.py", line 403, in form_valid
    raise Exception('exp')
Exception: exp
2015-03-12 19:59:02,909 ERROR base 11100 -1252000960 Internal Server Error: /calculation-parameters/doc4872/
Traceback (most recent call last):
  File "/usr/local/lib/python2.7/dist-packages/django/core/handlers/base.py", line 114, in get_response
    response = wrapped_callback(request, *callback_args, **callback_kwargs)
  File "/usr/local/lib/python2.7/dist-packages/django/views/generic/base.py", line 69, in view
    return self.dispatch(request, *args, **kwargs)
  File "/usr/local/lib/python2.7/dist-packages/django/utils/decorators.py", line 29, in _wrapper
    return bound_func(*args, **kwargs)
  File "/usr/local/lib/python2.7/dist-packages/django/contrib/auth/decorators.py", line 22, in _wrapped_view
    return view_func(request, *args, **kwargs)
  File "/usr/local/lib/python2.7/dist-packages/django/utils/decorators.py", line 25, in bound_func
    return func(self, *args2, **kwargs2)
  File "/home/mikhail/EclipseWorkspace/oncoFinder2/oncoFinder2/core/views.py", line 45, in dispatch
    return super(CoreSetCalculationParameters, self).dispatch(request, *args, **kwargs)
  File "/usr/local/lib/python2.7/dist-packages/django/views/generic/base.py", line 87, in dispatch
    return handler(request, *args, **kwargs)
  File "/usr/local/lib/python2.7/dist-packages/django/views/generic/edit.py", line 171, in post
    return self.form_valid(form)
  File "/home/mikhail/EclipseWorkspace/oncoFinder2/oncoFinder2/core/views.py", line 489, in form_valid
    raise Exception('exppp')
Exception: exppp
2015-03-12 20:01:28,815 ERROR base 12224 -1250432192 Internal Server Error: /calculation-parameters/doc4872/
Traceback (most recent call last):
  File "/usr/local/lib/python2.7/dist-packages/django/core/handlers/base.py", line 114, in get_response
    response = wrapped_callback(request, *callback_args, **callback_kwargs)
  File "/usr/local/lib/python2.7/dist-packages/django/views/generic/base.py", line 69, in view
    return self.dispatch(request, *args, **kwargs)
  File "/usr/local/lib/python2.7/dist-packages/django/utils/decorators.py", line 29, in _wrapper
    return bound_func(*args, **kwargs)
  File "/usr/local/lib/python2.7/dist-packages/django/contrib/auth/decorators.py", line 22, in _wrapped_view
    return view_func(request, *args, **kwargs)
  File "/usr/local/lib/python2.7/dist-packages/django/utils/decorators.py", line 25, in bound_func
    return func(self, *args2, **kwargs2)
  File "/home/mikhail/EclipseWorkspace/oncoFinder2/oncoFinder2/core/views.py", line 45, in dispatch
    return super(CoreSetCalculationParameters, self).dispatch(request, *args, **kwargs)
  File "/usr/local/lib/python2.7/dist-packages/django/views/generic/base.py", line 87, in dispatch
    return handler(request, *args, **kwargs)
  File "/usr/local/lib/python2.7/dist-packages/django/views/generic/edit.py", line 171, in post
    return self.form_valid(form)
  File "/home/mikhail/EclipseWorkspace/oncoFinder2/oncoFinder2/core/views.py", line 489, in form_valid
    raise Exception('exppp')
Exception: exppp
2015-03-12 20:10:50,375 ERROR base 15783 -1251480768 Internal Server Error: /calculation-parameters/doc4872/
Traceback (most recent call last):
  File "/usr/local/lib/python2.7/dist-packages/django/core/handlers/base.py", line 114, in get_response
    response = wrapped_callback(request, *callback_args, **callback_kwargs)
  File "/usr/local/lib/python2.7/dist-packages/django/views/generic/base.py", line 69, in view
    return self.dispatch(request, *args, **kwargs)
  File "/usr/local/lib/python2.7/dist-packages/django/utils/decorators.py", line 29, in _wrapper
    return bound_func(*args, **kwargs)
  File "/usr/local/lib/python2.7/dist-packages/django/contrib/auth/decorators.py", line 22, in _wrapped_view
    return view_func(request, *args, **kwargs)
  File "/usr/local/lib/python2.7/dist-packages/django/utils/decorators.py", line 25, in bound_func
    return func(self, *args2, **kwargs2)
  File "/home/mikhail/EclipseWorkspace/oncoFinder2/oncoFinder2/core/views.py", line 45, in dispatch
    return super(CoreSetCalculationParameters, self).dispatch(request, *args, **kwargs)
  File "/usr/local/lib/python2.7/dist-packages/django/views/generic/base.py", line 87, in dispatch
    return handler(request, *args, **kwargs)
  File "/usr/local/lib/python2.7/dist-packages/django/views/generic/edit.py", line 171, in post
    return self.form_valid(form)
  File "/home/mikhail/EclipseWorkspace/oncoFinder2/oncoFinder2/core/views.py", line 361, in form_valid
    serie = serie[serie>0 | serie<0]
  File "/usr/local/lib/python2.7/dist-packages/pandas/core/ops.py", line 665, in wrapper
    res = self._constructor(na_op(self.values, other),
  File "/usr/local/lib/python2.7/dist-packages/pandas/core/ops.py", line 649, in na_op
    x.dtype, type(y).__name__))
TypeError: cannot compare a dtyped [float64] array with a scalar of type [bool]
2015-03-12 20:12:31,645 ERROR base 16261 -1250432192 Internal Server Error: /calculation-parameters/doc4872/
Traceback (most recent call last):
  File "/usr/local/lib/python2.7/dist-packages/django/core/handlers/base.py", line 114, in get_response
    response = wrapped_callback(request, *callback_args, **callback_kwargs)
  File "/usr/local/lib/python2.7/dist-packages/django/views/generic/base.py", line 69, in view
    return self.dispatch(request, *args, **kwargs)
  File "/usr/local/lib/python2.7/dist-packages/django/utils/decorators.py", line 29, in _wrapper
    return bound_func(*args, **kwargs)
  File "/usr/local/lib/python2.7/dist-packages/django/contrib/auth/decorators.py", line 22, in _wrapped_view
    return view_func(request, *args, **kwargs)
  File "/usr/local/lib/python2.7/dist-packages/django/utils/decorators.py", line 25, in bound_func
    return func(self, *args2, **kwargs2)
  File "/home/mikhail/EclipseWorkspace/oncoFinder2/oncoFinder2/core/views.py", line 45, in dispatch
    return super(CoreSetCalculationParameters, self).dispatch(request, *args, **kwargs)
  File "/usr/local/lib/python2.7/dist-packages/django/views/generic/base.py", line 87, in dispatch
    return handler(request, *args, **kwargs)
  File "/usr/local/lib/python2.7/dist-packages/django/views/generic/edit.py", line 171, in post
    return self.form_valid(form)
  File "/home/mikhail/EclipseWorkspace/oncoFinder2/oncoFinder2/core/views.py", line 490, in form_valid
    raise Exception('exppp')
Exception: exppp
2015-03-17 12:13:52,671 ERROR base 15659 -1250432192 Internal Server Error: /xpn/
Traceback (most recent call last):
  File "/usr/local/lib/python2.7/dist-packages/django/core/handlers/base.py", line 139, in get_response
    response = response.render()
  File "/usr/local/lib/python2.7/dist-packages/django/template/response.py", line 105, in render
    self.content = self.rendered_content
  File "/usr/local/lib/python2.7/dist-packages/django/template/response.py", line 80, in rendered_content
    template = self.resolve_template(self.template_name)
  File "/usr/local/lib/python2.7/dist-packages/django/template/response.py", line 56, in resolve_template
    return loader.select_template(template)
  File "/usr/local/lib/python2.7/dist-packages/django/template/loader.py", line 186, in select_template
    raise TemplateDoesNotExist(', '.join(not_found))
TemplateDoesNotExist: core/xpnform.html
2015-03-17 12:21:56,060 ERROR base 18854 -1250432192 Internal Server Error: /xpn/
Traceback (most recent call last):
  File "/usr/local/lib/python2.7/dist-packages/django/core/handlers/base.py", line 114, in get_response
    response = wrapped_callback(request, *callback_args, **callback_kwargs)
  File "/usr/local/lib/python2.7/dist-packages/django/views/generic/base.py", line 69, in view
    return self.dispatch(request, *args, **kwargs)
  File "/usr/local/lib/python2.7/dist-packages/django/utils/decorators.py", line 29, in _wrapper
    return bound_func(*args, **kwargs)
  File "/usr/local/lib/python2.7/dist-packages/django/contrib/auth/decorators.py", line 22, in _wrapped_view
    return view_func(request, *args, **kwargs)
  File "/usr/local/lib/python2.7/dist-packages/django/utils/decorators.py", line 25, in bound_func
    return func(self, *args2, **kwargs2)
  File "/home/mikhail/EclipseWorkspace/oncoFinder2/oncoFinder2/core/xpn_views.py", line 15, in dispatch
    return super(XpnForm, self).dispatch(request, *args, **kwargs)
  File "/usr/local/lib/python2.7/dist-packages/django/views/generic/base.py", line 87, in dispatch
    return handler(request, *args, **kwargs)
  File "/usr/local/lib/python2.7/dist-packages/django/views/generic/edit.py", line 160, in get
    form = self.get_form(form_class)
  File "/usr/local/lib/python2.7/dist-packages/django/views/generic/edit.py", line 44, in get_form
    return form_class(**self.get_form_kwargs())
TypeError: 'NoneType' object is not callable
2015-03-17 12:22:04,410 ERROR base 18854 -1270875328 Internal Server Error: /xpn/
Traceback (most recent call last):
  File "/usr/local/lib/python2.7/dist-packages/django/core/handlers/base.py", line 114, in get_response
    response = wrapped_callback(request, *callback_args, **callback_kwargs)
  File "/usr/local/lib/python2.7/dist-packages/django/views/generic/base.py", line 69, in view
    return self.dispatch(request, *args, **kwargs)
  File "/usr/local/lib/python2.7/dist-packages/django/utils/decorators.py", line 29, in _wrapper
    return bound_func(*args, **kwargs)
  File "/usr/local/lib/python2.7/dist-packages/django/contrib/auth/decorators.py", line 22, in _wrapped_view
    return view_func(request, *args, **kwargs)
  File "/usr/local/lib/python2.7/dist-packages/django/utils/decorators.py", line 25, in bound_func
    return func(self, *args2, **kwargs2)
  File "/home/mikhail/EclipseWorkspace/oncoFinder2/oncoFinder2/core/xpn_views.py", line 15, in dispatch
    return super(XpnForm, self).dispatch(request, *args, **kwargs)
  File "/usr/local/lib/python2.7/dist-packages/django/views/generic/base.py", line 87, in dispatch
    return handler(request, *args, **kwargs)
  File "/usr/local/lib/python2.7/dist-packages/django/views/generic/edit.py", line 160, in get
    form = self.get_form(form_class)
  File "/usr/local/lib/python2.7/dist-packages/django/views/generic/edit.py", line 44, in get_form
    return form_class(**self.get_form_kwargs())
TypeError: 'NoneType' object is not callable
2015-03-17 12:54:57,608 ERROR base 31443 -1250485440 Internal Server Error: /xpn/
Traceback (most recent call last):
  File "/usr/local/lib/python2.7/dist-packages/django/core/handlers/base.py", line 114, in get_response
    response = wrapped_callback(request, *callback_args, **callback_kwargs)
  File "/usr/local/lib/python2.7/dist-packages/django/views/generic/base.py", line 69, in view
    return self.dispatch(request, *args, **kwargs)
  File "/usr/local/lib/python2.7/dist-packages/django/utils/decorators.py", line 29, in _wrapper
    return bound_func(*args, **kwargs)
  File "/usr/local/lib/python2.7/dist-packages/django/contrib/auth/decorators.py", line 22, in _wrapped_view
    return view_func(request, *args, **kwargs)
  File "/usr/local/lib/python2.7/dist-packages/django/utils/decorators.py", line 25, in bound_func
    return func(self, *args2, **kwargs2)
  File "/home/mikhail/EclipseWorkspace/oncoFinder2/oncoFinder2/core/xpn_views.py", line 20, in dispatch
    return super(XpnForm, self).dispatch(request, *args, **kwargs)
  File "/usr/local/lib/python2.7/dist-packages/django/views/generic/base.py", line 87, in dispatch
    return handler(request, *args, **kwargs)
  File "/usr/local/lib/python2.7/dist-packages/django/views/generic/edit.py", line 160, in get
    form = self.get_form(form_class)
  File "/usr/local/lib/python2.7/dist-packages/django/views/generic/edit.py", line 44, in get_form
    return form_class(**self.get_form_kwargs())
  File "/home/mikhail/EclipseWorkspace/oncoFinder2/oncoFinder2/core/forms.py", line 92, in __init__
    self.fields['pvalue_threshold'].widget.attrs.update({'class' : 'form-control input-sm', 'style':'width:60px; display:inline'})
KeyError: 'pvalue_threshold'
2015-03-17 12:55:06,849 ERROR base 31443 -1279268032 Internal Server Error: /xpn/
Traceback (most recent call last):
  File "/usr/local/lib/python2.7/dist-packages/django/core/handlers/base.py", line 114, in get_response
    response = wrapped_callback(request, *callback_args, **callback_kwargs)
  File "/usr/local/lib/python2.7/dist-packages/django/views/generic/base.py", line 69, in view
    return self.dispatch(request, *args, **kwargs)
  File "/usr/local/lib/python2.7/dist-packages/django/utils/decorators.py", line 29, in _wrapper
    return bound_func(*args, **kwargs)
  File "/usr/local/lib/python2.7/dist-packages/django/contrib/auth/decorators.py", line 22, in _wrapped_view
    return view_func(request, *args, **kwargs)
  File "/usr/local/lib/python2.7/dist-packages/django/utils/decorators.py", line 25, in bound_func
    return func(self, *args2, **kwargs2)
  File "/home/mikhail/EclipseWorkspace/oncoFinder2/oncoFinder2/core/xpn_views.py", line 20, in dispatch
    return super(XpnForm, self).dispatch(request, *args, **kwargs)
  File "/usr/local/lib/python2.7/dist-packages/django/views/generic/base.py", line 87, in dispatch
    return handler(request, *args, **kwargs)
  File "/usr/local/lib/python2.7/dist-packages/django/views/generic/edit.py", line 160, in get
    form = self.get_form(form_class)
  File "/usr/local/lib/python2.7/dist-packages/django/views/generic/edit.py", line 44, in get_form
    return form_class(**self.get_form_kwargs())
  File "/home/mikhail/EclipseWorkspace/oncoFinder2/oncoFinder2/core/forms.py", line 92, in __init__
    
KeyError: 'pvalue_threshold'
2015-03-17 12:55:09,729 ERROR base 31443 -1260389568 Internal Server Error: /xpn/
Traceback (most recent call last):
  File "/usr/local/lib/python2.7/dist-packages/django/core/handlers/base.py", line 114, in get_response
    response = wrapped_callback(request, *callback_args, **callback_kwargs)
  File "/usr/local/lib/python2.7/dist-packages/django/views/generic/base.py", line 69, in view
    return self.dispatch(request, *args, **kwargs)
  File "/usr/local/lib/python2.7/dist-packages/django/utils/decorators.py", line 29, in _wrapper
    return bound_func(*args, **kwargs)
  File "/usr/local/lib/python2.7/dist-packages/django/contrib/auth/decorators.py", line 22, in _wrapped_view
    return view_func(request, *args, **kwargs)
  File "/usr/local/lib/python2.7/dist-packages/django/utils/decorators.py", line 25, in bound_func
    return func(self, *args2, **kwargs2)
  File "/home/mikhail/EclipseWorkspace/oncoFinder2/oncoFinder2/core/xpn_views.py", line 20, in dispatch
    return super(XpnForm, self).dispatch(request, *args, **kwargs)
  File "/usr/local/lib/python2.7/dist-packages/django/views/generic/base.py", line 87, in dispatch
    return handler(request, *args, **kwargs)
  File "/usr/local/lib/python2.7/dist-packages/django/views/generic/edit.py", line 160, in get
    form = self.get_form(form_class)
  File "/usr/local/lib/python2.7/dist-packages/django/views/generic/edit.py", line 44, in get_form
    return form_class(**self.get_form_kwargs())
  File "/home/mikhail/EclipseWorkspace/oncoFinder2/oncoFinder2/core/forms.py", line 92, in __init__
    
KeyError: 'pvalue_threshold'
2015-03-17 13:37:26,583 ERROR base 15637 -1325827264 Internal Server Error: /xpn/
Traceback (most recent call last):
  File "/usr/local/lib/python2.7/dist-packages/django/core/handlers/base.py", line 139, in get_response
    response = response.render()
  File "/usr/local/lib/python2.7/dist-packages/django/template/response.py", line 105, in render
    self.content = self.rendered_content
  File "/usr/local/lib/python2.7/dist-packages/django/template/response.py", line 80, in rendered_content
    template = self.resolve_template(self.template_name)
  File "/usr/local/lib/python2.7/dist-packages/django/template/response.py", line 56, in resolve_template
    return loader.select_template(template)
  File "/usr/local/lib/python2.7/dist-packages/django/template/loader.py", line 180, in select_template
    return get_template(template_name)
  File "/usr/local/lib/python2.7/dist-packages/django/template/loader.py", line 138, in get_template
    template, origin = find_template(template_name)
  File "/usr/local/lib/python2.7/dist-packages/django/template/loader.py", line 127, in find_template
    source, display_name = loader(name, dirs)
  File "/usr/local/lib/python2.7/dist-packages/django/template/loader.py", line 43, in __call__
    return self.load_template(template_name, template_dirs)
  File "/usr/local/lib/python2.7/dist-packages/django/template/loader.py", line 49, in load_template
    template = get_template_from_string(source, origin, template_name)
  File "/usr/local/lib/python2.7/dist-packages/django/template/loader.py", line 149, in get_template_from_string
    return Template(source, origin, name)
  File "/usr/local/lib/python2.7/dist-packages/django_debug_toolbar-0.9.4-py2.7.egg/debug_toolbar/panels/template.py", line 37, in new_template_init
    old_template_init(self, template_string, origin, name)
  File "/usr/local/lib/python2.7/dist-packages/django/template/base.py", line 125, in __init__
    self.nodelist = compile_string(template_string, origin)
  File "/usr/local/lib/python2.7/dist-packages/django/template/base.py", line 153, in compile_string
    return parser.parse()
  File "/usr/local/lib/python2.7/dist-packages/django/template/base.py", line 278, in parse
    compiled_result = compile_func(self, token)
  File "/usr/local/lib/python2.7/dist-packages/django/template/loader_tags.py", line 215, in do_extends
    nodelist = parser.parse()
  File "/usr/local/lib/python2.7/dist-packages/django/template/base.py", line 278, in parse
    compiled_result = compile_func(self, token)
  File "/usr/local/lib/python2.7/dist-packages/django/template/loader_tags.py", line 190, in do_block
    nodelist = parser.parse(('endblock',))
  File "/usr/local/lib/python2.7/dist-packages/django/template/base.py", line 278, in parse
    compiled_result = compile_func(self, token)
  File "/usr/local/lib/python2.7/dist-packages/django/template/defaulttags.py", line 942, in do_if
    nodelist = parser.parse(('elif', 'else', 'endif'))
  File "/usr/local/lib/python2.7/dist-packages/django/template/base.py", line 278, in parse
    compiled_result = compile_func(self, token)
  File "/usr/local/lib/python2.7/dist-packages/django/template/defaulttags.py", line 806, in do_for
    nodelist_loop = parser.parse(('empty', 'endfor',))
  File "/usr/local/lib/python2.7/dist-packages/django/template/base.py", line 278, in parse
    compiled_result = compile_func(self, token)
  File "/usr/local/lib/python2.7/dist-packages/django/template/defaulttags.py", line 806, in do_for
    nodelist_loop = parser.parse(('empty', 'endfor',))
  File "/usr/local/lib/python2.7/dist-packages/django/template/base.py", line 276, in parse
    self.invalid_block_tag(token, command, parse_until)
  File "/usr/local/lib/python2.7/dist-packages/django/template/base.py", line 331, in invalid_block_tag
    (command, get_text_list(["'%s'" % p for p in parse_until])))
TemplateSyntaxError: Invalid block tag: 'endif', expected 'empty' or 'endfor'
2015-03-17 13:46:11,381 ERROR base 19326 -1260389568 Internal Server Error: /xpn/
Traceback (most recent call last):
  File "/usr/local/lib/python2.7/dist-packages/django/core/handlers/base.py", line 114, in get_response
    response = wrapped_callback(request, *callback_args, **callback_kwargs)
  File "/usr/local/lib/python2.7/dist-packages/django/views/generic/base.py", line 69, in view
    return self.dispatch(request, *args, **kwargs)
  File "/usr/local/lib/python2.7/dist-packages/django/utils/decorators.py", line 29, in _wrapper
    return bound_func(*args, **kwargs)
  File "/usr/local/lib/python2.7/dist-packages/django/contrib/auth/decorators.py", line 22, in _wrapped_view
    return view_func(request, *args, **kwargs)
  File "/usr/local/lib/python2.7/dist-packages/django/utils/decorators.py", line 25, in bound_func
    return func(self, *args2, **kwargs2)
  File "/home/mikhail/EclipseWorkspace/oncoFinder2/oncoFinder2/core/xpn_views.py", line 20, in dispatch
    return super(XpnForm, self).dispatch(request, *args, **kwargs)
  File "/usr/local/lib/python2.7/dist-packages/django/views/generic/base.py", line 87, in dispatch
    return handler(request, *args, **kwargs)
  File "/usr/local/lib/python2.7/dist-packages/django/views/generic/edit.py", line 171, in post
    return self.form_valid(form)
  File "/home/mikhail/EclipseWorkspace/oncoFinder2/oncoFinder2/core/xpn_views.py", line 30, in form_valid
    raise Exception("test")
Exception: test
2015-03-17 13:48:22,900 ERROR base 20253 -1250432192 Internal Server Error: /xpn/
Traceback (most recent call last):
  File "/usr/local/lib/python2.7/dist-packages/django/core/handlers/base.py", line 114, in get_response
    response = wrapped_callback(request, *callback_args, **callback_kwargs)
  File "/usr/local/lib/python2.7/dist-packages/django/views/generic/base.py", line 69, in view
    return self.dispatch(request, *args, **kwargs)
  File "/usr/local/lib/python2.7/dist-packages/django/utils/decorators.py", line 29, in _wrapper
    return bound_func(*args, **kwargs)
  File "/usr/local/lib/python2.7/dist-packages/django/contrib/auth/decorators.py", line 22, in _wrapped_view
    return view_func(request, *args, **kwargs)
  File "/usr/local/lib/python2.7/dist-packages/django/utils/decorators.py", line 25, in bound_func
    return func(self, *args2, **kwargs2)
  File "/home/mikhail/EclipseWorkspace/oncoFinder2/oncoFinder2/core/xpn_views.py", line 20, in dispatch
    return super(XpnForm, self).dispatch(request, *args, **kwargs)
  File "/usr/local/lib/python2.7/dist-packages/django/views/generic/base.py", line 87, in dispatch
    return handler(request, *args, **kwargs)
  File "/usr/local/lib/python2.7/dist-packages/django/views/generic/edit.py", line 171, in post
    return self.form_valid(form)
  File "/home/mikhail/EclipseWorkspace/oncoFinder2/oncoFinder2/core/xpn_views.py", line 31, in form_valid
    raise Exception("test")
Exception: test
2015-03-17 13:52:41,494 ERROR base 21924 -1251480768 Internal Server Error: /xpn/
Traceback (most recent call last):
  File "/usr/local/lib/python2.7/dist-packages/django/core/handlers/base.py", line 114, in get_response
    response = wrapped_callback(request, *callback_args, **callback_kwargs)
  File "/usr/local/lib/python2.7/dist-packages/django/views/generic/base.py", line 69, in view
    return self.dispatch(request, *args, **kwargs)
  File "/usr/local/lib/python2.7/dist-packages/django/utils/decorators.py", line 29, in _wrapper
    return bound_func(*args, **kwargs)
  File "/usr/local/lib/python2.7/dist-packages/django/contrib/auth/decorators.py", line 22, in _wrapped_view
    return view_func(request, *args, **kwargs)
  File "/usr/local/lib/python2.7/dist-packages/django/utils/decorators.py", line 25, in bound_func
    return func(self, *args2, **kwargs2)
  File "/home/mikhail/EclipseWorkspace/oncoFinder2/oncoFinder2/core/xpn_views.py", line 20, in dispatch
    return super(XpnForm, self).dispatch(request, *args, **kwargs)
  File "/usr/local/lib/python2.7/dist-packages/django/views/generic/base.py", line 87, in dispatch
    return handler(request, *args, **kwargs)
  File "/usr/local/lib/python2.7/dist-packages/django/views/generic/edit.py", line 171, in post
    return self.form_valid(form)
  File "/home/mikhail/EclipseWorkspace/oncoFinder2/oncoFinder2/core/xpn_views.py", line 34, in form_valid
    raise Exception("test")
Exception: test
2015-03-17 13:56:10,579 ERROR base 22409 -1250432192 Internal Server Error: /xpn/
Traceback (most recent call last):
  File "/usr/local/lib/python2.7/dist-packages/django/core/handlers/base.py", line 114, in get_response
    response = wrapped_callback(request, *callback_args, **callback_kwargs)
  File "/usr/local/lib/python2.7/dist-packages/django/views/generic/base.py", line 69, in view
    return self.dispatch(request, *args, **kwargs)
  File "/usr/local/lib/python2.7/dist-packages/django/utils/decorators.py", line 29, in _wrapper
    return bound_func(*args, **kwargs)
  File "/usr/local/lib/python2.7/dist-packages/django/contrib/auth/decorators.py", line 22, in _wrapped_view
    return view_func(request, *args, **kwargs)
  File "/usr/local/lib/python2.7/dist-packages/django/utils/decorators.py", line 25, in bound_func
    return func(self, *args2, **kwargs2)
  File "/home/mikhail/EclipseWorkspace/oncoFinder2/oncoFinder2/core/xpn_views.py", line 20, in dispatch
    return super(XpnForm, self).dispatch(request, *args, **kwargs)
  File "/usr/local/lib/python2.7/dist-packages/django/views/generic/base.py", line 87, in dispatch
    return handler(request, *args, **kwargs)
  File "/usr/local/lib/python2.7/dist-packages/django/views/generic/edit.py", line 171, in post
    return self.form_valid(form)
  File "/home/mikhail/EclipseWorkspace/oncoFinder2/oncoFinder2/core/xpn_views.py", line 45, in form_valid
    raise Exception("test")
Exception: test
2015-03-17 13:56:31,534 ERROR base 23610 -1251480768 Internal Server Error: /xpn/
Traceback (most recent call last):
  File "/usr/local/lib/python2.7/dist-packages/django/core/handlers/base.py", line 114, in get_response
    response = wrapped_callback(request, *callback_args, **callback_kwargs)
  File "/usr/local/lib/python2.7/dist-packages/django/views/generic/base.py", line 69, in view
    return self.dispatch(request, *args, **kwargs)
  File "/usr/local/lib/python2.7/dist-packages/django/utils/decorators.py", line 29, in _wrapper
    return bound_func(*args, **kwargs)
  File "/usr/local/lib/python2.7/dist-packages/django/contrib/auth/decorators.py", line 22, in _wrapped_view
    return view_func(request, *args, **kwargs)
  File "/usr/local/lib/python2.7/dist-packages/django/utils/decorators.py", line 25, in bound_func
    return func(self, *args2, **kwargs2)
  File "/home/mikhail/EclipseWorkspace/oncoFinder2/oncoFinder2/core/xpn_views.py", line 20, in dispatch
    return super(XpnForm, self).dispatch(request, *args, **kwargs)
  File "/usr/local/lib/python2.7/dist-packages/django/views/generic/base.py", line 87, in dispatch
    return handler(request, *args, **kwargs)
  File "/usr/local/lib/python2.7/dist-packages/django/views/generic/edit.py", line 171, in post
    return self.form_valid(form)
  File "/home/mikhail/EclipseWorkspace/oncoFinder2/oncoFinder2/core/xpn_views.py", line 45, in form_valid
    raise Exception("test")
Exception: test
2015-03-17 14:07:38,136 ERROR base 26984 -1250432192 Internal Server Error: /xpn/
Traceback (most recent call last):
  File "/usr/local/lib/python2.7/dist-packages/django/core/handlers/base.py", line 114, in get_response
    response = wrapped_callback(request, *callback_args, **callback_kwargs)
  File "/usr/local/lib/python2.7/dist-packages/django/views/generic/base.py", line 69, in view
    return self.dispatch(request, *args, **kwargs)
  File "/usr/local/lib/python2.7/dist-packages/django/utils/decorators.py", line 29, in _wrapper
    return bound_func(*args, **kwargs)
  File "/usr/local/lib/python2.7/dist-packages/django/contrib/auth/decorators.py", line 22, in _wrapped_view
    return view_func(request, *args, **kwargs)
  File "/usr/local/lib/python2.7/dist-packages/django/utils/decorators.py", line 25, in bound_func
    return func(self, *args2, **kwargs2)
  File "/home/mikhail/EclipseWorkspace/oncoFinder2/oncoFinder2/core/xpn_views.py", line 25, in dispatch
    return super(XpnForm, self).dispatch(request, *args, **kwargs)
  File "/usr/local/lib/python2.7/dist-packages/django/views/generic/base.py", line 87, in dispatch
    return handler(request, *args, **kwargs)
  File "/usr/local/lib/python2.7/dist-packages/django/views/generic/edit.py", line 171, in post
    return self.form_valid(form)
  File "/home/mikhail/EclipseWorkspace/oncoFinder2/oncoFinder2/core/xpn_views.py", line 50, in form_valid
    dialect = sniffer.sniff(open(pl1, 'r').read(), delimiters='\t,;') # defining the separator of the csv file
TypeError: coercing to Unicode: need string or buffer, TemporaryUploadedFile found
2015-03-17 14:08:41,406 ERROR base 28089 -1251480768 Internal Server Error: /xpn/
Traceback (most recent call last):
  File "/usr/local/lib/python2.7/dist-packages/django/core/handlers/base.py", line 114, in get_response
    response = wrapped_callback(request, *callback_args, **callback_kwargs)
  File "/usr/local/lib/python2.7/dist-packages/django/views/generic/base.py", line 69, in view
    return self.dispatch(request, *args, **kwargs)
  File "/usr/local/lib/python2.7/dist-packages/django/utils/decorators.py", line 29, in _wrapper
    return bound_func(*args, **kwargs)
  File "/usr/local/lib/python2.7/dist-packages/django/contrib/auth/decorators.py", line 22, in _wrapped_view
    return view_func(request, *args, **kwargs)
  File "/usr/local/lib/python2.7/dist-packages/django/utils/decorators.py", line 25, in bound_func
    return func(self, *args2, **kwargs2)
  File "/home/mikhail/EclipseWorkspace/oncoFinder2/oncoFinder2/core/xpn_views.py", line 25, in dispatch
    return super(XpnForm, self).dispatch(request, *args, **kwargs)
  File "/usr/local/lib/python2.7/dist-packages/django/views/generic/base.py", line 87, in dispatch
    return handler(request, *args, **kwargs)
  File "/usr/local/lib/python2.7/dist-packages/django/views/generic/edit.py", line 171, in post
    return self.form_valid(form)
  File "/home/mikhail/EclipseWorkspace/oncoFinder2/oncoFinder2/core/xpn_views.py", line 51, in form_valid
    df = read_csv(pl1, delimiter=dialect.delimiter)
  File "/usr/local/lib/python2.7/dist-packages/pandas/io/parsers.py", line 463, in parser_f
    return _read(filepath_or_buffer, kwds)
  File "/usr/local/lib/python2.7/dist-packages/pandas/io/parsers.py", line 239, in _read
    parser = TextFileReader(filepath_or_buffer, **kwds)
  File "/usr/local/lib/python2.7/dist-packages/pandas/io/parsers.py", line 553, in __init__
    self._make_engine(self.engine)
  File "/usr/local/lib/python2.7/dist-packages/pandas/io/parsers.py", line 690, in _make_engine
    self._engine = CParserWrapper(self.f, **self.options)
  File "/usr/local/lib/python2.7/dist-packages/pandas/io/parsers.py", line 1052, in __init__
    self._reader = _parser.TextReader(src, **kwds)
  File "pandas/parser.pyx", line 508, in pandas.parser.TextReader.__cinit__ (pandas/parser.c:4770)
ValueError: No columns to parse from file
2015-03-17 14:10:52,283 ERROR base 28928 -1250432192 Internal Server Error: /xpn/
Traceback (most recent call last):
  File "/usr/local/lib/python2.7/dist-packages/django/core/handlers/base.py", line 114, in get_response
    response = wrapped_callback(request, *callback_args, **callback_kwargs)
  File "/usr/local/lib/python2.7/dist-packages/django/views/generic/base.py", line 69, in view
    return self.dispatch(request, *args, **kwargs)
  File "/usr/local/lib/python2.7/dist-packages/django/utils/decorators.py", line 29, in _wrapper
    return bound_func(*args, **kwargs)
  File "/usr/local/lib/python2.7/dist-packages/django/contrib/auth/decorators.py", line 22, in _wrapped_view
    return view_func(request, *args, **kwargs)
  File "/usr/local/lib/python2.7/dist-packages/django/utils/decorators.py", line 25, in bound_func
    return func(self, *args2, **kwargs2)
  File "/home/mikhail/EclipseWorkspace/oncoFinder2/oncoFinder2/core/xpn_views.py", line 25, in dispatch
    return super(XpnForm, self).dispatch(request, *args, **kwargs)
  File "/usr/local/lib/python2.7/dist-packages/django/views/generic/base.py", line 87, in dispatch
    return handler(request, *args, **kwargs)
  File "/usr/local/lib/python2.7/dist-packages/django/views/generic/edit.py", line 171, in post
    return self.form_valid(form)
  File "/home/mikhail/EclipseWorkspace/oncoFinder2/oncoFinder2/core/xpn_views.py", line 55, in form_valid
    raise Exception("test")
Exception: test
2015-03-17 14:12:02,317 ERROR base 29400 -1251480768 Internal Server Error: /xpn/
Traceback (most recent call last):
  File "/usr/local/lib/python2.7/dist-packages/django/core/handlers/base.py", line 114, in get_response
    response = wrapped_callback(request, *callback_args, **callback_kwargs)
  File "/usr/local/lib/python2.7/dist-packages/django/views/generic/base.py", line 69, in view
    return self.dispatch(request, *args, **kwargs)
  File "/usr/local/lib/python2.7/dist-packages/django/utils/decorators.py", line 29, in _wrapper
    return bound_func(*args, **kwargs)
  File "/usr/local/lib/python2.7/dist-packages/django/contrib/auth/decorators.py", line 22, in _wrapped_view
    return view_func(request, *args, **kwargs)
  File "/usr/local/lib/python2.7/dist-packages/django/utils/decorators.py", line 25, in bound_func
    return func(self, *args2, **kwargs2)
  File "/home/mikhail/EclipseWorkspace/oncoFinder2/oncoFinder2/core/xpn_views.py", line 25, in dispatch
    return super(XpnForm, self).dispatch(request, *args, **kwargs)
  File "/usr/local/lib/python2.7/dist-packages/django/views/generic/base.py", line 87, in dispatch
    return handler(request, *args, **kwargs)
  File "/usr/local/lib/python2.7/dist-packages/django/views/generic/edit.py", line 171, in post
    return self.form_valid(form)
  File "/home/mikhail/EclipseWorkspace/oncoFinder2/oncoFinder2/core/xpn_views.py", line 59, in form_valid
    raise Exception("test")
Exception: test
2015-03-17 14:13:27,126 ERROR base 30000 -1252000960 Internal Server Error: /xpn/
Traceback (most recent call last):
  File "/usr/local/lib/python2.7/dist-packages/django/core/handlers/base.py", line 114, in get_response
    response = wrapped_callback(request, *callback_args, **callback_kwargs)
  File "/usr/local/lib/python2.7/dist-packages/django/views/generic/base.py", line 69, in view
    return self.dispatch(request, *args, **kwargs)
  File "/usr/local/lib/python2.7/dist-packages/django/utils/decorators.py", line 29, in _wrapper
    return bound_func(*args, **kwargs)
  File "/usr/local/lib/python2.7/dist-packages/django/contrib/auth/decorators.py", line 22, in _wrapped_view
    return view_func(request, *args, **kwargs)
  File "/usr/local/lib/python2.7/dist-packages/django/utils/decorators.py", line 25, in bound_func
    return func(self, *args2, **kwargs2)
  File "/home/mikhail/EclipseWorkspace/oncoFinder2/oncoFinder2/core/xpn_views.py", line 25, in dispatch
    return super(XpnForm, self).dispatch(request, *args, **kwargs)
  File "/usr/local/lib/python2.7/dist-packages/django/views/generic/base.py", line 87, in dispatch
    return handler(request, *args, **kwargs)
  File "/usr/local/lib/python2.7/dist-packages/django/views/generic/edit.py", line 171, in post
    return self.form_valid(form)
  File "/home/mikhail/EclipseWorkspace/oncoFinder2/oncoFinder2/core/xpn_views.py", line 61, in form_valid
    raise Exception("test")
Exception: test
2015-03-17 14:16:08,550 ERROR base 30418 -1251480768 Internal Server Error: /xpn/
Traceback (most recent call last):
  File "/usr/local/lib/python2.7/dist-packages/django/core/handlers/base.py", line 114, in get_response
    response = wrapped_callback(request, *callback_args, **callback_kwargs)
  File "/usr/local/lib/python2.7/dist-packages/django/views/generic/base.py", line 69, in view
    return self.dispatch(request, *args, **kwargs)
  File "/usr/local/lib/python2.7/dist-packages/django/utils/decorators.py", line 29, in _wrapper
    return bound_func(*args, **kwargs)
  File "/usr/local/lib/python2.7/dist-packages/django/contrib/auth/decorators.py", line 22, in _wrapped_view
    return view_func(request, *args, **kwargs)
  File "/usr/local/lib/python2.7/dist-packages/django/utils/decorators.py", line 25, in bound_func
    return func(self, *args2, **kwargs2)
  File "/home/mikhail/EclipseWorkspace/oncoFinder2/oncoFinder2/core/xpn_views.py", line 25, in dispatch
    return super(XpnForm, self).dispatch(request, *args, **kwargs)
  File "/usr/local/lib/python2.7/dist-packages/django/views/generic/base.py", line 87, in dispatch
    return handler(request, *args, **kwargs)
  File "/usr/local/lib/python2.7/dist-packages/django/views/generic/edit.py", line 171, in post
    return self.form_valid(form)
  File "/home/mikhail/EclipseWorkspace/oncoFinder2/oncoFinder2/core/xpn_views.py", line 69, in form_valid
    raise Exception("test")
Exception: test
2015-03-17 14:18:08,799 ERROR base 31605 -1251480768 Internal Server Error: /xpn/
Traceback (most recent call last):
  File "/usr/local/lib/python2.7/dist-packages/django/core/handlers/base.py", line 114, in get_response
    response = wrapped_callback(request, *callback_args, **callback_kwargs)
  File "/usr/local/lib/python2.7/dist-packages/django/views/generic/base.py", line 69, in view
    return self.dispatch(request, *args, **kwargs)
  File "/usr/local/lib/python2.7/dist-packages/django/utils/decorators.py", line 29, in _wrapper
    return bound_func(*args, **kwargs)
  File "/usr/local/lib/python2.7/dist-packages/django/contrib/auth/decorators.py", line 22, in _wrapped_view
    return view_func(request, *args, **kwargs)
  File "/usr/local/lib/python2.7/dist-packages/django/utils/decorators.py", line 25, in bound_func
    return func(self, *args2, **kwargs2)
  File "/home/mikhail/EclipseWorkspace/oncoFinder2/oncoFinder2/core/xpn_views.py", line 25, in dispatch
    return super(XpnForm, self).dispatch(request, *args, **kwargs)
  File "/usr/local/lib/python2.7/dist-packages/django/views/generic/base.py", line 87, in dispatch
    return handler(request, *args, **kwargs)
  File "/usr/local/lib/python2.7/dist-packages/django/views/generic/edit.py", line 171, in post
    return self.form_valid(form)
  File "/home/mikhail/EclipseWorkspace/oncoFinder2/oncoFinder2/core/xpn_views.py", line 69, in form_valid
    raise Exception("namw is "+df_out_x.index.name)
TypeError: cannot concatenate 'str' and 'NoneType' objects
2015-03-17 14:19:56,439 ERROR base 32365 -1252000960 Internal Server Error: /xpn/
Traceback (most recent call last):
  File "/usr/local/lib/python2.7/dist-packages/django/core/handlers/base.py", line 114, in get_response
    response = wrapped_callback(request, *callback_args, **callback_kwargs)
  File "/usr/local/lib/python2.7/dist-packages/django/views/generic/base.py", line 69, in view
    return self.dispatch(request, *args, **kwargs)
  File "/usr/local/lib/python2.7/dist-packages/django/utils/decorators.py", line 29, in _wrapper
    return bound_func(*args, **kwargs)
  File "/usr/local/lib/python2.7/dist-packages/django/contrib/auth/decorators.py", line 22, in _wrapped_view
    return view_func(request, *args, **kwargs)
  File "/usr/local/lib/python2.7/dist-packages/django/utils/decorators.py", line 25, in bound_func
    return func(self, *args2, **kwargs2)
  File "/home/mikhail/EclipseWorkspace/oncoFinder2/oncoFinder2/core/xpn_views.py", line 25, in dispatch
    return super(XpnForm, self).dispatch(request, *args, **kwargs)
  File "/usr/local/lib/python2.7/dist-packages/django/views/generic/base.py", line 87, in dispatch
    return handler(request, *args, **kwargs)
  File "/usr/local/lib/python2.7/dist-packages/django/views/generic/edit.py", line 171, in post
    return self.form_valid(form)
  File "/home/mikhail/EclipseWorkspace/oncoFinder2/oncoFinder2/core/xpn_views.py", line 70, in form_valid
    raise Exception("exp")
Exception: exp
2015-03-17 14:30:57,495 ERROR base 556 -1250432192 Internal Server Error: /xpn/
Traceback (most recent call last):
  File "/usr/local/lib/python2.7/dist-packages/django/core/handlers/base.py", line 114, in get_response
    response = wrapped_callback(request, *callback_args, **callback_kwargs)
  File "/usr/local/lib/python2.7/dist-packages/django/views/generic/base.py", line 69, in view
    return self.dispatch(request, *args, **kwargs)
  File "/usr/local/lib/python2.7/dist-packages/django/utils/decorators.py", line 29, in _wrapper
    return bound_func(*args, **kwargs)
  File "/usr/local/lib/python2.7/dist-packages/django/contrib/auth/decorators.py", line 22, in _wrapped_view
    return view_func(request, *args, **kwargs)
  File "/usr/local/lib/python2.7/dist-packages/django/utils/decorators.py", line 25, in bound_func
    return func(self, *args2, **kwargs2)
  File "/home/mikhail/EclipseWorkspace/oncoFinder2/oncoFinder2/core/xpn_views.py", line 26, in dispatch
    return super(XpnForm, self).dispatch(request, *args, **kwargs)
  File "/usr/local/lib/python2.7/dist-packages/django/views/generic/base.py", line 87, in dispatch
    return handler(request, *args, **kwargs)
  File "/usr/local/lib/python2.7/dist-packages/django/views/generic/edit.py", line 171, in post
    return self.form_valid(form)
  File "/home/mikhail/EclipseWorkspace/oncoFinder2/oncoFinder2/core/xpn_views.py", line 74, in form_valid
    writer = ExcelWriter(response)
  File "/usr/local/lib/python2.7/dist-packages/pandas/io/excel.py", line 444, in __new__
    ext = os.path.splitext(path)[-1][1:]
  File "/usr/lib/python2.7/posixpath.py", line 96, in splitext
    return genericpath._splitext(p, sep, altsep, extsep)
  File "/usr/lib/python2.7/genericpath.py", line 91, in _splitext
    sepIndex = p.rfind(sep)
AttributeError: 'HttpResponse' object has no attribute 'rfind'
2015-03-17 14:36:27,662 ERROR base 6498 -1249903808 Internal Server Error: /xpn/
Traceback (most recent call last):
  File "/usr/local/lib/python2.7/dist-packages/django/core/handlers/base.py", line 114, in get_response
    response = wrapped_callback(request, *callback_args, **callback_kwargs)
  File "/usr/local/lib/python2.7/dist-packages/django/views/generic/base.py", line 69, in view
    return self.dispatch(request, *args, **kwargs)
  File "/usr/local/lib/python2.7/dist-packages/django/utils/decorators.py", line 29, in _wrapper
    return bound_func(*args, **kwargs)
  File "/usr/local/lib/python2.7/dist-packages/django/contrib/auth/decorators.py", line 22, in _wrapped_view
    return view_func(request, *args, **kwargs)
  File "/usr/local/lib/python2.7/dist-packages/django/utils/decorators.py", line 25, in bound_func
    return func(self, *args2, **kwargs2)
  File "/home/mikhail/EclipseWorkspace/oncoFinder2/oncoFinder2/core/xpn_views.py", line 26, in dispatch
    return super(XpnForm, self).dispatch(request, *args, **kwargs)
  File "/usr/local/lib/python2.7/dist-packages/django/views/generic/base.py", line 87, in dispatch
    return handler(request, *args, **kwargs)
  File "/usr/local/lib/python2.7/dist-packages/django/views/generic/edit.py", line 171, in post
    return self.form_valid(form)
  File "/home/mikhail/EclipseWorkspace/oncoFinder2/oncoFinder2/core/xpn_views.py", line 62, in form_valid
    R_output = conor.xpn(Rdf_pl1, Rdf_pl2, p1_names=0, p2_names=0, iterations=10)
  File "/usr/local/lib/python2.7/dist-packages/rpy2/robjects/functions.py", line 170, in __call__
    return super(SignatureTranslatedFunction, self).__call__(*args, **kwargs)
  File "/usr/local/lib/python2.7/dist-packages/rpy2/robjects/functions.py", line 100, in __call__
    res = super(Function, self).__call__(*new_args, **new_kwargs)
RRuntimeError: Error in FUN(left, right) : non-numeric argument to binary operator

2015-03-17 14:52:35,206 ERROR base 12955 -1375737024 Internal Server Error: /xpn/
Traceback (most recent call last):
  File "/usr/local/lib/python2.7/dist-packages/django/core/handlers/base.py", line 114, in get_response
    response = wrapped_callback(request, *callback_args, **callback_kwargs)
  File "/usr/local/lib/python2.7/dist-packages/django/views/generic/base.py", line 69, in view
    return self.dispatch(request, *args, **kwargs)
  File "/usr/local/lib/python2.7/dist-packages/django/utils/decorators.py", line 29, in _wrapper
    return bound_func(*args, **kwargs)
  File "/usr/local/lib/python2.7/dist-packages/django/contrib/auth/decorators.py", line 22, in _wrapped_view
    return view_func(request, *args, **kwargs)
  File "/usr/local/lib/python2.7/dist-packages/django/utils/decorators.py", line 25, in bound_func
    return func(self, *args2, **kwargs2)
  File "/home/mikhail/EclipseWorkspace/oncoFinder2/oncoFinder2/core/xpn_views.py", line 27, in dispatch
    return super(XpnForm, self).dispatch(request, *args, **kwargs)
  File "/usr/local/lib/python2.7/dist-packages/django/views/generic/base.py", line 87, in dispatch
    return handler(request, *args, **kwargs)
  File "/usr/local/lib/python2.7/dist-packages/django/views/generic/edit.py", line 171, in post
    return self.form_valid(form)
  File "/home/mikhail/EclipseWorkspace/oncoFinder2/oncoFinder2/core/xpn_views.py", line 61, in form_valid
    df_pl1 = np.log(df_pl1).fillna(0)
AttributeError: log
2015-03-17 14:54:29,360 ERROR base 12955 -1375737024 Internal Server Error: /xpn/
Traceback (most recent call last):
  File "/usr/local/lib/python2.7/dist-packages/django/core/handlers/base.py", line 114, in get_response
    response = wrapped_callback(request, *callback_args, **callback_kwargs)
  File "/usr/local/lib/python2.7/dist-packages/django/views/generic/base.py", line 69, in view
    return self.dispatch(request, *args, **kwargs)
  File "/usr/local/lib/python2.7/dist-packages/django/utils/decorators.py", line 29, in _wrapper
    return bound_func(*args, **kwargs)
  File "/usr/local/lib/python2.7/dist-packages/django/contrib/auth/decorators.py", line 22, in _wrapped_view
    return view_func(request, *args, **kwargs)
  File "/usr/local/lib/python2.7/dist-packages/django/utils/decorators.py", line 25, in bound_func
    return func(self, *args2, **kwargs2)
  File "/home/mikhail/EclipseWorkspace/oncoFinder2/oncoFinder2/core/xpn_views.py", line 27, in dispatch
    return super(XpnForm, self).dispatch(request, *args, **kwargs)
  File "/usr/local/lib/python2.7/dist-packages/django/views/generic/base.py", line 87, in dispatch
    return handler(request, *args, **kwargs)
  File "/usr/local/lib/python2.7/dist-packages/django/views/generic/edit.py", line 171, in post
    return self.form_valid(form)
  File "/home/mikhail/EclipseWorkspace/oncoFinder2/oncoFinder2/core/xpn_views.py", line 61, in form_valid
    df_pl1 = np.log(df_pl1).fillna(0)
AttributeError: log
2015-03-17 14:55:59,784 ERROR base 14203 -1250432192 Internal Server Error: /xpn/
Traceback (most recent call last):
  File "/usr/local/lib/python2.7/dist-packages/django/core/handlers/base.py", line 114, in get_response
    response = wrapped_callback(request, *callback_args, **callback_kwargs)
  File "/usr/local/lib/python2.7/dist-packages/django/views/generic/base.py", line 69, in view
    return self.dispatch(request, *args, **kwargs)
  File "/usr/local/lib/python2.7/dist-packages/django/utils/decorators.py", line 29, in _wrapper
    return bound_func(*args, **kwargs)
  File "/usr/local/lib/python2.7/dist-packages/django/contrib/auth/decorators.py", line 22, in _wrapped_view
    return view_func(request, *args, **kwargs)
  File "/usr/local/lib/python2.7/dist-packages/django/utils/decorators.py", line 25, in bound_func
    return func(self, *args2, **kwargs2)
  File "/home/mikhail/EclipseWorkspace/oncoFinder2/oncoFinder2/core/xpn_views.py", line 26, in dispatch
    return super(XpnForm, self).dispatch(request, *args, **kwargs)
  File "/usr/local/lib/python2.7/dist-packages/django/views/generic/base.py", line 87, in dispatch
    return handler(request, *args, **kwargs)
  File "/usr/local/lib/python2.7/dist-packages/django/views/generic/edit.py", line 171, in post
    return self.form_valid(form)
  File "/home/mikhail/EclipseWorkspace/oncoFinder2/oncoFinder2/core/xpn_views.py", line 60, in form_valid
    df_pl1 = np.log(df_pl1).fillna(0)
AttributeError: log
2015-03-17 14:59:53,165 ERROR base 15912 -1251480768 Internal Server Error: /xpn/
Traceback (most recent call last):
  File "/usr/local/lib/python2.7/dist-packages/django/core/handlers/base.py", line 114, in get_response
    response = wrapped_callback(request, *callback_args, **callback_kwargs)
  File "/usr/local/lib/python2.7/dist-packages/django/views/generic/base.py", line 69, in view
    return self.dispatch(request, *args, **kwargs)
  File "/usr/local/lib/python2.7/dist-packages/django/utils/decorators.py", line 29, in _wrapper
    return bound_func(*args, **kwargs)
  File "/usr/local/lib/python2.7/dist-packages/django/contrib/auth/decorators.py", line 22, in _wrapped_view
    return view_func(request, *args, **kwargs)
  File "/usr/local/lib/python2.7/dist-packages/django/utils/decorators.py", line 25, in bound_func
    return func(self, *args2, **kwargs2)
  File "/home/mikhail/EclipseWorkspace/oncoFinder2/oncoFinder2/core/xpn_views.py", line 26, in dispatch
    return super(XpnForm, self).dispatch(request, *args, **kwargs)
  File "/usr/local/lib/python2.7/dist-packages/django/views/generic/base.py", line 87, in dispatch
    return handler(request, *args, **kwargs)
  File "/usr/local/lib/python2.7/dist-packages/django/views/generic/edit.py", line 171, in post
    return self.form_valid(form)
  File "/home/mikhail/EclipseWorkspace/oncoFinder2/oncoFinder2/core/xpn_views.py", line 71, in form_valid
    corr=corr, iterations=iterations, skip_match=skip_match )
  File "/usr/local/lib/python2.7/dist-packages/rpy2/robjects/functions.py", line 170, in __call__
    return super(SignatureTranslatedFunction, self).__call__(*args, **kwargs)
  File "/usr/local/lib/python2.7/dist-packages/rpy2/robjects/functions.py", line 100, in __call__
    res = super(Function, self).__call__(*new_args, **new_kwargs)
RRuntimeError: Error in (function (platform1.data, platform2.data, K = 10, L = 4, p1.names = 0,  : 
  unused arguments (k = 10, l = 4)

2015-03-17 15:01:27,857 ERROR base 16480 -1251480768 Internal Server Error: /xpn/
Traceback (most recent call last):
  File "/usr/local/lib/python2.7/dist-packages/django/core/handlers/base.py", line 114, in get_response
    response = wrapped_callback(request, *callback_args, **callback_kwargs)
  File "/usr/local/lib/python2.7/dist-packages/django/views/generic/base.py", line 69, in view
    return self.dispatch(request, *args, **kwargs)
  File "/usr/local/lib/python2.7/dist-packages/django/utils/decorators.py", line 29, in _wrapper
    return bound_func(*args, **kwargs)
  File "/usr/local/lib/python2.7/dist-packages/django/contrib/auth/decorators.py", line 22, in _wrapped_view
    return view_func(request, *args, **kwargs)
  File "/usr/local/lib/python2.7/dist-packages/django/utils/decorators.py", line 25, in bound_func
    return func(self, *args2, **kwargs2)
  File "/home/mikhail/EclipseWorkspace/oncoFinder2/oncoFinder2/core/xpn_views.py", line 26, in dispatch
    return super(XpnForm, self).dispatch(request, *args, **kwargs)
  File "/usr/local/lib/python2.7/dist-packages/django/views/generic/base.py", line 87, in dispatch
    return handler(request, *args, **kwargs)
  File "/usr/local/lib/python2.7/dist-packages/django/views/generic/edit.py", line 171, in post
    return self.form_valid(form)
  File "/home/mikhail/EclipseWorkspace/oncoFinder2/oncoFinder2/core/xpn_views.py", line 71, in form_valid
    corr=corr, iterations=iterations, skip_match=skip_match )
  File "/usr/local/lib/python2.7/dist-packages/rpy2/robjects/functions.py", line 170, in __call__
    return super(SignatureTranslatedFunction, self).__call__(*args, **kwargs)
  File "/usr/local/lib/python2.7/dist-packages/rpy2/robjects/functions.py", line 100, in __call__
    res = super(Function, self).__call__(*new_args, **new_kwargs)
RRuntimeError: Error in `row.names<-.data.frame`(`*tmp*`, value = value) : 
  duplicate 'row.names' are not allowed

2015-03-17 15:03:03,240 ERROR base 17110 -1250432192 Internal Server Error: /xpn/
Traceback (most recent call last):
  File "/usr/local/lib/python2.7/dist-packages/django/core/handlers/base.py", line 114, in get_response
    response = wrapped_callback(request, *callback_args, **callback_kwargs)
  File "/usr/local/lib/python2.7/dist-packages/django/views/generic/base.py", line 69, in view
    return self.dispatch(request, *args, **kwargs)
  File "/usr/local/lib/python2.7/dist-packages/django/utils/decorators.py", line 29, in _wrapper
    return bound_func(*args, **kwargs)
  File "/usr/local/lib/python2.7/dist-packages/django/contrib/auth/decorators.py", line 22, in _wrapped_view
    return view_func(request, *args, **kwargs)
  File "/usr/local/lib/python2.7/dist-packages/django/utils/decorators.py", line 25, in bound_func
    return func(self, *args2, **kwargs2)
  File "/home/mikhail/EclipseWorkspace/oncoFinder2/oncoFinder2/core/xpn_views.py", line 26, in dispatch
    return super(XpnForm, self).dispatch(request, *args, **kwargs)
  File "/usr/local/lib/python2.7/dist-packages/django/views/generic/base.py", line 87, in dispatch
    return handler(request, *args, **kwargs)
  File "/usr/local/lib/python2.7/dist-packages/django/views/generic/edit.py", line 171, in post
    return self.form_valid(form)
  File "/home/mikhail/EclipseWorkspace/oncoFinder2/oncoFinder2/core/xpn_views.py", line 69, in form_valid
    p1_names=p1_names, p2_names=p2_names)
  File "/usr/local/lib/python2.7/dist-packages/rpy2/robjects/functions.py", line 170, in __call__
    return super(SignatureTranslatedFunction, self).__call__(*args, **kwargs)
  File "/usr/local/lib/python2.7/dist-packages/rpy2/robjects/functions.py", line 100, in __call__
    res = super(Function, self).__call__(*new_args, **new_kwargs)
RRuntimeError: Error in `row.names<-.data.frame`(`*tmp*`, value = value) : 
  duplicate 'row.names' are not allowed

2015-03-17 15:04:06,145 ERROR base 17555 -1250432192 Internal Server Error: /xpn/
Traceback (most recent call last):
  File "/usr/local/lib/python2.7/dist-packages/django/core/handlers/base.py", line 114, in get_response
    response = wrapped_callback(request, *callback_args, **callback_kwargs)
  File "/usr/local/lib/python2.7/dist-packages/django/views/generic/base.py", line 69, in view
    return self.dispatch(request, *args, **kwargs)
  File "/usr/local/lib/python2.7/dist-packages/django/utils/decorators.py", line 29, in _wrapper
    return bound_func(*args, **kwargs)
  File "/usr/local/lib/python2.7/dist-packages/django/contrib/auth/decorators.py", line 22, in _wrapped_view
    return view_func(request, *args, **kwargs)
  File "/usr/local/lib/python2.7/dist-packages/django/utils/decorators.py", line 25, in bound_func
    return func(self, *args2, **kwargs2)
  File "/home/mikhail/EclipseWorkspace/oncoFinder2/oncoFinder2/core/xpn_views.py", line 26, in dispatch
    return super(XpnForm, self).dispatch(request, *args, **kwargs)
  File "/usr/local/lib/python2.7/dist-packages/django/views/generic/base.py", line 87, in dispatch
    return handler(request, *args, **kwargs)
  File "/usr/local/lib/python2.7/dist-packages/django/views/generic/edit.py", line 171, in post
    return self.form_valid(form)
  File "/home/mikhail/EclipseWorkspace/oncoFinder2/oncoFinder2/core/xpn_views.py", line 68, in form_valid
    R_output = conor.xpn(Rdf_pl1, Rdf_pl2, p1_names=int(p1_names), p2_names=int(p2_names))
  File "/usr/local/lib/python2.7/dist-packages/rpy2/robjects/functions.py", line 170, in __call__
    return super(SignatureTranslatedFunction, self).__call__(*args, **kwargs)
  File "/usr/local/lib/python2.7/dist-packages/rpy2/robjects/functions.py", line 100, in __call__
    res = super(Function, self).__call__(*new_args, **new_kwargs)
RRuntimeError: Error in `row.names<-.data.frame`(`*tmp*`, value = value) : 
  duplicate 'row.names' are not allowed

2015-03-17 15:05:01,233 ERROR base 17875 -1251480768 Internal Server Error: /xpn/
Traceback (most recent call last):
  File "/usr/local/lib/python2.7/dist-packages/django/core/handlers/base.py", line 114, in get_response
    response = wrapped_callback(request, *callback_args, **callback_kwargs)
  File "/usr/local/lib/python2.7/dist-packages/django/views/generic/base.py", line 69, in view
    return self.dispatch(request, *args, **kwargs)
  File "/usr/local/lib/python2.7/dist-packages/django/utils/decorators.py", line 29, in _wrapper
    return bound_func(*args, **kwargs)
  File "/usr/local/lib/python2.7/dist-packages/django/contrib/auth/decorators.py", line 22, in _wrapped_view
    return view_func(request, *args, **kwargs)
  File "/usr/local/lib/python2.7/dist-packages/django/utils/decorators.py", line 25, in bound_func
    return func(self, *args2, **kwargs2)
  File "/home/mikhail/EclipseWorkspace/oncoFinder2/oncoFinder2/core/xpn_views.py", line 26, in dispatch
    return super(XpnForm, self).dispatch(request, *args, **kwargs)
  File "/usr/local/lib/python2.7/dist-packages/django/views/generic/base.py", line 87, in dispatch
    return handler(request, *args, **kwargs)
  File "/usr/local/lib/python2.7/dist-packages/django/views/generic/edit.py", line 171, in post
    return self.form_valid(form)
  File "/home/mikhail/EclipseWorkspace/oncoFinder2/oncoFinder2/core/xpn_views.py", line 68, in form_valid
    R_output = conor.xpn(Rdf_pl1, Rdf_pl2, p1_names=1, p2_names=1, iterations=10)
  File "/usr/local/lib/python2.7/dist-packages/rpy2/robjects/functions.py", line 170, in __call__
    return super(SignatureTranslatedFunction, self).__call__(*args, **kwargs)
  File "/usr/local/lib/python2.7/dist-packages/rpy2/robjects/functions.py", line 100, in __call__
    res = super(Function, self).__call__(*new_args, **new_kwargs)
RRuntimeError: Error in `row.names<-.data.frame`(`*tmp*`, value = value) : 
  duplicate 'row.names' are not allowed

2015-03-17 15:05:52,798 ERROR base 18216 -1251480768 Internal Server Error: /xpn/
Traceback (most recent call last):
  File "/usr/local/lib/python2.7/dist-packages/django/core/handlers/base.py", line 114, in get_response
    response = wrapped_callback(request, *callback_args, **callback_kwargs)
  File "/usr/local/lib/python2.7/dist-packages/django/views/generic/base.py", line 69, in view
    return self.dispatch(request, *args, **kwargs)
  File "/usr/local/lib/python2.7/dist-packages/django/utils/decorators.py", line 29, in _wrapper
    return bound_func(*args, **kwargs)
  File "/usr/local/lib/python2.7/dist-packages/django/contrib/auth/decorators.py", line 22, in _wrapped_view
    return view_func(request, *args, **kwargs)
  File "/usr/local/lib/python2.7/dist-packages/django/utils/decorators.py", line 25, in bound_func
    return func(self, *args2, **kwargs2)
  File "/home/mikhail/EclipseWorkspace/oncoFinder2/oncoFinder2/core/xpn_views.py", line 26, in dispatch
    return super(XpnForm, self).dispatch(request, *args, **kwargs)
  File "/usr/local/lib/python2.7/dist-packages/django/views/generic/base.py", line 87, in dispatch
    return handler(request, *args, **kwargs)
  File "/usr/local/lib/python2.7/dist-packages/django/views/generic/edit.py", line 171, in post
    return self.form_valid(form)
  File "/home/mikhail/EclipseWorkspace/oncoFinder2/oncoFinder2/core/xpn_views.py", line 71, in form_valid
    py_output = com.convert_robj(R_output)
UnboundLocalError: local variable 'R_output' referenced before assignment
2015-03-17 15:06:11,931 ERROR base 18216 -1498416320 Internal Server Error: /xpn/
Traceback (most recent call last):
  File "/usr/local/lib/python2.7/dist-packages/django/core/handlers/base.py", line 114, in get_response
    response = wrapped_callback(request, *callback_args, **callback_kwargs)
  File "/usr/local/lib/python2.7/dist-packages/django/views/generic/base.py", line 69, in view
    return self.dispatch(request, *args, **kwargs)
  File "/usr/local/lib/python2.7/dist-packages/django/utils/decorators.py", line 29, in _wrapper
    return bound_func(*args, **kwargs)
  File "/usr/local/lib/python2.7/dist-packages/django/contrib/auth/decorators.py", line 22, in _wrapped_view
    return view_func(request, *args, **kwargs)
  File "/usr/local/lib/python2.7/dist-packages/django/utils/decorators.py", line 25, in bound_func
    return func(self, *args2, **kwargs2)
  File "/home/mikhail/EclipseWorkspace/oncoFinder2/oncoFinder2/core/xpn_views.py", line 26, in dispatch
    return super(XpnForm, self).dispatch(request, *args, **kwargs)
  File "/usr/local/lib/python2.7/dist-packages/django/views/generic/base.py", line 87, in dispatch
    return handler(request, *args, **kwargs)
  File "/usr/local/lib/python2.7/dist-packages/django/views/generic/edit.py", line 171, in post
    return self.form_valid(form)
  File "/home/mikhail/EclipseWorkspace/oncoFinder2/oncoFinder2/core/xpn_views.py", line 71, in form_valid
    py_output = com.convert_robj(R_output)
UnboundLocalError: local variable 'R_output' referenced before assignment
2015-03-17 15:07:01,510 ERROR base 18692 -1250432192 Internal Server Error: /xpn/
Traceback (most recent call last):
  File "/usr/local/lib/python2.7/dist-packages/django/core/handlers/base.py", line 114, in get_response
    response = wrapped_callback(request, *callback_args, **callback_kwargs)
  File "/usr/local/lib/python2.7/dist-packages/django/views/generic/base.py", line 69, in view
    return self.dispatch(request, *args, **kwargs)
  File "/usr/local/lib/python2.7/dist-packages/django/utils/decorators.py", line 29, in _wrapper
    return bound_func(*args, **kwargs)
  File "/usr/local/lib/python2.7/dist-packages/django/contrib/auth/decorators.py", line 22, in _wrapped_view
    return view_func(request, *args, **kwargs)
  File "/usr/local/lib/python2.7/dist-packages/django/utils/decorators.py", line 25, in bound_func
    return func(self, *args2, **kwargs2)
  File "/home/mikhail/EclipseWorkspace/oncoFinder2/oncoFinder2/core/xpn_views.py", line 26, in dispatch
    return super(XpnForm, self).dispatch(request, *args, **kwargs)
  File "/usr/local/lib/python2.7/dist-packages/django/views/generic/base.py", line 87, in dispatch
    return handler(request, *args, **kwargs)
  File "/usr/local/lib/python2.7/dist-packages/django/views/generic/edit.py", line 171, in post
    return self.form_valid(form)
  File "/home/mikhail/EclipseWorkspace/oncoFinder2/oncoFinder2/core/xpn_views.py", line 71, in form_valid
    R_output = conor.xpn(Rdf_pl1, Rdf_pl2, p1_names=1, p2_names=1, iterations=10)
  File "/usr/local/lib/python2.7/dist-packages/rpy2/robjects/functions.py", line 170, in __call__
    return super(SignatureTranslatedFunction, self).__call__(*args, **kwargs)
  File "/usr/local/lib/python2.7/dist-packages/rpy2/robjects/functions.py", line 100, in __call__
    res = super(Function, self).__call__(*new_args, **new_kwargs)
RRuntimeError: Error in `row.names<-.data.frame`(`*tmp*`, value = value) : 
  duplicate 'row.names' are not allowed

2015-03-17 15:12:17,681 ERROR base 20844 -1251480768 Internal Server Error: /xpn/
Traceback (most recent call last):
  File "/usr/local/lib/python2.7/dist-packages/django/core/handlers/base.py", line 114, in get_response
    response = wrapped_callback(request, *callback_args, **callback_kwargs)
  File "/usr/local/lib/python2.7/dist-packages/django/views/generic/base.py", line 69, in view
    return self.dispatch(request, *args, **kwargs)
  File "/usr/local/lib/python2.7/dist-packages/django/utils/decorators.py", line 29, in _wrapper
    return bound_func(*args, **kwargs)
  File "/usr/local/lib/python2.7/dist-packages/django/contrib/auth/decorators.py", line 22, in _wrapped_view
    return view_func(request, *args, **kwargs)
  File "/usr/local/lib/python2.7/dist-packages/django/utils/decorators.py", line 25, in bound_func
    return func(self, *args2, **kwargs2)
  File "/home/mikhail/EclipseWorkspace/oncoFinder2/oncoFinder2/core/xpn_views.py", line 26, in dispatch
    return super(XpnForm, self).dispatch(request, *args, **kwargs)
  File "/usr/local/lib/python2.7/dist-packages/django/views/generic/base.py", line 87, in dispatch
    return handler(request, *args, **kwargs)
  File "/usr/local/lib/python2.7/dist-packages/django/views/generic/edit.py", line 171, in post
    return self.form_valid(form)
  File "/home/mikhail/EclipseWorkspace/oncoFinder2/oncoFinder2/core/xpn_views.py", line 60, in form_valid
    df_pl1 = np.log(df_pl1).fillna(0)
AttributeError: log
2015-03-17 16:22:40,496 ERROR base 15142 -1260389568 Internal Server Error: /xpn/
Traceback (most recent call last):
  File "/usr/local/lib/python2.7/dist-packages/django/core/handlers/base.py", line 114, in get_response
    response = wrapped_callback(request, *callback_args, **callback_kwargs)
  File "/usr/local/lib/python2.7/dist-packages/django/views/generic/base.py", line 69, in view
    return self.dispatch(request, *args, **kwargs)
  File "/usr/local/lib/python2.7/dist-packages/django/utils/decorators.py", line 29, in _wrapper
    return bound_func(*args, **kwargs)
  File "/usr/local/lib/python2.7/dist-packages/django/contrib/auth/decorators.py", line 22, in _wrapped_view
    return view_func(request, *args, **kwargs)
  File "/usr/local/lib/python2.7/dist-packages/django/utils/decorators.py", line 25, in bound_func
    return func(self, *args2, **kwargs2)
  File "/home/mikhail/EclipseWorkspace/oncoFinder2/oncoFinder2/core/xpn_views.py", line 28, in dispatch
    return super(XpnForm, self).dispatch(request, *args, **kwargs)
  File "/usr/local/lib/python2.7/dist-packages/django/views/generic/base.py", line 87, in dispatch
    return handler(request, *args, **kwargs)
  File "/usr/local/lib/python2.7/dist-packages/django/views/generic/edit.py", line 171, in post
    return self.form_valid(form)
  File "/home/mikhail/EclipseWorkspace/oncoFinder2/oncoFinder2/core/xpn_views.py", line 92, in form_valid
    return HttpResponseRedirect(reverse(self.get_success_url(), kwargs={'f': filename}))
  File "/usr/local/lib/python2.7/dist-packages/django/core/urlresolvers.py", line 509, in reverse
    return iri_to_uri(resolver._reverse_with_prefix(view, prefix, *args, **kwargs))
  File "/usr/local/lib/python2.7/dist-packages/django/core/urlresolvers.py", line 429, in _reverse_with_prefix
    (lookup_view_s, args, kwargs, len(patterns), patterns))
NoReverseMatch: Reverse for '/thanks/' with arguments '()' and keyword arguments '{'f': u'canada_GSE49972_normalized.txtrussia_GSE49972_normalized.txt.csv'}' not found. 0 pattern(s) tried: []
2015-03-17 16:29:51,135 ERROR base 16996 -1251480768 Internal Server Error: /xpn/
Traceback (most recent call last):
  File "/usr/local/lib/python2.7/dist-packages/django/core/handlers/base.py", line 114, in get_response
    response = wrapped_callback(request, *callback_args, **callback_kwargs)
  File "/usr/local/lib/python2.7/dist-packages/django/views/generic/base.py", line 69, in view
    return self.dispatch(request, *args, **kwargs)
  File "/usr/local/lib/python2.7/dist-packages/django/utils/decorators.py", line 29, in _wrapper
    return bound_func(*args, **kwargs)
  File "/usr/local/lib/python2.7/dist-packages/django/contrib/auth/decorators.py", line 22, in _wrapped_view
    return view_func(request, *args, **kwargs)
  File "/usr/local/lib/python2.7/dist-packages/django/utils/decorators.py", line 25, in bound_func
    return func(self, *args2, **kwargs2)
  File "/home/mikhail/EclipseWorkspace/oncoFinder2/oncoFinder2/core/xpn_views.py", line 29, in dispatch
    return super(XpnForm, self).dispatch(request, *args, **kwargs)
  File "/usr/local/lib/python2.7/dist-packages/django/views/generic/base.py", line 87, in dispatch
    return handler(request, *args, **kwargs)
  File "/usr/local/lib/python2.7/dist-packages/django/views/generic/edit.py", line 171, in post
    return self.form_valid(form)
  File "/home/mikhail/EclipseWorkspace/oncoFinder2/oncoFinder2/core/xpn_views.py", line 93, in form_valid
    return HttpResponseRedirect(reverse('xpn_done', args=[filename]))
  File "/usr/local/lib/python2.7/dist-packages/django/core/urlresolvers.py", line 509, in reverse
    return iri_to_uri(resolver._reverse_with_prefix(view, prefix, *args, **kwargs))
  File "/usr/local/lib/python2.7/dist-packages/django/core/urlresolvers.py", line 429, in _reverse_with_prefix
    (lookup_view_s, args, kwargs, len(patterns), patterns))
NoReverseMatch: Reverse for 'xpn_done' with arguments '(u'canada_GSE49972_normalized.txtrussia_GSE49972_normalized.txt.csv',)' and keyword arguments '{}' not found. 1 pattern(s) tried: ['xpn/done/(?P<filename>\\d+)$']
2015-03-17 16:31:06,137 ERROR base 18504 -1251480768 Internal Server Error: /xpn/
Traceback (most recent call last):
  File "/usr/local/lib/python2.7/dist-packages/django/core/handlers/base.py", line 114, in get_response
    response = wrapped_callback(request, *callback_args, **callback_kwargs)
  File "/usr/local/lib/python2.7/dist-packages/django/views/generic/base.py", line 69, in view
    return self.dispatch(request, *args, **kwargs)
  File "/usr/local/lib/python2.7/dist-packages/django/utils/decorators.py", line 29, in _wrapper
    return bound_func(*args, **kwargs)
  File "/usr/local/lib/python2.7/dist-packages/django/contrib/auth/decorators.py", line 22, in _wrapped_view
    return view_func(request, *args, **kwargs)
  File "/usr/local/lib/python2.7/dist-packages/django/utils/decorators.py", line 25, in bound_func
    return func(self, *args2, **kwargs2)
  File "/home/mikhail/EclipseWorkspace/oncoFinder2/oncoFinder2/core/xpn_views.py", line 29, in dispatch
    return super(XpnForm, self).dispatch(request, *args, **kwargs)
  File "/usr/local/lib/python2.7/dist-packages/django/views/generic/base.py", line 87, in dispatch
    return handler(request, *args, **kwargs)
  File "/usr/local/lib/python2.7/dist-packages/django/views/generic/edit.py", line 171, in post
    return self.form_valid(form)
  File "/home/mikhail/EclipseWorkspace/oncoFinder2/oncoFinder2/core/xpn_views.py", line 93, in form_valid
    return HttpResponseRedirect(reverse('xpn_done', args=[filename]))
  File "/usr/local/lib/python2.7/dist-packages/django/core/urlresolvers.py", line 509, in reverse
    return iri_to_uri(resolver._reverse_with_prefix(view, prefix, *args, **kwargs))
  File "/usr/local/lib/python2.7/dist-packages/django/core/urlresolvers.py", line 429, in _reverse_with_prefix
    (lookup_view_s, args, kwargs, len(patterns), patterns))
NoReverseMatch: Reverse for 'xpn_done' with arguments '(u'canada_GSE49972_normalized.txtrussia_GSE49972_normalized.txt.csv',)' and keyword arguments '{}' not found. 1 pattern(s) tried: ['xpn/done/(?P<filename>\\d+)/$']
2015-03-17 16:32:14,367 ERROR base 18768 -1251480768 Internal Server Error: /xpn/
Traceback (most recent call last):
  File "/usr/local/lib/python2.7/dist-packages/django/core/handlers/base.py", line 114, in get_response
    response = wrapped_callback(request, *callback_args, **callback_kwargs)
  File "/usr/local/lib/python2.7/dist-packages/django/views/generic/base.py", line 69, in view
    return self.dispatch(request, *args, **kwargs)
  File "/usr/local/lib/python2.7/dist-packages/django/utils/decorators.py", line 29, in _wrapper
    return bound_func(*args, **kwargs)
  File "/usr/local/lib/python2.7/dist-packages/django/contrib/auth/decorators.py", line 22, in _wrapped_view
    return view_func(request, *args, **kwargs)
  File "/usr/local/lib/python2.7/dist-packages/django/utils/decorators.py", line 25, in bound_func
    return func(self, *args2, **kwargs2)
  File "/home/mikhail/EclipseWorkspace/oncoFinder2/oncoFinder2/core/xpn_views.py", line 29, in dispatch
    return super(XpnForm, self).dispatch(request, *args, **kwargs)
  File "/usr/local/lib/python2.7/dist-packages/django/views/generic/base.py", line 87, in dispatch
    return handler(request, *args, **kwargs)
  File "/usr/local/lib/python2.7/dist-packages/django/views/generic/edit.py", line 171, in post
    return self.form_valid(form)
  File "/home/mikhail/EclipseWorkspace/oncoFinder2/oncoFinder2/core/xpn_views.py", line 93, in form_valid
    return HttpResponseRedirect(reverse('xpn_done', args=[filename]))
  File "/usr/local/lib/python2.7/dist-packages/django/core/urlresolvers.py", line 509, in reverse
    return iri_to_uri(resolver._reverse_with_prefix(view, prefix, *args, **kwargs))
  File "/usr/local/lib/python2.7/dist-packages/django/core/urlresolvers.py", line 429, in _reverse_with_prefix
    (lookup_view_s, args, kwargs, len(patterns), patterns))
NoReverseMatch: Reverse for 'xpn_done' with arguments '(u'canada_GSE49972_normalized.txtrussia_GSE49972_normalized.txt.csv',)' and keyword arguments '{}' not found. 1 pattern(s) tried: ['xpn/done/(?P<filename>\\[-\\w]+)/$']
2015-03-17 16:33:54,382 ERROR base 19626 -1250432192 Internal Server Error: /xpn/
Traceback (most recent call last):
  File "/usr/local/lib/python2.7/dist-packages/django/core/handlers/base.py", line 114, in get_response
    response = wrapped_callback(request, *callback_args, **callback_kwargs)
  File "/usr/local/lib/python2.7/dist-packages/django/views/generic/base.py", line 69, in view
    return self.dispatch(request, *args, **kwargs)
  File "/usr/local/lib/python2.7/dist-packages/django/utils/decorators.py", line 29, in _wrapper
    return bound_func(*args, **kwargs)
  File "/usr/local/lib/python2.7/dist-packages/django/contrib/auth/decorators.py", line 22, in _wrapped_view
    return view_func(request, *args, **kwargs)
  File "/usr/local/lib/python2.7/dist-packages/django/utils/decorators.py", line 25, in bound_func
    return func(self, *args2, **kwargs2)
  File "/home/mikhail/EclipseWorkspace/oncoFinder2/oncoFinder2/core/xpn_views.py", line 29, in dispatch
    return super(XpnForm, self).dispatch(request, *args, **kwargs)
  File "/usr/local/lib/python2.7/dist-packages/django/views/generic/base.py", line 87, in dispatch
    return handler(request, *args, **kwargs)
  File "/usr/local/lib/python2.7/dist-packages/django/views/generic/edit.py", line 171, in post
    return self.form_valid(form)
  File "/home/mikhail/EclipseWorkspace/oncoFinder2/oncoFinder2/core/xpn_views.py", line 93, in form_valid
    return HttpResponseRedirect(reverse('xpn_done', kwargs={'filename': filename}))
  File "/usr/local/lib/python2.7/dist-packages/django/core/urlresolvers.py", line 509, in reverse
    return iri_to_uri(resolver._reverse_with_prefix(view, prefix, *args, **kwargs))
  File "/usr/local/lib/python2.7/dist-packages/django/core/urlresolvers.py", line 429, in _reverse_with_prefix
    (lookup_view_s, args, kwargs, len(patterns), patterns))
NoReverseMatch: Reverse for 'xpn_done' with arguments '()' and keyword arguments '{'filename': u'canada_GSE49972_normalized.txtrussia_GSE49972_normalized.txt.csv'}' not found. 1 pattern(s) tried: ['xpn/done/(?P<filename>\\[-\\w]+)/$']
2015-03-17 16:37:28,423 ERROR base 20905 -1251480768 Internal Server Error: /xpn/
Traceback (most recent call last):
  File "/usr/local/lib/python2.7/dist-packages/django/core/handlers/base.py", line 114, in get_response
    response = wrapped_callback(request, *callback_args, **callback_kwargs)
  File "/usr/local/lib/python2.7/dist-packages/django/views/generic/base.py", line 69, in view
    return self.dispatch(request, *args, **kwargs)
  File "/usr/local/lib/python2.7/dist-packages/django/utils/decorators.py", line 29, in _wrapper
    return bound_func(*args, **kwargs)
  File "/usr/local/lib/python2.7/dist-packages/django/contrib/auth/decorators.py", line 22, in _wrapped_view
    return view_func(request, *args, **kwargs)
  File "/usr/local/lib/python2.7/dist-packages/django/utils/decorators.py", line 25, in bound_func
    return func(self, *args2, **kwargs2)
  File "/home/mikhail/EclipseWorkspace/oncoFinder2/oncoFinder2/core/xpn_views.py", line 29, in dispatch
    return super(XpnForm, self).dispatch(request, *args, **kwargs)
  File "/usr/local/lib/python2.7/dist-packages/django/views/generic/base.py", line 87, in dispatch
    return handler(request, *args, **kwargs)
  File "/usr/local/lib/python2.7/dist-packages/django/views/generic/edit.py", line 171, in post
    return self.form_valid(form)
  File "/home/mikhail/EclipseWorkspace/oncoFinder2/oncoFinder2/core/xpn_views.py", line 93, in form_valid
    return HttpResponseRedirect(reverse('xpn_done', kwargs={'filename': filename}))
  File "/usr/local/lib/python2.7/dist-packages/django/core/urlresolvers.py", line 509, in reverse
    return iri_to_uri(resolver._reverse_with_prefix(view, prefix, *args, **kwargs))
  File "/usr/local/lib/python2.7/dist-packages/django/core/urlresolvers.py", line 429, in _reverse_with_prefix
    (lookup_view_s, args, kwargs, len(patterns), patterns))
NoReverseMatch: Reverse for 'xpn_done' with arguments '()' and keyword arguments '{'filename': u'canada_GSE49972_normalized.txtrussia_GSE49972_normalized.txt.csv'}' not found. 1 pattern(s) tried: ['xpn/done/$']
2015-03-17 16:40:18,288 ERROR base 21823 -1250432192 Internal Server Error: /xpn/
Traceback (most recent call last):
  File "/usr/local/lib/python2.7/dist-packages/django/core/handlers/base.py", line 114, in get_response
    response = wrapped_callback(request, *callback_args, **callback_kwargs)
  File "/usr/local/lib/python2.7/dist-packages/django/views/generic/base.py", line 69, in view
    return self.dispatch(request, *args, **kwargs)
  File "/usr/local/lib/python2.7/dist-packages/django/utils/decorators.py", line 29, in _wrapper
    return bound_func(*args, **kwargs)
  File "/usr/local/lib/python2.7/dist-packages/django/contrib/auth/decorators.py", line 22, in _wrapped_view
    return view_func(request, *args, **kwargs)
  File "/usr/local/lib/python2.7/dist-packages/django/utils/decorators.py", line 25, in bound_func
    return func(self, *args2, **kwargs2)
  File "/home/mikhail/EclipseWorkspace/oncoFinder2/oncoFinder2/core/xpn_views.py", line 29, in dispatch
    return super(XpnForm, self).dispatch(request, *args, **kwargs)
  File "/usr/local/lib/python2.7/dist-packages/django/views/generic/base.py", line 87, in dispatch
    return handler(request, *args, **kwargs)
  File "/usr/local/lib/python2.7/dist-packages/django/views/generic/edit.py", line 171, in post
    return self.form_valid(form)
  File "/home/mikhail/EclipseWorkspace/oncoFinder2/oncoFinder2/core/xpn_views.py", line 93, in form_valid
    return HttpResponseRedirect(reverse('xpn_done', args=[filename]))
  File "/usr/local/lib/python2.7/dist-packages/django/core/urlresolvers.py", line 509, in reverse
    return iri_to_uri(resolver._reverse_with_prefix(view, prefix, *args, **kwargs))
  File "/usr/local/lib/python2.7/dist-packages/django/core/urlresolvers.py", line 429, in _reverse_with_prefix
    (lookup_view_s, args, kwargs, len(patterns), patterns))
NoReverseMatch: Reverse for 'xpn_done' with arguments '(u'canada_GSE49972_normalized.txtrussia_GSE49972_normalized.txt.csv',)' and keyword arguments '{}' not found. 1 pattern(s) tried: ['xpn/done/([-\\w]+)/$']
2015-03-17 16:43:39,338 ERROR base 23175 -1251480768 Internal Server Error: /xpn/
Traceback (most recent call last):
  File "/usr/local/lib/python2.7/dist-packages/django/core/handlers/base.py", line 114, in get_response
    response = wrapped_callback(request, *callback_args, **callback_kwargs)
  File "/usr/local/lib/python2.7/dist-packages/django/views/generic/base.py", line 69, in view
    return self.dispatch(request, *args, **kwargs)
  File "/usr/local/lib/python2.7/dist-packages/django/utils/decorators.py", line 29, in _wrapper
    return bound_func(*args, **kwargs)
  File "/usr/local/lib/python2.7/dist-packages/django/contrib/auth/decorators.py", line 22, in _wrapped_view
    return view_func(request, *args, **kwargs)
  File "/usr/local/lib/python2.7/dist-packages/django/utils/decorators.py", line 25, in bound_func
    return func(self, *args2, **kwargs2)
  File "/home/mikhail/EclipseWorkspace/oncoFinder2/oncoFinder2/core/xpn_views.py", line 29, in dispatch
    return super(XpnForm, self).dispatch(request, *args, **kwargs)
  File "/usr/local/lib/python2.7/dist-packages/django/views/generic/base.py", line 87, in dispatch
    return handler(request, *args, **kwargs)
  File "/usr/local/lib/python2.7/dist-packages/django/views/generic/edit.py", line 171, in post
    return self.form_valid(form)
  File "/home/mikhail/EclipseWorkspace/oncoFinder2/oncoFinder2/core/xpn_views.py", line 93, in form_valid
    return HttpResponseRedirect(reverse('xpn_done', args=[filename]))
  File "/usr/local/lib/python2.7/dist-packages/django/core/urlresolvers.py", line 509, in reverse
    return iri_to_uri(resolver._reverse_with_prefix(view, prefix, *args, **kwargs))
  File "/usr/local/lib/python2.7/dist-packages/django/core/urlresolvers.py", line 429, in _reverse_with_prefix
    (lookup_view_s, args, kwargs, len(patterns), patterns))
NoReverseMatch: Reverse for 'xpn_done' with arguments '(u'canada_GSE49972_normalized.txtrussia_GSE49972_normalized.txt.csv',)' and keyword arguments '{}' not found. 1 pattern(s) tried: ['xpn/done/(?P<filename>\\.*)/$']
2015-03-17 16:45:15,703 ERROR base 23880 -1250432192 Internal Server Error: /xpn/
Traceback (most recent call last):
  File "/usr/local/lib/python2.7/dist-packages/django/core/handlers/base.py", line 114, in get_response
    response = wrapped_callback(request, *callback_args, **callback_kwargs)
  File "/usr/local/lib/python2.7/dist-packages/django/views/generic/base.py", line 69, in view
    return self.dispatch(request, *args, **kwargs)
  File "/usr/local/lib/python2.7/dist-packages/django/utils/decorators.py", line 29, in _wrapper
    return bound_func(*args, **kwargs)
  File "/usr/local/lib/python2.7/dist-packages/django/contrib/auth/decorators.py", line 22, in _wrapped_view
    return view_func(request, *args, **kwargs)
  File "/usr/local/lib/python2.7/dist-packages/django/utils/decorators.py", line 25, in bound_func
    return func(self, *args2, **kwargs2)
  File "/home/mikhail/EclipseWorkspace/oncoFinder2/oncoFinder2/core/xpn_views.py", line 29, in dispatch
    return super(XpnForm, self).dispatch(request, *args, **kwargs)
  File "/usr/local/lib/python2.7/dist-packages/django/views/generic/base.py", line 87, in dispatch
    return handler(request, *args, **kwargs)
  File "/usr/local/lib/python2.7/dist-packages/django/views/generic/edit.py", line 171, in post
    return self.form_valid(form)
  File "/home/mikhail/EclipseWorkspace/oncoFinder2/oncoFinder2/core/xpn_views.py", line 93, in form_valid
    return HttpResponseRedirect(reverse('xpn_done', kwargs={'filename': filename}))
  File "/usr/local/lib/python2.7/dist-packages/django/core/urlresolvers.py", line 509, in reverse
    return iri_to_uri(resolver._reverse_with_prefix(view, prefix, *args, **kwargs))
  File "/usr/local/lib/python2.7/dist-packages/django/core/urlresolvers.py", line 429, in _reverse_with_prefix
    (lookup_view_s, args, kwargs, len(patterns), patterns))
NoReverseMatch: Reverse for 'xpn_done' with arguments '()' and keyword arguments '{'filename': u'canada_GSE49972_normalized.txtrussia_GSE49972_normalized.txt.csv'}' not found. 1 pattern(s) tried: ['xpn/done/(?P<filename>\\.*)/$']
2015-03-17 16:49:51,816 ERROR base 25947 -1251480768 Internal Server Error: /xpn/done/canada_GSE49972_normalized.txtrussia_GSE49972_normalized.txt.csv/
Traceback (most recent call last):
  File "/usr/local/lib/python2.7/dist-packages/django/core/handlers/base.py", line 114, in get_response
    response = wrapped_callback(request, *callback_args, **callback_kwargs)
  File "/usr/local/lib/python2.7/dist-packages/django/views/generic/base.py", line 69, in view
    return self.dispatch(request, *args, **kwargs)
  File "/usr/local/lib/python2.7/dist-packages/django/utils/decorators.py", line 29, in _wrapper
    return bound_func(*args, **kwargs)
  File "/usr/local/lib/python2.7/dist-packages/django/contrib/auth/decorators.py", line 22, in _wrapped_view
    return view_func(request, *args, **kwargs)
  File "/usr/local/lib/python2.7/dist-packages/django/utils/decorators.py", line 25, in bound_func
    return func(self, *args2, **kwargs2)
  File "/home/mikhail/EclipseWorkspace/oncoFinder2/oncoFinder2/core/xpn_views.py", line 105, in dispatch
    return super(XpnDone, self).dispatch(request, *args, **kwargs)
  File "/usr/local/lib/python2.7/dist-packages/django/views/generic/base.py", line 87, in dispatch
    return handler(request, *args, **kwargs)
  File "/usr/local/lib/python2.7/dist-packages/django/views/generic/base.py", line 154, in get
    context = self.get_context_data(**kwargs)
  File "/home/mikhail/EclipseWorkspace/oncoFinder2/oncoFinder2/core/xpn_views.py", line 111, in get_context_data
    context['arg'] = self.request.args
AttributeError: 'WSGIRequest' object has no attribute 'args'
